<?xml version="1.0" encoding="utf-8"?>
<robot name="iiwa">
  <link name="world"/>
  <link name="link_1">
    <inertial>
      <origin rpy="0 0 0" xyz="0.0444 0.0044 0.0182"/>
      <mass value="5"/>
      <inertia ixx="-0.0258" ixy="0.0713" ixz="-0.0327" iyy="-0.0777" iyz="0.0691" izz="-0.0652"/>
    </inertial>
  </link>
  <joint name="joint_1" type="revolute">
    <parent link="world"/>
    <child link="link_1"/>
    <origin rpy="0 -1.5707963267948966 1.5707963267948966" xyz="0 0 0.1461"/>
    <axis xyz="0 0 1"/>
    <limit effort="300" lower="-2.09439510239" upper="2.09439510239" velocity="10"/>
    <dynamics damping="0.5"/>
  </joint>
  <link name="link_2">
    <inertial>
      <origin rpy="0 0 0" xyz="0.0651 0.0756 0.0602"/>
      <mass value="5"/>
      <inertia ixx="0.0628" ixy="-0.0427" ixz="0.0454" iyy="0.0209" iyz="0.0867" izz="0.0204"/>
    </inertial>
  </link>
  <joint name="joint_2" type="revolute">
    <parent link="link_1"/>
    <child link="link_2"/>
    <origin rpy="-3.141592653589793 1.5707963267948966 3.141592653589793" xyz="0 0 0.096"/>
    <axis xyz="0 0 1"/>
    <limit effort="300" lower="-2.09439510239" upper="2.09439510239" velocity="10"/>
    <dynamics damping="0.5"/>
  </joint>
  <link name="link_3">
    <inertial>
      <origin rpy="0 0 0" xyz="0.0106 0.0947 0.0016"/>
      <mass value="5"/>
      <inertia ixx="-0.0332" ixy="0.0629" ixz="-0.0561" iyy="-0.0172" iyz="0.0746" izz="0.0478"/>
    </inertial>
  </link>
  <joint name="joint_3" type="revolute">
    <parent link="link_2"/>
    <child link="link_3"/>
    <origin rpy="3.141592653589793 3.141592653589793 -3.141592653589793" xyz="0 0 0.1534"/>
    <axis xyz="0 0 1"/>
    <limit effort="300" lower="-2.09439510239" upper="2.09439510239" velocity="10"/>
    <dynamics damping="0.5"/>
  </joint>
  <link name="link_4">
    <inertial>
      <origin rpy="0 0 0" xyz="0.088 0.0599 0.0042"/>
      <mass value="5"/>
      <inertia ixx="0.0008" ixy="0.0003" ixz="0.0259" iyy="0.0732" iyz="0.0268" izz="0.0634"/>
    </inertial>
  </link>
  <joint name="joint_4" type="revolute">
    <parent link="link_3"/>
    <child link="link_4"/>
    <origin rpy="1.5707963267948966 -1.5707963267948966 0" xyz="0 0 0.1461"/>
    <axis xyz="0 0 1"/>
    <limit effort="300" lower="-2.09439510239" upper="2.09439510239" velocity="10"/>
    <dynamics damping="0.5"/>
  </joint>
  <link name="link_5">
    <inertial>
      <origin rpy="0 0 0" xyz="0.0886 0.0098 0.0599"/>
      <mass value="5"/>
      <inertia ixx="0.0141" ixy="0.0815" ixz="-0.0477" iyy="0.0869" iyz="0.0678" izz="0.0428"/>
    </inertial>
  </link>
  <joint name="joint_5" type="revolute">
    <parent link="link_4"/>
    <child link="link_5"/>
    <origin rpy="-3.141592653589793 1.5707963267948966 3.141592653589793" xyz="0 0 0.0237"/>
    <axis xyz="0 0 1"/>
    <limit effort="300" lower="-2.09439510239" upper="2.09439510239" velocity="10"/>
    <dynamics damping="0.5"/>
  </joint>
  <link name="link_6">
    <inertial>
      <origin rpy="0 0 0" xyz="0.047 0.0119 0.0103"/>
      <mass value="5"/>
      <inertia ixx="-0.0339" ixy="-0.0724" ixz="0.0548" iyy="-0.0257" iyz="-0.0637" izz="-0.0818"/>
    </inertial>
  </link>
  <joint name="joint_6" type="revolute">
    <parent link="link_5"/>
    <child link="link_6"/>
    <origin rpy="1.5707963267948966 0 0" xyz="0 0 0.1254"/>
    <axis xyz="0 0 1"/>
    <limit effort="300" lower="-2.09439510239" upper="2.09439510239" velocity="10"/>
    <dynamics damping="0.5"/>
  </joint>
</robot>
