<?xml version="1.0" encoding="utf-8"?>
<robot name="iiwa">
  <link name="world"/>
  <link name="link_1">
    <inertial>
      <origin rpy="0 0 0" xyz="0.0096 0.0029 0.0677"/>
      <mass value="5"/>
      <inertia ixx="-0.0791" ixy="0.03" ixz="0.0283" iyy="0.0613" iyz="-0.0596" izz="0.0511"/>
    </inertial>
  </link>
  <joint name="joint_1" type="revolute">
    <parent link="world"/>
    <child link="link_1"/>
    <origin rpy="3.141592653589793 -1.5707963267948966 1.5707963267948966" xyz="0 0 0.0208"/>
    <axis xyz="0 0 1"/>
    <limit effort="300" lower="-2.09439510239" upper="2.09439510239" velocity="10"/>
    <dynamics damping="0.5"/>
  </joint>
  <link name="link_2">
    <inertial>
      <origin rpy="0 0 0" xyz="0.0974 0.0305 0.0466"/>
      <mass value="5"/>
      <inertia ixx="0.0251" ixy="-0.05" ixz="-0.0872" iyy="-0.0528" iyz="-0.0903" izz="0.0429"/>
    </inertial>
  </link>
  <joint name="joint_2" type="revolute">
    <parent link="link_1"/>
    <child link="link_2"/>
    <origin rpy="1.5707963267948966 3.141592653589793 -3.141592653589793" xyz="0 0 0.1158"/>
    <axis xyz="0 0 1"/>
    <limit effort="300" lower="-2.09439510239" upper="2.09439510239" velocity="10"/>
    <dynamics damping="0.5"/>
  </joint>
  <link name="link_3">
    <inertial>
      <origin rpy="0 0 0" xyz="0.007 0.0682 0.0302"/>
      <mass value="5"/>
      <inertia ixx="-0.0271" ixy="-0.0578" ixz="-0.0516" iyy="-0.0528" iyz="0.0676" izz="-0.0894"/>
    </inertial>
  </link>
  <joint name="joint_3" type="revolute">
    <parent link="link_2"/>
    <child link="link_3"/>
    <origin rpy="3.141592653589793 1.5707963267948966 -3.141592653589793" xyz="0 0 0.152"/>
    <axis xyz="0 0 1"/>
    <limit effort="300" lower="-2.09439510239" upper="2.09439510239" velocity="10"/>
    <dynamics damping="0.5"/>
  </joint>
  <link name="link_4">
    <inertial>
      <origin rpy="0 0 0" xyz="0.0996 0.0106 0.0994"/>
      <mass value="5"/>
      <inertia ixx="0.0168" ixy="0.003" ixz="0.0907" iyy="0.0829" iyz="-0.0208" izz="-0.097"/>
    </inertial>
  </link>
  <joint name="joint_4" type="revolute">
    <parent link="link_3"/>
    <child link="link_4"/>
    <origin rpy="1.5707963267948966 3.141592653589793 -1.5707963267948966" xyz="0 0 0.1749"/>
    <axis xyz="0 0 1"/>
    <limit effort="300" lower="-2.09439510239" upper="2.09439510239" velocity="10"/>
    <dynamics damping="0.5"/>
  </joint>
  <link name="link_5">
    <inertial>
      <origin rpy="0 0 0" xyz="0.0275 0.0924 0.0229"/>
      <mass value="5"/>
      <inertia ixx="0.0751" ixy="0.0626" ixz="-0.0934" iyy="-0.0461" iyz="0.076" izz="0.0833"/>
    </inertial>
  </link>
  <joint name="joint_5" type="revolute">
    <parent link="link_4"/>
    <child link="link_5"/>
    <origin rpy="-3.141592653589793 -1.5707963267948966 -3.141592653589793" xyz="0 0 0.1178"/>
    <axis xyz="0 0 1"/>
    <limit effort="300" lower="-2.09439510239" upper="2.09439510239" velocity="10"/>
    <dynamics damping="0.5"/>
  </joint>
  <link name="link_6">
    <inertial>
      <origin rpy="0 0 0" xyz="0.0318 0.0983 0.0222"/>
      <mass value="5"/>
      <inertia ixx="0.0548" ixy="0.0111" ixz="0.039" iyy="-0.0416" iyz="-0.0553" izz="-0.0723"/>
    </inertial>
  </link>
  <joint name="joint_6" type="revolute">
    <parent link="link_5"/>
    <child link="link_6"/>
    <origin rpy="-1.5707963267948966 3.141592653589793 -3.141592653589793" xyz="0 0 0.1975"/>
    <axis xyz="0 0 1"/>
    <limit effort="300" lower="-2.09439510239" upper="2.09439510239" velocity="10"/>
    <dynamics damping="0.5"/>
  </joint>
  <link name="link_7">
    <inertial>
      <origin rpy="0 0 0" xyz="0.0058 0.0305 0.011"/>
      <mass value="5"/>
      <inertia ixx="0.0433" ixy="-0.0305" ixz="0.0778" iyy="-0.0868" iyz="0.078" izz="-0.0321"/>
    </inertial>
  </link>
  <joint name="joint_7" type="revolute">
    <parent link="link_6"/>
    <child link="link_7"/>
    <origin rpy="3.141592653589793 0 0" xyz="0 0 0.1151"/>
    <axis xyz="0 0 1"/>
    <limit effort="300" lower="-2.09439510239" upper="2.09439510239" velocity="10"/>
    <dynamics damping="0.5"/>
  </joint>
  <link name="link_8">
    <inertial>
      <origin rpy="0 0 0" xyz="0.0665 0.0299 0.0837"/>
      <mass value="5"/>
      <inertia ixx="-0.0643" ixy="0.0233" ixz="-0.0168" iyy="0.0952" iyz="0.0166" izz="-0.0128"/>
    </inertial>
  </link>
  <joint name="joint_8" type="revolute">
    <parent link="link_7"/>
    <child link="link_8"/>
    <origin rpy="-3.141592653589793 -1.5707963267948966 -3.141592653589793" xyz="0 0 0.0022"/>
    <axis xyz="0 0 1"/>
    <limit effort="300" lower="-2.09439510239" upper="2.09439510239" velocity="10"/>
    <dynamics damping="0.5"/>
  </joint>
</robot>
