<?xml version="1.0" encoding="utf-8"?>
<robot name="iiwa">
  <link name="world"/>
  <link name="link_1">
    <inertial>
      <origin rpy="0 0 0" xyz="0.0053 0.0792 0.0746"/>
      <mass value="5"/>
      <inertia ixx="0.0965" ixy="0.0725" ixz="-0.0154" iyy="0.0831" iyz="0.0099" izz="0.0989"/>
    </inertial>
  </link>
  <joint name="joint_1" type="revolute">
    <parent link="world"/>
    <child link="link_1"/>
    <origin rpy="-3.141592653589793 0 -3.141592653589793" xyz="0 0 0.0394"/>
    <axis xyz="0 0 1"/>
    <limit effort="300" lower="-2.09439510239" upper="2.09439510239" velocity="10"/>
    <dynamics damping="0.5"/>
  </joint>
  <link name="link_2">
    <inertial>
      <origin rpy="0 0 0" xyz="0.0574 0.0678 0.0856"/>
      <mass value="5"/>
      <inertia ixx="-0.0097" ixy="-0.0807" ixz="0.016" iyy="-0.0146" iyz="0.0555" izz="-0.0876"/>
    </inertial>
  </link>
  <joint name="joint_2" type="revolute">
    <parent link="link_1"/>
    <child link="link_2"/>
    <origin rpy="0 0 0" xyz="0 0 0.183"/>
    <axis xyz="0 0 1"/>
    <limit effort="300" lower="-2.09439510239" upper="2.09439510239" velocity="10"/>
    <dynamics damping="0.5"/>
  </joint>
  <link name="link_3">
    <inertial>
      <origin rpy="0 0 0" xyz="0.0708 0.0392 0.0957"/>
      <mass value="5"/>
      <inertia ixx="0.058" ixy="-0.0325" ixz="-0.0231" iyy="0.0471" iyz="-0.0492" izz="0.0753"/>
    </inertial>
  </link>
  <joint name="joint_3" type="revolute">
    <parent link="link_2"/>
    <child link="link_3"/>
    <origin rpy="-3.141592653589793 3.141592653589793 3.141592653589793" xyz="0 0 0.0077"/>
    <axis xyz="0 0 1"/>
    <limit effort="300" lower="-2.09439510239" upper="2.09439510239" velocity="10"/>
    <dynamics damping="0.5"/>
  </joint>
  <link name="link_4">
    <inertial>
      <origin rpy="0 0 0" xyz="0.0054 0.0493 0.0711"/>
      <mass value="5"/>
      <inertia ixx="0.0748" ixy="0.0993" ixz="0.0005" iyy="0.0052" iyz="0.0634" izz="0.0817"/>
    </inertial>
  </link>
  <joint name="joint_4" type="revolute">
    <parent link="link_3"/>
    <child link="link_4"/>
    <origin rpy="1.5707963267948966 3.141592653589793 -3.141592653589793" xyz="0 0 0.1601"/>
    <axis xyz="0 0 1"/>
    <limit effort="300" lower="-2.09439510239" upper="2.09439510239" velocity="10"/>
    <dynamics damping="0.5"/>
  </joint>
  <link name="link_5">
    <inertial>
      <origin rpy="0 0 0" xyz="0.0637 0.0432 0.0689"/>
      <mass value="5"/>
      <inertia ixx="-0.0691" ixy="-0.0248" ixz="0.0722" iyy="-0.0039" iyz="0.0548" izz="-0.0079"/>
    </inertial>
  </link>
  <joint name="joint_5" type="revolute">
    <parent link="link_4"/>
    <child link="link_5"/>
    <origin rpy="1.5707963267948966 -3.141592653589793 1.5707963267948966" xyz="0 0 0.1882"/>
    <axis xyz="0 0 1"/>
    <limit effort="300" lower="-2.09439510239" upper="2.09439510239" velocity="10"/>
    <dynamics damping="0.5"/>
  </joint>
  <link name="link_6">
    <inertial>
      <origin rpy="0 0 0" xyz="0.0174 0.0641 0.0234"/>
      <mass value="5"/>
      <inertia ixx="0.028" ixy="-0.0794" ixz="0.0433" iyy="0.0628" iyz="0.0651" izz="-0.0283"/>
    </inertial>
  </link>
  <joint name="joint_6" type="revolute">
    <parent link="link_5"/>
    <child link="link_6"/>
    <origin rpy="-1.5707963267948966 3.141592653589793 3.141592653589793" xyz="0 0 0.1976"/>
    <axis xyz="0 0 1"/>
    <limit effort="300" lower="-2.09439510239" upper="2.09439510239" velocity="10"/>
    <dynamics damping="0.5"/>
  </joint>
  <link name="link_7">
    <inertial>
      <origin rpy="0 0 0" xyz="0.0198 0.0739 0.0535"/>
      <mass value="5"/>
      <inertia ixx="0.0625" ixy="-0.0352" ixz="-0.001" iyy="0.0907" iyz="0.0751" izz="-0.0724"/>
    </inertial>
  </link>
  <joint name="joint_7" type="revolute">
    <parent link="link_6"/>
    <child link="link_7"/>
    <origin rpy="1.5707963267948966 -3.141592653589793 1.5707963267948966" xyz="0 0 0.057"/>
    <axis xyz="0 0 1"/>
    <limit effort="300" lower="-2.09439510239" upper="2.09439510239" velocity="10"/>
    <dynamics damping="0.5"/>
  </joint>
  <link name="link_8">
    <inertial>
      <origin rpy="0 0 0" xyz="0.0656 0.0351 0.0505"/>
      <mass value="5"/>
      <inertia ixx="-0.0531" ixy="-0.0507" ixz="-0.0754" iyy="-0.0637" iyz="0.0906" izz="-0.0883"/>
    </inertial>
  </link>
  <joint name="joint_8" type="revolute">
    <parent link="link_7"/>
    <child link="link_8"/>
    <origin rpy="1.5707963267948966 0 -3.141592653589793" xyz="0 0 0.1221"/>
    <axis xyz="0 0 1"/>
    <limit effort="300" lower="-2.09439510239" upper="2.09439510239" velocity="10"/>
    <dynamics damping="0.5"/>
  </joint>
  <link name="link_9">
    <inertial>
      <origin rpy="0 0 0" xyz="0.0386 0.0399 0.0961"/>
      <mass value="5"/>
      <inertia ixx="0.0767" ixy="0.0536" ixz="0.0089" iyy="0.0967" iyz="-0.0898" izz="-0.0585"/>
    </inertial>
  </link>
  <joint name="joint_9" type="revolute">
    <parent link="link_8"/>
    <child link="link_9"/>
    <origin rpy="-1.5707963267948966 1.5707963267948966 1.5707963267948966" xyz="0 0 0.0436"/>
    <axis xyz="0 0 1"/>
    <limit effort="300" lower="-2.09439510239" upper="2.09439510239" velocity="10"/>
    <dynamics damping="0.5"/>
  </joint>
</robot>
