<?xml version="1.0" encoding="utf-8"?>
<robot name="iiwa">
  <link name="world"/>
  <link name="link_1">
    <inertial>
      <origin rpy="0 0 0" xyz="0.0434 0.0697 0.0458"/>
      <mass value="5"/>
      <inertia ixx="-0.0459" ixy="0.0073" ixz="0.0687" iyy="0.0022" iyz="-0.0471" izz="0.0123"/>
    </inertial>
  </link>
  <joint name="joint_1" type="revolute">
    <parent link="world"/>
    <child link="link_1"/>
    <origin rpy="3.141592653589793 -1.5707963267948966 -1.5707963267948966" xyz="0 0 0.0661"/>
    <axis xyz="0 0 1"/>
    <limit effort="300" lower="-2.09439510239" upper="2.09439510239" velocity="10"/>
    <dynamics damping="0.5"/>
  </joint>
</robot>
