<?xml version="1.0" encoding="utf-8"?>
<robot name="iiwa">
  <link name="world"/>
  <link name="link_1">
    <inertial>
      <origin rpy="0 0 0" xyz="0.0935 0.0705 0.0324"/>
      <mass value="5"/>
      <inertia ixx="0.056" ixy="-0.0641" ixz="-0.0865" iyy="0.0032" iyz="0.0763" izz="0.0862"/>
    </inertial>
  </link>
  <joint name="joint_1" type="revolute">
    <parent link="world"/>
    <child link="link_1"/>
    <origin rpy="-1.5707963267948966 -3.141592653589793 3.141592653589793" xyz="0 0 0.1916"/>
    <axis xyz="0 0 1"/>
    <limit effort="300" lower="-2.09439510239" upper="2.09439510239" velocity="10"/>
    <dynamics damping="0.5"/>
  </joint>
  <link name="link_2">
    <inertial>
      <origin rpy="0 0 0" xyz="0.0091 0.0525 0.0529"/>
      <mass value="5"/>
      <inertia ixx="0.0008" ixy="-0.0596" ixz="-0.0768" iyy="0.0816" iyz="-0.0287" izz="0.0217"/>
    </inertial>
  </link>
  <joint name="joint_2" type="revolute">
    <parent link="link_1"/>
    <child link="link_2"/>
    <origin rpy="-3.141592653589793 1.5707963267948966 1.5707963267948966" xyz="0 0 0.03"/>
    <axis xyz="0 0 1"/>
    <limit effort="300" lower="-2.09439510239" upper="2.09439510239" velocity="10"/>
    <dynamics damping="0.5"/>
  </joint>
</robot>
