<?xml version="1.0" encoding="utf-8"?>
<robot name="iiwa">
  <link name="world"/>
  <link name="link_1">
    <inertial>
      <origin rpy="0 0 0" xyz="0.0161 0.0451 0.0383"/>
      <mass value="5"/>
      <inertia ixx="0.02" ixy="0.0967" ixz="0.0003" iyy="0.0954" iyz="0.0151" izz="0.0099"/>
    </inertial>
  </link>
  <joint name="joint_1" type="revolute">
    <parent link="world"/>
    <child link="link_1"/>
    <origin rpy="-3.141592653589793 -1.5707963267948966 -3.141592653589793" xyz="0 0 0.1193"/>
    <axis xyz="0 0 1"/>
    <limit effort="300" lower="-2.09439510239" upper="2.09439510239" velocity="10"/>
    <dynamics damping="0.5"/>
  </joint>
  <link name="link_2">
    <inertial>
      <origin rpy="0 0 0" xyz="0.0537 0.0337 0.015"/>
      <mass value="5"/>
      <inertia ixx="-0.0354" ixy="-0.0972" ixz="0.0301" iyy="0.0955" iyz="0.0048" izz="0.0647"/>
    </inertial>
  </link>
  <joint name="joint_2" type="revolute">
    <parent link="link_1"/>
    <child link="link_2"/>
    <origin rpy="-1.5707963267948966 -3.141592653589793 0" xyz="0 0 0.1354"/>
    <axis xyz="0 0 1"/>
    <limit effort="300" lower="-2.09439510239" upper="2.09439510239" velocity="10"/>
    <dynamics damping="0.5"/>
  </joint>
  <link name="link_3">
    <inertial>
      <origin rpy="0 0 0" xyz="0.0924 0.0477 0.0817"/>
      <mass value="5"/>
      <inertia ixx="-0.0498" ixy="-0.0805" ixz="-0.0061" iyy="0.0991" iyz="0.0549" izz="0.066"/>
    </inertial>
  </link>
  <joint name="joint_3" type="revolute">
    <parent link="link_2"/>
    <child link="link_3"/>
    <origin rpy="-1.5707963267948966 -1.5707963267948966 -3.141592653589793" xyz="0 0 0.1805"/>
    <axis xyz="0 0 1"/>
    <limit effort="300" lower="-2.09439510239" upper="2.09439510239" velocity="10"/>
    <dynamics damping="0.5"/>
  </joint>
  <link name="link_4">
    <inertial>
      <origin rpy="0 0 0" xyz="0.0563 0.0575 0.061"/>
      <mass value="5"/>
      <inertia ixx="-0.0486" ixy="0.0262" ixz="0.0559" iyy="-0.0767" iyz="-0.0775" izz="0.0269"/>
    </inertial>
  </link>
  <joint name="joint_4" type="revolute">
    <parent link="link_3"/>
    <child link="link_4"/>
    <origin rpy="1.5707963267948966 -3.141592653589793 0" xyz="0 0 0.0196"/>
    <axis xyz="0 0 1"/>
    <limit effort="300" lower="-2.09439510239" upper="2.09439510239" velocity="10"/>
    <dynamics damping="0.5"/>
  </joint>
  <link name="link_5">
    <inertial>
      <origin rpy="0 0 0" xyz="0.0885 0.0518 0.045"/>
      <mass value="5"/>
      <inertia ixx="0.0055" ixy="-0.0167" ixz="-0.0231" iyy="-0.0571" iyz="0.0303" izz="-0.0198"/>
    </inertial>
  </link>
  <joint name="joint_5" type="revolute">
    <parent link="link_4"/>
    <child link="link_5"/>
    <origin rpy="-1.5707963267948966 -3.141592653589793 3.141592653589793" xyz="0 0 0.1993"/>
    <axis xyz="0 0 1"/>
    <limit effort="300" lower="-2.09439510239" upper="2.09439510239" velocity="10"/>
    <dynamics damping="0.5"/>
  </joint>
  <link name="link_6">
    <inertial>
      <origin rpy="0 0 0" xyz="0.002 0.0694 0.0666"/>
      <mass value="5"/>
      <inertia ixx="-0.0318" ixy="0.0696" ixz="0.084" iyy="-0.0659" iyz="-0.037" izz="-0.0404"/>
    </inertial>
  </link>
  <joint name="joint_6" type="revolute">
    <parent link="link_5"/>
    <child link="link_6"/>
    <origin rpy="1.5707963267948966 -3.141592653589793 -1.5707963267948966" xyz="0 0 0.0773"/>
    <axis xyz="0 0 1"/>
    <limit effort="300" lower="-2.09439510239" upper="2.09439510239" velocity="10"/>
    <dynamics damping="0.5"/>
  </joint>
  <link name="link_7">
    <inertial>
      <origin rpy="0 0 0" xyz="0.0238 0.0531 0.0149"/>
      <mass value="5"/>
      <inertia ixx="0.027" ixy="0.0005" ixz="-0.0165" iyy="0.0724" iyz="-0.0963" izz="0.081"/>
    </inertial>
  </link>
  <joint name="joint_7" type="revolute">
    <parent link="link_6"/>
    <child link="link_7"/>
    <origin rpy="1.5707963267948966 -3.141592653589793 -3.141592653589793" xyz="0 0 0.1566"/>
    <axis xyz="0 0 1"/>
    <limit effort="300" lower="-2.09439510239" upper="2.09439510239" velocity="10"/>
    <dynamics damping="0.5"/>
  </joint>
  <link name="link_8">
    <inertial>
      <origin rpy="0 0 0" xyz="0.0004 0.0411 0.0949"/>
      <mass value="5"/>
      <inertia ixx="0.0433" ixy="0.0174" ixz="-0.0261" iyy="0.0611" iyz="-0.0007" izz="-0.0249"/>
    </inertial>
  </link>
  <joint name="joint_8" type="revolute">
    <parent link="link_7"/>
    <child link="link_8"/>
    <origin rpy="0 -3.141592653589793 1.5707963267948966" xyz="0 0 0.1431"/>
    <axis xyz="0 0 1"/>
    <limit effort="300" lower="-2.09439510239" upper="2.09439510239" velocity="10"/>
    <dynamics damping="0.5"/>
  </joint>
  <link name="link_9">
    <inertial>
      <origin rpy="0 0 0" xyz="0.0011 0.0991 0.041"/>
      <mass value="5"/>
      <inertia ixx="-0.0732" ixy="-0.0891" ixz="-0.092" iyy="0.0747" iyz="0.0288" izz="0.0932"/>
    </inertial>
  </link>
  <joint name="joint_9" type="revolute">
    <parent link="link_8"/>
    <child link="link_9"/>
    <origin rpy="-1.5707963267948966 3.141592653589793 0" xyz="0 0 0.1711"/>
    <axis xyz="0 0 1"/>
    <limit effort="300" lower="-2.09439510239" upper="2.09439510239" velocity="10"/>
    <dynamics damping="0.5"/>
  </joint>
  <link name="link_10">
    <inertial>
      <origin rpy="0 0 0" xyz="0.0518 0.0545 0.0878"/>
      <mass value="5"/>
      <inertia ixx="-0.0275" ixy="-0.0451" ixz="-0.0075" iyy="-0.0188" iyz="-0.083" izz="0.0496"/>
    </inertial>
  </link>
  <joint name="joint_10" type="revolute">
    <parent link="link_9"/>
    <child link="link_10"/>
    <origin rpy="-3.141592653589793 -3.141592653589793 -3.141592653589793" xyz="0 0 0.1291"/>
    <axis xyz="0 0 1"/>
    <limit effort="300" lower="-2.09439510239" upper="2.09439510239" velocity="10"/>
    <dynamics damping="0.5"/>
  </joint>
</robot>
