<?xml version="1.0" encoding="utf-8"?>
<robot name="iiwa">
  <link name="world"/>
  <link name="link_1">
    <inertial>
      <origin rpy="0 0 0" xyz="0.0011 0.0472 0.0121"/>
      <mass value="5"/>
      <inertia ixx="-0.054" ixy="0.0029" ixz="0.0796" iyy="-0.0759" iyz="-0.0091" izz="-0.0776"/>
    </inertial>
  </link>
  <joint name="joint_1" type="revolute">
    <parent link="world"/>
    <child link="link_1"/>
    <origin rpy="0 3.141592653589793 -1.5707963267948966" xyz="0 0 0.1272"/>
    <axis xyz="0 0 1"/>
    <limit effort="300" lower="-2.09439510239" upper="2.09439510239" velocity="10"/>
    <dynamics damping="0.5"/>
  </joint>
  <link name="link_2">
    <inertial>
      <origin rpy="0 0 0" xyz="0.0441 0.0797 0.0438"/>
      <mass value="5"/>
      <inertia ixx="0.0313" ixy="-0.0969" ixz="0.0463" iyy="-0.0469" iyz="0.0324" izz="-0.0534"/>
    </inertial>
  </link>
  <joint name="joint_2" type="revolute">
    <parent link="link_1"/>
    <child link="link_2"/>
    <origin rpy="1.5707963267948966 3.141592653589793 -3.141592653589793" xyz="0 0 0.0076"/>
    <axis xyz="0 0 1"/>
    <limit effort="300" lower="-2.09439510239" upper="2.09439510239" velocity="10"/>
    <dynamics damping="0.5"/>
  </joint>
  <link name="link_3">
    <inertial>
      <origin rpy="0 0 0" xyz="0.0152 0.0569 0.0716"/>
      <mass value="5"/>
      <inertia ixx="0.0919" ixy="0.0968" ixz="0.0195" iyy="-0.0383" iyz="0.0239" izz="0.0808"/>
    </inertial>
  </link>
  <joint name="joint_3" type="revolute">
    <parent link="link_2"/>
    <child link="link_3"/>
    <origin rpy="3.141592653589793 -1.5707963267948966 -3.141592653589793" xyz="0 0 0.0165"/>
    <axis xyz="0 0 1"/>
    <limit effort="300" lower="-2.09439510239" upper="2.09439510239" velocity="10"/>
    <dynamics damping="0.5"/>
  </joint>
  <link name="link_4">
    <inertial>
      <origin rpy="0 0 0" xyz="0.0309 0.0939 0.0483"/>
      <mass value="5"/>
      <inertia ixx="0.0992" ixy="0.0358" ixz="0.0412" iyy="0.0865" iyz="0.0579" izz="0.0871"/>
    </inertial>
  </link>
  <joint name="joint_4" type="revolute">
    <parent link="link_3"/>
    <child link="link_4"/>
    <origin rpy="-3.141592653589793 1.5707963267948966 3.141592653589793" xyz="0 0 0.112"/>
    <axis xyz="0 0 1"/>
    <limit effort="300" lower="-2.09439510239" upper="2.09439510239" velocity="10"/>
    <dynamics damping="0.5"/>
  </joint>
  <link name="link_5">
    <inertial>
      <origin rpy="0 0 0" xyz="0.0835 0.0942 0.0851"/>
      <mass value="5"/>
      <inertia ixx="0.0469" ixy="0.086" ixz="0.082" iyy="-0.0223" iyz="-0.0348" izz="-0.0801"/>
    </inertial>
  </link>
  <joint name="joint_5" type="revolute">
    <parent link="link_4"/>
    <child link="link_5"/>
    <origin rpy="0 1.5707963267948966 -1.5707963267948966" xyz="0 0 0.1721"/>
    <axis xyz="0 0 1"/>
    <limit effort="300" lower="-2.09439510239" upper="2.09439510239" velocity="10"/>
    <dynamics damping="0.5"/>
  </joint>
  <link name="link_6">
    <inertial>
      <origin rpy="0 0 0" xyz="0.0645 0.0728 0.0146"/>
      <mass value="5"/>
      <inertia ixx="-0.0548" ixy="0.056" ixz="0.0227" iyy="-0.0414" iyz="0.0032" izz="-0.0114"/>
    </inertial>
  </link>
  <joint name="joint_6" type="revolute">
    <parent link="link_5"/>
    <child link="link_6"/>
    <origin rpy="1.5707963267948966 1.5707963267948966 -3.141592653589793" xyz="0 0 0.1298"/>
    <axis xyz="0 0 1"/>
    <limit effort="300" lower="-2.09439510239" upper="2.09439510239" velocity="10"/>
    <dynamics damping="0.5"/>
  </joint>
  <link name="link_7">
    <inertial>
      <origin rpy="0 0 0" xyz="0.0867 0.0252 0.0141"/>
      <mass value="5"/>
      <inertia ixx="0.0128" ixy="0.0825" ixz="-0.0918" iyy="0.0346" iyz="0.0014" izz="0.0891"/>
    </inertial>
  </link>
  <joint name="joint_7" type="revolute">
    <parent link="link_6"/>
    <child link="link_7"/>
    <origin rpy="3.141592653589793 -3.141592653589793 0" xyz="0 0 0.072"/>
    <axis xyz="0 0 1"/>
    <limit effort="300" lower="-2.09439510239" upper="2.09439510239" velocity="10"/>
    <dynamics damping="0.5"/>
  </joint>
  <link name="link_8">
    <inertial>
      <origin rpy="0 0 0" xyz="0.0392 0.0436 0.0914"/>
      <mass value="5"/>
      <inertia ixx="0.0129" ixy="0.0001" ixz="-0.0411" iyy="-0.098" iyz="0.0657" izz="0.0068"/>
    </inertial>
  </link>
  <joint name="joint_8" type="revolute">
    <parent link="link_7"/>
    <child link="link_8"/>
    <origin rpy="-1.5707963267948966 1.5707963267948966 -3.141592653589793" xyz="0 0 0.0127"/>
    <axis xyz="0 0 1"/>
    <limit effort="300" lower="-2.09439510239" upper="2.09439510239" velocity="10"/>
    <dynamics damping="0.5"/>
  </joint>
  <link name="link_9">
    <inertial>
      <origin rpy="0 0 0" xyz="0.031 0.0988 0.0774"/>
      <mass value="5"/>
      <inertia ixx="-0.0935" ixy="0.0808" ixz="-0.0284" iyy="0.02" iyz="0.0834" izz="0.0624"/>
    </inertial>
  </link>
  <joint name="joint_9" type="revolute">
    <parent link="link_8"/>
    <child link="link_9"/>
    <origin rpy="0 0 3.141592653589793" xyz="0 0 0.014"/>
    <axis xyz="0 0 1"/>
    <limit effort="300" lower="-2.09439510239" upper="2.09439510239" velocity="10"/>
    <dynamics damping="0.5"/>
  </joint>
  <link name="link_10">
    <inertial>
      <origin rpy="0 0 0" xyz="0.0304 0.0836 0.0219"/>
      <mass value="5"/>
      <inertia ixx="0.0769" ixy="0.0044" ixz="0.0611" iyy="0.0492" iyz="0.0372" izz="-0.0537"/>
    </inertial>
  </link>
  <joint name="joint_10" type="revolute">
    <parent link="link_9"/>
    <child link="link_10"/>
    <origin rpy="-1.5707963267948966 0 0" xyz="0 0 0.1528"/>
    <axis xyz="0 0 1"/>
    <limit effort="300" lower="-2.09439510239" upper="2.09439510239" velocity="10"/>
    <dynamics damping="0.5"/>
  </joint>
  <link name="link_11">
    <inertial>
      <origin rpy="0 0 0" xyz="0.078 0.0015 0.0683"/>
      <mass value="5"/>
      <inertia ixx="0.0931" ixy="0.0293" ixz="0.0833" iyy="-0.0734" iyz="0.0325" izz="-0.0606"/>
    </inertial>
  </link>
  <joint name="joint_11" type="revolute">
    <parent link="link_10"/>
    <child link="link_11"/>
    <origin rpy="-1.5707963267948966 0 1.5707963267948966" xyz="0 0 0.1892"/>
    <axis xyz="0 0 1"/>
    <limit effort="300" lower="-2.09439510239" upper="2.09439510239" velocity="10"/>
    <dynamics damping="0.5"/>
  </joint>
</robot>
