<?xml version="1.0" encoding="utf-8"?>
<robot name="iiwa">
  <link name="world"/>
  <link name="link_1">
    <inertial>
      <origin rpy="0 0 0" xyz="0.0459 0.0765 0.0744"/>
      <mass value="5"/>
      <inertia ixx="0.0894" ixy="0.0807" ixz="-0.0917" iyy="-0.0137" iyz="0.0946" izz="-0.0634"/>
    </inertial>
  </link>
  <joint name="joint_1" type="revolute">
    <parent link="world"/>
    <child link="link_1"/>
    <origin rpy="1.5707963267948966 0 -1.5707963267948966" xyz="0 0 0.1339"/>
    <axis xyz="0 0 1"/>
    <limit effort="300" lower="-2.09439510239" upper="2.09439510239" velocity="10"/>
    <dynamics damping="0.5"/>
  </joint>
  <link name="link_2">
    <inertial>
      <origin rpy="0 0 0" xyz="0.0713 0.0045 0.0887"/>
      <mass value="5"/>
      <inertia ixx="-0.0023" ixy="-0.0848" ixz="0.0952" iyy="-0.0178" iyz="0.0471" izz="-0.0119"/>
    </inertial>
  </link>
  <joint name="joint_2" type="revolute">
    <parent link="link_1"/>
    <child link="link_2"/>
    <origin rpy="1.5707963267948966 -1.5707963267948966 -3.141592653589793" xyz="0 0 0.0343"/>
    <axis xyz="0 0 1"/>
    <limit effort="300" lower="-2.09439510239" upper="2.09439510239" velocity="10"/>
    <dynamics damping="0.5"/>
  </joint>
  <link name="link_3">
    <inertial>
      <origin rpy="0 0 0" xyz="0.0308 0.0027 0.0382"/>
      <mass value="5"/>
      <inertia ixx="-0.0444" ixy="-0.0637" ixz="0.0838" iyy="0.0547" iyz="0.0366" izz="-0.0847"/>
    </inertial>
  </link>
  <joint name="joint_3" type="revolute">
    <parent link="link_2"/>
    <child link="link_3"/>
    <origin rpy="0 1.5707963267948966 3.141592653589793" xyz="0 0 0.011"/>
    <axis xyz="0 0 1"/>
    <limit effort="300" lower="-2.09439510239" upper="2.09439510239" velocity="10"/>
    <dynamics damping="0.5"/>
  </joint>
  <link name="link_4">
    <inertial>
      <origin rpy="0 0 0" xyz="0.0681 0.0764 0.0945"/>
      <mass value="5"/>
      <inertia ixx="0.0271" ixy="-0.0113" ixz="0.0736" iyy="-0.0674" iyz="-0.0099" izz="0.0742"/>
    </inertial>
  </link>
  <joint name="joint_4" type="revolute">
    <parent link="link_3"/>
    <child link="link_4"/>
    <origin rpy="3.141592653589793 3.141592653589793 -1.5707963267948966" xyz="0 0 0.089"/>
    <axis xyz="0 0 1"/>
    <limit effort="300" lower="-2.09439510239" upper="2.09439510239" velocity="10"/>
    <dynamics damping="0.5"/>
  </joint>
  <link name="link_5">
    <inertial>
      <origin rpy="0 0 0" xyz="0.0946 0.0976 0.0998"/>
      <mass value="5"/>
      <inertia ixx="-0.0091" ixy="0.0716" ixz="0.0993" iyy="-0.0281" iyz="-0.0222" izz="0.0141"/>
    </inertial>
  </link>
  <joint name="joint_5" type="revolute">
    <parent link="link_4"/>
    <child link="link_5"/>
    <origin rpy="-1.5707963267948966 0 3.141592653589793" xyz="0 0 0.1652"/>
    <axis xyz="0 0 1"/>
    <limit effort="300" lower="-2.09439510239" upper="2.09439510239" velocity="10"/>
    <dynamics damping="0.5"/>
  </joint>
  <link name="link_6">
    <inertial>
      <origin rpy="0 0 0" xyz="0.058 0.0341 0.058"/>
      <mass value="5"/>
      <inertia ixx="-0.0086" ixy="-0.0086" ixz="0.0006" iyy="0.0318" iyz="-0.0703" izz="0.0059"/>
    </inertial>
  </link>
  <joint name="joint_6" type="revolute">
    <parent link="link_5"/>
    <child link="link_6"/>
    <origin rpy="3.141592653589793 3.141592653589793 1.5707963267948966" xyz="0 0 0.0611"/>
    <axis xyz="0 0 1"/>
    <limit effort="300" lower="-2.09439510239" upper="2.09439510239" velocity="10"/>
    <dynamics damping="0.5"/>
  </joint>
  <link name="link_7">
    <inertial>
      <origin rpy="0 0 0" xyz="0.0136 0.0844 0.0066"/>
      <mass value="5"/>
      <inertia ixx="0.0164" ixy="0.0792" ixz="0.0258" iyy="0.0636" iyz="-0.0877" izz="0.0747"/>
    </inertial>
  </link>
  <joint name="joint_7" type="revolute">
    <parent link="link_6"/>
    <child link="link_7"/>
    <origin rpy="-1.5707963267948966 3.141592653589793 -1.5707963267948966" xyz="0 0 0.0438"/>
    <axis xyz="0 0 1"/>
    <limit effort="300" lower="-2.09439510239" upper="2.09439510239" velocity="10"/>
    <dynamics damping="0.5"/>
  </joint>
</robot>
