<?xml version="1.0" encoding="utf-8"?>
<robot name="iiwa">
  <link name="world"/>
  <link name="link_1">
    <inertial>
      <origin rpy="0 0 0" xyz="0.0445 0.0034 0.0747"/>
      <mass value="5"/>
      <inertia ixx="-0.0289" ixy="-0.044" ixz="-0.0197" iyy="-0.0641" iyz="0.096" izz="0.0686"/>
    </inertial>
  </link>
  <joint name="joint_1" type="revolute">
    <parent link="world"/>
    <child link="link_1"/>
    <origin rpy="-1.5707963267948966 0 3.141592653589793" xyz="0 0 0.1824"/>
    <axis xyz="0 0 1"/>
    <limit effort="300" lower="-2.09439510239" upper="2.09439510239" velocity="10"/>
    <dynamics damping="0.5"/>
  </joint>
  <link name="link_2">
    <inertial>
      <origin rpy="0 0 0" xyz="0.0527 0.0817 0.0411"/>
      <mass value="5"/>
      <inertia ixx="-0.0888" ixy="-0.0132" ixz="0.0465" iyy="0.0903" iyz="0.0535" izz="-0.0903"/>
    </inertial>
  </link>
  <joint name="joint_2" type="revolute">
    <parent link="link_1"/>
    <child link="link_2"/>
    <origin rpy="0 0 1.5707963267948966" xyz="0 0 0.0705"/>
    <axis xyz="0 0 1"/>
    <limit effort="300" lower="-2.09439510239" upper="2.09439510239" velocity="10"/>
    <dynamics damping="0.5"/>
  </joint>
  <link name="link_3">
    <inertial>
      <origin rpy="0 0 0" xyz="0.0874 0.0038 0.0297"/>
      <mass value="5"/>
      <inertia ixx="0.0129" ixy="-0.0695" ixz="0.0602" iyy="-0.0256" iyz="0.01" izz="-0.0402"/>
    </inertial>
  </link>
  <joint name="joint_3" type="revolute">
    <parent link="link_2"/>
    <child link="link_3"/>
    <origin rpy="-1.5707963267948966 0 0" xyz="0 0 0.0518"/>
    <axis xyz="0 0 1"/>
    <limit effort="300" lower="-2.09439510239" upper="2.09439510239" velocity="10"/>
    <dynamics damping="0.5"/>
  </joint>
  <link name="link_4">
    <inertial>
      <origin rpy="0 0 0" xyz="0.0433 0.0504 0.0909"/>
      <mass value="5"/>
      <inertia ixx="0.0757" ixy="-0.0245" ixz="0.0485" iyy="-0.0913" iyz="-0.0944" izz="-0.0076"/>
    </inertial>
  </link>
  <joint name="joint_4" type="revolute">
    <parent link="link_3"/>
    <child link="link_4"/>
    <origin rpy="-3.141592653589793 -1.5707963267948966 -1.5707963267948966" xyz="0 0 0.0544"/>
    <axis xyz="0 0 1"/>
    <limit effort="300" lower="-2.09439510239" upper="2.09439510239" velocity="10"/>
    <dynamics damping="0.5"/>
  </joint>
  <link name="link_5">
    <inertial>
      <origin rpy="0 0 0" xyz="0.0216 0.0765 0.036"/>
      <mass value="5"/>
      <inertia ixx="-0.0607" ixy="0.0586" ixz="-0.0871" iyy="0.0978" iyz="0.0501" izz="-0.0119"/>
    </inertial>
  </link>
  <joint name="joint_5" type="revolute">
    <parent link="link_4"/>
    <child link="link_5"/>
    <origin rpy="0 0 -1.5707963267948966" xyz="0 0 0.0746"/>
    <axis xyz="0 0 1"/>
    <limit effort="300" lower="-2.09439510239" upper="2.09439510239" velocity="10"/>
    <dynamics damping="0.5"/>
  </joint>
  <link name="link_6">
    <inertial>
      <origin rpy="0 0 0" xyz="0.0507 0.0977 0.0385"/>
      <mass value="5"/>
      <inertia ixx="0.0461" ixy="-0.0852" ixz="-0.0261" iyy="-0.0723" iyz="-0.0055" izz="-0.0889"/>
    </inertial>
  </link>
  <joint name="joint_6" type="revolute">
    <parent link="link_5"/>
    <child link="link_6"/>
    <origin rpy="0 3.141592653589793 1.5707963267948966" xyz="0 0 0.0268"/>
    <axis xyz="0 0 1"/>
    <limit effort="300" lower="-2.09439510239" upper="2.09439510239" velocity="10"/>
    <dynamics damping="0.5"/>
  </joint>
  <link name="link_7">
    <inertial>
      <origin rpy="0 0 0" xyz="0.0391 0.0203 0.0066"/>
      <mass value="5"/>
      <inertia ixx="-0.045" ixy="-0.058" ixz="0.099" iyy="-0.0476" iyz="-0.0231" izz="0.0327"/>
    </inertial>
  </link>
  <joint name="joint_7" type="revolute">
    <parent link="link_6"/>
    <child link="link_7"/>
    <origin rpy="3.141592653589793 3.141592653589793 -1.5707963267948966" xyz="0 0 0.1611"/>
    <axis xyz="0 0 1"/>
    <limit effort="300" lower="-2.09439510239" upper="2.09439510239" velocity="10"/>
    <dynamics damping="0.5"/>
  </joint>
  <link name="link_8">
    <inertial>
      <origin rpy="0 0 0" xyz="0.0959 0.0058 0.0922"/>
      <mass value="5"/>
      <inertia ixx="0.064" ixy="0.0338" ixz="-0.0122" iyy="-0.0458" iyz="0.0231" izz="-0.0661"/>
    </inertial>
  </link>
  <joint name="joint_8" type="revolute">
    <parent link="link_7"/>
    <child link="link_8"/>
    <origin rpy="0 -3.141592653589793 1.5707963267948966" xyz="0 0 0.0184"/>
    <axis xyz="0 0 1"/>
    <limit effort="300" lower="-2.09439510239" upper="2.09439510239" velocity="10"/>
    <dynamics damping="0.5"/>
  </joint>
  <link name="link_9">
    <inertial>
      <origin rpy="0 0 0" xyz="0.0935 0.0127 0.0072"/>
      <mass value="5"/>
      <inertia ixx="-0.0015" ixy="0.0633" ixz="-0.0268" iyy="-0.0656" iyz="0.0704" izz="0.0915"/>
    </inertial>
  </link>
  <joint name="joint_9" type="revolute">
    <parent link="link_8"/>
    <child link="link_9"/>
    <origin rpy="-1.5707963267948966 3.141592653589793 -3.141592653589793" xyz="0 0 0.0089"/>
    <axis xyz="0 0 1"/>
    <limit effort="300" lower="-2.09439510239" upper="2.09439510239" velocity="10"/>
    <dynamics damping="0.5"/>
  </joint>
  <link name="link_10">
    <inertial>
      <origin rpy="0 0 0" xyz="0.0457 0.0258 0.0272"/>
      <mass value="5"/>
      <inertia ixx="0.0404" ixy="-0.0361" ixz="-0.0027" iyy="0.0665" iyz="-0.0054" izz="0.0165"/>
    </inertial>
  </link>
  <joint name="joint_10" type="revolute">
    <parent link="link_9"/>
    <child link="link_10"/>
    <origin rpy="3.141592653589793 0 0" xyz="0 0 0.0592"/>
    <axis xyz="0 0 1"/>
    <limit effort="300" lower="-2.09439510239" upper="2.09439510239" velocity="10"/>
    <dynamics damping="0.5"/>
  </joint>
  <link name="link_11">
    <inertial>
      <origin rpy="0 0 0" xyz="0.0581 0.0703 0.0734"/>
      <mass value="5"/>
      <inertia ixx="-0.0991" ixy="0.0721" ixz="-0.0402" iyy="-0.0087" iyz="-0.0516" izz="-0.0519"/>
    </inertial>
  </link>
  <joint name="joint_11" type="revolute">
    <parent link="link_10"/>
    <child link="link_11"/>
    <origin rpy="-3.141592653589793 -1.5707963267948966 -1.5707963267948966" xyz="0 0 0.0152"/>
    <axis xyz="0 0 1"/>
    <limit effort="300" lower="-2.09439510239" upper="2.09439510239" velocity="10"/>
    <dynamics damping="0.5"/>
  </joint>
  <link name="link_12">
    <inertial>
      <origin rpy="0 0 0" xyz="0.0395 0.0026 0.0186"/>
      <mass value="5"/>
      <inertia ixx="0.057" ixy="0.0067" ixz="0.0279" iyy="-0.0527" iyz="0.0587" izz="0.0604"/>
    </inertial>
  </link>
  <joint name="joint_12" type="revolute">
    <parent link="link_11"/>
    <child link="link_12"/>
    <origin rpy="-1.5707963267948966 3.141592653589793 0" xyz="0 0 0.0512"/>
    <axis xyz="0 0 1"/>
    <limit effort="300" lower="-2.09439510239" upper="2.09439510239" velocity="10"/>
    <dynamics damping="0.5"/>
  </joint>
</robot>
