<?xml version="1.0" encoding="utf-8"?>
<robot name="iiwa">
  <link name="world"/>
  <link name="link_1">
    <inertial>
      <origin rpy="0 0 0" xyz="0.0644 0.0885 0.0145"/>
      <mass value="5"/>
      <inertia ixx="0.0489" ixy="0.0217" ixz="-0.0265" iyy="0.0196" iyz="-0.0152" izz="-0.0111"/>
    </inertial>
  </link>
  <joint name="joint_1" type="revolute">
    <parent link="world"/>
    <child link="link_1"/>
    <origin rpy="1.5707963267948966 3.141592653589793 -3.141592653589793" xyz="0 0 0.025"/>
    <axis xyz="0 0 1"/>
    <limit effort="300" lower="-2.09439510239" upper="2.09439510239" velocity="10"/>
    <dynamics damping="0.5"/>
  </joint>
  <link name="link_2">
    <inertial>
      <origin rpy="0 0 0" xyz="0.0746 0.0508 0.031"/>
      <mass value="5"/>
      <inertia ixx="0.0451" ixy="-0.0902" ixz="0.0527" iyy="-0.0227" iyz="-0.0179" izz="-0.055"/>
    </inertial>
  </link>
  <joint name="joint_2" type="revolute">
    <parent link="world"/>
    <child link="link_2"/>
    <origin rpy="0 3.141592653589793 -1.5707963267948966" xyz="0 0 0.0876"/>
    <axis xyz="0 0 1"/>
    <limit effort="300" lower="-2.09439510239" upper="2.09439510239" velocity="10"/>
    <dynamics damping="0.5"/>
  </joint>
  <link name="link_3">
    <inertial>
      <origin rpy="0 0 0" xyz="0.0348 0.0608 0.0222"/>
      <mass value="5"/>
      <inertia ixx="-0.0703" ixy="0.0689" ixz="0.0955" iyy="-0.0339" iyz="-0.0815" izz="0.093"/>
    </inertial>
  </link>
  <joint name="joint_3" type="revolute">
    <parent link="link_2"/>
    <child link="link_3"/>
    <origin rpy="1.5707963267948966 -3.141592653589793 -3.141592653589793" xyz="0 0 0.0724"/>
    <axis xyz="0 0 1"/>
    <limit effort="300" lower="-2.09439510239" upper="2.09439510239" velocity="10"/>
    <dynamics damping="0.5"/>
  </joint>
  <link name="link_4">
    <inertial>
      <origin rpy="0 0 0" xyz="0.0625 0.0561 0.0304"/>
      <mass value="5"/>
      <inertia ixx="0.0761" ixy="0.0379" ixz="-0.0798" iyy="-0.0753" iyz="-0.002" izz="-0.0292"/>
    </inertial>
  </link>
  <joint name="joint_4" type="revolute">
    <parent link="link_3"/>
    <child link="link_4"/>
    <origin rpy="1.5707963267948966 -3.141592653589793 -3.141592653589793" xyz="0 0 0.1547"/>
    <axis xyz="0 0 1"/>
    <limit effort="300" lower="-2.09439510239" upper="2.09439510239" velocity="10"/>
    <dynamics damping="0.5"/>
  </joint>
  <link name="link_5">
    <inertial>
      <origin rpy="0 0 0" xyz="0.0258 0.0072 0.0624"/>
      <mass value="5"/>
      <inertia ixx="-0.0988" ixy="0.0104" ixz="-0.0333" iyy="-0.0306" iyz="-0.0786" izz="0.004"/>
    </inertial>
  </link>
  <joint name="joint_5" type="revolute">
    <parent link="link_4"/>
    <child link="link_5"/>
    <origin rpy="1.5707963267948966 0 3.141592653589793" xyz="0 0 0.1278"/>
    <axis xyz="0 0 1"/>
    <limit effort="300" lower="-2.09439510239" upper="2.09439510239" velocity="10"/>
    <dynamics damping="0.5"/>
  </joint>
  <link name="link_6">
    <inertial>
      <origin rpy="0 0 0" xyz="0.0568 0.0386 0.0816"/>
      <mass value="5"/>
      <inertia ixx="-0.0574" ixy="-0.0027" ixz="0.0042" iyy="-0.0795" iyz="-0.0068" izz="-0.0724"/>
    </inertial>
  </link>
  <joint name="joint_6" type="revolute">
    <parent link="link_5"/>
    <child link="link_6"/>
    <origin rpy="-1.5707963267948966 -1.5707963267948966 -3.141592653589793" xyz="0 0 0.0825"/>
    <axis xyz="0 0 1"/>
    <limit effort="300" lower="-2.09439510239" upper="2.09439510239" velocity="10"/>
    <dynamics damping="0.5"/>
  </joint>
  <link name="link_7">
    <inertial>
      <origin rpy="0 0 0" xyz="0.0123 0.0972 0.0175"/>
      <mass value="5"/>
      <inertia ixx="-0.0622" ixy="-0.0288" ixz="0.0797" iyy="0.0446" iyz="-0.0341" izz="-0.0433"/>
    </inertial>
  </link>
  <joint name="joint_7" type="revolute">
    <parent link="link_6"/>
    <child link="link_7"/>
    <origin rpy="3.141592653589793 1.5707963267948966 -3.141592653589793" xyz="0 0 0.0275"/>
    <axis xyz="0 0 1"/>
    <limit effort="300" lower="-2.09439510239" upper="2.09439510239" velocity="10"/>
    <dynamics damping="0.5"/>
  </joint>
  <link name="link_8">
    <inertial>
      <origin rpy="0 0 0" xyz="0.0417 0.0751 0.0534"/>
      <mass value="5"/>
      <inertia ixx="-0.0632" ixy="0.0287" ixz="0.0572" iyy="-0.0559" iyz="-0.008" izz="-0.0486"/>
    </inertial>
  </link>
  <joint name="joint_8" type="revolute">
    <parent link="link_7"/>
    <child link="link_8"/>
    <origin rpy="-3.141592653589793 -3.141592653589793 3.141592653589793" xyz="0 0 0.0097"/>
    <axis xyz="0 0 1"/>
    <limit effort="300" lower="-2.09439510239" upper="2.09439510239" velocity="10"/>
    <dynamics damping="0.5"/>
  </joint>
  <link name="link_9">
    <inertial>
      <origin rpy="0 0 0" xyz="0.0589 0.0916 0.0385"/>
      <mass value="5"/>
      <inertia ixx="0.0509" ixy="0.0302" ixz="0.0261" iyy="-0.0964" iyz="0.0967" izz="0.0656"/>
    </inertial>
  </link>
  <joint name="joint_9" type="revolute">
    <parent link="link_8"/>
    <child link="link_9"/>
    <origin rpy="3.141592653589793 1.5707963267948966 -3.141592653589793" xyz="0 0 0.1323"/>
    <axis xyz="0 0 1"/>
    <limit effort="300" lower="-2.09439510239" upper="2.09439510239" velocity="10"/>
    <dynamics damping="0.5"/>
  </joint>
  <link name="link_10">
    <inertial>
      <origin rpy="0 0 0" xyz="0.0742 0.0869 0.0825"/>
      <mass value="5"/>
      <inertia ixx="-0.0308" ixy="-0.0506" ixz="0.0871" iyy="0.0534" iyz="-0.0378" izz="0.0694"/>
    </inertial>
  </link>
  <joint name="joint_10" type="revolute">
    <parent link="link_9"/>
    <child link="link_10"/>
    <origin rpy="3.141592653589793 3.141592653589793 3.141592653589793" xyz="0 0 0.0617"/>
    <axis xyz="0 0 1"/>
    <limit effort="300" lower="-2.09439510239" upper="2.09439510239" velocity="10"/>
    <dynamics damping="0.5"/>
  </joint>
  <link name="link_11">
    <inertial>
      <origin rpy="0 0 0" xyz="0.0907 0.0071 0.0792"/>
      <mass value="5"/>
      <inertia ixx="-0.0695" ixy="0.0657" ixz="-0.0078" iyy="-0.0821" iyz="0.0628" izz="0.0052"/>
    </inertial>
  </link>
  <joint name="joint_11" type="revolute">
    <parent link="world"/>
    <child link="link_11"/>
    <origin rpy="-1.5707963267948966 -3.141592653589793 0" xyz="0 0 0.1752"/>
    <axis xyz="0 0 1"/>
    <limit effort="300" lower="-2.09439510239" upper="2.09439510239" velocity="10"/>
    <dynamics damping="0.5"/>
  </joint>
  <link name="link_12">
    <inertial>
      <origin rpy="0 0 0" xyz="0.0924 0.0864 0.0533"/>
      <mass value="5"/>
      <inertia ixx="0.0333" ixy="-0.0784" ixz="0.0816" iyy="-0.0545" iyz="-0.0818" izz="0.0299"/>
    </inertial>
  </link>
  <joint name="joint_12" type="revolute">
    <parent link="link_11"/>
    <child link="link_12"/>
    <origin rpy="1.5707963267948966 -1.5707963267948966 -3.141592653589793" xyz="0 0 0.177"/>
    <axis xyz="0 0 1"/>
    <limit effort="300" lower="-2.09439510239" upper="2.09439510239" velocity="10"/>
    <dynamics damping="0.5"/>
  </joint>
  <link name="link_13">
    <inertial>
      <origin rpy="0 0 0" xyz="0.0859 0.0288 0.0849"/>
      <mass value="5"/>
      <inertia ixx="0.0654" ixy="0.0639" ixz="0.0073" iyy="0.041" iyz="0.0022" izz="0.0548"/>
    </inertial>
  </link>
  <joint name="joint_13" type="revolute">
    <parent link="link_12"/>
    <child link="link_13"/>
    <origin rpy="1.5707963267948966 -1.5707963267948966 0" xyz="0 0 0.1572"/>
    <axis xyz="0 0 1"/>
    <limit effort="300" lower="-2.09439510239" upper="2.09439510239" velocity="10"/>
    <dynamics damping="0.5"/>
  </joint>
  <link name="link_14">
    <inertial>
      <origin rpy="0 0 0" xyz="0.0779 0.0587 0.0143"/>
      <mass value="5"/>
      <inertia ixx="-0.0513" ixy="0.011" ixz="-0.0655" iyy="-0.0992" iyz="0.0925" izz="-0.002"/>
    </inertial>
  </link>
  <joint name="joint_14" type="revolute">
    <parent link="link_13"/>
    <child link="link_14"/>
    <origin rpy="1.5707963267948966 -3.141592653589793 1.5707963267948966" xyz="0 0 0.1469"/>
    <axis xyz="0 0 1"/>
    <limit effort="300" lower="-2.09439510239" upper="2.09439510239" velocity="10"/>
    <dynamics damping="0.5"/>
  </joint>
  <link name="link_15">
    <inertial>
      <origin rpy="0 0 0" xyz="0.0192 0.043 0.0743"/>
      <mass value="5"/>
      <inertia ixx="-0.0248" ixy="-0.0311" ixz="0.0211" iyy="-0.0459" iyz="0.0766" izz="-0.0333"/>
    </inertial>
  </link>
  <joint name="joint_15" type="revolute">
    <parent link="link_14"/>
    <child link="link_15"/>
    <origin rpy="0 0 1.5707963267948966" xyz="0 0 0.0563"/>
    <axis xyz="0 0 1"/>
    <limit effort="300" lower="-2.09439510239" upper="2.09439510239" velocity="10"/>
    <dynamics damping="0.5"/>
  </joint>
  <link name="link_16">
    <inertial>
      <origin rpy="0 0 0" xyz="0.0815 0.0273 0.045"/>
      <mass value="5"/>
      <inertia ixx="0.0739" ixy="0.0248" ixz="-0.03" iyy="0.0726" iyz="0.0776" izz="-0.0524"/>
    </inertial>
  </link>
  <joint name="joint_16" type="revolute">
    <parent link="link_15"/>
    <child link="link_16"/>
    <origin rpy="1.5707963267948966 1.5707963267948966 -3.141592653589793" xyz="0 0 0.0097"/>
    <axis xyz="0 0 1"/>
    <limit effort="300" lower="-2.09439510239" upper="2.09439510239" velocity="10"/>
    <dynamics damping="0.5"/>
  </joint>
  <link name="link_17">
    <inertial>
      <origin rpy="0 0 0" xyz="0.0189 0.0119 0.0239"/>
      <mass value="5"/>
      <inertia ixx="-0.0795" ixy="0.0636" ixz="-0.0082" iyy="-0.0802" iyz="0.0845" izz="0.0562"/>
    </inertial>
  </link>
  <joint name="joint_17" type="revolute">
    <parent link="link_16"/>
    <child link="link_17"/>
    <origin rpy="-1.5707963267948966 -1.5707963267948966 -3.141592653589793" xyz="0 0 0.1098"/>
    <axis xyz="0 0 1"/>
    <limit effort="300" lower="-2.09439510239" upper="2.09439510239" velocity="10"/>
    <dynamics damping="0.5"/>
  </joint>
  <link name="link_18">
    <inertial>
      <origin rpy="0 0 0" xyz="0.0726 0.0077 0.0681"/>
      <mass value="5"/>
      <inertia ixx="-0.0208" ixy="-0.0677" ixz="0.0867" iyy="0.082" iyz="0.0101" izz="0.0582"/>
    </inertial>
  </link>
  <joint name="joint_18" type="revolute">
    <parent link="link_17"/>
    <child link="link_18"/>
    <origin rpy="-1.5707963267948966 0 -1.5707963267948966" xyz="0 0 0.1694"/>
    <axis xyz="0 0 1"/>
    <limit effort="300" lower="-2.09439510239" upper="2.09439510239" velocity="10"/>
    <dynamics damping="0.5"/>
  </joint>
  <link name="link_19">
    <inertial>
      <origin rpy="0 0 0" xyz="0.0679 0.0525 0.0256"/>
      <mass value="5"/>
      <inertia ixx="-0.0828" ixy="0.0032" ixz="0.0812" iyy="-0.0086" iyz="-0.0135" izz="-0.0102"/>
    </inertial>
  </link>
  <joint name="joint_19" type="revolute">
    <parent link="link_18"/>
    <child link="link_19"/>
    <origin rpy="-1.5707963267948966 -1.5707963267948966 -1.5707963267948966" xyz="0 0 0.0206"/>
    <axis xyz="0 0 1"/>
    <limit effort="300" lower="-2.09439510239" upper="2.09439510239" velocity="10"/>
    <dynamics damping="0.5"/>
  </joint>
</robot>
