<?xml version="1.0" encoding="utf-8"?>
<robot name="iiwa">
  <link name="world"/>
  <link name="link_1">
    <inertial>
      <origin rpy="0 0 0" xyz="0.0236 0.0607 0.0878"/>
      <mass value="5"/>
      <inertia ixx="-0.0388" ixy="-0.0161" ixz="-0.003" iyy="0.0872" iyz="-0.059" izz="0.0531"/>
    </inertial>
  </link>
  <joint name="joint_1" type="revolute">
    <parent link="world"/>
    <child link="link_1"/>
    <origin rpy="-1.5707963267948966 1.5707963267948966 1.5707963267948966" xyz="0 0 0.0102"/>
    <axis xyz="0 0 1"/>
    <limit effort="300" lower="-2.09439510239" upper="2.09439510239" velocity="10"/>
    <dynamics damping="0.5"/>
  </joint>
  <link name="link_2">
    <inertial>
      <origin rpy="0 0 0" xyz="0.0248 0.0988 0.0977"/>
      <mass value="5"/>
      <inertia ixx="-0.054" ixy="-0.0172" ixz="0.0052" iyy="-0.0534" iyz="-0.0109" izz="0.0192"/>
    </inertial>
  </link>
  <joint name="joint_2" type="revolute">
    <parent link="world"/>
    <child link="link_2"/>
    <origin rpy="-1.5707963267948966 0 -1.5707963267948966" xyz="0 0 0.1299"/>
    <axis xyz="0 0 1"/>
    <limit effort="300" lower="-2.09439510239" upper="2.09439510239" velocity="10"/>
    <dynamics damping="0.5"/>
  </joint>
  <link name="link_3">
    <inertial>
      <origin rpy="0 0 0" xyz="0.078 0.0148 0.0913"/>
      <mass value="5"/>
      <inertia ixx="0.0052" ixy="-0.0897" ixz="-0.0053" iyy="0.0418" iyz="0.0349" izz="0.0674"/>
    </inertial>
  </link>
  <joint name="joint_3" type="revolute">
    <parent link="link_2"/>
    <child link="link_3"/>
    <origin rpy="1.5707963267948966 -1.5707963267948966 3.141592653589793" xyz="0 0 0.0722"/>
    <axis xyz="0 0 1"/>
    <limit effort="300" lower="-2.09439510239" upper="2.09439510239" velocity="10"/>
    <dynamics damping="0.5"/>
  </joint>
  <link name="link_4">
    <inertial>
      <origin rpy="0 0 0" xyz="0.0381 0.0966 0.035"/>
      <mass value="5"/>
      <inertia ixx="-0.0951" ixy="0.0577" ixz="-0.074" iyy="-0.053" iyz="0.0694" izz="-0.0643"/>
    </inertial>
  </link>
  <joint name="joint_4" type="revolute">
    <parent link="world"/>
    <child link="link_4"/>
    <origin rpy="1.5707963267948966 1.5707963267948966 -1.5707963267948966" xyz="0 0 0.194"/>
    <axis xyz="0 0 1"/>
    <limit effort="300" lower="-2.09439510239" upper="2.09439510239" velocity="10"/>
    <dynamics damping="0.5"/>
  </joint>
  <link name="link_5">
    <inertial>
      <origin rpy="0 0 0" xyz="0.0604 0.0581 0.0863"/>
      <mass value="5"/>
      <inertia ixx="-0.0379" ixy="-0.0804" ixz="0.0105" iyy="0.085" iyz="0.0736" izz="-0.0124"/>
    </inertial>
  </link>
  <joint name="joint_5" type="revolute">
    <parent link="link_4"/>
    <child link="link_5"/>
    <origin rpy="1.5707963267948966 3.141592653589793 3.141592653589793" xyz="0 0 0.0271"/>
    <axis xyz="0 0 1"/>
    <limit effort="300" lower="-2.09439510239" upper="2.09439510239" velocity="10"/>
    <dynamics damping="0.5"/>
  </joint>
</robot>
