<?xml version="1.0" encoding="utf-8"?>
<robot name="iiwa">
  <link name="world"/>
  <link name="link_1">
    <inertial>
      <origin rpy="0 0 0" xyz="0.0928 0.0743 0.0648"/>
      <mass value="5"/>
      <inertia ixx="0.0535" ixy="-0.0997" ixz="0.0775" iyy="-0.0881" iyz="0.0976" izz="0.035"/>
    </inertial>
  </link>
  <joint name="joint_1" type="revolute">
    <parent link="world"/>
    <child link="link_1"/>
    <origin rpy="3.141592653589793 3.141592653589793 0" xyz="0 0 0.197"/>
    <axis xyz="0 0 1"/>
    <limit effort="300" lower="-2.09439510239" upper="2.09439510239" velocity="10"/>
    <dynamics damping="0.5"/>
  </joint>
  <link name="link_2">
    <inertial>
      <origin rpy="0 0 0" xyz="0.0048 0.0343 0.0512"/>
      <mass value="5"/>
      <inertia ixx="0.0147" ixy="-0.0429" ixz="-0.077" iyy="-0.0583" iyz="0.0886" izz="-0.0696"/>
    </inertial>
  </link>
  <joint name="joint_2" type="revolute">
    <parent link="world"/>
    <child link="link_2"/>
    <origin rpy="-1.5707963267948966 3.141592653589793 1.5707963267948966" xyz="0 0 0.1114"/>
    <axis xyz="0 0 1"/>
    <limit effort="300" lower="-2.09439510239" upper="2.09439510239" velocity="10"/>
    <dynamics damping="0.5"/>
  </joint>
  <link name="link_3">
    <inertial>
      <origin rpy="0 0 0" xyz="0.0816 0.068 0.0451"/>
      <mass value="5"/>
      <inertia ixx="-0.0893" ixy="0.0512" ixz="0.0034" iyy="0.0071" iyz="0.0409" izz="-0.0623"/>
    </inertial>
  </link>
  <joint name="joint_3" type="revolute">
    <parent link="link_2"/>
    <child link="link_3"/>
    <origin rpy="-3.141592653589793 -3.141592653589793 0" xyz="0 0 0.0891"/>
    <axis xyz="0 0 1"/>
    <limit effort="300" lower="-2.09439510239" upper="2.09439510239" velocity="10"/>
    <dynamics damping="0.5"/>
  </joint>
  <link name="link_4">
    <inertial>
      <origin rpy="0 0 0" xyz="0.0842 0.01 0.0126"/>
      <mass value="5"/>
      <inertia ixx="0.0454" ixy="-0.0139" ixz="-0.0312" iyy="-0.0523" iyz="-0.0416" izz="-0.0415"/>
    </inertial>
  </link>
  <joint name="joint_4" type="revolute">
    <parent link="link_3"/>
    <child link="link_4"/>
    <origin rpy="0 1.5707963267948966 1.5707963267948966" xyz="0 0 0.1132"/>
    <axis xyz="0 0 1"/>
    <limit effort="300" lower="-2.09439510239" upper="2.09439510239" velocity="10"/>
    <dynamics damping="0.5"/>
  </joint>
  <link name="link_5">
    <inertial>
      <origin rpy="0 0 0" xyz="0.0515 0.0904 0.0957"/>
      <mass value="5"/>
      <inertia ixx="0.0888" ixy="0.0337" ixz="0.0938" iyy="0.0488" iyz="0.0616" izz="-0.0537"/>
    </inertial>
  </link>
  <joint name="joint_5" type="revolute">
    <parent link="link_4"/>
    <child link="link_5"/>
    <origin rpy="1.5707963267948966 -1.5707963267948966 1.5707963267948966" xyz="0 0 0.1484"/>
    <axis xyz="0 0 1"/>
    <limit effort="300" lower="-2.09439510239" upper="2.09439510239" velocity="10"/>
    <dynamics damping="0.5"/>
  </joint>
  <link name="link_6">
    <inertial>
      <origin rpy="0 0 0" xyz="0.0125 0.0585 0.0472"/>
      <mass value="5"/>
      <inertia ixx="0.025" ixy="0.0491" ixz="0.0358" iyy="-0.0012" iyz="-0.0224" izz="-0.0536"/>
    </inertial>
  </link>
  <joint name="joint_6" type="revolute">
    <parent link="world"/>
    <child link="link_6"/>
    <origin rpy="-3.141592653589793 1.5707963267948966 3.141592653589793" xyz="0 0 0.1487"/>
    <axis xyz="0 0 1"/>
    <limit effort="300" lower="-2.09439510239" upper="2.09439510239" velocity="10"/>
    <dynamics damping="0.5"/>
  </joint>
  <link name="link_7">
    <inertial>
      <origin rpy="0 0 0" xyz="0.063 0.0395 0.0331"/>
      <mass value="5"/>
      <inertia ixx="-0.0548" ixy="0.0236" ixz="-0.088" iyy="-0.0644" iyz="-0.0162" izz="-0.0057"/>
    </inertial>
  </link>
  <joint name="joint_7" type="revolute">
    <parent link="link_6"/>
    <child link="link_7"/>
    <origin rpy="0 -1.5707963267948966 0" xyz="0 0 0.1629"/>
    <axis xyz="0 0 1"/>
    <limit effort="300" lower="-2.09439510239" upper="2.09439510239" velocity="10"/>
    <dynamics damping="0.5"/>
  </joint>
  <link name="link_8">
    <inertial>
      <origin rpy="0 0 0" xyz="0.0381 0.0833 0.0541"/>
      <mass value="5"/>
      <inertia ixx="0.0814" ixy="-0.0501" ixz="-0.0739" iyy="0.0847" iyz="-0.0702" izz="-0.0971"/>
    </inertial>
  </link>
  <joint name="joint_8" type="revolute">
    <parent link="link_7"/>
    <child link="link_8"/>
    <origin rpy="1.5707963267948966 3.141592653589793 -3.141592653589793" xyz="0 0 0.0801"/>
    <axis xyz="0 0 1"/>
    <limit effort="300" lower="-2.09439510239" upper="2.09439510239" velocity="10"/>
    <dynamics damping="0.5"/>
  </joint>
  <link name="link_9">
    <inertial>
      <origin rpy="0 0 0" xyz="0.0662 0.0302 0.0322"/>
      <mass value="5"/>
      <inertia ixx="0.0473" ixy="-0.0242" ixz="0.0885" iyy="0.0273" iyz="0.0333" izz="0.024"/>
    </inertial>
  </link>
  <joint name="joint_9" type="revolute">
    <parent link="link_8"/>
    <child link="link_9"/>
    <origin rpy="-3.141592653589793 1.5707963267948966 -1.5707963267948966" xyz="0 0 0.0819"/>
    <axis xyz="0 0 1"/>
    <limit effort="300" lower="-2.09439510239" upper="2.09439510239" velocity="10"/>
    <dynamics damping="0.5"/>
  </joint>
</robot>
