<?xml version="1.0" encoding="utf-8"?>
<robot name="iiwa">
  <link name="world"/>
  <link name="link_1">
    <inertial>
      <origin rpy="0 0 0" xyz="0.0683 0.0418 0.0446"/>
      <mass value="5"/>
      <inertia ixx="0.0266" ixy="0.075" ixz="-0.061" iyy="-0.0254" iyz="-0.0496" izz="-0.0581"/>
    </inertial>
  </link>
  <joint name="joint_1" type="revolute">
    <parent link="world"/>
    <child link="link_1"/>
    <origin rpy="-3.141592653589793 0 -3.141592653589793" xyz="0 0 0.0267"/>
    <axis xyz="0 0 1"/>
    <limit effort="300" lower="-2.09439510239" upper="2.09439510239" velocity="10"/>
    <dynamics damping="0.5"/>
  </joint>
  <link name="link_2">
    <inertial>
      <origin rpy="0 0 0" xyz="0.0746 0.0164 0.0524"/>
      <mass value="5"/>
      <inertia ixx="0.0916" ixy="-0.0823" ixz="0.0934" iyy="0.0616" iyz="-0.0837" izz="0.0753"/>
    </inertial>
  </link>
  <joint name="joint_2" type="revolute">
    <parent link="world"/>
    <child link="link_2"/>
    <origin rpy="-3.141592653589793 1.5707963267948966 -3.141592653589793" xyz="0 0 0.045"/>
    <axis xyz="0 0 1"/>
    <limit effort="300" lower="-2.09439510239" upper="2.09439510239" velocity="10"/>
    <dynamics damping="0.5"/>
  </joint>
  <link name="link_3">
    <inertial>
      <origin rpy="0 0 0" xyz="0.0222 0.05 0.0172"/>
      <mass value="5"/>
      <inertia ixx="0.0477" ixy="0.0668" ixz="0.0283" iyy="0.096" iyz="0.0205" izz="-0.0367"/>
    </inertial>
  </link>
  <joint name="joint_3" type="revolute">
    <parent link="link_2"/>
    <child link="link_3"/>
    <origin rpy="1.5707963267948966 -3.141592653589793 -1.5707963267948966" xyz="0 0 0.1496"/>
    <axis xyz="0 0 1"/>
    <limit effort="300" lower="-2.09439510239" upper="2.09439510239" velocity="10"/>
    <dynamics damping="0.5"/>
  </joint>
  <link name="link_4">
    <inertial>
      <origin rpy="0 0 0" xyz="0.0111 0.0585 0.0678"/>
      <mass value="5"/>
      <inertia ixx="0.0666" ixy="-0.0223" ixz="0.0547" iyy="-0.0552" iyz="0.0697" izz="0.0781"/>
    </inertial>
  </link>
  <joint name="joint_4" type="revolute">
    <parent link="link_3"/>
    <child link="link_4"/>
    <origin rpy="-1.5707963267948966 0 3.141592653589793" xyz="0 0 0.1616"/>
    <axis xyz="0 0 1"/>
    <limit effort="300" lower="-2.09439510239" upper="2.09439510239" velocity="10"/>
    <dynamics damping="0.5"/>
  </joint>
  <link name="link_5">
    <inertial>
      <origin rpy="0 0 0" xyz="0.0657 0.013 0.0737"/>
      <mass value="5"/>
      <inertia ixx="-0.0159" ixy="0.0095" ixz="0.0342" iyy="0.0562" iyz="0.0394" izz="-0.0495"/>
    </inertial>
  </link>
  <joint name="joint_5" type="revolute">
    <parent link="world"/>
    <child link="link_5"/>
    <origin rpy="1.5707963267948966 1.5707963267948966 0" xyz="0 0 0.0838"/>
    <axis xyz="0 0 1"/>
    <limit effort="300" lower="-2.09439510239" upper="2.09439510239" velocity="10"/>
    <dynamics damping="0.5"/>
  </joint>
  <link name="link_6">
    <inertial>
      <origin rpy="0 0 0" xyz="0.0032 0.0696 0.0527"/>
      <mass value="5"/>
      <inertia ixx="-0.0272" ixy="-0.0404" ixz="0.0622" iyy="-0.0441" iyz="0.0783" izz="0.049"/>
    </inertial>
  </link>
  <joint name="joint_6" type="revolute">
    <parent link="link_5"/>
    <child link="link_6"/>
    <origin rpy="-1.5707963267948966 -1.5707963267948966 1.5707963267948966" xyz="0 0 0.0994"/>
    <axis xyz="0 0 1"/>
    <limit effort="300" lower="-2.09439510239" upper="2.09439510239" velocity="10"/>
    <dynamics damping="0.5"/>
  </joint>
  <link name="link_7">
    <inertial>
      <origin rpy="0 0 0" xyz="0.0545 0.0042 0.0349"/>
      <mass value="5"/>
      <inertia ixx="0.0785" ixy="0.0467" ixz="0.0921" iyy="0.0989" iyz="-0.0915" izz="0.0318"/>
    </inertial>
  </link>
  <joint name="joint_7" type="revolute">
    <parent link="link_6"/>
    <child link="link_7"/>
    <origin rpy="0 0 -3.141592653589793" xyz="0 0 0.0062"/>
    <axis xyz="0 0 1"/>
    <limit effort="300" lower="-2.09439510239" upper="2.09439510239" velocity="10"/>
    <dynamics damping="0.5"/>
  </joint>
</robot>
