<?xml version="1.0" encoding="utf-8"?>
<robot name="iiwa">
  <link name="world"/>
  <link name="link_1">
    <inertial>
      <origin rpy="0 0 0" xyz="0.0313 0.0278 0.0808"/>
      <mass value="5"/>
      <inertia ixx="0.0589" ixy="-0.0734" ixz="0.0991" iyy="-0.0197" iyz="0.0437" izz="-0.0578"/>
    </inertial>
  </link>
  <joint name="joint_1" type="revolute">
    <parent link="world"/>
    <child link="link_1"/>
    <origin rpy="0 -1.5707963267948966 0" xyz="0 0 0.1345"/>
    <axis xyz="0 0 1"/>
    <limit effort="300" lower="-2.09439510239" upper="2.09439510239" velocity="10"/>
    <dynamics damping="0.5"/>
  </joint>
  <link name="link_2">
    <inertial>
      <origin rpy="0 0 0" xyz="0.0479 0.0779 0.0343"/>
      <mass value="5"/>
      <inertia ixx="-0.0537" ixy="-0.0714" ixz="0.0364" iyy="0.036" iyz="0.0906" izz="0.0454"/>
    </inertial>
  </link>
  <joint name="joint_2" type="revolute">
    <parent link="world"/>
    <child link="link_2"/>
    <origin rpy="0 0 -3.141592653589793" xyz="0 0 0.0501"/>
    <axis xyz="0 0 1"/>
    <limit effort="300" lower="-2.09439510239" upper="2.09439510239" velocity="10"/>
    <dynamics damping="0.5"/>
  </joint>
  <link name="link_3">
    <inertial>
      <origin rpy="0 0 0" xyz="0.0926 0.0268 0.0129"/>
      <mass value="5"/>
      <inertia ixx="-0.0367" ixy="0.0756" ixz="-0.0509" iyy="0.0591" iyz="-0.0863" izz="0.0288"/>
    </inertial>
  </link>
  <joint name="joint_3" type="revolute">
    <parent link="link_2"/>
    <child link="link_3"/>
    <origin rpy="1.5707963267948966 -3.141592653589793 3.141592653589793" xyz="0 0 0.1569"/>
    <axis xyz="0 0 1"/>
    <limit effort="300" lower="-2.09439510239" upper="2.09439510239" velocity="10"/>
    <dynamics damping="0.5"/>
  </joint>
  <link name="link_4">
    <inertial>
      <origin rpy="0 0 0" xyz="0.0822 0.0048 0.0391"/>
      <mass value="5"/>
      <inertia ixx="0.0836" ixy="0.0979" ixz="0.0659" iyy="0.0994" iyz="-0.0831" izz="0.0059"/>
    </inertial>
  </link>
  <joint name="joint_4" type="revolute">
    <parent link="link_3"/>
    <child link="link_4"/>
    <origin rpy="3.141592653589793 -1.5707963267948966 -1.5707963267948966" xyz="0 0 0.0047"/>
    <axis xyz="0 0 1"/>
    <limit effort="300" lower="-2.09439510239" upper="2.09439510239" velocity="10"/>
    <dynamics damping="0.5"/>
  </joint>
  <link name="link_5">
    <inertial>
      <origin rpy="0 0 0" xyz="0.0002 0.0822 0.0854"/>
      <mass value="5"/>
      <inertia ixx="0.0498" ixy="0.0227" ixz="0.0629" iyy="0.0481" iyz="0.0448" izz="-0.098"/>
    </inertial>
  </link>
  <joint name="joint_5" type="revolute">
    <parent link="link_4"/>
    <child link="link_5"/>
    <origin rpy="0 -1.5707963267948966 3.141592653589793" xyz="0 0 0.0045"/>
    <axis xyz="0 0 1"/>
    <limit effort="300" lower="-2.09439510239" upper="2.09439510239" velocity="10"/>
    <dynamics damping="0.5"/>
  </joint>
  <link name="link_6">
    <inertial>
      <origin rpy="0 0 0" xyz="0.0087 0.0928 0.0259"/>
      <mass value="5"/>
      <inertia ixx="-0.0939" ixy="0.0759" ixz="0.0212" iyy="0.09" iyz="0.0986" izz="0.0475"/>
    </inertial>
  </link>
  <joint name="joint_6" type="revolute">
    <parent link="link_5"/>
    <child link="link_6"/>
    <origin rpy="1.5707963267948966 3.141592653589793 3.141592653589793" xyz="0 0 0.0043"/>
    <axis xyz="0 0 1"/>
    <limit effort="300" lower="-2.09439510239" upper="2.09439510239" velocity="10"/>
    <dynamics damping="0.5"/>
  </joint>
  <link name="link_7">
    <inertial>
      <origin rpy="0 0 0" xyz="0.08 0.0948 0.0654"/>
      <mass value="5"/>
      <inertia ixx="-0.0305" ixy="0.0827" ixz="0.0634" iyy="0.049" iyz="-0.0976" izz="0.074"/>
    </inertial>
  </link>
  <joint name="joint_7" type="revolute">
    <parent link="link_6"/>
    <child link="link_7"/>
    <origin rpy="-1.5707963267948966 -3.141592653589793 1.5707963267948966" xyz="0 0 0.1921"/>
    <axis xyz="0 0 1"/>
    <limit effort="300" lower="-2.09439510239" upper="2.09439510239" velocity="10"/>
    <dynamics damping="0.5"/>
  </joint>
  <link name="link_8">
    <inertial>
      <origin rpy="0 0 0" xyz="0.0558 0.0212 0.0596"/>
      <mass value="5"/>
      <inertia ixx="0.0216" ixy="-0.0847" ixz="-0.067" iyy="-0.0567" iyz="-0.0237" izz="0.0164"/>
    </inertial>
  </link>
  <joint name="joint_8" type="revolute">
    <parent link="link_7"/>
    <child link="link_8"/>
    <origin rpy="-1.5707963267948966 1.5707963267948966 0" xyz="0 0 0.0251"/>
    <axis xyz="0 0 1"/>
    <limit effort="300" lower="-2.09439510239" upper="2.09439510239" velocity="10"/>
    <dynamics damping="0.5"/>
  </joint>
  <link name="link_9">
    <inertial>
      <origin rpy="0 0 0" xyz="0.0694 0.05 0.0162"/>
      <mass value="5"/>
      <inertia ixx="0.0863" ixy="-0.0632" ixz="-0.0174" iyy="-0.066" iyz="0.0697" izz="0.0348"/>
    </inertial>
  </link>
  <joint name="joint_9" type="revolute">
    <parent link="link_8"/>
    <child link="link_9"/>
    <origin rpy="3.141592653589793 -3.141592653589793 -3.141592653589793" xyz="0 0 0.1758"/>
    <axis xyz="0 0 1"/>
    <limit effort="300" lower="-2.09439510239" upper="2.09439510239" velocity="10"/>
    <dynamics damping="0.5"/>
  </joint>
  <link name="link_10">
    <inertial>
      <origin rpy="0 0 0" xyz="0.0832 0.0778 0.0412"/>
      <mass value="5"/>
      <inertia ixx="-0.0861" ixy="-0.0624" ixz="0.0178" iyy="-0.0305" iyz="-0.0236" izz="0.085"/>
    </inertial>
  </link>
  <joint name="joint_10" type="revolute">
    <parent link="link_9"/>
    <child link="link_10"/>
    <origin rpy="-3.141592653589793 -1.5707963267948966 -1.5707963267948966" xyz="0 0 0.198"/>
    <axis xyz="0 0 1"/>
    <limit effort="300" lower="-2.09439510239" upper="2.09439510239" velocity="10"/>
    <dynamics damping="0.5"/>
  </joint>
  <link name="link_11">
    <inertial>
      <origin rpy="0 0 0" xyz="0.0398 0.0356 0.0527"/>
      <mass value="5"/>
      <inertia ixx="0.0319" ixy="-0.0693" ixz="-0.0877" iyy="-0.077" iyz="-0.0892" izz="-0.095"/>
    </inertial>
  </link>
  <joint name="joint_11" type="revolute">
    <parent link="link_10"/>
    <child link="link_11"/>
    <origin rpy="-1.5707963267948966 1.5707963267948966 -3.141592653589793" xyz="0 0 0.1799"/>
    <axis xyz="0 0 1"/>
    <limit effort="300" lower="-2.09439510239" upper="2.09439510239" velocity="10"/>
    <dynamics damping="0.5"/>
  </joint>
  <link name="link_12">
    <inertial>
      <origin rpy="0 0 0" xyz="0.0993 0.0807 0.0441"/>
      <mass value="5"/>
      <inertia ixx="-0.0098" ixy="-0.058" ixz="0.0923" iyy="0.0038" iyz="0.0736" izz="-0.0199"/>
    </inertial>
  </link>
  <joint name="joint_12" type="revolute">
    <parent link="world"/>
    <child link="link_12"/>
    <origin rpy="-3.141592653589793 1.5707963267948966 1.5707963267948966" xyz="0 0 0.0636"/>
    <axis xyz="0 0 1"/>
    <limit effort="300" lower="-2.09439510239" upper="2.09439510239" velocity="10"/>
    <dynamics damping="0.5"/>
  </joint>
  <link name="link_13">
    <inertial>
      <origin rpy="0 0 0" xyz="0.0517 0.0739 0.079"/>
      <mass value="5"/>
      <inertia ixx="-0.0219" ixy="0.0022" ixz="-0.0101" iyy="-0.0179" iyz="-0.0018" izz="-0.0934"/>
    </inertial>
  </link>
  <joint name="joint_13" type="revolute">
    <parent link="link_12"/>
    <child link="link_13"/>
    <origin rpy="1.5707963267948966 3.141592653589793 1.5707963267948966" xyz="0 0 0.1097"/>
    <axis xyz="0 0 1"/>
    <limit effort="300" lower="-2.09439510239" upper="2.09439510239" velocity="10"/>
    <dynamics damping="0.5"/>
  </joint>
  <link name="link_14">
    <inertial>
      <origin rpy="0 0 0" xyz="0.0907 0.075 0.0725"/>
      <mass value="5"/>
      <inertia ixx="-0.0882" ixy="0.0752" ixz="-0.0128" iyy="0.0858" iyz="-0.0731" izz="-0.0483"/>
    </inertial>
  </link>
  <joint name="joint_14" type="revolute">
    <parent link="link_13"/>
    <child link="link_14"/>
    <origin rpy="3.141592653589793 -1.5707963267948966 -1.5707963267948966" xyz="0 0 0.1052"/>
    <axis xyz="0 0 1"/>
    <limit effort="300" lower="-2.09439510239" upper="2.09439510239" velocity="10"/>
    <dynamics damping="0.5"/>
  </joint>
  <link name="link_15">
    <inertial>
      <origin rpy="0 0 0" xyz="0.0705 0.0663 0.0892"/>
      <mass value="5"/>
      <inertia ixx="-0.0426" ixy="0.028" ixz="0.009" iyy="0.0118" iyz="-0.0994" izz="-0.0715"/>
    </inertial>
  </link>
  <joint name="joint_15" type="revolute">
    <parent link="link_14"/>
    <child link="link_15"/>
    <origin rpy="0 0 3.141592653589793" xyz="0 0 0.008"/>
    <axis xyz="0 0 1"/>
    <limit effort="300" lower="-2.09439510239" upper="2.09439510239" velocity="10"/>
    <dynamics damping="0.5"/>
  </joint>
  <link name="link_16">
    <inertial>
      <origin rpy="0 0 0" xyz="0.0264 0.0633 0.0704"/>
      <mass value="5"/>
      <inertia ixx="-0.0041" ixy="-0.077" ixz="0.0029" iyy="-0.0482" iyz="-0.0724" izz="-0.0754"/>
    </inertial>
  </link>
  <joint name="joint_16" type="revolute">
    <parent link="link_15"/>
    <child link="link_16"/>
    <origin rpy="-1.5707963267948966 0 -3.141592653589793" xyz="0 0 0.0771"/>
    <axis xyz="0 0 1"/>
    <limit effort="300" lower="-2.09439510239" upper="2.09439510239" velocity="10"/>
    <dynamics damping="0.5"/>
  </joint>
  <link name="link_17">
    <inertial>
      <origin rpy="0 0 0" xyz="0.0041 0.0389 0.0866"/>
      <mass value="5"/>
      <inertia ixx="0.0368" ixy="-0.0816" ixz="-0.0163" iyy="0.0296" iyz="-0.084" izz="-0.0999"/>
    </inertial>
  </link>
  <joint name="joint_17" type="revolute">
    <parent link="link_16"/>
    <child link="link_17"/>
    <origin rpy="-3.141592653589793 -1.5707963267948966 -3.141592653589793" xyz="0 0 0.0054"/>
    <axis xyz="0 0 1"/>
    <limit effort="300" lower="-2.09439510239" upper="2.09439510239" velocity="10"/>
    <dynamics damping="0.5"/>
  </joint>
  <link name="link_18">
    <inertial>
      <origin rpy="0 0 0" xyz="0.0661 0.0457 0.0763"/>
      <mass value="5"/>
      <inertia ixx="-0.0357" ixy="0.0447" ixz="0.0085" iyy="0.0325" iyz="-0.0181" izz="-0.0196"/>
    </inertial>
  </link>
  <joint name="joint_18" type="revolute">
    <parent link="link_17"/>
    <child link="link_18"/>
    <origin rpy="0 -1.5707963267948966 -3.141592653589793" xyz="0 0 0.1509"/>
    <axis xyz="0 0 1"/>
    <limit effort="300" lower="-2.09439510239" upper="2.09439510239" velocity="10"/>
    <dynamics damping="0.5"/>
  </joint>
  <link name="link_19">
    <inertial>
      <origin rpy="0 0 0" xyz="0.0094 0.0699 0.0422"/>
      <mass value="5"/>
      <inertia ixx="-0.0409" ixy="-0.0581" ixz="0.0941" iyy="0.0095" iyz="-0.0454" izz="-0.01"/>
    </inertial>
  </link>
  <joint name="joint_19" type="revolute">
    <parent link="link_18"/>
    <child link="link_19"/>
    <origin rpy="1.5707963267948966 3.141592653589793 -3.141592653589793" xyz="0 0 0.1814"/>
    <axis xyz="0 0 1"/>
    <limit effort="300" lower="-2.09439510239" upper="2.09439510239" velocity="10"/>
    <dynamics damping="0.5"/>
  </joint>
  <link name="link_20">
    <inertial>
      <origin rpy="0 0 0" xyz="0.0015 0.0014 0.0181"/>
      <mass value="5"/>
      <inertia ixx="-0.0309" ixy="0.0552" ixz="0.0238" iyy="0.0091" iyz="-0.0561" izz="-0.0436"/>
    </inertial>
  </link>
  <joint name="joint_20" type="revolute">
    <parent link="link_19"/>
    <child link="link_20"/>
    <origin rpy="3.141592653589793 -1.5707963267948966 -3.141592653589793" xyz="0 0 0.1531"/>
    <axis xyz="0 0 1"/>
    <limit effort="300" lower="-2.09439510239" upper="2.09439510239" velocity="10"/>
    <dynamics damping="0.5"/>
  </joint>
  <link name="link_21">
    <inertial>
      <origin rpy="0 0 0" xyz="0.0081 0.0621 0.0349"/>
      <mass value="5"/>
      <inertia ixx="-0.0852" ixy="0.0193" ixz="0.0707" iyy="0.0826" iyz="-0.0173" izz="-0.0264"/>
    </inertial>
  </link>
  <joint name="joint_21" type="revolute">
    <parent link="link_20"/>
    <child link="link_21"/>
    <origin rpy="-3.141592653589793 1.5707963267948966 -1.5707963267948966" xyz="0 0 0.177"/>
    <axis xyz="0 0 1"/>
    <limit effort="300" lower="-2.09439510239" upper="2.09439510239" velocity="10"/>
    <dynamics damping="0.5"/>
  </joint>
</robot>
