<?xml version="1.0" encoding="utf-8"?>
<robot name="iiwa">
  <link name="world"/>
  <link name="link_1">
    <inertial>
      <origin rpy="0 0 0" xyz="0.045 0.0874 0.0446"/>
      <mass value="5"/>
      <inertia ixx="-0.0817" ixy="0.0767" ixz="-0.0266" iyy="0.0344" iyz="-0.0367" izz="-0.0491"/>
    </inertial>
  </link>
  <joint name="joint_1" type="revolute">
    <parent link="world"/>
    <child link="link_1"/>
    <origin rpy="0 0 0" xyz="0 0 0.0059"/>
    <axis xyz="0 0 1"/>
    <limit effort="300" lower="-2.09439510239" upper="2.09439510239" velocity="10"/>
    <dynamics damping="0.5"/>
  </joint>
  <link name="link_2">
    <inertial>
      <origin rpy="0 0 0" xyz="0.0134 0.0343 0.0271"/>
      <mass value="5"/>
      <inertia ixx="0.0043" ixy="-0.0609" ixz="0.0464" iyy="0.0834" iyz="0.097" izz="0.0386"/>
    </inertial>
  </link>
  <joint name="joint_2" type="revolute">
    <parent link="world"/>
    <child link="link_2"/>
    <origin rpy="3.141592653589793 3.141592653589793 1.5707963267948966" xyz="0 0 0.093"/>
    <axis xyz="0 0 1"/>
    <limit effort="300" lower="-2.09439510239" upper="2.09439510239" velocity="10"/>
    <dynamics damping="0.5"/>
  </joint>
  <link name="link_3">
    <inertial>
      <origin rpy="0 0 0" xyz="0.0091 0.0667 0.0163"/>
      <mass value="5"/>
      <inertia ixx="-0.0376" ixy="-0.0283" ixz="0.079" iyy="-0.0345" iyz="-0.0153" izz="-0.0768"/>
    </inertial>
  </link>
  <joint name="joint_3" type="revolute">
    <parent link="world"/>
    <child link="link_3"/>
    <origin rpy="0 0 -3.141592653589793" xyz="0 0 0.1684"/>
    <axis xyz="0 0 1"/>
    <limit effort="300" lower="-2.09439510239" upper="2.09439510239" velocity="10"/>
    <dynamics damping="0.5"/>
  </joint>
</robot>
