<?xml version="1.0" encoding="utf-8"?>
<robot name="iiwa">
  <link name="world"/>
  <link name="link_1">
    <inertial>
      <origin rpy="0 0 0" xyz="0.0675 0.0235 0.0463"/>
      <mass value="5"/>
      <inertia ixx="0.0423" ixy="-0.0799" ixz="0.0249" iyy="0.0284" iyz="0.0804" izz="-0.0784"/>
    </inertial>
  </link>
  <joint name="joint_1" type="revolute">
    <parent link="world"/>
    <child link="link_1"/>
    <origin rpy="1.5707963267948966 -1.5707963267948966 0" xyz="0 0 0.1116"/>
    <axis xyz="0 0 1"/>
    <limit effort="300" lower="-2.09439510239" upper="2.09439510239" velocity="10"/>
    <dynamics damping="0.5"/>
  </joint>
  <link name="link_2">
    <inertial>
      <origin rpy="0 0 0" xyz="0.0426 0.0738 0.0082"/>
      <mass value="5"/>
      <inertia ixx="0.0107" ixy="-0.0058" ixz="0.0798" iyy="0.0697" iyz="0.0672" izz="-0.0751"/>
    </inertial>
  </link>
  <joint name="joint_2" type="revolute">
    <parent link="world"/>
    <child link="link_2"/>
    <origin rpy="-1.5707963267948966 0 -3.141592653589793" xyz="0 0 0.0227"/>
    <axis xyz="0 0 1"/>
    <limit effort="300" lower="-2.09439510239" upper="2.09439510239" velocity="10"/>
    <dynamics damping="0.5"/>
  </joint>
  <link name="link_3">
    <inertial>
      <origin rpy="0 0 0" xyz="0.0674 0.0666 0.0526"/>
      <mass value="5"/>
      <inertia ixx="0.0403" ixy="0.0601" ixz="-0.0787" iyy="-0.0842" iyz="-0.0676" izz="-0.0563"/>
    </inertial>
  </link>
  <joint name="joint_3" type="revolute">
    <parent link="link_2"/>
    <child link="link_3"/>
    <origin rpy="0 -1.5707963267948966 1.5707963267948966" xyz="0 0 0.0637"/>
    <axis xyz="0 0 1"/>
    <limit effort="300" lower="-2.09439510239" upper="2.09439510239" velocity="10"/>
    <dynamics damping="0.5"/>
  </joint>
  <link name="link_4">
    <inertial>
      <origin rpy="0 0 0" xyz="0.0613 0.0121 0.0139"/>
      <mass value="5"/>
      <inertia ixx="-0.0256" ixy="-0.0791" ixz="-0.0716" iyy="-0.0862" iyz="-0.0893" izz="-0.0053"/>
    </inertial>
  </link>
  <joint name="joint_4" type="revolute">
    <parent link="link_3"/>
    <child link="link_4"/>
    <origin rpy="3.141592653589793 3.141592653589793 0" xyz="0 0 0.003"/>
    <axis xyz="0 0 1"/>
    <limit effort="300" lower="-2.09439510239" upper="2.09439510239" velocity="10"/>
    <dynamics damping="0.5"/>
  </joint>
  <link name="link_5">
    <inertial>
      <origin rpy="0 0 0" xyz="0.0653 0.0577 0.031"/>
      <mass value="5"/>
      <inertia ixx="-0.0162" ixy="-0.0049" ixz="0.0429" iyy="-0.0393" iyz="0.0489" izz="-0.017"/>
    </inertial>
  </link>
  <joint name="joint_5" type="revolute">
    <parent link="link_4"/>
    <child link="link_5"/>
    <origin rpy="1.5707963267948966 3.141592653589793 0" xyz="0 0 0.178"/>
    <axis xyz="0 0 1"/>
    <limit effort="300" lower="-2.09439510239" upper="2.09439510239" velocity="10"/>
    <dynamics damping="0.5"/>
  </joint>
  <link name="link_6">
    <inertial>
      <origin rpy="0 0 0" xyz="0.0531 0.0404 0.0175"/>
      <mass value="5"/>
      <inertia ixx="0.0602" ixy="0.0611" ixz="-0.061" iyy="0.027" iyz="0.0011" izz="0.0443"/>
    </inertial>
  </link>
  <joint name="joint_6" type="revolute">
    <parent link="link_5"/>
    <child link="link_6"/>
    <origin rpy="-1.5707963267948966 -3.141592653589793 1.5707963267948966" xyz="0 0 0.0188"/>
    <axis xyz="0 0 1"/>
    <limit effort="300" lower="-2.09439510239" upper="2.09439510239" velocity="10"/>
    <dynamics damping="0.5"/>
  </joint>
  <link name="link_7">
    <inertial>
      <origin rpy="0 0 0" xyz="0.0046 0.0203 0.0367"/>
      <mass value="5"/>
      <inertia ixx="-0.0654" ixy="0.03" ixz="0.0563" iyy="0.0351" iyz="-0.0249" izz="0.0525"/>
    </inertial>
  </link>
  <joint name="joint_7" type="revolute">
    <parent link="link_6"/>
    <child link="link_7"/>
    <origin rpy="3.141592653589793 0 1.5707963267948966" xyz="0 0 0.0475"/>
    <axis xyz="0 0 1"/>
    <limit effort="300" lower="-2.09439510239" upper="2.09439510239" velocity="10"/>
    <dynamics damping="0.5"/>
  </joint>
  <link name="link_8">
    <inertial>
      <origin rpy="0 0 0" xyz="0.0526 0.0451 0.0452"/>
      <mass value="5"/>
      <inertia ixx="0.0352" ixy="-0.0807" ixz="-0.0967" iyy="0.0048" iyz="0.0089" izz="0.0778"/>
    </inertial>
  </link>
  <joint name="joint_8" type="revolute">
    <parent link="link_7"/>
    <child link="link_8"/>
    <origin rpy="-1.5707963267948966 1.5707963267948966 3.141592653589793" xyz="0 0 0.1439"/>
    <axis xyz="0 0 1"/>
    <limit effort="300" lower="-2.09439510239" upper="2.09439510239" velocity="10"/>
    <dynamics damping="0.5"/>
  </joint>
  <link name="link_9">
    <inertial>
      <origin rpy="0 0 0" xyz="0.0749 0.065 0.0526"/>
      <mass value="5"/>
      <inertia ixx="0.0932" ixy="0.0143" ixz="-0.0817" iyy="0.0531" iyz="0.0974" izz="-0.0584"/>
    </inertial>
  </link>
  <joint name="joint_9" type="revolute">
    <parent link="world"/>
    <child link="link_9"/>
    <origin rpy="0 3.141592653589793 3.141592653589793" xyz="0 0 0.0106"/>
    <axis xyz="0 0 1"/>
    <limit effort="300" lower="-2.09439510239" upper="2.09439510239" velocity="10"/>
    <dynamics damping="0.5"/>
  </joint>
  <link name="link_10">
    <inertial>
      <origin rpy="0 0 0" xyz="0.0511 0.0653 0.0894"/>
      <mass value="5"/>
      <inertia ixx="-0.0276" ixy="0.0487" ixz="-0.0423" iyy="-0.0835" iyz="0.089" izz="0.0225"/>
    </inertial>
  </link>
  <joint name="joint_10" type="revolute">
    <parent link="link_9"/>
    <child link="link_10"/>
    <origin rpy="-3.141592653589793 0 -1.5707963267948966" xyz="0 0 0.0421"/>
    <axis xyz="0 0 1"/>
    <limit effort="300" lower="-2.09439510239" upper="2.09439510239" velocity="10"/>
    <dynamics damping="0.5"/>
  </joint>
  <link name="link_11">
    <inertial>
      <origin rpy="0 0 0" xyz="0.0431 0.0769 0.0764"/>
      <mass value="5"/>
      <inertia ixx="0.0743" ixy="-0.0624" ixz="-0.0137" iyy="0.0275" iyz="0.0295" izz="0.0726"/>
    </inertial>
  </link>
  <joint name="joint_11" type="revolute">
    <parent link="link_10"/>
    <child link="link_11"/>
    <origin rpy="0 -1.5707963267948966 -1.5707963267948966" xyz="0 0 0.0794"/>
    <axis xyz="0 0 1"/>
    <limit effort="300" lower="-2.09439510239" upper="2.09439510239" velocity="10"/>
    <dynamics damping="0.5"/>
  </joint>
  <link name="link_12">
    <inertial>
      <origin rpy="0 0 0" xyz="0.0399 0.0438 0.0645"/>
      <mass value="5"/>
      <inertia ixx="-0.0845" ixy="0.0199" ixz="-0.0009" iyy="0.0681" iyz="0.0367" izz="-0.0905"/>
    </inertial>
  </link>
  <joint name="joint_12" type="revolute">
    <parent link="link_11"/>
    <child link="link_12"/>
    <origin rpy="0 0 3.141592653589793" xyz="0 0 0.1284"/>
    <axis xyz="0 0 1"/>
    <limit effort="300" lower="-2.09439510239" upper="2.09439510239" velocity="10"/>
    <dynamics damping="0.5"/>
  </joint>
  <link name="link_13">
    <inertial>
      <origin rpy="0 0 0" xyz="0.0596 0.0136 0.0655"/>
      <mass value="5"/>
      <inertia ixx="0.03" ixy="-0.0673" ixz="0.0931" iyy="0.0345" iyz="-0.0202" izz="0.0009"/>
    </inertial>
  </link>
  <joint name="joint_13" type="revolute">
    <parent link="link_12"/>
    <child link="link_13"/>
    <origin rpy="-3.141592653589793 3.141592653589793 -1.5707963267948966" xyz="0 0 0.0579"/>
    <axis xyz="0 0 1"/>
    <limit effort="300" lower="-2.09439510239" upper="2.09439510239" velocity="10"/>
    <dynamics damping="0.5"/>
  </joint>
  <link name="link_14">
    <inertial>
      <origin rpy="0 0 0" xyz="0.0103 0.0975 0.0075"/>
      <mass value="5"/>
      <inertia ixx="-0.0288" ixy="-0.0239" ixz="0.0325" iyy="0.0358" iyz="0.0578" izz="-0.0155"/>
    </inertial>
  </link>
  <joint name="joint_14" type="revolute">
    <parent link="link_13"/>
    <child link="link_14"/>
    <origin rpy="-3.141592653589793 1.5707963267948966 -3.141592653589793" xyz="0 0 0.1603"/>
    <axis xyz="0 0 1"/>
    <limit effort="300" lower="-2.09439510239" upper="2.09439510239" velocity="10"/>
    <dynamics damping="0.5"/>
  </joint>
  <link name="link_15">
    <inertial>
      <origin rpy="0 0 0" xyz="0.0386 0.0725 0.0997"/>
      <mass value="5"/>
      <inertia ixx="0.0565" ixy="-0.071" ixz="0.0774" iyy="0.0408" iyz="-0.0791" izz="-0.0864"/>
    </inertial>
  </link>
  <joint name="joint_15" type="revolute">
    <parent link="link_14"/>
    <child link="link_15"/>
    <origin rpy="-1.5707963267948966 0 0" xyz="0 0 0.1998"/>
    <axis xyz="0 0 1"/>
    <limit effort="300" lower="-2.09439510239" upper="2.09439510239" velocity="10"/>
    <dynamics damping="0.5"/>
  </joint>
</robot>
