<?xml version="1.0" encoding="utf-8"?>
<robot name="iiwa">
  <link name="world"/>
  <link name="link_1">
    <inertial>
      <origin rpy="0 0 0" xyz="0.0944 0.0601 0.0001"/>
      <mass value="5"/>
      <inertia ixx="0.011" ixy="-0.0393" ixz="-0.0721" iyy="0.014" iyz="0.0882" izz="-0.06"/>
    </inertial>
  </link>
  <joint name="joint_1" type="revolute">
    <parent link="world"/>
    <child link="link_1"/>
    <origin rpy="3.141592653589793 1.5707963267948966 -1.5707963267948966" xyz="0 0 0.1547"/>
    <axis xyz="0 0 1"/>
    <limit effort="300" lower="-2.09439510239" upper="2.09439510239" velocity="10"/>
    <dynamics damping="0.5"/>
  </joint>
  <link name="link_2">
    <inertial>
      <origin rpy="0 0 0" xyz="0.0216 0.0081 0.0989"/>
      <mass value="5"/>
      <inertia ixx="0.0698" ixy="0.0447" ixz="0.0603" iyy="-0.0518" iyz="0.0644" izz="0.0213"/>
    </inertial>
  </link>
  <joint name="joint_2" type="revolute">
    <parent link="world"/>
    <child link="link_2"/>
    <origin rpy="1.5707963267948966 -3.141592653589793 -3.141592653589793" xyz="0 0 0.037"/>
    <axis xyz="0 0 1"/>
    <limit effort="300" lower="-2.09439510239" upper="2.09439510239" velocity="10"/>
    <dynamics damping="0.5"/>
  </joint>
  <link name="link_3">
    <inertial>
      <origin rpy="0 0 0" xyz="0.0407 0.0647 0.0045"/>
      <mass value="5"/>
      <inertia ixx="-0.0154" ixy="-0.0128" ixz="-0.0284" iyy="-0.0567" iyz="0.0468" izz="-0.0922"/>
    </inertial>
  </link>
  <joint name="joint_3" type="revolute">
    <parent link="link_2"/>
    <child link="link_3"/>
    <origin rpy="3.141592653589793 3.141592653589793 -3.141592653589793" xyz="0 0 0.1022"/>
    <axis xyz="0 0 1"/>
    <limit effort="300" lower="-2.09439510239" upper="2.09439510239" velocity="10"/>
    <dynamics damping="0.5"/>
  </joint>
  <link name="link_4">
    <inertial>
      <origin rpy="0 0 0" xyz="0.0186 0.0311 0.0991"/>
      <mass value="5"/>
      <inertia ixx="-0.0978" ixy="-0.0004" ixz="0.0998" iyy="0.0901" iyz="0.007" izz="0.0579"/>
    </inertial>
  </link>
  <joint name="joint_4" type="revolute">
    <parent link="link_3"/>
    <child link="link_4"/>
    <origin rpy="3.141592653589793 1.5707963267948966 3.141592653589793" xyz="0 0 0.1166"/>
    <axis xyz="0 0 1"/>
    <limit effort="300" lower="-2.09439510239" upper="2.09439510239" velocity="10"/>
    <dynamics damping="0.5"/>
  </joint>
  <link name="link_5">
    <inertial>
      <origin rpy="0 0 0" xyz="0.0043 0.0264 0.0537"/>
      <mass value="5"/>
      <inertia ixx="0.0428" ixy="-0.0765" ixz="0.0801" iyy="0.0247" iyz="-0.0291" izz="0.0267"/>
    </inertial>
  </link>
  <joint name="joint_5" type="revolute">
    <parent link="link_4"/>
    <child link="link_5"/>
    <origin rpy="-1.5707963267948966 1.5707963267948966 -1.5707963267948966" xyz="0 0 0.174"/>
    <axis xyz="0 0 1"/>
    <limit effort="300" lower="-2.09439510239" upper="2.09439510239" velocity="10"/>
    <dynamics damping="0.5"/>
  </joint>
  <link name="link_6">
    <inertial>
      <origin rpy="0 0 0" xyz="0.0107 0.0756 0.0366"/>
      <mass value="5"/>
      <inertia ixx="-0.069" ixy="-0.0366" ixz="-0.0252" iyy="0.0133" iyz="0.0987" izz="0.0784"/>
    </inertial>
  </link>
  <joint name="joint_6" type="revolute">
    <parent link="link_5"/>
    <child link="link_6"/>
    <origin rpy="-3.141592653589793 -3.141592653589793 -1.5707963267948966" xyz="0 0 0.0956"/>
    <axis xyz="0 0 1"/>
    <limit effort="300" lower="-2.09439510239" upper="2.09439510239" velocity="10"/>
    <dynamics damping="0.5"/>
  </joint>
  <link name="link_7">
    <inertial>
      <origin rpy="0 0 0" xyz="0.0955 0.0596 0.08"/>
      <mass value="5"/>
      <inertia ixx="0.0867" ixy="0.0997" ixz="0.0258" iyy="-0.0413" iyz="0.0624" izz="0.0763"/>
    </inertial>
  </link>
  <joint name="joint_7" type="revolute">
    <parent link="link_6"/>
    <child link="link_7"/>
    <origin rpy="-3.141592653589793 1.5707963267948966 -1.5707963267948966" xyz="0 0 0.125"/>
    <axis xyz="0 0 1"/>
    <limit effort="300" lower="-2.09439510239" upper="2.09439510239" velocity="10"/>
    <dynamics damping="0.5"/>
  </joint>
  <link name="link_8">
    <inertial>
      <origin rpy="0 0 0" xyz="0.0177 0.0688 0.0759"/>
      <mass value="5"/>
      <inertia ixx="-0.0365" ixy="-0.0964" ixz="-0.055" iyy="-0.0463" iyz="0.0166" izz="0.0777"/>
    </inertial>
  </link>
  <joint name="joint_8" type="revolute">
    <parent link="world"/>
    <child link="link_8"/>
    <origin rpy="1.5707963267948966 0 -3.141592653589793" xyz="0 0 0.1148"/>
    <axis xyz="0 0 1"/>
    <limit effort="300" lower="-2.09439510239" upper="2.09439510239" velocity="10"/>
    <dynamics damping="0.5"/>
  </joint>
  <link name="link_9">
    <inertial>
      <origin rpy="0 0 0" xyz="0.0555 0.0408 0.0832"/>
      <mass value="5"/>
      <inertia ixx="0.0308" ixy="-0.0954" ixz="-0.0684" iyy="0.0176" iyz="0.0316" izz="-0.018"/>
    </inertial>
  </link>
  <joint name="joint_9" type="revolute">
    <parent link="link_8"/>
    <child link="link_9"/>
    <origin rpy="0 3.141592653589793 -1.5707963267948966" xyz="0 0 0.185"/>
    <axis xyz="0 0 1"/>
    <limit effort="300" lower="-2.09439510239" upper="2.09439510239" velocity="10"/>
    <dynamics damping="0.5"/>
  </joint>
  <link name="link_10">
    <inertial>
      <origin rpy="0 0 0" xyz="0.0332 0.0304 0.0487"/>
      <mass value="5"/>
      <inertia ixx="0.0046" ixy="-0.0659" ixz="0.0515" iyy="-0.0229" iyz="0.0476" izz="-0.058"/>
    </inertial>
  </link>
  <joint name="joint_10" type="revolute">
    <parent link="link_9"/>
    <child link="link_10"/>
    <origin rpy="3.141592653589793 1.5707963267948966 -3.141592653589793" xyz="0 0 0.0377"/>
    <axis xyz="0 0 1"/>
    <limit effort="300" lower="-2.09439510239" upper="2.09439510239" velocity="10"/>
    <dynamics damping="0.5"/>
  </joint>
  <link name="link_11">
    <inertial>
      <origin rpy="0 0 0" xyz="0.0898 0.0001 0.0406"/>
      <mass value="5"/>
      <inertia ixx="0.0144" ixy="-0.0575" ixz="-0.0649" iyy="-0.0439" iyz="-0.0261" izz="0.0576"/>
    </inertial>
  </link>
  <joint name="joint_11" type="revolute">
    <parent link="link_10"/>
    <child link="link_11"/>
    <origin rpy="1.5707963267948966 -1.5707963267948966 -1.5707963267948966" xyz="0 0 0.1995"/>
    <axis xyz="0 0 1"/>
    <limit effort="300" lower="-2.09439510239" upper="2.09439510239" velocity="10"/>
    <dynamics damping="0.5"/>
  </joint>
  <link name="link_12">
    <inertial>
      <origin rpy="0 0 0" xyz="0.009 0.03 0.0446"/>
      <mass value="5"/>
      <inertia ixx="-0.0197" ixy="-0.0053" ixz="0.0804" iyy="-0.0725" iyz="-0.0766" izz="0.0006"/>
    </inertial>
  </link>
  <joint name="joint_12" type="revolute">
    <parent link="link_11"/>
    <child link="link_12"/>
    <origin rpy="-3.141592653589793 3.141592653589793 -1.5707963267948966" xyz="0 0 0.1043"/>
    <axis xyz="0 0 1"/>
    <limit effort="300" lower="-2.09439510239" upper="2.09439510239" velocity="10"/>
    <dynamics damping="0.5"/>
  </joint>
  <link name="link_13">
    <inertial>
      <origin rpy="0 0 0" xyz="0.0041 0.0829 0.0158"/>
      <mass value="5"/>
      <inertia ixx="0.0868" ixy="0.059" ixz="-0.0794" iyy="0.0056" iyz="0.0966" izz="-0.0485"/>
    </inertial>
  </link>
  <joint name="joint_13" type="revolute">
    <parent link="link_12"/>
    <child link="link_13"/>
    <origin rpy="1.5707963267948966 0 1.5707963267948966" xyz="0 0 0.0426"/>
    <axis xyz="0 0 1"/>
    <limit effort="300" lower="-2.09439510239" upper="2.09439510239" velocity="10"/>
    <dynamics damping="0.5"/>
  </joint>
</robot>
