<?xml version="1.0" encoding="utf-8"?>
<robot name="iiwa">
  <link name="world"/>
  <link name="link_1">
    <inertial>
      <origin rpy="0 0 0" xyz="0.0286 0.0384 0.0846"/>
      <mass value="5"/>
      <inertia ixx="0.0759" ixy="-0.047" ixz="-0.0793" iyy="-0.0109" iyz="-0.0281" izz="0.0998"/>
    </inertial>
  </link>
  <joint name="joint_1" type="revolute">
    <parent link="world"/>
    <child link="link_1"/>
    <origin rpy="-3.141592653589793 1.5707963267948966 1.5707963267948966" xyz="0 0 0.179"/>
    <axis xyz="0 0 1"/>
    <limit effort="300" lower="-2.09439510239" upper="2.09439510239" velocity="10"/>
    <dynamics damping="0.5"/>
  </joint>
  <link name="link_2">
    <inertial>
      <origin rpy="0 0 0" xyz="0.0573 0.0319 0.0337"/>
      <mass value="5"/>
      <inertia ixx="-0.0956" ixy="-0.0983" ixz="-0.0119" iyy="-0.093" iyz="0.0661" izz="0.0099"/>
    </inertial>
  </link>
  <joint name="joint_2" type="revolute">
    <parent link="world"/>
    <child link="link_2"/>
    <origin rpy="1.5707963267948966 0 0" xyz="0 0 0.017"/>
    <axis xyz="0 0 1"/>
    <limit effort="300" lower="-2.09439510239" upper="2.09439510239" velocity="10"/>
    <dynamics damping="0.5"/>
  </joint>
  <link name="link_3">
    <inertial>
      <origin rpy="0 0 0" xyz="0.0766 0.0643 0.0731"/>
      <mass value="5"/>
      <inertia ixx="-0.0862" ixy="0.0842" ixz="0.0144" iyy="-0.0437" iyz="-0.0923" izz="-0.0083"/>
    </inertial>
  </link>
  <joint name="joint_3" type="revolute">
    <parent link="link_2"/>
    <child link="link_3"/>
    <origin rpy="0 3.141592653589793 0" xyz="0 0 0.1994"/>
    <axis xyz="0 0 1"/>
    <limit effort="300" lower="-2.09439510239" upper="2.09439510239" velocity="10"/>
    <dynamics damping="0.5"/>
  </joint>
  <link name="link_4">
    <inertial>
      <origin rpy="0 0 0" xyz="0.0853 0.0314 0.0654"/>
      <mass value="5"/>
      <inertia ixx="-0.0032" ixy="0.0057" ixz="0.0604" iyy="0.0559" iyz="-0.0623" izz="-0.0581"/>
    </inertial>
  </link>
  <joint name="joint_4" type="revolute">
    <parent link="link_3"/>
    <child link="link_4"/>
    <origin rpy="1.5707963267948966 -1.5707963267948966 1.5707963267948966" xyz="0 0 0.0531"/>
    <axis xyz="0 0 1"/>
    <limit effort="300" lower="-2.09439510239" upper="2.09439510239" velocity="10"/>
    <dynamics damping="0.5"/>
  </joint>
  <link name="link_5">
    <inertial>
      <origin rpy="0 0 0" xyz="0.0901 0.0914 0.0411"/>
      <mass value="5"/>
      <inertia ixx="0.0537" ixy="-0.0411" ixz="0.0266" iyy="0.0168" iyz="-0.0395" izz="0.0534"/>
    </inertial>
  </link>
  <joint name="joint_5" type="revolute">
    <parent link="link_4"/>
    <child link="link_5"/>
    <origin rpy="0 3.141592653589793 -3.141592653589793" xyz="0 0 0.1384"/>
    <axis xyz="0 0 1"/>
    <limit effort="300" lower="-2.09439510239" upper="2.09439510239" velocity="10"/>
    <dynamics damping="0.5"/>
  </joint>
  <link name="link_6">
    <inertial>
      <origin rpy="0 0 0" xyz="0.0501 0.0373 0.0786"/>
      <mass value="5"/>
      <inertia ixx="0.043" ixy="0.0702" ixz="0.0772" iyy="0.0365" iyz="-0.036" izz="-0.0165"/>
    </inertial>
  </link>
  <joint name="joint_6" type="revolute">
    <parent link="link_5"/>
    <child link="link_6"/>
    <origin rpy="0 0 -3.141592653589793" xyz="0 0 0.1075"/>
    <axis xyz="0 0 1"/>
    <limit effort="300" lower="-2.09439510239" upper="2.09439510239" velocity="10"/>
    <dynamics damping="0.5"/>
  </joint>
  <link name="link_7">
    <inertial>
      <origin rpy="0 0 0" xyz="0.0304 0.018 0.0793"/>
      <mass value="5"/>
      <inertia ixx="0.0496" ixy="-0.0909" ixz="-0.0448" iyy="0.0009" iyz="-0.0401" izz="-0.0978"/>
    </inertial>
  </link>
  <joint name="joint_7" type="revolute">
    <parent link="world"/>
    <child link="link_7"/>
    <origin rpy="-3.141592653589793 1.5707963267948966 -1.5707963267948966" xyz="0 0 0.0548"/>
    <axis xyz="0 0 1"/>
    <limit effort="300" lower="-2.09439510239" upper="2.09439510239" velocity="10"/>
    <dynamics damping="0.5"/>
  </joint>
  <link name="link_8">
    <inertial>
      <origin rpy="0 0 0" xyz="0.0541 0.0591 0.0414"/>
      <mass value="5"/>
      <inertia ixx="-0.0145" ixy="-0.022" ixz="-0.0385" iyy="-0.0124" iyz="-0.0029" izz="0.0947"/>
    </inertial>
  </link>
  <joint name="joint_8" type="revolute">
    <parent link="link_7"/>
    <child link="link_8"/>
    <origin rpy="-3.141592653589793 3.141592653589793 1.5707963267948966" xyz="0 0 0.0469"/>
    <axis xyz="0 0 1"/>
    <limit effort="300" lower="-2.09439510239" upper="2.09439510239" velocity="10"/>
    <dynamics damping="0.5"/>
  </joint>
  <link name="link_9">
    <inertial>
      <origin rpy="0 0 0" xyz="0.032 0.0692 0.0803"/>
      <mass value="5"/>
      <inertia ixx="-0.0385" ixy="-0.0561" ixz="-0.0028" iyy="0.0619" iyz="0.0061" izz="-0.0073"/>
    </inertial>
  </link>
  <joint name="joint_9" type="revolute">
    <parent link="link_8"/>
    <child link="link_9"/>
    <origin rpy="0 -3.141592653589793 1.5707963267948966" xyz="0 0 0.1586"/>
    <axis xyz="0 0 1"/>
    <limit effort="300" lower="-2.09439510239" upper="2.09439510239" velocity="10"/>
    <dynamics damping="0.5"/>
  </joint>
  <link name="link_10">
    <inertial>
      <origin rpy="0 0 0" xyz="0.0798 0.0782 0.0192"/>
      <mass value="5"/>
      <inertia ixx="-0.0936" ixy="0.0401" ixz="-0.0015" iyy="-0.0818" iyz="-0.0916" izz="0.072"/>
    </inertial>
  </link>
  <joint name="joint_10" type="revolute">
    <parent link="link_9"/>
    <child link="link_10"/>
    <origin rpy="3.141592653589793 0 -3.141592653589793" xyz="0 0 0.0641"/>
    <axis xyz="0 0 1"/>
    <limit effort="300" lower="-2.09439510239" upper="2.09439510239" velocity="10"/>
    <dynamics damping="0.5"/>
  </joint>
  <link name="link_11">
    <inertial>
      <origin rpy="0 0 0" xyz="0.0744 0.0375 0.0782"/>
      <mass value="5"/>
      <inertia ixx="-0.0011" ixy="-0.0213" ixz="0.0727" iyy="0.0151" iyz="0.0212" izz="0.0481"/>
    </inertial>
  </link>
  <joint name="joint_11" type="revolute">
    <parent link="link_10"/>
    <child link="link_11"/>
    <origin rpy="1.5707963267948966 -3.141592653589793 -1.5707963267948966" xyz="0 0 0.1272"/>
    <axis xyz="0 0 1"/>
    <limit effort="300" lower="-2.09439510239" upper="2.09439510239" velocity="10"/>
    <dynamics damping="0.5"/>
  </joint>
</robot>
