<?xml version="1.0" encoding="utf-8"?>
<robot name="iiwa">
  <link name="world"/>
  <link name="link_1">
    <inertial>
      <origin rpy="0 0 0" xyz="0.0271 0.0585 0.0558"/>
      <mass value="5"/>
      <inertia ixx="-0.059" ixy="-0.0874" ixz="-0.0735" iyy="-0.0151" iyz="-0.0609" izz="-0.0197"/>
    </inertial>
  </link>
  <joint name="joint_1" type="revolute">
    <parent link="world"/>
    <child link="link_1"/>
    <origin rpy="3.141592653589793 3.141592653589793 1.5707963267948966" xyz="0 0 0.0984"/>
    <axis xyz="0 0 1"/>
    <limit effort="300" lower="-2.09439510239" upper="2.09439510239" velocity="10"/>
    <dynamics damping="0.5"/>
  </joint>
  <link name="link_2">
    <inertial>
      <origin rpy="0 0 0" xyz="0.0808 0.0341 0.027"/>
      <mass value="5"/>
      <inertia ixx="0.0562" ixy="0.0578" ixz="-0.0041" iyy="0.0372" iyz="-0.0968" izz="-0.0912"/>
    </inertial>
  </link>
  <joint name="joint_2" type="revolute">
    <parent link="link_1"/>
    <child link="link_2"/>
    <origin rpy="-3.141592653589793 -3.141592653589793 0" xyz="0 0 0.126"/>
    <axis xyz="0 0 1"/>
    <limit effort="300" lower="-2.09439510239" upper="2.09439510239" velocity="10"/>
    <dynamics damping="0.5"/>
  </joint>
  <link name="link_3">
    <inertial>
      <origin rpy="0 0 0" xyz="0.0093 0.0077 0.0558"/>
      <mass value="5"/>
      <inertia ixx="0.0629" ixy="0.0732" ixz="0.0488" iyy="0.0312" iyz="0.0374" izz="-0.0474"/>
    </inertial>
  </link>
  <joint name="joint_3" type="revolute">
    <parent link="link_2"/>
    <child link="link_3"/>
    <origin rpy="0 3.141592653589793 3.141592653589793" xyz="0 0 0.0063"/>
    <axis xyz="0 0 1"/>
    <limit effort="300" lower="-2.09439510239" upper="2.09439510239" velocity="10"/>
    <dynamics damping="0.5"/>
  </joint>
  <link name="link_4">
    <inertial>
      <origin rpy="0 0 0" xyz="0.0707 0.0321 0.0327"/>
      <mass value="5"/>
      <inertia ixx="0.0454" ixy="0.0269" ixz="-0.0466" iyy="-0.006" iyz="-0.03" izz="0.0343"/>
    </inertial>
  </link>
  <joint name="joint_4" type="revolute">
    <parent link="link_3"/>
    <child link="link_4"/>
    <origin rpy="3.141592653589793 -1.5707963267948966 0" xyz="0 0 0.1216"/>
    <axis xyz="0 0 1"/>
    <limit effort="300" lower="-2.09439510239" upper="2.09439510239" velocity="10"/>
    <dynamics damping="0.5"/>
  </joint>
  <link name="link_5">
    <inertial>
      <origin rpy="0 0 0" xyz="0.0121 0.0403 0.0383"/>
      <mass value="5"/>
      <inertia ixx="0.0651" ixy="0.055" ixz="-0.0011" iyy="0.0262" iyz="0.0087" izz="0.0041"/>
    </inertial>
  </link>
  <joint name="joint_5" type="revolute">
    <parent link="link_4"/>
    <child link="link_5"/>
    <origin rpy="-1.5707963267948966 -3.141592653589793 1.5707963267948966" xyz="0 0 0.0345"/>
    <axis xyz="0 0 1"/>
    <limit effort="300" lower="-2.09439510239" upper="2.09439510239" velocity="10"/>
    <dynamics damping="0.5"/>
  </joint>
  <link name="link_6">
    <inertial>
      <origin rpy="0 0 0" xyz="0.0559 0.0369 0.0746"/>
      <mass value="5"/>
      <inertia ixx="-0.095" ixy="-0.0638" ixz="-0.0382" iyy="0.0821" iyz="0.0305" izz="0.0933"/>
    </inertial>
  </link>
  <joint name="joint_6" type="revolute">
    <parent link="link_5"/>
    <child link="link_6"/>
    <origin rpy="1.5707963267948966 -1.5707963267948966 -1.5707963267948966" xyz="0 0 0.0016"/>
    <axis xyz="0 0 1"/>
    <limit effort="300" lower="-2.09439510239" upper="2.09439510239" velocity="10"/>
    <dynamics damping="0.5"/>
  </joint>
  <link name="link_7">
    <inertial>
      <origin rpy="0 0 0" xyz="0.0701 0.0168 0.017"/>
      <mass value="5"/>
      <inertia ixx="-0.0326" ixy="-0.0624" ixz="0.0341" iyy="-0.0224" iyz="-0.0062" izz="0.0626"/>
    </inertial>
  </link>
  <joint name="joint_7" type="revolute">
    <parent link="link_6"/>
    <child link="link_7"/>
    <origin rpy="-3.141592653589793 1.5707963267948966 1.5707963267948966" xyz="0 0 0.1517"/>
    <axis xyz="0 0 1"/>
    <limit effort="300" lower="-2.09439510239" upper="2.09439510239" velocity="10"/>
    <dynamics damping="0.5"/>
  </joint>
  <link name="link_8">
    <inertial>
      <origin rpy="0 0 0" xyz="0.0128 0.0626 0.0249"/>
      <mass value="5"/>
      <inertia ixx="-0.0824" ixy="0.0938" ixz="-0.0708" iyy="-0.0129" iyz="-0.0511" izz="0.016"/>
    </inertial>
  </link>
  <joint name="joint_8" type="revolute">
    <parent link="link_6"/>
    <child link="link_8"/>
    <origin rpy="-3.141592653589793 1.5707963267948966 3.141592653589793" xyz="0 0 0.063"/>
    <axis xyz="0 0 1"/>
    <limit effort="300" lower="-2.09439510239" upper="2.09439510239" velocity="10"/>
    <dynamics damping="0.5"/>
  </joint>
  <link name="link_9">
    <inertial>
      <origin rpy="0 0 0" xyz="0.0725 0.0882 0.0879"/>
      <mass value="5"/>
      <inertia ixx="-0.0615" ixy="0.0125" ixz="0.0315" iyy="-0.0913" iyz="0.0085" izz="-0.018"/>
    </inertial>
  </link>
  <joint name="joint_9" type="revolute">
    <parent link="link_6"/>
    <child link="link_9"/>
    <origin rpy="1.5707963267948966 1.5707963267948966 1.5707963267948966" xyz="0 0 0.1995"/>
    <axis xyz="0 0 1"/>
    <limit effort="300" lower="-2.09439510239" upper="2.09439510239" velocity="10"/>
    <dynamics damping="0.5"/>
  </joint>
</robot>
