<?xml version="1.0" encoding="utf-8"?>
<robot name="iiwa">
  <link name="world"/>
  <link name="link_1">
    <inertial>
      <origin rpy="0 0 0" xyz="0.0555 0.0076 0.0603"/>
      <mass value="5"/>
      <inertia ixx="0.0823" ixy="-0.0219" ixz="-0.0853" iyy="-0.0748" iyz="-0.0794" izz="0.0717"/>
    </inertial>
  </link>
  <joint name="joint_1" type="revolute">
    <parent link="world"/>
    <child link="link_1"/>
    <origin rpy="-3.141592653589793 3.141592653589793 -1.5707963267948966" xyz="0 0 0.0184"/>
    <axis xyz="0 0 1"/>
    <limit effort="300" lower="-2.09439510239" upper="2.09439510239" velocity="10"/>
    <dynamics damping="0.5"/>
  </joint>
  <link name="link_2">
    <inertial>
      <origin rpy="0 0 0" xyz="0.0026 0.034 0.0469"/>
      <mass value="5"/>
      <inertia ixx="-0.0606" ixy="0.0942" ixz="0.0966" iyy="0.0308" iyz="0.0539" izz="0.0364"/>
    </inertial>
  </link>
  <joint name="joint_2" type="revolute">
    <parent link="link_1"/>
    <child link="link_2"/>
    <origin rpy="-1.5707963267948966 -1.5707963267948966 0" xyz="0 0 0.0772"/>
    <axis xyz="0 0 1"/>
    <limit effort="300" lower="-2.09439510239" upper="2.09439510239" velocity="10"/>
    <dynamics damping="0.5"/>
  </joint>
  <link name="link_3">
    <inertial>
      <origin rpy="0 0 0" xyz="0.0915 0.0519 0.003"/>
      <mass value="5"/>
      <inertia ixx="-0.007" ixy="-0.081" ixz="0.0847" iyy="0.0627" iyz="-0.0714" izz="0.0814"/>
    </inertial>
  </link>
  <joint name="joint_3" type="revolute">
    <parent link="link_2"/>
    <child link="link_3"/>
    <origin rpy="3.141592653589793 0 -1.5707963267948966" xyz="0 0 0.1068"/>
    <axis xyz="0 0 1"/>
    <limit effort="300" lower="-2.09439510239" upper="2.09439510239" velocity="10"/>
    <dynamics damping="0.5"/>
  </joint>
  <link name="link_4">
    <inertial>
      <origin rpy="0 0 0" xyz="0.0569 0.0321 0.0892"/>
      <mass value="5"/>
      <inertia ixx="-0.0396" ixy="0.0159" ixz="0.0524" iyy="-0.0671" iyz="0.0739" izz="0.0012"/>
    </inertial>
  </link>
  <joint name="joint_4" type="revolute">
    <parent link="link_3"/>
    <child link="link_4"/>
    <origin rpy="-3.141592653589793 3.141592653589793 1.5707963267948966" xyz="0 0 0.042"/>
    <axis xyz="0 0 1"/>
    <limit effort="300" lower="-2.09439510239" upper="2.09439510239" velocity="10"/>
    <dynamics damping="0.5"/>
  </joint>
  <link name="link_5">
    <inertial>
      <origin rpy="0 0 0" xyz="0.0704 0.042 0.0847"/>
      <mass value="5"/>
      <inertia ixx="0.0811" ixy="0.0649" ixz="0.003" iyy="0.0744" iyz="0.0139" izz="0.0195"/>
    </inertial>
  </link>
  <joint name="joint_5" type="revolute">
    <parent link="link_4"/>
    <child link="link_5"/>
    <origin rpy="-1.5707963267948966 -3.141592653589793 0" xyz="0 0 0.187"/>
    <axis xyz="0 0 1"/>
    <limit effort="300" lower="-2.09439510239" upper="2.09439510239" velocity="10"/>
    <dynamics damping="0.5"/>
  </joint>
  <link name="link_6">
    <inertial>
      <origin rpy="0 0 0" xyz="0.0381 0.0137 0.0705"/>
      <mass value="5"/>
      <inertia ixx="0.075" ixy="0.0812" ixz="-0.0304" iyy="-0.0083" iyz="-0.0222" izz="-0.0847"/>
    </inertial>
  </link>
  <joint name="joint_6" type="revolute">
    <parent link="link_5"/>
    <child link="link_6"/>
    <origin rpy="3.141592653589793 1.5707963267948966 3.141592653589793" xyz="0 0 0.1041"/>
    <axis xyz="0 0 1"/>
    <limit effort="300" lower="-2.09439510239" upper="2.09439510239" velocity="10"/>
    <dynamics damping="0.5"/>
  </joint>
  <link name="link_7">
    <inertial>
      <origin rpy="0 0 0" xyz="0.0123 0.0805 0.0813"/>
      <mass value="5"/>
      <inertia ixx="0.0012" ixy="-0.0331" ixz="0.0181" iyy="-0.0567" iyz="-0.0928" izz="-0.0797"/>
    </inertial>
  </link>
  <joint name="joint_7" type="revolute">
    <parent link="link_6"/>
    <child link="link_7"/>
    <origin rpy="-3.141592653589793 0 -3.141592653589793" xyz="0 0 0.0972"/>
    <axis xyz="0 0 1"/>
    <limit effort="300" lower="-2.09439510239" upper="2.09439510239" velocity="10"/>
    <dynamics damping="0.5"/>
  </joint>
  <link name="link_8">
    <inertial>
      <origin rpy="0 0 0" xyz="0.044 0.0479 0.0326"/>
      <mass value="5"/>
      <inertia ixx="-0.0193" ixy="-0.0156" ixz="-0.0" iyy="0.0651" iyz="0.018" izz="0.0993"/>
    </inertial>
  </link>
  <joint name="joint_8" type="revolute">
    <parent link="link_7"/>
    <child link="link_8"/>
    <origin rpy="-3.141592653589793 -3.141592653589793 0" xyz="0 0 0.0765"/>
    <axis xyz="0 0 1"/>
    <limit effort="300" lower="-2.09439510239" upper="2.09439510239" velocity="10"/>
    <dynamics damping="0.5"/>
  </joint>
  <link name="link_9">
    <inertial>
      <origin rpy="0 0 0" xyz="0.042 0.0964 0.0775"/>
      <mass value="5"/>
      <inertia ixx="0.0969" ixy="0.0861" ixz="-0.0886" iyy="-0.0331" iyz="-0.0113" izz="0.005"/>
    </inertial>
  </link>
  <joint name="joint_9" type="revolute">
    <parent link="link_8"/>
    <child link="link_9"/>
    <origin rpy="0 -3.141592653589793 3.141592653589793" xyz="0 0 0.1657"/>
    <axis xyz="0 0 1"/>
    <limit effort="300" lower="-2.09439510239" upper="2.09439510239" velocity="10"/>
    <dynamics damping="0.5"/>
  </joint>
  <link name="link_10">
    <inertial>
      <origin rpy="0 0 0" xyz="0.0939 0.0474 0.0227"/>
      <mass value="5"/>
      <inertia ixx="0.0243" ixy="0.0426" ixz="-0.0981" iyy="-0.0" iyz="0.0738" izz="0.0109"/>
    </inertial>
  </link>
  <joint name="joint_10" type="revolute">
    <parent link="link_6"/>
    <child link="link_10"/>
    <origin rpy="3.141592653589793 0 -3.141592653589793" xyz="0 0 0.0431"/>
    <axis xyz="0 0 1"/>
    <limit effort="300" lower="-2.09439510239" upper="2.09439510239" velocity="10"/>
    <dynamics damping="0.5"/>
  </joint>
  <link name="link_11">
    <inertial>
      <origin rpy="0 0 0" xyz="0.0565 0.0429 0.09"/>
      <mass value="5"/>
      <inertia ixx="-0.0787" ixy="-0.0529" ixz="0.0892" iyy="-0.0923" iyz="-0.0186" izz="0.006"/>
    </inertial>
  </link>
  <joint name="joint_11" type="revolute">
    <parent link="link_10"/>
    <child link="link_11"/>
    <origin rpy="0 -1.5707963267948966 -1.5707963267948966" xyz="0 0 0.1187"/>
    <axis xyz="0 0 1"/>
    <limit effort="300" lower="-2.09439510239" upper="2.09439510239" velocity="10"/>
    <dynamics damping="0.5"/>
  </joint>
  <link name="link_12">
    <inertial>
      <origin rpy="0 0 0" xyz="0.0925 0.0912 0.0396"/>
      <mass value="5"/>
      <inertia ixx="0.0378" ixy="0.0127" ixz="0.0349" iyy="0.0559" iyz="0.0888" izz="0.037"/>
    </inertial>
  </link>
  <joint name="joint_12" type="revolute">
    <parent link="link_11"/>
    <child link="link_12"/>
    <origin rpy="1.5707963267948966 -3.141592653589793 1.5707963267948966" xyz="0 0 0.0005"/>
    <axis xyz="0 0 1"/>
    <limit effort="300" lower="-2.09439510239" upper="2.09439510239" velocity="10"/>
    <dynamics damping="0.5"/>
  </joint>
  <link name="link_13">
    <inertial>
      <origin rpy="0 0 0" xyz="0.0262 0.0383 0.0402"/>
      <mass value="5"/>
      <inertia ixx="0.0009" ixy="0.0066" ixz="0.0338" iyy="-0.0099" iyz="0.0144" izz="0.041"/>
    </inertial>
  </link>
  <joint name="joint_13" type="revolute">
    <parent link="link_6"/>
    <child link="link_13"/>
    <origin rpy="0 0 3.141592653589793" xyz="0 0 0.0818"/>
    <axis xyz="0 0 1"/>
    <limit effort="300" lower="-2.09439510239" upper="2.09439510239" velocity="10"/>
    <dynamics damping="0.5"/>
  </joint>
  <link name="link_14">
    <inertial>
      <origin rpy="0 0 0" xyz="0.0739 0.029 0.0941"/>
      <mass value="5"/>
      <inertia ixx="-0.0782" ixy="-0.0769" ixz="0.0558" iyy="0.0127" iyz="-0.0253" izz="0.0996"/>
    </inertial>
  </link>
  <joint name="joint_14" type="revolute">
    <parent link="link_13"/>
    <child link="link_14"/>
    <origin rpy="3.141592653589793 1.5707963267948966 3.141592653589793" xyz="0 0 0.0736"/>
    <axis xyz="0 0 1"/>
    <limit effort="300" lower="-2.09439510239" upper="2.09439510239" velocity="10"/>
    <dynamics damping="0.5"/>
  </joint>
  <link name="link_15">
    <inertial>
      <origin rpy="0 0 0" xyz="0.0907 0.0838 0.054"/>
      <mass value="5"/>
      <inertia ixx="0.0934" ixy="-0.0471" ixz="-0.0589" iyy="0.0735" iyz="-0.0664" izz="-0.0579"/>
    </inertial>
  </link>
  <joint name="joint_15" type="revolute">
    <parent link="link_14"/>
    <child link="link_15"/>
    <origin rpy="1.5707963267948966 1.5707963267948966 0" xyz="0 0 0.1131"/>
    <axis xyz="0 0 1"/>
    <limit effort="300" lower="-2.09439510239" upper="2.09439510239" velocity="10"/>
    <dynamics damping="0.5"/>
  </joint>
</robot>
