<?xml version="1.0" encoding="utf-8"?>
<robot name="iiwa">
  <link name="world"/>
  <link name="link_1">
    <inertial>
      <origin rpy="0 0 0" xyz="0.0258 0.0521 0.0266"/>
      <mass value="5"/>
      <inertia ixx="-0.0924" ixy="-0.0477" ixz="0.0001" iyy="-0.0176" iyz="0.0601" izz="-0.006"/>
    </inertial>
  </link>
  <joint name="joint_1" type="revolute">
    <parent link="world"/>
    <child link="link_1"/>
    <origin rpy="3.141592653589793 -3.141592653589793 0" xyz="0 0 0.0525"/>
    <axis xyz="0 0 1"/>
    <limit effort="300" lower="-2.09439510239" upper="2.09439510239" velocity="10"/>
    <dynamics damping="0.5"/>
  </joint>
  <link name="link_2">
    <inertial>
      <origin rpy="0 0 0" xyz="0.0027 0.0387 0.0826"/>
      <mass value="5"/>
      <inertia ixx="-0.0858" ixy="-0.0841" ixz="0.0047" iyy="0.0385" iyz="-0.0392" izz="-0.0604"/>
    </inertial>
  </link>
  <joint name="joint_2" type="revolute">
    <parent link="link_1"/>
    <child link="link_2"/>
    <origin rpy="-1.5707963267948966 -1.5707963267948966 0" xyz="0 0 0.0214"/>
    <axis xyz="0 0 1"/>
    <limit effort="300" lower="-2.09439510239" upper="2.09439510239" velocity="10"/>
    <dynamics damping="0.5"/>
  </joint>
  <link name="link_3">
    <inertial>
      <origin rpy="0 0 0" xyz="0.0387 0.0952 0.0433"/>
      <mass value="5"/>
      <inertia ixx="-0.0215" ixy="0.0303" ixz="0.0904" iyy="0.0732" iyz="0.0491" izz="0.0912"/>
    </inertial>
  </link>
  <joint name="joint_3" type="revolute">
    <parent link="link_2"/>
    <child link="link_3"/>
    <origin rpy="3.141592653589793 3.141592653589793 1.5707963267948966" xyz="0 0 0.0845"/>
    <axis xyz="0 0 1"/>
    <limit effort="300" lower="-2.09439510239" upper="2.09439510239" velocity="10"/>
    <dynamics damping="0.5"/>
  </joint>
  <link name="link_4">
    <inertial>
      <origin rpy="0 0 0" xyz="0.0463 0.0076 0.0222"/>
      <mass value="5"/>
      <inertia ixx="-0.0541" ixy="-0.0809" ixz="-0.0425" iyy="0.0367" iyz="0.0786" izz="0.0687"/>
    </inertial>
  </link>
  <joint name="joint_4" type="revolute">
    <parent link="link_3"/>
    <child link="link_4"/>
    <origin rpy="-1.5707963267948966 -3.141592653589793 0" xyz="0 0 0.0628"/>
    <axis xyz="0 0 1"/>
    <limit effort="300" lower="-2.09439510239" upper="2.09439510239" velocity="10"/>
    <dynamics damping="0.5"/>
  </joint>
  <link name="link_5">
    <inertial>
      <origin rpy="0 0 0" xyz="0.0342 0.0171 0.0364"/>
      <mass value="5"/>
      <inertia ixx="0.0243" ixy="0.089" ixz="0.0056" iyy="0.0153" iyz="-0.0806" izz="0.0378"/>
    </inertial>
  </link>
  <joint name="joint_5" type="revolute">
    <parent link="link_4"/>
    <child link="link_5"/>
    <origin rpy="-1.5707963267948966 0 0" xyz="0 0 0.0516"/>
    <axis xyz="0 0 1"/>
    <limit effort="300" lower="-2.09439510239" upper="2.09439510239" velocity="10"/>
    <dynamics damping="0.5"/>
  </joint>
  <link name="link_6">
    <inertial>
      <origin rpy="0 0 0" xyz="0.0257 0.063 0.0269"/>
      <mass value="5"/>
      <inertia ixx="-0.0365" ixy="0.019" ixz="0.0933" iyy="0.0313" iyz="-0.0828" izz="0.0081"/>
    </inertial>
  </link>
  <joint name="joint_6" type="revolute">
    <parent link="link_5"/>
    <child link="link_6"/>
    <origin rpy="3.141592653589793 -3.141592653589793 -1.5707963267948966" xyz="0 0 0.1839"/>
    <axis xyz="0 0 1"/>
    <limit effort="300" lower="-2.09439510239" upper="2.09439510239" velocity="10"/>
    <dynamics damping="0.5"/>
  </joint>
  <link name="link_7">
    <inertial>
      <origin rpy="0 0 0" xyz="0.0592 0.0747 0.094"/>
      <mass value="5"/>
      <inertia ixx="0.0614" ixy="-0.09" ixz="0.0076" iyy="0.0118" iyz="-0.0152" izz="0.092"/>
    </inertial>
  </link>
  <joint name="joint_7" type="revolute">
    <parent link="link_6"/>
    <child link="link_7"/>
    <origin rpy="-1.5707963267948966 -3.141592653589793 1.5707963267948966" xyz="0 0 0.1221"/>
    <axis xyz="0 0 1"/>
    <limit effort="300" lower="-2.09439510239" upper="2.09439510239" velocity="10"/>
    <dynamics damping="0.5"/>
  </joint>
  <link name="link_8">
    <inertial>
      <origin rpy="0 0 0" xyz="0.0112 0.0579 0.0723"/>
      <mass value="5"/>
      <inertia ixx="-0.0121" ixy="0.0527" ixz="0.0178" iyy="-0.0051" iyz="0.0225" izz="-0.0737"/>
    </inertial>
  </link>
  <joint name="joint_8" type="revolute">
    <parent link="link_7"/>
    <child link="link_8"/>
    <origin rpy="-1.5707963267948966 -1.5707963267948966 0" xyz="0 0 0.122"/>
    <axis xyz="0 0 1"/>
    <limit effort="300" lower="-2.09439510239" upper="2.09439510239" velocity="10"/>
    <dynamics damping="0.5"/>
  </joint>
  <link name="link_9">
    <inertial>
      <origin rpy="0 0 0" xyz="0.0766 0.06 0.0865"/>
      <mass value="5"/>
      <inertia ixx="-0.095" ixy="-0.0514" ixz="0.0979" iyy="-0.0428" iyz="0.0936" izz="-0.0169"/>
    </inertial>
  </link>
  <joint name="joint_9" type="revolute">
    <parent link="link_8"/>
    <child link="link_9"/>
    <origin rpy="3.141592653589793 3.141592653589793 0" xyz="0 0 0.1491"/>
    <axis xyz="0 0 1"/>
    <limit effort="300" lower="-2.09439510239" upper="2.09439510239" velocity="10"/>
    <dynamics damping="0.5"/>
  </joint>
  <link name="link_10">
    <inertial>
      <origin rpy="0 0 0" xyz="0.0873 0.0399 0.0514"/>
      <mass value="5"/>
      <inertia ixx="-0.0119" ixy="0.041" ixz="0.0919" iyy="0.0869" iyz="0.0803" izz="0.0603"/>
    </inertial>
  </link>
  <joint name="joint_10" type="revolute">
    <parent link="link_9"/>
    <child link="link_10"/>
    <origin rpy="-1.5707963267948966 -1.5707963267948966 0" xyz="0 0 0.1408"/>
    <axis xyz="0 0 1"/>
    <limit effort="300" lower="-2.09439510239" upper="2.09439510239" velocity="10"/>
    <dynamics damping="0.5"/>
  </joint>
  <link name="link_11">
    <inertial>
      <origin rpy="0 0 0" xyz="0.0743 0.0287 0.0234"/>
      <mass value="5"/>
      <inertia ixx="-0.0078" ixy="-0.0042" ixz="0.0095" iyy="0.0673" iyz="0.0085" izz="0.0542"/>
    </inertial>
  </link>
  <joint name="joint_11" type="revolute">
    <parent link="link_6"/>
    <child link="link_11"/>
    <origin rpy="1.5707963267948966 -1.5707963267948966 3.141592653589793" xyz="0 0 0.1233"/>
    <axis xyz="0 0 1"/>
    <limit effort="300" lower="-2.09439510239" upper="2.09439510239" velocity="10"/>
    <dynamics damping="0.5"/>
  </joint>
  <link name="link_12">
    <inertial>
      <origin rpy="0 0 0" xyz="0.0166 0.0879 0.0983"/>
      <mass value="5"/>
      <inertia ixx="-0.0464" ixy="0.0283" ixz="-0.0535" iyy="-0.0347" iyz="0.0951" izz="0.0865"/>
    </inertial>
  </link>
  <joint name="joint_12" type="revolute">
    <parent link="link_11"/>
    <child link="link_12"/>
    <origin rpy="3.141592653589793 0 1.5707963267948966" xyz="0 0 0.0031"/>
    <axis xyz="0 0 1"/>
    <limit effort="300" lower="-2.09439510239" upper="2.09439510239" velocity="10"/>
    <dynamics damping="0.5"/>
  </joint>
  <link name="link_13">
    <inertial>
      <origin rpy="0 0 0" xyz="0.0657 0.0719 0.0304"/>
      <mass value="5"/>
      <inertia ixx="-0.0709" ixy="0.0832" ixz="0.0606" iyy="0.0703" iyz="0.0979" izz="0.0033"/>
    </inertial>
  </link>
  <joint name="joint_13" type="revolute">
    <parent link="link_12"/>
    <child link="link_13"/>
    <origin rpy="-3.141592653589793 0 -1.5707963267948966" xyz="0 0 0.1556"/>
    <axis xyz="0 0 1"/>
    <limit effort="300" lower="-2.09439510239" upper="2.09439510239" velocity="10"/>
    <dynamics damping="0.5"/>
  </joint>
  <link name="link_14">
    <inertial>
      <origin rpy="0 0 0" xyz="0.0565 0.0011 0.0781"/>
      <mass value="5"/>
      <inertia ixx="0.0749" ixy="-0.0656" ixz="-0.0282" iyy="-0.0849" iyz="0.0611" izz="0.0842"/>
    </inertial>
  </link>
  <joint name="joint_14" type="revolute">
    <parent link="link_13"/>
    <child link="link_14"/>
    <origin rpy="3.141592653589793 -1.5707963267948966 1.5707963267948966" xyz="0 0 0.147"/>
    <axis xyz="0 0 1"/>
    <limit effort="300" lower="-2.09439510239" upper="2.09439510239" velocity="10"/>
    <dynamics damping="0.5"/>
  </joint>
  <link name="link_15">
    <inertial>
      <origin rpy="0 0 0" xyz="0.0571 0.0271 0.0086"/>
      <mass value="5"/>
      <inertia ixx="-0.0008" ixy="-0.0854" ixz="0.0532" iyy="0.0889" iyz="0.0364" izz="-0.0014"/>
    </inertial>
  </link>
  <joint name="joint_15" type="revolute">
    <parent link="link_6"/>
    <child link="link_15"/>
    <origin rpy="-1.5707963267948966 -1.5707963267948966 -3.141592653589793" xyz="0 0 0.1682"/>
    <axis xyz="0 0 1"/>
    <limit effort="300" lower="-2.09439510239" upper="2.09439510239" velocity="10"/>
    <dynamics damping="0.5"/>
  </joint>
  <link name="link_16">
    <inertial>
      <origin rpy="0 0 0" xyz="0.0067 0.0889 0.0778"/>
      <mass value="5"/>
      <inertia ixx="-0.0065" ixy="-0.0007" ixz="-0.0281" iyy="0.0543" iyz="0.0221" izz="0.0075"/>
    </inertial>
  </link>
  <joint name="joint_16" type="revolute">
    <parent link="link_15"/>
    <child link="link_16"/>
    <origin rpy="0 1.5707963267948966 0" xyz="0 0 0.0509"/>
    <axis xyz="0 0 1"/>
    <limit effort="300" lower="-2.09439510239" upper="2.09439510239" velocity="10"/>
    <dynamics damping="0.5"/>
  </joint>
  <link name="link_17">
    <inertial>
      <origin rpy="0 0 0" xyz="0.0184 0.0305 0.0019"/>
      <mass value="5"/>
      <inertia ixx="-0.0035" ixy="-0.0725" ixz="0.0607" iyy="-0.024" iyz="0.0826" izz="-0.0847"/>
    </inertial>
  </link>
  <joint name="joint_17" type="revolute">
    <parent link="link_16"/>
    <child link="link_17"/>
    <origin rpy="-1.5707963267948966 1.5707963267948966 0" xyz="0 0 0.1333"/>
    <axis xyz="0 0 1"/>
    <limit effort="300" lower="-2.09439510239" upper="2.09439510239" velocity="10"/>
    <dynamics damping="0.5"/>
  </joint>
  <link name="link_18">
    <inertial>
      <origin rpy="0 0 0" xyz="0.0476 0.0081 0.0289"/>
      <mass value="5"/>
      <inertia ixx="0.0887" ixy="0.0654" ixz="0.0002" iyy="-0.0986" iyz="-0.0985" izz="-0.0887"/>
    </inertial>
  </link>
  <joint name="joint_18" type="revolute">
    <parent link="link_17"/>
    <child link="link_18"/>
    <origin rpy="-3.141592653589793 3.141592653589793 0" xyz="0 0 0.0705"/>
    <axis xyz="0 0 1"/>
    <limit effort="300" lower="-2.09439510239" upper="2.09439510239" velocity="10"/>
    <dynamics damping="0.5"/>
  </joint>
</robot>
