<?xml version="1.0" encoding="utf-8"?>
<robot name="iiwa">
  <link name="world"/>
  <link name="link_1">
    <inertial>
      <origin rpy="0 0 0" xyz="0.0239 0.0549 0.0405"/>
      <mass value="5"/>
      <inertia ixx="0.0594" ixy="0.0211" ixz="0.0723" iyy="0.0419" iyz="-0.0045" izz="0.0153"/>
    </inertial>
  </link>
  <joint name="joint_1" type="revolute">
    <parent link="world"/>
    <child link="link_1"/>
    <origin rpy="3.141592653589793 -3.141592653589793 1.5707963267948966" xyz="0 0 0.0807"/>
    <axis xyz="0 0 1"/>
    <limit effort="300" lower="-2.09439510239" upper="2.09439510239" velocity="10"/>
    <dynamics damping="0.5"/>
  </joint>
  <link name="link_2">
    <inertial>
      <origin rpy="0 0 0" xyz="0.077 0.0656 0.0676"/>
      <mass value="5"/>
      <inertia ixx="0.0621" ixy="0.0401" ixz="-0.0744" iyy="0.0154" iyz="0.0192" izz="-0.0429"/>
    </inertial>
  </link>
  <joint name="joint_2" type="revolute">
    <parent link="link_1"/>
    <child link="link_2"/>
    <origin rpy="0 -1.5707963267948966 3.141592653589793" xyz="0 0 0.1572"/>
    <axis xyz="0 0 1"/>
    <limit effort="300" lower="-2.09439510239" upper="2.09439510239" velocity="10"/>
    <dynamics damping="0.5"/>
  </joint>
  <link name="link_3">
    <inertial>
      <origin rpy="0 0 0" xyz="0.0819 0.0201 0.0797"/>
      <mass value="5"/>
      <inertia ixx="-0.0958" ixy="-0.0405" ixz="0.0232" iyy="-0.0905" iyz="-0.0065" izz="-0.0426"/>
    </inertial>
  </link>
  <joint name="joint_3" type="revolute">
    <parent link="link_2"/>
    <child link="link_3"/>
    <origin rpy="3.141592653589793 0 3.141592653589793" xyz="0 0 0.022"/>
    <axis xyz="0 0 1"/>
    <limit effort="300" lower="-2.09439510239" upper="2.09439510239" velocity="10"/>
    <dynamics damping="0.5"/>
  </joint>
  <link name="link_4">
    <inertial>
      <origin rpy="0 0 0" xyz="0.0163 0.0616 0.0289"/>
      <mass value="5"/>
      <inertia ixx="-0.0946" ixy="-0.0689" ixz="-0.0977" iyy="-0.0136" iyz="-0.0639" izz="-0.081"/>
    </inertial>
  </link>
  <joint name="joint_4" type="revolute">
    <parent link="link_3"/>
    <child link="link_4"/>
    <origin rpy="3.141592653589793 -3.141592653589793 -1.5707963267948966" xyz="0 0 0.0946"/>
    <axis xyz="0 0 1"/>
    <limit effort="300" lower="-2.09439510239" upper="2.09439510239" velocity="10"/>
    <dynamics damping="0.5"/>
  </joint>
  <link name="link_5">
    <inertial>
      <origin rpy="0 0 0" xyz="0.0616 0.0162 0.0244"/>
      <mass value="5"/>
      <inertia ixx="-0.0857" ixy="0.0715" ixz="-0.0543" iyy="-0.0055" iyz="0.0725" izz="-0.0576"/>
    </inertial>
  </link>
  <joint name="joint_5" type="revolute">
    <parent link="link_4"/>
    <child link="link_5"/>
    <origin rpy="0 -1.5707963267948966 1.5707963267948966" xyz="0 0 0.1884"/>
    <axis xyz="0 0 1"/>
    <limit effort="300" lower="-2.09439510239" upper="2.09439510239" velocity="10"/>
    <dynamics damping="0.5"/>
  </joint>
  <link name="link_6">
    <inertial>
      <origin rpy="0 0 0" xyz="0.0874 0.0533 0.0515"/>
      <mass value="5"/>
      <inertia ixx="0.0064" ixy="-0.0939" ixz="-0.0547" iyy="-0.0094" iyz="-0.0201" izz="-0.0443"/>
    </inertial>
  </link>
  <joint name="joint_6" type="revolute">
    <parent link="link_5"/>
    <child link="link_6"/>
    <origin rpy="-3.141592653589793 -3.141592653589793 1.5707963267948966" xyz="0 0 0.0608"/>
    <axis xyz="0 0 1"/>
    <limit effort="300" lower="-2.09439510239" upper="2.09439510239" velocity="10"/>
    <dynamics damping="0.5"/>
  </joint>
  <link name="link_7">
    <inertial>
      <origin rpy="0 0 0" xyz="0.0597 0.0824 0.0114"/>
      <mass value="5"/>
      <inertia ixx="-0.0403" ixy="0.0023" ixz="0.0849" iyy="0.0993" iyz="-0.0036" izz="-0.033"/>
    </inertial>
  </link>
  <joint name="joint_7" type="revolute">
    <parent link="link_6"/>
    <child link="link_7"/>
    <origin rpy="1.5707963267948966 0 1.5707963267948966" xyz="0 0 0.0756"/>
    <axis xyz="0 0 1"/>
    <limit effort="300" lower="-2.09439510239" upper="2.09439510239" velocity="10"/>
    <dynamics damping="0.5"/>
  </joint>
  <link name="link_8">
    <inertial>
      <origin rpy="0 0 0" xyz="0.0529 0.0911 0.0849"/>
      <mass value="5"/>
      <inertia ixx="-0.0682" ixy="0.0409" ixz="0.0646" iyy="-0.034" iyz="-0.0731" izz="-0.0513"/>
    </inertial>
  </link>
  <joint name="joint_8" type="revolute">
    <parent link="link_7"/>
    <child link="link_8"/>
    <origin rpy="3.141592653589793 1.5707963267948966 1.5707963267948966" xyz="0 0 0.159"/>
    <axis xyz="0 0 1"/>
    <limit effort="300" lower="-2.09439510239" upper="2.09439510239" velocity="10"/>
    <dynamics damping="0.5"/>
  </joint>
  <link name="link_9">
    <inertial>
      <origin rpy="0 0 0" xyz="0.0721 0.0505 0.0398"/>
      <mass value="5"/>
      <inertia ixx="-0.0955" ixy="-0.0107" ixz="0.0069" iyy="0.0983" iyz="-0.0663" izz="-0.0602"/>
    </inertial>
  </link>
  <joint name="joint_9" type="revolute">
    <parent link="link_6"/>
    <child link="link_9"/>
    <origin rpy="3.141592653589793 -1.5707963267948966 1.5707963267948966" xyz="0 0 0.163"/>
    <axis xyz="0 0 1"/>
    <limit effort="300" lower="-2.09439510239" upper="2.09439510239" velocity="10"/>
    <dynamics damping="0.5"/>
  </joint>
  <link name="link_10">
    <inertial>
      <origin rpy="0 0 0" xyz="0.071 0.0751 0.0965"/>
      <mass value="5"/>
      <inertia ixx="-0.0485" ixy="-0.0707" ixz="0.038" iyy="0.0291" iyz="-0.0613" izz="0.075"/>
    </inertial>
  </link>
  <joint name="joint_10" type="revolute">
    <parent link="link_9"/>
    <child link="link_10"/>
    <origin rpy="3.141592653589793 -1.5707963267948966 3.141592653589793" xyz="0 0 0.1087"/>
    <axis xyz="0 0 1"/>
    <limit effort="300" lower="-2.09439510239" upper="2.09439510239" velocity="10"/>
    <dynamics damping="0.5"/>
  </joint>
  <link name="link_11">
    <inertial>
      <origin rpy="0 0 0" xyz="0.0791 0.0852 0.041"/>
      <mass value="5"/>
      <inertia ixx="0.0705" ixy="0.0026" ixz="-0.0764" iyy="0.0586" iyz="0.0541" izz="0.0528"/>
    </inertial>
  </link>
  <joint name="joint_11" type="revolute">
    <parent link="link_6"/>
    <child link="link_11"/>
    <origin rpy="3.141592653589793 0 1.5707963267948966" xyz="0 0 0.0758"/>
    <axis xyz="0 0 1"/>
    <limit effort="300" lower="-2.09439510239" upper="2.09439510239" velocity="10"/>
    <dynamics damping="0.5"/>
  </joint>
  <link name="link_12">
    <inertial>
      <origin rpy="0 0 0" xyz="0.0317 0.0903 0.0251"/>
      <mass value="5"/>
      <inertia ixx="0.0421" ixy="0.0877" ixz="-0.0865" iyy="0.0808" iyz="0.0762" izz="-0.0405"/>
    </inertial>
  </link>
  <joint name="joint_12" type="revolute">
    <parent link="link_11"/>
    <child link="link_12"/>
    <origin rpy="0 -1.5707963267948966 0" xyz="0 0 0.0464"/>
    <axis xyz="0 0 1"/>
    <limit effort="300" lower="-2.09439510239" upper="2.09439510239" velocity="10"/>
    <dynamics damping="0.5"/>
  </joint>
</robot>
