<?xml version="1.0" encoding="utf-8"?>
<robot name="iiwa">
  <link name="world"/>
  <link name="link_1">
    <inertial>
      <origin rpy="0 0 0" xyz="0.0232 0.0094 0.0137"/>
      <mass value="5"/>
      <inertia ixx="-0.0618" ixy="0.049" ixz="0.0074" iyy="-0.0128" iyz="-0.088" izz="-0.0473"/>
    </inertial>
  </link>
  <joint name="joint_1" type="revolute">
    <parent link="world"/>
    <child link="link_1"/>
    <origin rpy="-1.5707963267948966 -3.141592653589793 -1.5707963267948966" xyz="0 0 0.1371"/>
    <axis xyz="0 0 1"/>
    <limit effort="300" lower="-2.09439510239" upper="2.09439510239" velocity="10"/>
    <dynamics damping="0.5"/>
  </joint>
  <link name="link_2">
    <inertial>
      <origin rpy="0 0 0" xyz="0.0491 0.0317 0.0288"/>
      <mass value="5"/>
      <inertia ixx="-0.0907" ixy="-0.0864" ixz="0.0925" iyy="-0.0323" iyz="0.0239" izz="0.0948"/>
    </inertial>
  </link>
  <joint name="joint_2" type="revolute">
    <parent link="link_1"/>
    <child link="link_2"/>
    <origin rpy="3.141592653589793 1.5707963267948966 1.5707963267948966" xyz="0 0 0.0682"/>
    <axis xyz="0 0 1"/>
    <limit effort="300" lower="-2.09439510239" upper="2.09439510239" velocity="10"/>
    <dynamics damping="0.5"/>
  </joint>
  <link name="link_3">
    <inertial>
      <origin rpy="0 0 0" xyz="0.0308 0.0312 0.0377"/>
      <mass value="5"/>
      <inertia ixx="-0.0604" ixy="-0.0473" ixz="0.0649" iyy="-0.0215" iyz="-0.0042" izz="0.0668"/>
    </inertial>
  </link>
  <joint name="joint_3" type="revolute">
    <parent link="link_2"/>
    <child link="link_3"/>
    <origin rpy="-1.5707963267948966 1.5707963267948966 -1.5707963267948966" xyz="0 0 0.0774"/>
    <axis xyz="0 0 1"/>
    <limit effort="300" lower="-2.09439510239" upper="2.09439510239" velocity="10"/>
    <dynamics damping="0.5"/>
  </joint>
  <link name="link_4">
    <inertial>
      <origin rpy="0 0 0" xyz="0.0073 0.019 0.0579"/>
      <mass value="5"/>
      <inertia ixx="-0.0484" ixy="-0.0617" ixz="-0.0489" iyy="-0.0353" iyz="0.0874" izz="0.0067"/>
    </inertial>
  </link>
  <joint name="joint_4" type="revolute">
    <parent link="link_3"/>
    <child link="link_4"/>
    <origin rpy="-1.5707963267948966 -3.141592653589793 -1.5707963267948966" xyz="0 0 0.1933"/>
    <axis xyz="0 0 1"/>
    <limit effort="300" lower="-2.09439510239" upper="2.09439510239" velocity="10"/>
    <dynamics damping="0.5"/>
  </joint>
  <link name="link_5">
    <inertial>
      <origin rpy="0 0 0" xyz="0.057 0.0915 0.0973"/>
      <mass value="5"/>
      <inertia ixx="-0.0454" ixy="-0.066" ixz="0.0914" iyy="-0.0434" iyz="-0.0833" izz="0.0406"/>
    </inertial>
  </link>
  <joint name="joint_5" type="revolute">
    <parent link="link_4"/>
    <child link="link_5"/>
    <origin rpy="0 -3.141592653589793 -1.5707963267948966" xyz="0 0 0.0351"/>
    <axis xyz="0 0 1"/>
    <limit effort="300" lower="-2.09439510239" upper="2.09439510239" velocity="10"/>
    <dynamics damping="0.5"/>
  </joint>
  <link name="link_6">
    <inertial>
      <origin rpy="0 0 0" xyz="0.0639 0.0748 0.0511"/>
      <mass value="5"/>
      <inertia ixx="-0.05" ixy="-0.0243" ixz="0.0333" iyy="-0.004" iyz="-0.086" izz="0.0095"/>
    </inertial>
  </link>
  <joint name="joint_6" type="revolute">
    <parent link="link_5"/>
    <child link="link_6"/>
    <origin rpy="-3.141592653589793 -3.141592653589793 1.5707963267948966" xyz="0 0 0.0141"/>
    <axis xyz="0 0 1"/>
    <limit effort="300" lower="-2.09439510239" upper="2.09439510239" velocity="10"/>
    <dynamics damping="0.5"/>
  </joint>
  <link name="link_7">
    <inertial>
      <origin rpy="0 0 0" xyz="0.0059 0.0624 0.0819"/>
      <mass value="5"/>
      <inertia ixx="0.0542" ixy="-0.0089" ixz="-0.0725" iyy="-0.0242" iyz="0.0832" izz="0.0032"/>
    </inertial>
  </link>
  <joint name="joint_7" type="revolute">
    <parent link="link_6"/>
    <child link="link_7"/>
    <origin rpy="3.141592653589793 -3.141592653589793 1.5707963267948966" xyz="0 0 0.1862"/>
    <axis xyz="0 0 1"/>
    <limit effort="300" lower="-2.09439510239" upper="2.09439510239" velocity="10"/>
    <dynamics damping="0.5"/>
  </joint>
  <link name="link_8">
    <inertial>
      <origin rpy="0 0 0" xyz="0.0675 0.0112 0.0993"/>
      <mass value="5"/>
      <inertia ixx="-0.0167" ixy="0.0513" ixz="0.0898" iyy="-0.0204" iyz="-0.029" izz="0.0344"/>
    </inertial>
  </link>
  <joint name="joint_8" type="revolute">
    <parent link="link_7"/>
    <child link="link_8"/>
    <origin rpy="-1.5707963267948966 3.141592653589793 0" xyz="0 0 0.0155"/>
    <axis xyz="0 0 1"/>
    <limit effort="300" lower="-2.09439510239" upper="2.09439510239" velocity="10"/>
    <dynamics damping="0.5"/>
  </joint>
  <link name="link_9">
    <inertial>
      <origin rpy="0 0 0" xyz="0.0108 0.0423 0.0369"/>
      <mass value="5"/>
      <inertia ixx="-0.0766" ixy="-0.023" ixz="0.0226" iyy="-0.0421" iyz="0.0713" izz="0.0088"/>
    </inertial>
  </link>
  <joint name="joint_9" type="revolute">
    <parent link="world"/>
    <child link="link_9"/>
    <origin rpy="3.141592653589793 -3.141592653589793 0" xyz="0 0 0.0348"/>
    <axis xyz="0 0 1"/>
    <limit effort="300" lower="-2.09439510239" upper="2.09439510239" velocity="10"/>
    <dynamics damping="0.5"/>
  </joint>
  <link name="link_10">
    <inertial>
      <origin rpy="0 0 0" xyz="0.0637 0.0041 0.0441"/>
      <mass value="5"/>
      <inertia ixx="0.0565" ixy="0.0042" ixz="-0.0292" iyy="0.0101" iyz="-0.0042" izz="-0.0498"/>
    </inertial>
  </link>
  <joint name="joint_10" type="revolute">
    <parent link="link_9"/>
    <child link="link_10"/>
    <origin rpy="1.5707963267948966 3.141592653589793 3.141592653589793" xyz="0 0 0.1954"/>
    <axis xyz="0 0 1"/>
    <limit effort="300" lower="-2.09439510239" upper="2.09439510239" velocity="10"/>
    <dynamics damping="0.5"/>
  </joint>
  <link name="link_11">
    <inertial>
      <origin rpy="0 0 0" xyz="0.0402 0.0585 0.0042"/>
      <mass value="5"/>
      <inertia ixx="-0.0164" ixy="0.0199" ixz="-0.0875" iyy="-0.0102" iyz="-0.0191" izz="-0.0295"/>
    </inertial>
  </link>
  <joint name="joint_11" type="revolute">
    <parent link="link_10"/>
    <child link="link_11"/>
    <origin rpy="-1.5707963267948966 1.5707963267948966 1.5707963267948966" xyz="0 0 0.1623"/>
    <axis xyz="0 0 1"/>
    <limit effort="300" lower="-2.09439510239" upper="2.09439510239" velocity="10"/>
    <dynamics damping="0.5"/>
  </joint>
  <link name="link_12">
    <inertial>
      <origin rpy="0 0 0" xyz="0.0248 0.0226 0.0693"/>
      <mass value="5"/>
      <inertia ixx="-0.0794" ixy="0.0273" ixz="-0.0596" iyy="-0.0878" iyz="-0.0629" izz="-0.0743"/>
    </inertial>
  </link>
  <joint name="joint_12" type="revolute">
    <parent link="link_11"/>
    <child link="link_12"/>
    <origin rpy="-3.141592653589793 -1.5707963267948966 0" xyz="0 0 0.1748"/>
    <axis xyz="0 0 1"/>
    <limit effort="300" lower="-2.09439510239" upper="2.09439510239" velocity="10"/>
    <dynamics damping="0.5"/>
  </joint>
  <link name="link_13">
    <inertial>
      <origin rpy="0 0 0" xyz="0.0933 0.012 0.0943"/>
      <mass value="5"/>
      <inertia ixx="0.0639" ixy="-0.063" ixz="0.0976" iyy="-0.0288" iyz="-0.0479" izz="-0.0617"/>
    </inertial>
  </link>
  <joint name="joint_13" type="revolute">
    <parent link="link_12"/>
    <child link="link_13"/>
    <origin rpy="0 -3.141592653589793 -1.5707963267948966" xyz="0 0 0.0125"/>
    <axis xyz="0 0 1"/>
    <limit effort="300" lower="-2.09439510239" upper="2.09439510239" velocity="10"/>
    <dynamics damping="0.5"/>
  </joint>
  <link name="link_14">
    <inertial>
      <origin rpy="0 0 0" xyz="0.0072 0.0028 0.0096"/>
      <mass value="5"/>
      <inertia ixx="-0.0876" ixy="-0.0331" ixz="0.0194" iyy="-0.0582" iyz="-0.047" izz="0.0675"/>
    </inertial>
  </link>
  <joint name="joint_14" type="revolute">
    <parent link="link_13"/>
    <child link="link_14"/>
    <origin rpy="3.141592653589793 1.5707963267948966 3.141592653589793" xyz="0 0 0.0528"/>
    <axis xyz="0 0 1"/>
    <limit effort="300" lower="-2.09439510239" upper="2.09439510239" velocity="10"/>
    <dynamics damping="0.5"/>
  </joint>
  <link name="link_15">
    <inertial>
      <origin rpy="0 0 0" xyz="0.0637 0.0508 0.069"/>
      <mass value="5"/>
      <inertia ixx="-0.0629" ixy="-0.0001" ixz="-0.0063" iyy="-0.0203" iyz="0.0551" izz="-0.098"/>
    </inertial>
  </link>
  <joint name="joint_15" type="revolute">
    <parent link="link_14"/>
    <child link="link_15"/>
    <origin rpy="1.5707963267948966 -1.5707963267948966 0" xyz="0 0 0.193"/>
    <axis xyz="0 0 1"/>
    <limit effort="300" lower="-2.09439510239" upper="2.09439510239" velocity="10"/>
    <dynamics damping="0.5"/>
  </joint>
  <link name="link_16">
    <inertial>
      <origin rpy="0 0 0" xyz="0.021 0.0387 0.0755"/>
      <mass value="5"/>
      <inertia ixx="0.0165" ixy="0.0673" ixz="0.0992" iyy="-0.002" iyz="0.0144" izz="0.0427"/>
    </inertial>
  </link>
  <joint name="joint_16" type="revolute">
    <parent link="link_15"/>
    <child link="link_16"/>
    <origin rpy="0 -1.5707963267948966 0" xyz="0 0 0.0112"/>
    <axis xyz="0 0 1"/>
    <limit effort="300" lower="-2.09439510239" upper="2.09439510239" velocity="10"/>
    <dynamics damping="0.5"/>
  </joint>
  <link name="link_17">
    <inertial>
      <origin rpy="0 0 0" xyz="0.084 0.0511 0.0941"/>
      <mass value="5"/>
      <inertia ixx="0.0943" ixy="-0.066" ixz="-0.0813" iyy="-0.0431" iyz="-0.0917" izz="0.0425"/>
    </inertial>
  </link>
  <joint name="joint_17" type="revolute">
    <parent link="world"/>
    <child link="link_17"/>
    <origin rpy="1.5707963267948966 -3.141592653589793 3.141592653589793" xyz="0 0 0.0027"/>
    <axis xyz="0 0 1"/>
    <limit effort="300" lower="-2.09439510239" upper="2.09439510239" velocity="10"/>
    <dynamics damping="0.5"/>
  </joint>
  <link name="link_18">
    <inertial>
      <origin rpy="0 0 0" xyz="0.0954 0.0072 0.0734"/>
      <mass value="5"/>
      <inertia ixx="-0.0266" ixy="-0.0124" ixz="0.0231" iyy="0.0006" iyz="0.0051" izz="-0.0883"/>
    </inertial>
  </link>
  <joint name="joint_18" type="revolute">
    <parent link="link_17"/>
    <child link="link_18"/>
    <origin rpy="-1.5707963267948966 -1.5707963267948966 0" xyz="0 0 0.086"/>
    <axis xyz="0 0 1"/>
    <limit effort="300" lower="-2.09439510239" upper="2.09439510239" velocity="10"/>
    <dynamics damping="0.5"/>
  </joint>
  <link name="link_19">
    <inertial>
      <origin rpy="0 0 0" xyz="0.0971 0.0314 0.0895"/>
      <mass value="5"/>
      <inertia ixx="0.0772" ixy="0.0917" ixz="0.0389" iyy="0.0574" iyz="0.0372" izz="-0.0375"/>
    </inertial>
  </link>
  <joint name="joint_19" type="revolute">
    <parent link="link_18"/>
    <child link="link_19"/>
    <origin rpy="1.5707963267948966 -1.5707963267948966 0" xyz="0 0 0.1386"/>
    <axis xyz="0 0 1"/>
    <limit effort="300" lower="-2.09439510239" upper="2.09439510239" velocity="10"/>
    <dynamics damping="0.5"/>
  </joint>
  <link name="link_20">
    <inertial>
      <origin rpy="0 0 0" xyz="0.016 0.0982 0.0153"/>
      <mass value="5"/>
      <inertia ixx="0.0252" ixy="-0.0064" ixz="0.0472" iyy="0.0092" iyz="0.0558" izz="0.0477"/>
    </inertial>
  </link>
  <joint name="joint_20" type="revolute">
    <parent link="link_19"/>
    <child link="link_20"/>
    <origin rpy="0 -1.5707963267948966 -1.5707963267948966" xyz="0 0 0.0678"/>
    <axis xyz="0 0 1"/>
    <limit effort="300" lower="-2.09439510239" upper="2.09439510239" velocity="10"/>
    <dynamics damping="0.5"/>
  </joint>
  <link name="link_21">
    <inertial>
      <origin rpy="0 0 0" xyz="0.0322 0.0794 0.0172"/>
      <mass value="5"/>
      <inertia ixx="-0.0068" ixy="0.0286" ixz="0.0848" iyy="-0.0688" iyz="0.0181" izz="-0.0746"/>
    </inertial>
  </link>
  <joint name="joint_21" type="revolute">
    <parent link="link_20"/>
    <child link="link_21"/>
    <origin rpy="3.141592653589793 0 3.141592653589793" xyz="0 0 0.1214"/>
    <axis xyz="0 0 1"/>
    <limit effort="300" lower="-2.09439510239" upper="2.09439510239" velocity="10"/>
    <dynamics damping="0.5"/>
  </joint>
  <link name="link_22">
    <inertial>
      <origin rpy="0 0 0" xyz="0.0075 0.0992 0.0704"/>
      <mass value="5"/>
      <inertia ixx="0.0073" ixy="-0.034" ixz="0.0903" iyy="-0.0935" iyz="-0.037" izz="0.0113"/>
    </inertial>
  </link>
  <joint name="joint_22" type="revolute">
    <parent link="link_21"/>
    <child link="link_22"/>
    <origin rpy="0 3.141592653589793 -1.5707963267948966" xyz="0 0 0.0671"/>
    <axis xyz="0 0 1"/>
    <limit effort="300" lower="-2.09439510239" upper="2.09439510239" velocity="10"/>
    <dynamics damping="0.5"/>
  </joint>
  <link name="link_23">
    <inertial>
      <origin rpy="0 0 0" xyz="0.0753 0.0154 0.0807"/>
      <mass value="5"/>
      <inertia ixx="-0.0527" ixy="-0.08" ixz="-0.0215" iyy="0.0055" iyz="0.0464" izz="0.0227"/>
    </inertial>
  </link>
  <joint name="joint_23" type="revolute">
    <parent link="link_22"/>
    <child link="link_23"/>
    <origin rpy="0 -1.5707963267948966 3.141592653589793" xyz="0 0 0.1775"/>
    <axis xyz="0 0 1"/>
    <limit effort="300" lower="-2.09439510239" upper="2.09439510239" velocity="10"/>
    <dynamics damping="0.5"/>
  </joint>
  <link name="link_24">
    <inertial>
      <origin rpy="0 0 0" xyz="0.0263 0.0931 0.0085"/>
      <mass value="5"/>
      <inertia ixx="-0.0411" ixy="0.094" ixz="-0.0356" iyy="-0.0877" iyz="-0.0365" izz="0.0344"/>
    </inertial>
  </link>
  <joint name="joint_24" type="revolute">
    <parent link="link_23"/>
    <child link="link_24"/>
    <origin rpy="1.5707963267948966 0 0" xyz="0 0 0.0337"/>
    <axis xyz="0 0 1"/>
    <limit effort="300" lower="-2.09439510239" upper="2.09439510239" velocity="10"/>
    <dynamics damping="0.5"/>
  </joint>
  <link name="link_25">
    <inertial>
      <origin rpy="0 0 0" xyz="0.0066 0.0422 0.0358"/>
      <mass value="5"/>
      <inertia ixx="0.0388" ixy="-0.0391" ixz="-0.073" iyy="-0.0178" iyz="0.0711" izz="0.0006"/>
    </inertial>
  </link>
  <joint name="joint_25" type="revolute">
    <parent link="world"/>
    <child link="link_25"/>
    <origin rpy="1.5707963267948966 1.5707963267948966 -1.5707963267948966" xyz="0 0 0.0975"/>
    <axis xyz="0 0 1"/>
    <limit effort="300" lower="-2.09439510239" upper="2.09439510239" velocity="10"/>
    <dynamics damping="0.5"/>
  </joint>
  <link name="link_26">
    <inertial>
      <origin rpy="0 0 0" xyz="0.0336 0.0639 0.0278"/>
      <mass value="5"/>
      <inertia ixx="0.0854" ixy="-0.0885" ixz="0.0273" iyy="-0.0568" iyz="-0.028" izz="-0.0511"/>
    </inertial>
  </link>
  <joint name="joint_26" type="revolute">
    <parent link="link_25"/>
    <child link="link_26"/>
    <origin rpy="1.5707963267948966 0 1.5707963267948966" xyz="0 0 0.0776"/>
    <axis xyz="0 0 1"/>
    <limit effort="300" lower="-2.09439510239" upper="2.09439510239" velocity="10"/>
    <dynamics damping="0.5"/>
  </joint>
  <link name="link_27">
    <inertial>
      <origin rpy="0 0 0" xyz="0.0181 0.0204 0.0506"/>
      <mass value="5"/>
      <inertia ixx="-0.0086" ixy="-0.0803" ixz="0.0605" iyy="-0.0979" iyz="0.0611" izz="0.0416"/>
    </inertial>
  </link>
  <joint name="joint_27" type="revolute">
    <parent link="link_26"/>
    <child link="link_27"/>
    <origin rpy="1.5707963267948966 -1.5707963267948966 -1.5707963267948966" xyz="0 0 0.1624"/>
    <axis xyz="0 0 1"/>
    <limit effort="300" lower="-2.09439510239" upper="2.09439510239" velocity="10"/>
    <dynamics damping="0.5"/>
  </joint>
  <link name="link_28">
    <inertial>
      <origin rpy="0 0 0" xyz="0.0684 0.0415 0.0733"/>
      <mass value="5"/>
      <inertia ixx="0.0655" ixy="-0.0012" ixz="0.0553" iyy="0.0916" iyz="-0.0558" izz="-0.0045"/>
    </inertial>
  </link>
  <joint name="joint_28" type="revolute">
    <parent link="link_27"/>
    <child link="link_28"/>
    <origin rpy="3.141592653589793 1.5707963267948966 1.5707963267948966" xyz="0 0 0.1292"/>
    <axis xyz="0 0 1"/>
    <limit effort="300" lower="-2.09439510239" upper="2.09439510239" velocity="10"/>
    <dynamics damping="0.5"/>
  </joint>
  <link name="link_29">
    <inertial>
      <origin rpy="0 0 0" xyz="0.0689 0.0852 0.0019"/>
      <mass value="5"/>
      <inertia ixx="0.0788" ixy="-0.0072" ixz="-0.0422" iyy="-0.0171" iyz="0.0694" izz="0.0607"/>
    </inertial>
  </link>
  <joint name="joint_29" type="revolute">
    <parent link="link_28"/>
    <child link="link_29"/>
    <origin rpy="3.141592653589793 -1.5707963267948966 1.5707963267948966" xyz="0 0 0.061"/>
    <axis xyz="0 0 1"/>
    <limit effort="300" lower="-2.09439510239" upper="2.09439510239" velocity="10"/>
    <dynamics damping="0.5"/>
  </joint>
  <link name="link_30">
    <inertial>
      <origin rpy="0 0 0" xyz="0.0104 0.0726 0.0151"/>
      <mass value="5"/>
      <inertia ixx="-0.0056" ixy="0.0798" ixz="-0.0836" iyy="0.009" iyz="-0.0112" izz="0.0833"/>
    </inertial>
  </link>
  <joint name="joint_30" type="revolute">
    <parent link="link_29"/>
    <child link="link_30"/>
    <origin rpy="-3.141592653589793 0 0" xyz="0 0 0.0624"/>
    <axis xyz="0 0 1"/>
    <limit effort="300" lower="-2.09439510239" upper="2.09439510239" velocity="10"/>
    <dynamics damping="0.5"/>
  </joint>
  <link name="link_31">
    <inertial>
      <origin rpy="0 0 0" xyz="0.0167 0.0446 0.059"/>
      <mass value="5"/>
      <inertia ixx="-0.0433" ixy="-0.0787" ixz="0.066" iyy="0.0947" iyz="-0.0059" izz="0.0194"/>
    </inertial>
  </link>
  <joint name="joint_31" type="revolute">
    <parent link="link_30"/>
    <child link="link_31"/>
    <origin rpy="-3.141592653589793 -3.141592653589793 -3.141592653589793" xyz="0 0 0.0379"/>
    <axis xyz="0 0 1"/>
    <limit effort="300" lower="-2.09439510239" upper="2.09439510239" velocity="10"/>
    <dynamics damping="0.5"/>
  </joint>
  <link name="link_32">
    <inertial>
      <origin rpy="0 0 0" xyz="0.0458 0.0098 0.0019"/>
      <mass value="5"/>
      <inertia ixx="0.0208" ixy="-0.0382" ixz="0.0089" iyy="-0.0505" iyz="-0.0753" izz="0.0737"/>
    </inertial>
  </link>
  <joint name="joint_32" type="revolute">
    <parent link="link_31"/>
    <child link="link_32"/>
    <origin rpy="0 3.141592653589793 1.5707963267948966" xyz="0 0 0.1123"/>
    <axis xyz="0 0 1"/>
    <limit effort="300" lower="-2.09439510239" upper="2.09439510239" velocity="10"/>
    <dynamics damping="0.5"/>
  </joint>
</robot>
