<?xml version="1.0" encoding="utf-8"?>
<robot name="iiwa">
  <link name="world"/>
  <link name="link_1">
    <inertial>
      <origin rpy="0 0 0" xyz="0.0719 0.0112 0.0398"/>
      <mass value="5"/>
      <inertia ixx="-0.0686" ixy="-0.0205" ixz="0.0429" iyy="0.04" iyz="-0.08" izz="-0.009"/>
    </inertial>
  </link>
  <joint name="joint_1" type="revolute">
    <parent link="world"/>
    <child link="link_1"/>
    <origin rpy="1.5707963267948966 3.141592653589793 -1.5707963267948966" xyz="0 0 0.1719"/>
    <axis xyz="0 0 1"/>
    <limit effort="300" lower="-2.09439510239" upper="2.09439510239" velocity="10"/>
    <dynamics damping="0.5"/>
  </joint>
  <link name="link_2">
    <inertial>
      <origin rpy="0 0 0" xyz="0.0744 0.0536 0.0396"/>
      <mass value="5"/>
      <inertia ixx="0.0309" ixy="0.0974" ixz="0.0649" iyy="-0.0057" iyz="0.0703" izz="-0.0771"/>
    </inertial>
  </link>
  <joint name="joint_2" type="revolute">
    <parent link="link_1"/>
    <child link="link_2"/>
    <origin rpy="3.141592653589793 0 0" xyz="0 0 0.0567"/>
    <axis xyz="0 0 1"/>
    <limit effort="300" lower="-2.09439510239" upper="2.09439510239" velocity="10"/>
    <dynamics damping="0.5"/>
  </joint>
  <link name="link_3">
    <inertial>
      <origin rpy="0 0 0" xyz="0.0079 0.0503 0.0442"/>
      <mass value="5"/>
      <inertia ixx="0.0687" ixy="0.0469" ixz="-0.0693" iyy="0.0544" iyz="0.0623" izz="0.0333"/>
    </inertial>
  </link>
  <joint name="joint_3" type="revolute">
    <parent link="link_2"/>
    <child link="link_3"/>
    <origin rpy="0 -3.141592653589793 -3.141592653589793" xyz="0 0 0.1127"/>
    <axis xyz="0 0 1"/>
    <limit effort="300" lower="-2.09439510239" upper="2.09439510239" velocity="10"/>
    <dynamics damping="0.5"/>
  </joint>
  <link name="link_4">
    <inertial>
      <origin rpy="0 0 0" xyz="0.0459 0.0503 0.0305"/>
      <mass value="5"/>
      <inertia ixx="0.0022" ixy="-0.0728" ixz="-0.0077" iyy="0.0889" iyz="0.0571" izz="-0.066"/>
    </inertial>
  </link>
  <joint name="joint_4" type="revolute">
    <parent link="link_3"/>
    <child link="link_4"/>
    <origin rpy="3.141592653589793 -1.5707963267948966 -3.141592653589793" xyz="0 0 0.0774"/>
    <axis xyz="0 0 1"/>
    <limit effort="300" lower="-2.09439510239" upper="2.09439510239" velocity="10"/>
    <dynamics damping="0.5"/>
  </joint>
  <link name="link_5">
    <inertial>
      <origin rpy="0 0 0" xyz="0.0577 0.0648 0.0075"/>
      <mass value="5"/>
      <inertia ixx="0.0107" ixy="0.0215" ixz="0.0156" iyy="0.0629" iyz="-0.0741" izz="-0.0686"/>
    </inertial>
  </link>
  <joint name="joint_5" type="revolute">
    <parent link="link_4"/>
    <child link="link_5"/>
    <origin rpy="-1.5707963267948966 -1.5707963267948966 -3.141592653589793" xyz="0 0 0.129"/>
    <axis xyz="0 0 1"/>
    <limit effort="300" lower="-2.09439510239" upper="2.09439510239" velocity="10"/>
    <dynamics damping="0.5"/>
  </joint>
  <link name="link_6">
    <inertial>
      <origin rpy="0 0 0" xyz="0.0103 0.0455 0.0088"/>
      <mass value="5"/>
      <inertia ixx="-0.0686" ixy="0.0955" ixz="-0.0391" iyy="-0.0466" iyz="0.0402" izz="0.0466"/>
    </inertial>
  </link>
  <joint name="joint_6" type="revolute">
    <parent link="link_5"/>
    <child link="link_6"/>
    <origin rpy="0 -3.141592653589793 1.5707963267948966" xyz="0 0 0.0406"/>
    <axis xyz="0 0 1"/>
    <limit effort="300" lower="-2.09439510239" upper="2.09439510239" velocity="10"/>
    <dynamics damping="0.5"/>
  </joint>
  <link name="link_7">
    <inertial>
      <origin rpy="0 0 0" xyz="0.0928 0.0114 0.0869"/>
      <mass value="5"/>
      <inertia ixx="0.0119" ixy="-0.0314" ixz="-0.0775" iyy="-0.0227" iyz="-0.0141" izz="0.008"/>
    </inertial>
  </link>
  <joint name="joint_7" type="revolute">
    <parent link="world"/>
    <child link="link_7"/>
    <origin rpy="3.141592653589793 -3.141592653589793 0" xyz="0 0 0.0886"/>
    <axis xyz="0 0 1"/>
    <limit effort="300" lower="-2.09439510239" upper="2.09439510239" velocity="10"/>
    <dynamics damping="0.5"/>
  </joint>
  <link name="link_8">
    <inertial>
      <origin rpy="0 0 0" xyz="0.042 0.0205 0.0868"/>
      <mass value="5"/>
      <inertia ixx="0.0703" ixy="0.0148" ixz="0.0364" iyy="0.0762" iyz="0.0555" izz="-0.092"/>
    </inertial>
  </link>
  <joint name="joint_8" type="revolute">
    <parent link="link_7"/>
    <child link="link_8"/>
    <origin rpy="3.141592653589793 1.5707963267948966 1.5707963267948966" xyz="0 0 0.1108"/>
    <axis xyz="0 0 1"/>
    <limit effort="300" lower="-2.09439510239" upper="2.09439510239" velocity="10"/>
    <dynamics damping="0.5"/>
  </joint>
  <link name="link_9">
    <inertial>
      <origin rpy="0 0 0" xyz="0.0016 0.0316 0.0839"/>
      <mass value="5"/>
      <inertia ixx="0.0387" ixy="-0.0669" ixz="-0.0932" iyy="0.0471" iyz="0.0247" izz="-0.0396"/>
    </inertial>
  </link>
  <joint name="joint_9" type="revolute">
    <parent link="link_8"/>
    <child link="link_9"/>
    <origin rpy="3.141592653589793 -1.5707963267948966 -3.141592653589793" xyz="0 0 0.1884"/>
    <axis xyz="0 0 1"/>
    <limit effort="300" lower="-2.09439510239" upper="2.09439510239" velocity="10"/>
    <dynamics damping="0.5"/>
  </joint>
  <link name="link_10">
    <inertial>
      <origin rpy="0 0 0" xyz="0.0787 0.0414 0.0217"/>
      <mass value="5"/>
      <inertia ixx="0.0579" ixy="-0.022" ixz="0.0494" iyy="0.0287" iyz="-0.0663" izz="0.0584"/>
    </inertial>
  </link>
  <joint name="joint_10" type="revolute">
    <parent link="link_9"/>
    <child link="link_10"/>
    <origin rpy="-3.141592653589793 0 3.141592653589793" xyz="0 0 0.1463"/>
    <axis xyz="0 0 1"/>
    <limit effort="300" lower="-2.09439510239" upper="2.09439510239" velocity="10"/>
    <dynamics damping="0.5"/>
  </joint>
  <link name="link_11">
    <inertial>
      <origin rpy="0 0 0" xyz="0.0169 0.0004 0.0687"/>
      <mass value="5"/>
      <inertia ixx="-0.023" ixy="0.049" ixz="-0.07" iyy="0.0496" iyz="-0.0952" izz="-0.0948"/>
    </inertial>
  </link>
  <joint name="joint_11" type="revolute">
    <parent link="link_10"/>
    <child link="link_11"/>
    <origin rpy="1.5707963267948966 -3.141592653589793 -3.141592653589793" xyz="0 0 0.1578"/>
    <axis xyz="0 0 1"/>
    <limit effort="300" lower="-2.09439510239" upper="2.09439510239" velocity="10"/>
    <dynamics damping="0.5"/>
  </joint>
  <link name="link_12">
    <inertial>
      <origin rpy="0 0 0" xyz="0.0675 0.0058 0.0554"/>
      <mass value="5"/>
      <inertia ixx="-0.0653" ixy="-0.0489" ixz="-0.0607" iyy="-0.0242" iyz="0.0691" izz="0.0927"/>
    </inertial>
  </link>
  <joint name="joint_12" type="revolute">
    <parent link="link_11"/>
    <child link="link_12"/>
    <origin rpy="0 1.5707963267948966 3.141592653589793" xyz="0 0 0.1997"/>
    <axis xyz="0 0 1"/>
    <limit effort="300" lower="-2.09439510239" upper="2.09439510239" velocity="10"/>
    <dynamics damping="0.5"/>
  </joint>
  <link name="link_13">
    <inertial>
      <origin rpy="0 0 0" xyz="0.0218 0.0101 0.0747"/>
      <mass value="5"/>
      <inertia ixx="0.0246" ixy="-0.0915" ixz="-0.0691" iyy="0.0725" iyz="0.0137" izz="-0.0987"/>
    </inertial>
  </link>
  <joint name="joint_13" type="revolute">
    <parent link="world"/>
    <child link="link_13"/>
    <origin rpy="-1.5707963267948966 -1.5707963267948966 -1.5707963267948966" xyz="0 0 0.095"/>
    <axis xyz="0 0 1"/>
    <limit effort="300" lower="-2.09439510239" upper="2.09439510239" velocity="10"/>
    <dynamics damping="0.5"/>
  </joint>
  <link name="link_14">
    <inertial>
      <origin rpy="0 0 0" xyz="0.0499 0.0394 0.0509"/>
      <mass value="5"/>
      <inertia ixx="0.0977" ixy="0.0013" ixz="0.0245" iyy="0.0306" iyz="-0.0757" izz="0.0981"/>
    </inertial>
  </link>
  <joint name="joint_14" type="revolute">
    <parent link="link_13"/>
    <child link="link_14"/>
    <origin rpy="1.5707963267948966 1.5707963267948966 0" xyz="0 0 0.1986"/>
    <axis xyz="0 0 1"/>
    <limit effort="300" lower="-2.09439510239" upper="2.09439510239" velocity="10"/>
    <dynamics damping="0.5"/>
  </joint>
  <link name="link_15">
    <inertial>
      <origin rpy="0 0 0" xyz="0.0401 0.0997 0.0776"/>
      <mass value="5"/>
      <inertia ixx="0.0853" ixy="-0.0716" ixz="0.0206" iyy="0.0619" iyz="0.0291" izz="-0.0791"/>
    </inertial>
  </link>
  <joint name="joint_15" type="revolute">
    <parent link="link_14"/>
    <child link="link_15"/>
    <origin rpy="-3.141592653589793 -3.141592653589793 -1.5707963267948966" xyz="0 0 0.1109"/>
    <axis xyz="0 0 1"/>
    <limit effort="300" lower="-2.09439510239" upper="2.09439510239" velocity="10"/>
    <dynamics damping="0.5"/>
  </joint>
  <link name="link_16">
    <inertial>
      <origin rpy="0 0 0" xyz="0.0568 0.0081 0.0035"/>
      <mass value="5"/>
      <inertia ixx="-0.0902" ixy="0.0089" ixz="-0.0751" iyy="-0.0038" iyz="0.0477" izz="0.0243"/>
    </inertial>
  </link>
  <joint name="joint_16" type="revolute">
    <parent link="link_15"/>
    <child link="link_16"/>
    <origin rpy="0 3.141592653589793 -1.5707963267948966" xyz="0 0 0.0644"/>
    <axis xyz="0 0 1"/>
    <limit effort="300" lower="-2.09439510239" upper="2.09439510239" velocity="10"/>
    <dynamics damping="0.5"/>
  </joint>
  <link name="link_17">
    <inertial>
      <origin rpy="0 0 0" xyz="0.0834 0.0038 0.0795"/>
      <mass value="5"/>
      <inertia ixx="0.0616" ixy="-0.0406" ixz="0.0357" iyy="-0.087" iyz="-0.0113" izz="0.0018"/>
    </inertial>
  </link>
  <joint name="joint_17" type="revolute">
    <parent link="link_16"/>
    <child link="link_17"/>
    <origin rpy="0 -3.141592653589793 -3.141592653589793" xyz="0 0 0.0578"/>
    <axis xyz="0 0 1"/>
    <limit effort="300" lower="-2.09439510239" upper="2.09439510239" velocity="10"/>
    <dynamics damping="0.5"/>
  </joint>
  <link name="link_18">
    <inertial>
      <origin rpy="0 0 0" xyz="0.0735 0.0476 0.0434"/>
      <mass value="5"/>
      <inertia ixx="0.0961" ixy="-0.0597" ixz="0.0019" iyy="-0.0762" iyz="-0.0638" izz="-0.0466"/>
    </inertial>
  </link>
  <joint name="joint_18" type="revolute">
    <parent link="link_17"/>
    <child link="link_18"/>
    <origin rpy="-3.141592653589793 -1.5707963267948966 1.5707963267948966" xyz="0 0 0.0596"/>
    <axis xyz="0 0 1"/>
    <limit effort="300" lower="-2.09439510239" upper="2.09439510239" velocity="10"/>
    <dynamics damping="0.5"/>
  </joint>
  <link name="link_19">
    <inertial>
      <origin rpy="0 0 0" xyz="0.0592 0.0451 0.0944"/>
      <mass value="5"/>
      <inertia ixx="0.0332" ixy="-0.099" ixz="0.0909" iyy="0.0223" iyz="-0.0974" izz="0.0461"/>
    </inertial>
  </link>
  <joint name="joint_19" type="revolute">
    <parent link="world"/>
    <child link="link_19"/>
    <origin rpy="0 -1.5707963267948966 -1.5707963267948966" xyz="0 0 0.1916"/>
    <axis xyz="0 0 1"/>
    <limit effort="300" lower="-2.09439510239" upper="2.09439510239" velocity="10"/>
    <dynamics damping="0.5"/>
  </joint>
  <link name="link_20">
    <inertial>
      <origin rpy="0 0 0" xyz="0.0773 0.0413 0.0282"/>
      <mass value="5"/>
      <inertia ixx="0.0775" ixy="-0.0204" ixz="-0.084" iyy="-0.0157" iyz="-0.0495" izz="0.094"/>
    </inertial>
  </link>
  <joint name="joint_20" type="revolute">
    <parent link="link_19"/>
    <child link="link_20"/>
    <origin rpy="-3.141592653589793 -3.141592653589793 1.5707963267948966" xyz="0 0 0.0234"/>
    <axis xyz="0 0 1"/>
    <limit effort="300" lower="-2.09439510239" upper="2.09439510239" velocity="10"/>
    <dynamics damping="0.5"/>
  </joint>
  <link name="link_21">
    <inertial>
      <origin rpy="0 0 0" xyz="0.0909 0.0826 0.0644"/>
      <mass value="5"/>
      <inertia ixx="-0.0978" ixy="-0.0704" ixz="0.0443" iyy="-0.0722" iyz="-0.0152" izz="0.0024"/>
    </inertial>
  </link>
  <joint name="joint_21" type="revolute">
    <parent link="link_20"/>
    <child link="link_21"/>
    <origin rpy="0 0 0" xyz="0 0 0.0518"/>
    <axis xyz="0 0 1"/>
    <limit effort="300" lower="-2.09439510239" upper="2.09439510239" velocity="10"/>
    <dynamics damping="0.5"/>
  </joint>
  <link name="link_22">
    <inertial>
      <origin rpy="0 0 0" xyz="0.0951 0.0122 0.037"/>
      <mass value="5"/>
      <inertia ixx="-0.0847" ixy="0.0265" ixz="0.0936" iyy="0.027" iyz="-0.0527" izz="0.0314"/>
    </inertial>
  </link>
  <joint name="joint_22" type="revolute">
    <parent link="link_21"/>
    <child link="link_22"/>
    <origin rpy="-1.5707963267948966 0 -1.5707963267948966" xyz="0 0 0.1653"/>
    <axis xyz="0 0 1"/>
    <limit effort="300" lower="-2.09439510239" upper="2.09439510239" velocity="10"/>
    <dynamics damping="0.5"/>
  </joint>
  <link name="link_23">
    <inertial>
      <origin rpy="0 0 0" xyz="0.0479 0.1 0.0427"/>
      <mass value="5"/>
      <inertia ixx="-0.0005" ixy="0.0791" ixz="0.0987" iyy="-0.029" iyz="-0.0164" izz="-0.0318"/>
    </inertial>
  </link>
  <joint name="joint_23" type="revolute">
    <parent link="link_22"/>
    <child link="link_23"/>
    <origin rpy="1.5707963267948966 -3.141592653589793 1.5707963267948966" xyz="0 0 0.1292"/>
    <axis xyz="0 0 1"/>
    <limit effort="300" lower="-2.09439510239" upper="2.09439510239" velocity="10"/>
    <dynamics damping="0.5"/>
  </joint>
  <link name="link_24">
    <inertial>
      <origin rpy="0 0 0" xyz="0.0859 0.0936 0.0375"/>
      <mass value="5"/>
      <inertia ixx="-0.0621" ixy="0.0823" ixz="0.0352" iyy="-0.0164" iyz="0.0245" izz="0.073"/>
    </inertial>
  </link>
  <joint name="joint_24" type="revolute">
    <parent link="link_23"/>
    <child link="link_24"/>
    <origin rpy="3.141592653589793 1.5707963267948966 -3.141592653589793" xyz="0 0 0.1161"/>
    <axis xyz="0 0 1"/>
    <limit effort="300" lower="-2.09439510239" upper="2.09439510239" velocity="10"/>
    <dynamics damping="0.5"/>
  </joint>
</robot>
