<?xml version="1.0" encoding="utf-8"?>
<robot name="iiwa">
  <link name="world"/>
  <link name="link_1">
    <inertial>
      <origin rpy="0 0 0" xyz="0.0151 0.016 0.0146"/>
      <mass value="5"/>
      <inertia ixx="-0.0888" ixy="0.0523" ixz="-0.0225" iyy="-0.0927" iyz="0.0285" izz="-0.0364"/>
    </inertial>
  </link>
  <joint name="joint_1" type="revolute">
    <parent link="world"/>
    <child link="link_1"/>
    <origin rpy="0 3.141592653589793 3.141592653589793" xyz="0 0 0.1216"/>
    <axis xyz="0 0 1"/>
    <limit effort="300" lower="-2.09439510239" upper="2.09439510239" velocity="10"/>
    <dynamics damping="0.5"/>
  </joint>
  <link name="link_2">
    <inertial>
      <origin rpy="0 0 0" xyz="0.0015 0.0831 0.066"/>
      <mass value="5"/>
      <inertia ixx="0.0837" ixy="-0.0773" ixz="0.0349" iyy="0.0718" iyz="-0.0719" izz="-0.0864"/>
    </inertial>
  </link>
  <joint name="joint_2" type="revolute">
    <parent link="link_1"/>
    <child link="link_2"/>
    <origin rpy="0 -3.141592653589793 0" xyz="0 0 0.1691"/>
    <axis xyz="0 0 1"/>
    <limit effort="300" lower="-2.09439510239" upper="2.09439510239" velocity="10"/>
    <dynamics damping="0.5"/>
  </joint>
  <link name="link_3">
    <inertial>
      <origin rpy="0 0 0" xyz="0.0759 0.087 0.0904"/>
      <mass value="5"/>
      <inertia ixx="-0.0991" ixy="0.0033" ixz="-0.0992" iyy="-0.0308" iyz="0.0696" izz="0.0601"/>
    </inertial>
  </link>
  <joint name="joint_3" type="revolute">
    <parent link="world"/>
    <child link="link_3"/>
    <origin rpy="0 -1.5707963267948966 1.5707963267948966" xyz="0 0 0.0546"/>
    <axis xyz="0 0 1"/>
    <limit effort="300" lower="-2.09439510239" upper="2.09439510239" velocity="10"/>
    <dynamics damping="0.5"/>
  </joint>
  <link name="link_4">
    <inertial>
      <origin rpy="0 0 0" xyz="0.0239 0.0162 0.0674"/>
      <mass value="5"/>
      <inertia ixx="-0.0917" ixy="0.0903" ixz="0.0312" iyy="0.0973" iyz="-0.0859" izz="0.0381"/>
    </inertial>
  </link>
  <joint name="joint_4" type="revolute">
    <parent link="link_3"/>
    <child link="link_4"/>
    <origin rpy="1.5707963267948966 1.5707963267948966 1.5707963267948966" xyz="0 0 0.1091"/>
    <axis xyz="0 0 1"/>
    <limit effort="300" lower="-2.09439510239" upper="2.09439510239" velocity="10"/>
    <dynamics damping="0.5"/>
  </joint>
  <link name="link_5">
    <inertial>
      <origin rpy="0 0 0" xyz="0.0528 0.0298 0.0231"/>
      <mass value="5"/>
      <inertia ixx="0.0255" ixy="-0.0725" ixz="-0.0024" iyy="-0.0488" iyz="0.0433" izz="0.0567"/>
    </inertial>
  </link>
  <joint name="joint_5" type="revolute">
    <parent link="world"/>
    <child link="link_5"/>
    <origin rpy="-3.141592653589793 -3.141592653589793 -1.5707963267948966" xyz="0 0 0.0064"/>
    <axis xyz="0 0 1"/>
    <limit effort="300" lower="-2.09439510239" upper="2.09439510239" velocity="10"/>
    <dynamics damping="0.5"/>
  </joint>
  <link name="link_6">
    <inertial>
      <origin rpy="0 0 0" xyz="0.0839 0.0873 0.0535"/>
      <mass value="5"/>
      <inertia ixx="0.0482" ixy="-0.0266" ixz="-0.032" iyy="0.0402" iyz="0.0193" izz="-0.0269"/>
    </inertial>
  </link>
  <joint name="joint_6" type="revolute">
    <parent link="link_5"/>
    <child link="link_6"/>
    <origin rpy="0 1.5707963267948966 1.5707963267948966" xyz="0 0 0.0597"/>
    <axis xyz="0 0 1"/>
    <limit effort="300" lower="-2.09439510239" upper="2.09439510239" velocity="10"/>
    <dynamics damping="0.5"/>
  </joint>
  <link name="link_7">
    <inertial>
      <origin rpy="0 0 0" xyz="0.0849 0.0085 0.0459"/>
      <mass value="5"/>
      <inertia ixx="-0.0721" ixy="0.0197" ixz="-0.0623" iyy="0.041" iyz="-0.0094" izz="-0.0323"/>
    </inertial>
  </link>
  <joint name="joint_7" type="revolute">
    <parent link="world"/>
    <child link="link_7"/>
    <origin rpy="3.141592653589793 -3.141592653589793 1.5707963267948966" xyz="0 0 0.0822"/>
    <axis xyz="0 0 1"/>
    <limit effort="300" lower="-2.09439510239" upper="2.09439510239" velocity="10"/>
    <dynamics damping="0.5"/>
  </joint>
  <link name="link_8">
    <inertial>
      <origin rpy="0 0 0" xyz="0.0255 0.0216 0.0867"/>
      <mass value="5"/>
      <inertia ixx="0.0408" ixy="-0.089" ixz="0.0731" iyy="0.0376" iyz="0.0465" izz="-0.0163"/>
    </inertial>
  </link>
  <joint name="joint_8" type="revolute">
    <parent link="link_7"/>
    <child link="link_8"/>
    <origin rpy="0 1.5707963267948966 -3.141592653589793" xyz="0 0 0.1246"/>
    <axis xyz="0 0 1"/>
    <limit effort="300" lower="-2.09439510239" upper="2.09439510239" velocity="10"/>
    <dynamics damping="0.5"/>
  </joint>
</robot>
