<?xml version="1.0" encoding="utf-8"?>
<robot name="iiwa">
  <link name="world"/>
  <link name="link_1">
    <inertial>
      <origin rpy="0 0 0" xyz="0.0029 0.0293 0.0764"/>
      <mass value="5"/>
      <inertia ixx="-0.0079" ixy="0.0633" ixz="-0.0495" iyy="-0.0725" iyz="-0.0547" izz="-0.0199"/>
    </inertial>
  </link>
  <joint name="joint_1" type="revolute">
    <parent link="world"/>
    <child link="link_1"/>
    <origin rpy="-3.141592653589793 3.141592653589793 3.141592653589793" xyz="0 0 0.0426"/>
    <axis xyz="0 0 1"/>
    <limit effort="300" lower="-2.09439510239" upper="2.09439510239" velocity="10"/>
    <dynamics damping="0.5"/>
  </joint>
  <link name="link_2">
    <inertial>
      <origin rpy="0 0 0" xyz="0.0715 0.0065 0.0609"/>
      <mass value="5"/>
      <inertia ixx="0.0406" ixy="-0.0293" ixz="0.0188" iyy="-0.022" iyz="0.0564" izz="-0.096"/>
    </inertial>
  </link>
  <joint name="joint_2" type="revolute">
    <parent link="link_1"/>
    <child link="link_2"/>
    <origin rpy="0 -1.5707963267948966 0" xyz="0 0 0.1286"/>
    <axis xyz="0 0 1"/>
    <limit effort="300" lower="-2.09439510239" upper="2.09439510239" velocity="10"/>
    <dynamics damping="0.5"/>
  </joint>
  <link name="link_3">
    <inertial>
      <origin rpy="0 0 0" xyz="0.0863 0.0544 0.0027"/>
      <mass value="5"/>
      <inertia ixx="0.0866" ixy="-0.074" ixz="-0.0093" iyy="0.0975" iyz="0.092" izz="-0.0085"/>
    </inertial>
  </link>
  <joint name="joint_3" type="revolute">
    <parent link="link_2"/>
    <child link="link_3"/>
    <origin rpy="-1.5707963267948966 0 0" xyz="0 0 0.1015"/>
    <axis xyz="0 0 1"/>
    <limit effort="300" lower="-2.09439510239" upper="2.09439510239" velocity="10"/>
    <dynamics damping="0.5"/>
  </joint>
  <link name="link_4">
    <inertial>
      <origin rpy="0 0 0" xyz="0.0337 0.0672 0.0242"/>
      <mass value="5"/>
      <inertia ixx="-0.0938" ixy="0.0356" ixz="0.057" iyy="-0.0803" iyz="-0.0586" izz="-0.0541"/>
    </inertial>
  </link>
  <joint name="joint_4" type="revolute">
    <parent link="link_3"/>
    <child link="link_4"/>
    <origin rpy="-1.5707963267948966 -3.141592653589793 0" xyz="0 0 0.0453"/>
    <axis xyz="0 0 1"/>
    <limit effort="300" lower="-2.09439510239" upper="2.09439510239" velocity="10"/>
    <dynamics damping="0.5"/>
  </joint>
  <link name="link_5">
    <inertial>
      <origin rpy="0 0 0" xyz="0.0513 0.0432 0.0147"/>
      <mass value="5"/>
      <inertia ixx="0.0917" ixy="0.0774" ixz="0.0916" iyy="-0.0604" iyz="0.0617" izz="0.0262"/>
    </inertial>
  </link>
  <joint name="joint_5" type="revolute">
    <parent link="link_4"/>
    <child link="link_5"/>
    <origin rpy="0 -3.141592653589793 0" xyz="0 0 0.1746"/>
    <axis xyz="0 0 1"/>
    <limit effort="300" lower="-2.09439510239" upper="2.09439510239" velocity="10"/>
    <dynamics damping="0.5"/>
  </joint>
  <link name="link_6">
    <inertial>
      <origin rpy="0 0 0" xyz="0.042 0.0835 0.0397"/>
      <mass value="5"/>
      <inertia ixx="-0.0692" ixy="-0.0198" ixz="0.0656" iyy="0.0074" iyz="0.0566" izz="-0.0928"/>
    </inertial>
  </link>
  <joint name="joint_6" type="revolute">
    <parent link="link_5"/>
    <child link="link_6"/>
    <origin rpy="3.141592653589793 1.5707963267948966 3.141592653589793" xyz="0 0 0.0655"/>
    <axis xyz="0 0 1"/>
    <limit effort="300" lower="-2.09439510239" upper="2.09439510239" velocity="10"/>
    <dynamics damping="0.5"/>
  </joint>
  <link name="link_7">
    <inertial>
      <origin rpy="0 0 0" xyz="0.0767 0.0391 0.0549"/>
      <mass value="5"/>
      <inertia ixx="0.0303" ixy="-0.0221" ixz="-0.0861" iyy="0.094" iyz="0.0918" izz="0.0932"/>
    </inertial>
  </link>
  <joint name="joint_7" type="revolute">
    <parent link="link_6"/>
    <child link="link_7"/>
    <origin rpy="-1.5707963267948966 1.5707963267948966 1.5707963267948966" xyz="0 0 0.0791"/>
    <axis xyz="0 0 1"/>
    <limit effort="300" lower="-2.09439510239" upper="2.09439510239" velocity="10"/>
    <dynamics damping="0.5"/>
  </joint>
  <link name="link_8">
    <inertial>
      <origin rpy="0 0 0" xyz="0.0641 0.0877 0.0311"/>
      <mass value="5"/>
      <inertia ixx="-0.0506" ixy="-0.0099" ixz="-0.0539" iyy="-0.0959" iyz="-0.0729" izz="0.06"/>
    </inertial>
  </link>
  <joint name="joint_8" type="revolute">
    <parent link="world"/>
    <child link="link_8"/>
    <origin rpy="0 0 1.5707963267948966" xyz="0 0 0.1233"/>
    <axis xyz="0 0 1"/>
    <limit effort="300" lower="-2.09439510239" upper="2.09439510239" velocity="10"/>
    <dynamics damping="0.5"/>
  </joint>
  <link name="link_9">
    <inertial>
      <origin rpy="0 0 0" xyz="0.0825 0.0505 0.0183"/>
      <mass value="5"/>
      <inertia ixx="-0.0951" ixy="-0.084" ixz="-0.0443" iyy="0.0271" iyz="0.0657" izz="0.0284"/>
    </inertial>
  </link>
  <joint name="joint_9" type="revolute">
    <parent link="link_8"/>
    <child link="link_9"/>
    <origin rpy="-3.141592653589793 -3.141592653589793 0" xyz="0 0 0.1571"/>
    <axis xyz="0 0 1"/>
    <limit effort="300" lower="-2.09439510239" upper="2.09439510239" velocity="10"/>
    <dynamics damping="0.5"/>
  </joint>
  <link name="link_10">
    <inertial>
      <origin rpy="0 0 0" xyz="0.0638 0.0353 0.0486"/>
      <mass value="5"/>
      <inertia ixx="0.0328" ixy="0.0303" ixz="-0.0805" iyy="-0.0472" iyz="0.0809" izz="0.0774"/>
    </inertial>
  </link>
  <joint name="joint_10" type="revolute">
    <parent link="link_9"/>
    <child link="link_10"/>
    <origin rpy="3.141592653589793 3.141592653589793 0" xyz="0 0 0.0921"/>
    <axis xyz="0 0 1"/>
    <limit effort="300" lower="-2.09439510239" upper="2.09439510239" velocity="10"/>
    <dynamics damping="0.5"/>
  </joint>
  <link name="link_11">
    <inertial>
      <origin rpy="0 0 0" xyz="0.0075 0.0535 0.0109"/>
      <mass value="5"/>
      <inertia ixx="0.0123" ixy="0.068" ixz="0.0135" iyy="-0.0438" iyz="0.0433" izz="-0.0003"/>
    </inertial>
  </link>
  <joint name="joint_11" type="revolute">
    <parent link="link_10"/>
    <child link="link_11"/>
    <origin rpy="0 0 3.141592653589793" xyz="0 0 0.157"/>
    <axis xyz="0 0 1"/>
    <limit effort="300" lower="-2.09439510239" upper="2.09439510239" velocity="10"/>
    <dynamics damping="0.5"/>
  </joint>
  <link name="link_12">
    <inertial>
      <origin rpy="0 0 0" xyz="0.0384 0.015 0.0554"/>
      <mass value="5"/>
      <inertia ixx="0.0411" ixy="0.0308" ixz="-0.0263" iyy="-0.0885" iyz="0.0835" izz="-0.0237"/>
    </inertial>
  </link>
  <joint name="joint_12" type="revolute">
    <parent link="link_11"/>
    <child link="link_12"/>
    <origin rpy="1.5707963267948966 1.5707963267948966 3.141592653589793" xyz="0 0 0.0995"/>
    <axis xyz="0 0 1"/>
    <limit effort="300" lower="-2.09439510239" upper="2.09439510239" velocity="10"/>
    <dynamics damping="0.5"/>
  </joint>
  <link name="link_13">
    <inertial>
      <origin rpy="0 0 0" xyz="0.0944 0.0849 0.0426"/>
      <mass value="5"/>
      <inertia ixx="-0.0423" ixy="-0.0808" ixz="0.002" iyy="0.0339" iyz="0.0737" izz="-0.0907"/>
    </inertial>
  </link>
  <joint name="joint_13" type="revolute">
    <parent link="link_12"/>
    <child link="link_13"/>
    <origin rpy="3.141592653589793 -1.5707963267948966 3.141592653589793" xyz="0 0 0.0136"/>
    <axis xyz="0 0 1"/>
    <limit effort="300" lower="-2.09439510239" upper="2.09439510239" velocity="10"/>
    <dynamics damping="0.5"/>
  </joint>
  <link name="link_14">
    <inertial>
      <origin rpy="0 0 0" xyz="0.0156 0.0289 0.0294"/>
      <mass value="5"/>
      <inertia ixx="0.0823" ixy="-0.0378" ixz="-0.0503" iyy="0.024" iyz="-0.0965" izz="-0.07"/>
    </inertial>
  </link>
  <joint name="joint_14" type="revolute">
    <parent link="link_13"/>
    <child link="link_14"/>
    <origin rpy="3.141592653589793 3.141592653589793 -1.5707963267948966" xyz="0 0 0.0047"/>
    <axis xyz="0 0 1"/>
    <limit effort="300" lower="-2.09439510239" upper="2.09439510239" velocity="10"/>
    <dynamics damping="0.5"/>
  </joint>
  <link name="link_15">
    <inertial>
      <origin rpy="0 0 0" xyz="0.0981 0.0162 0.0688"/>
      <mass value="5"/>
      <inertia ixx="0.0204" ixy="0.0277" ixz="-0.067" iyy="0.0127" iyz="-0.0656" izz="-0.0877"/>
    </inertial>
  </link>
  <joint name="joint_15" type="revolute">
    <parent link="world"/>
    <child link="link_15"/>
    <origin rpy="1.5707963267948966 3.141592653589793 -1.5707963267948966" xyz="0 0 0.132"/>
    <axis xyz="0 0 1"/>
    <limit effort="300" lower="-2.09439510239" upper="2.09439510239" velocity="10"/>
    <dynamics damping="0.5"/>
  </joint>
  <link name="link_16">
    <inertial>
      <origin rpy="0 0 0" xyz="0.0651 0.0447 0.0309"/>
      <mass value="5"/>
      <inertia ixx="-0.0536" ixy="-0.0328" ixz="-0.0398" iyy="0.0388" iyz="0.0192" izz="-0.0743"/>
    </inertial>
  </link>
  <joint name="joint_16" type="revolute">
    <parent link="link_15"/>
    <child link="link_16"/>
    <origin rpy="-3.141592653589793 -3.141592653589793 3.141592653589793" xyz="0 0 0.0822"/>
    <axis xyz="0 0 1"/>
    <limit effort="300" lower="-2.09439510239" upper="2.09439510239" velocity="10"/>
    <dynamics damping="0.5"/>
  </joint>
  <link name="link_17">
    <inertial>
      <origin rpy="0 0 0" xyz="0.0881 0.0783 0.0335"/>
      <mass value="5"/>
      <inertia ixx="-0.0439" ixy="0.0173" ixz="-0.0664" iyy="0.0373" iyz="-0.0379" izz="-0.0067"/>
    </inertial>
  </link>
  <joint name="joint_17" type="revolute">
    <parent link="link_16"/>
    <child link="link_17"/>
    <origin rpy="-3.141592653589793 1.5707963267948966 -3.141592653589793" xyz="0 0 0.183"/>
    <axis xyz="0 0 1"/>
    <limit effort="300" lower="-2.09439510239" upper="2.09439510239" velocity="10"/>
    <dynamics damping="0.5"/>
  </joint>
  <link name="link_18">
    <inertial>
      <origin rpy="0 0 0" xyz="0.0348 0.0368 0.0739"/>
      <mass value="5"/>
      <inertia ixx="0.0626" ixy="0.0389" ixz="-0.0531" iyy="-0.0807" iyz="0.0054" izz="0.0542"/>
    </inertial>
  </link>
  <joint name="joint_18" type="revolute">
    <parent link="link_17"/>
    <child link="link_18"/>
    <origin rpy="-1.5707963267948966 1.5707963267948966 0" xyz="0 0 0.0034"/>
    <axis xyz="0 0 1"/>
    <limit effort="300" lower="-2.09439510239" upper="2.09439510239" velocity="10"/>
    <dynamics damping="0.5"/>
  </joint>
  <link name="link_19">
    <inertial>
      <origin rpy="0 0 0" xyz="0.0141 0.0503 0.0061"/>
      <mass value="5"/>
      <inertia ixx="-0.0087" ixy="0.0756" ixz="0.0246" iyy="0.0408" iyz="0.0909" izz="0.0398"/>
    </inertial>
  </link>
  <joint name="joint_19" type="revolute">
    <parent link="link_18"/>
    <child link="link_19"/>
    <origin rpy="-3.141592653589793 3.141592653589793 -1.5707963267948966" xyz="0 0 0.1927"/>
    <axis xyz="0 0 1"/>
    <limit effort="300" lower="-2.09439510239" upper="2.09439510239" velocity="10"/>
    <dynamics damping="0.5"/>
  </joint>
  <link name="link_20">
    <inertial>
      <origin rpy="0 0 0" xyz="0.0308 0.0016 0.0361"/>
      <mass value="5"/>
      <inertia ixx="-0.0615" ixy="-0.0976" ixz="-0.027" iyy="0.0371" iyz="-0.0003" izz="0.0888"/>
    </inertial>
  </link>
  <joint name="joint_20" type="revolute">
    <parent link="link_19"/>
    <child link="link_20"/>
    <origin rpy="1.5707963267948966 0 3.141592653589793" xyz="0 0 0.0558"/>
    <axis xyz="0 0 1"/>
    <limit effort="300" lower="-2.09439510239" upper="2.09439510239" velocity="10"/>
    <dynamics damping="0.5"/>
  </joint>
  <link name="link_21">
    <inertial>
      <origin rpy="0 0 0" xyz="0.0681 0.0649 0.0549"/>
      <mass value="5"/>
      <inertia ixx="-0.0243" ixy="0.0459" ixz="0.0354" iyy="0.0648" iyz="0.025" izz="-0.019"/>
    </inertial>
  </link>
  <joint name="joint_21" type="revolute">
    <parent link="link_20"/>
    <child link="link_21"/>
    <origin rpy="1.5707963267948966 0 0" xyz="0 0 0.0196"/>
    <axis xyz="0 0 1"/>
    <limit effort="300" lower="-2.09439510239" upper="2.09439510239" velocity="10"/>
    <dynamics damping="0.5"/>
  </joint>
  <link name="link_22">
    <inertial>
      <origin rpy="0 0 0" xyz="0.0152 0.0719 0.0483"/>
      <mass value="5"/>
      <inertia ixx="0.0006" ixy="-0.0765" ixz="0.0777" iyy="0.0126" iyz="0.0093" izz="0.0748"/>
    </inertial>
  </link>
  <joint name="joint_22" type="revolute">
    <parent link="world"/>
    <child link="link_22"/>
    <origin rpy="-3.141592653589793 -1.5707963267948966 3.141592653589793" xyz="0 0 0.0763"/>
    <axis xyz="0 0 1"/>
    <limit effort="300" lower="-2.09439510239" upper="2.09439510239" velocity="10"/>
    <dynamics damping="0.5"/>
  </joint>
  <link name="link_23">
    <inertial>
      <origin rpy="0 0 0" xyz="0.0982 0.0537 0.0373"/>
      <mass value="5"/>
      <inertia ixx="-0.0125" ixy="-0.012" ixz="0.0765" iyy="-0.0081" iyz="-0.0249" izz="-0.0269"/>
    </inertial>
  </link>
  <joint name="joint_23" type="revolute">
    <parent link="link_22"/>
    <child link="link_23"/>
    <origin rpy="0 -3.141592653589793 -3.141592653589793" xyz="0 0 0.147"/>
    <axis xyz="0 0 1"/>
    <limit effort="300" lower="-2.09439510239" upper="2.09439510239" velocity="10"/>
    <dynamics damping="0.5"/>
  </joint>
  <link name="link_24">
    <inertial>
      <origin rpy="0 0 0" xyz="0.0018 0.0385 0.0275"/>
      <mass value="5"/>
      <inertia ixx="-0.0359" ixy="-0.0806" ixz="-0.0881" iyy="0.0769" iyz="-0.0556" izz="0.0594"/>
    </inertial>
  </link>
  <joint name="joint_24" type="revolute">
    <parent link="link_23"/>
    <child link="link_24"/>
    <origin rpy="-3.141592653589793 -1.5707963267948966 3.141592653589793" xyz="0 0 0.0099"/>
    <axis xyz="0 0 1"/>
    <limit effort="300" lower="-2.09439510239" upper="2.09439510239" velocity="10"/>
    <dynamics damping="0.5"/>
  </joint>
  <link name="link_25">
    <inertial>
      <origin rpy="0 0 0" xyz="0.0849 0.0482 0.0069"/>
      <mass value="5"/>
      <inertia ixx="-0.082" ixy="0.0259" ixz="-0.0858" iyy="-0.0271" iyz="0.0343" izz="0.0409"/>
    </inertial>
  </link>
  <joint name="joint_25" type="revolute">
    <parent link="link_24"/>
    <child link="link_25"/>
    <origin rpy="-1.5707963267948966 1.5707963267948966 0" xyz="0 0 0.1503"/>
    <axis xyz="0 0 1"/>
    <limit effort="300" lower="-2.09439510239" upper="2.09439510239" velocity="10"/>
    <dynamics damping="0.5"/>
  </joint>
  <link name="link_26">
    <inertial>
      <origin rpy="0 0 0" xyz="0.0493 0.0474 0.0666"/>
      <mass value="5"/>
      <inertia ixx="0.0675" ixy="0.0843" ixz="0.0236" iyy="0.0842" iyz="0.0199" izz="-0.0916"/>
    </inertial>
  </link>
  <joint name="joint_26" type="revolute">
    <parent link="link_25"/>
    <child link="link_26"/>
    <origin rpy="0 -3.141592653589793 -3.141592653589793" xyz="0 0 0.1145"/>
    <axis xyz="0 0 1"/>
    <limit effort="300" lower="-2.09439510239" upper="2.09439510239" velocity="10"/>
    <dynamics damping="0.5"/>
  </joint>
  <link name="link_27">
    <inertial>
      <origin rpy="0 0 0" xyz="0.0575 0.0135 0.0855"/>
      <mass value="5"/>
      <inertia ixx="0.0468" ixy="-0.0328" ixz="-0.0891" iyy="-0.0633" iyz="-0.0322" izz="0.0954"/>
    </inertial>
  </link>
  <joint name="joint_27" type="revolute">
    <parent link="link_26"/>
    <child link="link_27"/>
    <origin rpy="0 -1.5707963267948966 0" xyz="0 0 0.0068"/>
    <axis xyz="0 0 1"/>
    <limit effort="300" lower="-2.09439510239" upper="2.09439510239" velocity="10"/>
    <dynamics damping="0.5"/>
  </joint>
  <link name="link_28">
    <inertial>
      <origin rpy="0 0 0" xyz="0.0817 0.0741 0.0618"/>
      <mass value="5"/>
      <inertia ixx="0.0433" ixy="0.0114" ixz="-0.0956" iyy="0.0187" iyz="-0.0468" izz="0.0497"/>
    </inertial>
  </link>
  <joint name="joint_28" type="revolute">
    <parent link="link_27"/>
    <child link="link_28"/>
    <origin rpy="-1.5707963267948966 1.5707963267948966 3.141592653589793" xyz="0 0 0.1145"/>
    <axis xyz="0 0 1"/>
    <limit effort="300" lower="-2.09439510239" upper="2.09439510239" velocity="10"/>
    <dynamics damping="0.5"/>
  </joint>
</robot>
