<?xml version="1.0" encoding="utf-8"?>
<robot name="iiwa">
  <link name="world"/>
  <link name="link_1">
    <inertial>
      <origin rpy="0 0 0" xyz="0.0068 0.0986 0.026"/>
      <mass value="5"/>
      <inertia ixx="-0.069" ixy="-0.0883" ixz="-0.0761" iyy="0.061" iyz="0.0887" izz="0.0812"/>
    </inertial>
  </link>
  <joint name="joint_1" type="revolute">
    <parent link="world"/>
    <child link="link_1"/>
    <origin rpy="0 0 0" xyz="0 0 0.1511"/>
    <axis xyz="0 0 1"/>
    <limit effort="300" lower="-2.09439510239" upper="2.09439510239" velocity="10"/>
    <dynamics damping="0.5"/>
  </joint>
  <link name="link_2">
    <inertial>
      <origin rpy="0 0 0" xyz="0.0034 0.0307 0.0157"/>
      <mass value="5"/>
      <inertia ixx="0.0848" ixy="-0.0487" ixz="-0.0347" iyy="0.0192" iyz="0.0844" izz="0.0821"/>
    </inertial>
  </link>
  <joint name="joint_2" type="revolute">
    <parent link="link_1"/>
    <child link="link_2"/>
    <origin rpy="-3.141592653589793 1.5707963267948966 -3.141592653589793" xyz="0 0 0.0411"/>
    <axis xyz="0 0 1"/>
    <limit effort="300" lower="-2.09439510239" upper="2.09439510239" velocity="10"/>
    <dynamics damping="0.5"/>
  </joint>
  <link name="link_3">
    <inertial>
      <origin rpy="0 0 0" xyz="0.0506 0.0706 0.0357"/>
      <mass value="5"/>
      <inertia ixx="-0.0129" ixy="0.0729" ixz="0.0059" iyy="0.0228" iyz="0.0347" izz="-0.0339"/>
    </inertial>
  </link>
  <joint name="joint_3" type="revolute">
    <parent link="link_2"/>
    <child link="link_3"/>
    <origin rpy="-3.141592653589793 -3.141592653589793 -1.5707963267948966" xyz="0 0 0.0797"/>
    <axis xyz="0 0 1"/>
    <limit effort="300" lower="-2.09439510239" upper="2.09439510239" velocity="10"/>
    <dynamics damping="0.5"/>
  </joint>
  <link name="link_4">
    <inertial>
      <origin rpy="0 0 0" xyz="0.0761 0.0737 0.0619"/>
      <mass value="5"/>
      <inertia ixx="0.0379" ixy="0.0673" ixz="0.0477" iyy="0.072" iyz="0.052" izz="-0.0394"/>
    </inertial>
  </link>
  <joint name="joint_4" type="revolute">
    <parent link="link_3"/>
    <child link="link_4"/>
    <origin rpy="0 -3.141592653589793 0" xyz="0 0 0.0741"/>
    <axis xyz="0 0 1"/>
    <limit effort="300" lower="-2.09439510239" upper="2.09439510239" velocity="10"/>
    <dynamics damping="0.5"/>
  </joint>
  <link name="link_5">
    <inertial>
      <origin rpy="0 0 0" xyz="0.0352 0.0226 0.0384"/>
      <mass value="5"/>
      <inertia ixx="0.0075" ixy="0.0872" ixz="-0.0112" iyy="-0.0777" iyz="0.0641" izz="-0.0977"/>
    </inertial>
  </link>
  <joint name="joint_5" type="revolute">
    <parent link="world"/>
    <child link="link_5"/>
    <origin rpy="1.5707963267948966 1.5707963267948966 0" xyz="0 0 0.0736"/>
    <axis xyz="0 0 1"/>
    <limit effort="300" lower="-2.09439510239" upper="2.09439510239" velocity="10"/>
    <dynamics damping="0.5"/>
  </joint>
  <link name="link_6">
    <inertial>
      <origin rpy="0 0 0" xyz="0.0856 0.0534 0.0676"/>
      <mass value="5"/>
      <inertia ixx="0.0399" ixy="-0.0967" ixz="0.0954" iyy="-0.0827" iyz="0.0019" izz="-0.0571"/>
    </inertial>
  </link>
  <joint name="joint_6" type="revolute">
    <parent link="link_5"/>
    <child link="link_6"/>
    <origin rpy="3.141592653589793 1.5707963267948966 -3.141592653589793" xyz="0 0 0.0637"/>
    <axis xyz="0 0 1"/>
    <limit effort="300" lower="-2.09439510239" upper="2.09439510239" velocity="10"/>
    <dynamics damping="0.5"/>
  </joint>
  <link name="link_7">
    <inertial>
      <origin rpy="0 0 0" xyz="0.062 0.0131 0.01"/>
      <mass value="5"/>
      <inertia ixx="-0.0268" ixy="-0.0615" ixz="-0.02" iyy="0.0438" iyz="0.077" izz="0.0995"/>
    </inertial>
  </link>
  <joint name="joint_7" type="revolute">
    <parent link="link_6"/>
    <child link="link_7"/>
    <origin rpy="1.5707963267948966 -1.5707963267948966 1.5707963267948966" xyz="0 0 0.1172"/>
    <axis xyz="0 0 1"/>
    <limit effort="300" lower="-2.09439510239" upper="2.09439510239" velocity="10"/>
    <dynamics damping="0.5"/>
  </joint>
  <link name="link_8">
    <inertial>
      <origin rpy="0 0 0" xyz="0.0938 0.0752 0.0627"/>
      <mass value="5"/>
      <inertia ixx="-0.0837" ixy="-0.0254" ixz="-0.0943" iyy="-0.0166" iyz="-0.0814" izz="0.0387"/>
    </inertial>
  </link>
  <joint name="joint_8" type="revolute">
    <parent link="link_7"/>
    <child link="link_8"/>
    <origin rpy="-1.5707963267948966 1.5707963267948966 -1.5707963267948966" xyz="0 0 0.1207"/>
    <axis xyz="0 0 1"/>
    <limit effort="300" lower="-2.09439510239" upper="2.09439510239" velocity="10"/>
    <dynamics damping="0.5"/>
  </joint>
  <link name="link_9">
    <inertial>
      <origin rpy="0 0 0" xyz="0.0266 0.0372 0.0194"/>
      <mass value="5"/>
      <inertia ixx="-0.0128" ixy="-0.0339" ixz="-0.0843" iyy="0.0292" iyz="-0.06" izz="0.024"/>
    </inertial>
  </link>
  <joint name="joint_9" type="revolute">
    <parent link="world"/>
    <child link="link_9"/>
    <origin rpy="-3.141592653589793 3.141592653589793 1.5707963267948966" xyz="0 0 0.0007"/>
    <axis xyz="0 0 1"/>
    <limit effort="300" lower="-2.09439510239" upper="2.09439510239" velocity="10"/>
    <dynamics damping="0.5"/>
  </joint>
  <link name="link_10">
    <inertial>
      <origin rpy="0 0 0" xyz="0.0417 0.0008 0.0079"/>
      <mass value="5"/>
      <inertia ixx="0.0536" ixy="-0.0911" ixz="-0.021" iyy="0.0282" iyz="-0.0056" izz="-0.0508"/>
    </inertial>
  </link>
  <joint name="joint_10" type="revolute">
    <parent link="link_9"/>
    <child link="link_10"/>
    <origin rpy="0 3.141592653589793 -1.5707963267948966" xyz="0 0 0.1928"/>
    <axis xyz="0 0 1"/>
    <limit effort="300" lower="-2.09439510239" upper="2.09439510239" velocity="10"/>
    <dynamics damping="0.5"/>
  </joint>
  <link name="link_11">
    <inertial>
      <origin rpy="0 0 0" xyz="0.0448 0.0059 0.0949"/>
      <mass value="5"/>
      <inertia ixx="-0.072" ixy="-0.0861" ixz="-0.09" iyy="0.0887" iyz="-0.0353" izz="-0.0899"/>
    </inertial>
  </link>
  <joint name="joint_11" type="revolute">
    <parent link="link_10"/>
    <child link="link_11"/>
    <origin rpy="3.141592653589793 1.5707963267948966 -1.5707963267948966" xyz="0 0 0.0909"/>
    <axis xyz="0 0 1"/>
    <limit effort="300" lower="-2.09439510239" upper="2.09439510239" velocity="10"/>
    <dynamics damping="0.5"/>
  </joint>
  <link name="link_12">
    <inertial>
      <origin rpy="0 0 0" xyz="0.0637 0.0951 0.0225"/>
      <mass value="5"/>
      <inertia ixx="-0.0006" ixy="-0.0196" ixz="0.0062" iyy="0.0593" iyz="-0.0863" izz="0.0626"/>
    </inertial>
  </link>
  <joint name="joint_12" type="revolute">
    <parent link="link_11"/>
    <child link="link_12"/>
    <origin rpy="0 -3.141592653589793 0" xyz="0 0 0.1538"/>
    <axis xyz="0 0 1"/>
    <limit effort="300" lower="-2.09439510239" upper="2.09439510239" velocity="10"/>
    <dynamics damping="0.5"/>
  </joint>
  <link name="link_13">
    <inertial>
      <origin rpy="0 0 0" xyz="0.0001 0.0522 0.0048"/>
      <mass value="5"/>
      <inertia ixx="0.0866" ixy="-0.0653" ixz="-0.009" iyy="-0.0828" iyz="0.0564" izz="0.0085"/>
    </inertial>
  </link>
  <joint name="joint_13" type="revolute">
    <parent link="world"/>
    <child link="link_13"/>
    <origin rpy="0 3.141592653589793 1.5707963267948966" xyz="0 0 0.1066"/>
    <axis xyz="0 0 1"/>
    <limit effort="300" lower="-2.09439510239" upper="2.09439510239" velocity="10"/>
    <dynamics damping="0.5"/>
  </joint>
  <link name="link_14">
    <inertial>
      <origin rpy="0 0 0" xyz="0.0216 0.012 0.0274"/>
      <mass value="5"/>
      <inertia ixx="0.0924" ixy="0.043" ixz="0.0794" iyy="0.0522" iyz="-0.0386" izz="-0.0766"/>
    </inertial>
  </link>
  <joint name="joint_14" type="revolute">
    <parent link="link_13"/>
    <child link="link_14"/>
    <origin rpy="-1.5707963267948966 -3.141592653589793 -1.5707963267948966" xyz="0 0 0.0086"/>
    <axis xyz="0 0 1"/>
    <limit effort="300" lower="-2.09439510239" upper="2.09439510239" velocity="10"/>
    <dynamics damping="0.5"/>
  </joint>
  <link name="link_15">
    <inertial>
      <origin rpy="0 0 0" xyz="0.0911 0.0772 0.0568"/>
      <mass value="5"/>
      <inertia ixx="0.0875" ixy="0.0019" ixz="0.0475" iyy="-0.0546" iyz="-0.0975" izz="0.0769"/>
    </inertial>
  </link>
  <joint name="joint_15" type="revolute">
    <parent link="link_14"/>
    <child link="link_15"/>
    <origin rpy="-1.5707963267948966 0 -3.141592653589793" xyz="0 0 0.0624"/>
    <axis xyz="0 0 1"/>
    <limit effort="300" lower="-2.09439510239" upper="2.09439510239" velocity="10"/>
    <dynamics damping="0.5"/>
  </joint>
  <link name="link_16">
    <inertial>
      <origin rpy="0 0 0" xyz="0.0521 0.0158 0.0422"/>
      <mass value="5"/>
      <inertia ixx="0.0801" ixy="0.0322" ixz="-0.0552" iyy="-0.0489" iyz="0.0626" izz="-0.006"/>
    </inertial>
  </link>
  <joint name="joint_16" type="revolute">
    <parent link="link_15"/>
    <child link="link_16"/>
    <origin rpy="0 0 3.141592653589793" xyz="0 0 0.0129"/>
    <axis xyz="0 0 1"/>
    <limit effort="300" lower="-2.09439510239" upper="2.09439510239" velocity="10"/>
    <dynamics damping="0.5"/>
  </joint>
</robot>
