<?xml version="1.0" encoding="utf-8"?>
<robot name="iiwa">
  <link name="world"/>
  <link name="link_1">
    <inertial>
      <origin rpy="0 0 0" xyz="0.0935 0.0918 0.0709"/>
      <mass value="5"/>
      <inertia ixx="0.0978" ixy="-0.0369" ixz="-0.0771" iyy="0.072" iyz="-0.0917" izz="0.0137"/>
    </inertial>
  </link>
  <joint name="joint_1" type="revolute">
    <parent link="world"/>
    <child link="link_1"/>
    <origin rpy="1.5707963267948966 0 3.141592653589793" xyz="0 0 0.1711"/>
    <axis xyz="0 0 1"/>
    <limit effort="300" lower="-2.09439510239" upper="2.09439510239" velocity="10"/>
    <dynamics damping="0.5"/>
  </joint>
  <link name="link_2">
    <inertial>
      <origin rpy="0 0 0" xyz="0.0279 0.052 0.0588"/>
      <mass value="5"/>
      <inertia ixx="-0.032" ixy="0.0124" ixz="-0.0674" iyy="-0.0762" iyz="0.0238" izz="-0.0167"/>
    </inertial>
  </link>
  <joint name="joint_2" type="revolute">
    <parent link="link_1"/>
    <child link="link_2"/>
    <origin rpy="-1.5707963267948966 -3.141592653589793 -1.5707963267948966" xyz="0 0 0.1434"/>
    <axis xyz="0 0 1"/>
    <limit effort="300" lower="-2.09439510239" upper="2.09439510239" velocity="10"/>
    <dynamics damping="0.5"/>
  </joint>
  <link name="link_3">
    <inertial>
      <origin rpy="0 0 0" xyz="0.0005 0.0492 0.0837"/>
      <mass value="5"/>
      <inertia ixx="-0.007" ixy="-0.0745" ixz="0.0712" iyy="-0.0377" iyz="0.0038" izz="0.0822"/>
    </inertial>
  </link>
  <joint name="joint_3" type="revolute">
    <parent link="link_2"/>
    <child link="link_3"/>
    <origin rpy="3.141592653589793 0 0" xyz="0 0 0.1914"/>
    <axis xyz="0 0 1"/>
    <limit effort="300" lower="-2.09439510239" upper="2.09439510239" velocity="10"/>
    <dynamics damping="0.5"/>
  </joint>
  <link name="link_4">
    <inertial>
      <origin rpy="0 0 0" xyz="0.0238 0.0679 0.0734"/>
      <mass value="5"/>
      <inertia ixx="0.0366" ixy="-0.0627" ixz="-0.0438" iyy="-0.0966" iyz="-0.0719" izz="0.0225"/>
    </inertial>
  </link>
  <joint name="joint_4" type="revolute">
    <parent link="link_3"/>
    <child link="link_4"/>
    <origin rpy="-1.5707963267948966 0 3.141592653589793" xyz="0 0 0.09"/>
    <axis xyz="0 0 1"/>
    <limit effort="300" lower="-2.09439510239" upper="2.09439510239" velocity="10"/>
    <dynamics damping="0.5"/>
  </joint>
  <link name="link_5">
    <inertial>
      <origin rpy="0 0 0" xyz="0.0275 0.0937 0.0886"/>
      <mass value="5"/>
      <inertia ixx="-0.0745" ixy="-0.0019" ixz="0.0461" iyy="-0.0879" iyz="-0.008" izz="0.07"/>
    </inertial>
  </link>
  <joint name="joint_5" type="revolute">
    <parent link="link_4"/>
    <child link="link_5"/>
    <origin rpy="1.5707963267948966 -1.5707963267948966 3.141592653589793" xyz="0 0 0.1802"/>
    <axis xyz="0 0 1"/>
    <limit effort="300" lower="-2.09439510239" upper="2.09439510239" velocity="10"/>
    <dynamics damping="0.5"/>
  </joint>
  <link name="link_6">
    <inertial>
      <origin rpy="0 0 0" xyz="0.0593 0.0775 0.0763"/>
      <mass value="5"/>
      <inertia ixx="0.099" ixy="-0.0798" ixz="-0.0901" iyy="0.0722" iyz="-0.022" izz="0.0679"/>
    </inertial>
  </link>
  <joint name="joint_6" type="revolute">
    <parent link="world"/>
    <child link="link_6"/>
    <origin rpy="3.141592653589793 -1.5707963267948966 -3.141592653589793" xyz="0 0 0.0042"/>
    <axis xyz="0 0 1"/>
    <limit effort="300" lower="-2.09439510239" upper="2.09439510239" velocity="10"/>
    <dynamics damping="0.5"/>
  </joint>
  <link name="link_7">
    <inertial>
      <origin rpy="0 0 0" xyz="0.0401 0.0597 0.0656"/>
      <mass value="5"/>
      <inertia ixx="-0.0454" ixy="-0.0081" ixz="-0.0522" iyy="-0.0135" iyz="-0.0226" izz="0.0561"/>
    </inertial>
  </link>
  <joint name="joint_7" type="revolute">
    <parent link="link_6"/>
    <child link="link_7"/>
    <origin rpy="-1.5707963267948966 -1.5707963267948966 -3.141592653589793" xyz="0 0 0.099"/>
    <axis xyz="0 0 1"/>
    <limit effort="300" lower="-2.09439510239" upper="2.09439510239" velocity="10"/>
    <dynamics damping="0.5"/>
  </joint>
  <link name="link_8">
    <inertial>
      <origin rpy="0 0 0" xyz="0.0764 0.0669 0.0376"/>
      <mass value="5"/>
      <inertia ixx="-0.0449" ixy="0.0755" ixz="-0.0049" iyy="-0.0443" iyz="-0.0447" izz="0.0991"/>
    </inertial>
  </link>
  <joint name="joint_8" type="revolute">
    <parent link="link_7"/>
    <child link="link_8"/>
    <origin rpy="-3.141592653589793 0 -3.141592653589793" xyz="0 0 0.1273"/>
    <axis xyz="0 0 1"/>
    <limit effort="300" lower="-2.09439510239" upper="2.09439510239" velocity="10"/>
    <dynamics damping="0.5"/>
  </joint>
  <link name="link_9">
    <inertial>
      <origin rpy="0 0 0" xyz="0.0289 0.0465 0.0835"/>
      <mass value="5"/>
      <inertia ixx="-0.0559" ixy="0.0315" ixz="0.059" iyy="0.0223" iyz="0.0332" izz="0.0671"/>
    </inertial>
  </link>
  <joint name="joint_9" type="revolute">
    <parent link="link_8"/>
    <child link="link_9"/>
    <origin rpy="1.5707963267948966 0 -3.141592653589793" xyz="0 0 0.0405"/>
    <axis xyz="0 0 1"/>
    <limit effort="300" lower="-2.09439510239" upper="2.09439510239" velocity="10"/>
    <dynamics damping="0.5"/>
  </joint>
  <link name="link_10">
    <inertial>
      <origin rpy="0 0 0" xyz="0.0075 0.0427 0.0804"/>
      <mass value="5"/>
      <inertia ixx="-0.0268" ixy="0.0515" ixz="0.0148" iyy="-0.0134" iyz="-0.0325" izz="-0.0367"/>
    </inertial>
  </link>
  <joint name="joint_10" type="revolute">
    <parent link="link_9"/>
    <child link="link_10"/>
    <origin rpy="0 -3.141592653589793 3.141592653589793" xyz="0 0 0.1075"/>
    <axis xyz="0 0 1"/>
    <limit effort="300" lower="-2.09439510239" upper="2.09439510239" velocity="10"/>
    <dynamics damping="0.5"/>
  </joint>
  <link name="link_11">
    <inertial>
      <origin rpy="0 0 0" xyz="0.0714 0.054 0.0683"/>
      <mass value="5"/>
      <inertia ixx="-0.0453" ixy="-0.0022" ixz="-0.0108" iyy="-0.0862" iyz="-0.0027" izz="-0.0334"/>
    </inertial>
  </link>
  <joint name="joint_11" type="revolute">
    <parent link="world"/>
    <child link="link_11"/>
    <origin rpy="3.141592653589793 -1.5707963267948966 -1.5707963267948966" xyz="0 0 0.0152"/>
    <axis xyz="0 0 1"/>
    <limit effort="300" lower="-2.09439510239" upper="2.09439510239" velocity="10"/>
    <dynamics damping="0.5"/>
  </joint>
  <link name="link_12">
    <inertial>
      <origin rpy="0 0 0" xyz="0.0683 0.0125 0.0783"/>
      <mass value="5"/>
      <inertia ixx="-0.0933" ixy="-0.0327" ixz="-0.0014" iyy="-0.0441" iyz="-0.0285" izz="0.0124"/>
    </inertial>
  </link>
  <joint name="joint_12" type="revolute">
    <parent link="link_11"/>
    <child link="link_12"/>
    <origin rpy="-1.5707963267948966 -1.5707963267948966 1.5707963267948966" xyz="0 0 0.1444"/>
    <axis xyz="0 0 1"/>
    <limit effort="300" lower="-2.09439510239" upper="2.09439510239" velocity="10"/>
    <dynamics damping="0.5"/>
  </joint>
  <link name="link_13">
    <inertial>
      <origin rpy="0 0 0" xyz="0.0848 0.0024 0.0692"/>
      <mass value="5"/>
      <inertia ixx="0.0383" ixy="0.0315" ixz="-0.0687" iyy="0.0486" iyz="-0.0474" izz="-0.0989"/>
    </inertial>
  </link>
  <joint name="joint_13" type="revolute">
    <parent link="link_12"/>
    <child link="link_13"/>
    <origin rpy="0 -1.5707963267948966 1.5707963267948966" xyz="0 0 0.1992"/>
    <axis xyz="0 0 1"/>
    <limit effort="300" lower="-2.09439510239" upper="2.09439510239" velocity="10"/>
    <dynamics damping="0.5"/>
  </joint>
  <link name="link_14">
    <inertial>
      <origin rpy="0 0 0" xyz="0.0795 0.0721 0.032"/>
      <mass value="5"/>
      <inertia ixx="0.0385" ixy="-0.0448" ixz="0.0833" iyy="-0.039" iyz="-0.0382" izz="-0.0706"/>
    </inertial>
  </link>
  <joint name="joint_14" type="revolute">
    <parent link="link_13"/>
    <child link="link_14"/>
    <origin rpy="-3.141592653589793 -3.141592653589793 3.141592653589793" xyz="0 0 0.0215"/>
    <axis xyz="0 0 1"/>
    <limit effort="300" lower="-2.09439510239" upper="2.09439510239" velocity="10"/>
    <dynamics damping="0.5"/>
  </joint>
  <link name="link_15">
    <inertial>
      <origin rpy="0 0 0" xyz="0.0873 0.083 0.0307"/>
      <mass value="5"/>
      <inertia ixx="-0.0434" ixy="0.0119" ixz="-0.0422" iyy="0.0556" iyz="-0.0325" izz="0.0959"/>
    </inertial>
  </link>
  <joint name="joint_15" type="revolute">
    <parent link="link_14"/>
    <child link="link_15"/>
    <origin rpy="3.141592653589793 0 1.5707963267948966" xyz="0 0 0.0068"/>
    <axis xyz="0 0 1"/>
    <limit effort="300" lower="-2.09439510239" upper="2.09439510239" velocity="10"/>
    <dynamics damping="0.5"/>
  </joint>
  <link name="link_16">
    <inertial>
      <origin rpy="0 0 0" xyz="0.0917 0.0974 0.0437"/>
      <mass value="5"/>
      <inertia ixx="-0.0671" ixy="-0.0091" ixz="0.0442" iyy="-0.0604" iyz="-0.0122" izz="-0.0828"/>
    </inertial>
  </link>
  <joint name="joint_16" type="revolute">
    <parent link="world"/>
    <child link="link_16"/>
    <origin rpy="-3.141592653589793 3.141592653589793 0" xyz="0 0 0.0658"/>
    <axis xyz="0 0 1"/>
    <limit effort="300" lower="-2.09439510239" upper="2.09439510239" velocity="10"/>
    <dynamics damping="0.5"/>
  </joint>
  <link name="link_17">
    <inertial>
      <origin rpy="0 0 0" xyz="0.0497 0.0355 0.0832"/>
      <mass value="5"/>
      <inertia ixx="0.0186" ixy="-0.097" ixz="-0.0832" iyy="0.0296" iyz="-0.0351" izz="-0.0736"/>
    </inertial>
  </link>
  <joint name="joint_17" type="revolute">
    <parent link="link_16"/>
    <child link="link_17"/>
    <origin rpy="-1.5707963267948966 -1.5707963267948966 -1.5707963267948966" xyz="0 0 0.0364"/>
    <axis xyz="0 0 1"/>
    <limit effort="300" lower="-2.09439510239" upper="2.09439510239" velocity="10"/>
    <dynamics damping="0.5"/>
  </joint>
  <link name="link_18">
    <inertial>
      <origin rpy="0 0 0" xyz="0.0775 0.099 0.0445"/>
      <mass value="5"/>
      <inertia ixx="-0.0397" ixy="-0.0143" ixz="-0.0914" iyy="0.0984" iyz="0.0485" izz="0.0953"/>
    </inertial>
  </link>
  <joint name="joint_18" type="revolute">
    <parent link="link_17"/>
    <child link="link_18"/>
    <origin rpy="-3.141592653589793 3.141592653589793 -1.5707963267948966" xyz="0 0 0.1477"/>
    <axis xyz="0 0 1"/>
    <limit effort="300" lower="-2.09439510239" upper="2.09439510239" velocity="10"/>
    <dynamics damping="0.5"/>
  </joint>
  <link name="link_19">
    <inertial>
      <origin rpy="0 0 0" xyz="0.05 0.0463 0.0418"/>
      <mass value="5"/>
      <inertia ixx="-0.0199" ixy="-0.0016" ixz="-0.0899" iyy="0.0932" iyz="0.0205" izz="0.0231"/>
    </inertial>
  </link>
  <joint name="joint_19" type="revolute">
    <parent link="link_18"/>
    <child link="link_19"/>
    <origin rpy="-1.5707963267948966 1.5707963267948966 -3.141592653589793" xyz="0 0 0.0357"/>
    <axis xyz="0 0 1"/>
    <limit effort="300" lower="-2.09439510239" upper="2.09439510239" velocity="10"/>
    <dynamics damping="0.5"/>
  </joint>
  <link name="link_20">
    <inertial>
      <origin rpy="0 0 0" xyz="0.0174 0.0685 0.0711"/>
      <mass value="5"/>
      <inertia ixx="0.0841" ixy="-0.0699" ixz="-0.0273" iyy="0.038" iyz="0.0717" izz="-0.0332"/>
    </inertial>
  </link>
  <joint name="joint_20" type="revolute">
    <parent link="link_19"/>
    <child link="link_20"/>
    <origin rpy="-3.141592653589793 -3.141592653589793 3.141592653589793" xyz="0 0 0.1394"/>
    <axis xyz="0 0 1"/>
    <limit effort="300" lower="-2.09439510239" upper="2.09439510239" velocity="10"/>
    <dynamics damping="0.5"/>
  </joint>
</robot>
