<?xml version="1.0" encoding="utf-8"?>
<robot name="iiwa">
  <link name="world"/>
  <link name="link_1">
    <inertial>
      <origin rpy="0 0 0" xyz="0.0029 0.0056 0.0149"/>
      <mass value="5"/>
      <inertia ixx="-0.0287" ixy="-0.0524" ixz="-0.0707" iyy="-0.0092" iyz="-0.0996" izz="0.0349"/>
    </inertial>
  </link>
  <joint name="joint_1" type="revolute">
    <parent link="world"/>
    <child link="link_1"/>
    <origin rpy="3.141592653589793 -1.5707963267948966 -1.5707963267948966" xyz="0 0 0.1148"/>
    <axis xyz="0 0 1"/>
    <limit effort="300" lower="-2.09439510239" upper="2.09439510239" velocity="10"/>
    <dynamics damping="0.5"/>
  </joint>
  <link name="link_2">
    <inertial>
      <origin rpy="0 0 0" xyz="0.0056 0.0297 0.0982"/>
      <mass value="5"/>
      <inertia ixx="-0.0352" ixy="0.034" ixz="0.0538" iyy="-0.0267" iyz="-0.1" izz="0.0281"/>
    </inertial>
  </link>
  <joint name="joint_2" type="revolute">
    <parent link="link_1"/>
    <child link="link_2"/>
    <origin rpy="0 1.5707963267948966 -3.141592653589793" xyz="0 0 0.0516"/>
    <axis xyz="0 0 1"/>
    <limit effort="300" lower="-2.09439510239" upper="2.09439510239" velocity="10"/>
    <dynamics damping="0.5"/>
  </joint>
  <link name="link_3">
    <inertial>
      <origin rpy="0 0 0" xyz="0.0255 0.0137 0.0682"/>
      <mass value="5"/>
      <inertia ixx="-0.0606" ixy="-0.0173" ixz="-0.0551" iyy="0.0353" iyz="0.0341" izz="-0.0931"/>
    </inertial>
  </link>
  <joint name="joint_3" type="revolute">
    <parent link="link_2"/>
    <child link="link_3"/>
    <origin rpy="-3.141592653589793 -3.141592653589793 -1.5707963267948966" xyz="0 0 0.0954"/>
    <axis xyz="0 0 1"/>
    <limit effort="300" lower="-2.09439510239" upper="2.09439510239" velocity="10"/>
    <dynamics damping="0.5"/>
  </joint>
  <link name="link_4">
    <inertial>
      <origin rpy="0 0 0" xyz="0.0218 0.0625 0.0812"/>
      <mass value="5"/>
      <inertia ixx="-0.0039" ixy="0.0626" ixz="-0.0443" iyy="-0.0254" iyz="-0.0842" izz="0.0412"/>
    </inertial>
  </link>
  <joint name="joint_4" type="revolute">
    <parent link="world"/>
    <child link="link_4"/>
    <origin rpy="-3.141592653589793 1.5707963267948966 -3.141592653589793" xyz="0 0 0.1385"/>
    <axis xyz="0 0 1"/>
    <limit effort="300" lower="-2.09439510239" upper="2.09439510239" velocity="10"/>
    <dynamics damping="0.5"/>
  </joint>
  <link name="link_5">
    <inertial>
      <origin rpy="0 0 0" xyz="0.0714 0.0637 0.011"/>
      <mass value="5"/>
      <inertia ixx="-0.0881" ixy="-0.0907" ixz="-0.0161" iyy="-0.006" iyz="-0.0789" izz="-0.0365"/>
    </inertial>
  </link>
  <joint name="joint_5" type="revolute">
    <parent link="link_4"/>
    <child link="link_5"/>
    <origin rpy="3.141592653589793 0 -3.141592653589793" xyz="0 0 0.0628"/>
    <axis xyz="0 0 1"/>
    <limit effort="300" lower="-2.09439510239" upper="2.09439510239" velocity="10"/>
    <dynamics damping="0.5"/>
  </joint>
  <link name="link_6">
    <inertial>
      <origin rpy="0 0 0" xyz="0.0659 0.0473 0.0873"/>
      <mass value="5"/>
      <inertia ixx="-0.073" ixy="0.0345" ixz="-0.0131" iyy="0.0743" iyz="-0.0246" izz="0.03"/>
    </inertial>
  </link>
  <joint name="joint_6" type="revolute">
    <parent link="link_5"/>
    <child link="link_6"/>
    <origin rpy="-3.141592653589793 1.5707963267948966 3.141592653589793" xyz="0 0 0.0204"/>
    <axis xyz="0 0 1"/>
    <limit effort="300" lower="-2.09439510239" upper="2.09439510239" velocity="10"/>
    <dynamics damping="0.5"/>
  </joint>
  <link name="link_7">
    <inertial>
      <origin rpy="0 0 0" xyz="0.0124 0.0157 0.0217"/>
      <mass value="5"/>
      <inertia ixx="-0.0375" ixy="0.0309" ixz="-0.0319" iyy="-0.0525" iyz="0.0986" izz="-0.0779"/>
    </inertial>
  </link>
  <joint name="joint_7" type="revolute">
    <parent link="world"/>
    <child link="link_7"/>
    <origin rpy="-3.141592653589793 -3.141592653589793 0" xyz="0 0 0.0292"/>
    <axis xyz="0 0 1"/>
    <limit effort="300" lower="-2.09439510239" upper="2.09439510239" velocity="10"/>
    <dynamics damping="0.5"/>
  </joint>
  <link name="link_8">
    <inertial>
      <origin rpy="0 0 0" xyz="0.0247 0.052 0.0864"/>
      <mass value="5"/>
      <inertia ixx="0.017" ixy="0.0107" ixz="-0.0832" iyy="-0.0248" iyz="-0.0733" izz="-0.003"/>
    </inertial>
  </link>
  <joint name="joint_8" type="revolute">
    <parent link="link_7"/>
    <child link="link_8"/>
    <origin rpy="3.141592653589793 0 0" xyz="0 0 0.167"/>
    <axis xyz="0 0 1"/>
    <limit effort="300" lower="-2.09439510239" upper="2.09439510239" velocity="10"/>
    <dynamics damping="0.5"/>
  </joint>
  <link name="link_9">
    <inertial>
      <origin rpy="0 0 0" xyz="0.0068 0.0088 0.0755"/>
      <mass value="5"/>
      <inertia ixx="0.0661" ixy="-0.0618" ixz="-0.0077" iyy="-0.063" iyz="0.0425" izz="0.045"/>
    </inertial>
  </link>
  <joint name="joint_9" type="revolute">
    <parent link="link_8"/>
    <child link="link_9"/>
    <origin rpy="0 3.141592653589793 3.141592653589793" xyz="0 0 0.1305"/>
    <axis xyz="0 0 1"/>
    <limit effort="300" lower="-2.09439510239" upper="2.09439510239" velocity="10"/>
    <dynamics damping="0.5"/>
  </joint>
  <link name="link_10">
    <inertial>
      <origin rpy="0 0 0" xyz="0.0535 0.0318 0.082"/>
      <mass value="5"/>
      <inertia ixx="0.0812" ixy="0.0696" ixz="-0.0529" iyy="0.038" iyz="-0.0503" izz="-0.0505"/>
    </inertial>
  </link>
  <joint name="joint_10" type="revolute">
    <parent link="world"/>
    <child link="link_10"/>
    <origin rpy="-3.141592653589793 3.141592653589793 -1.5707963267948966" xyz="0 0 0.1673"/>
    <axis xyz="0 0 1"/>
    <limit effort="300" lower="-2.09439510239" upper="2.09439510239" velocity="10"/>
    <dynamics damping="0.5"/>
  </joint>
  <link name="link_11">
    <inertial>
      <origin rpy="0 0 0" xyz="0.0151 0.0252 0.0453"/>
      <mass value="5"/>
      <inertia ixx="-0.0181" ixy="-0.037" ixz="0.0498" iyy="-0.0487" iyz="0.0846" izz="0.0147"/>
    </inertial>
  </link>
  <joint name="joint_11" type="revolute">
    <parent link="link_10"/>
    <child link="link_11"/>
    <origin rpy="1.5707963267948966 3.141592653589793 -3.141592653589793" xyz="0 0 0.0649"/>
    <axis xyz="0 0 1"/>
    <limit effort="300" lower="-2.09439510239" upper="2.09439510239" velocity="10"/>
    <dynamics damping="0.5"/>
  </joint>
  <link name="link_12">
    <inertial>
      <origin rpy="0 0 0" xyz="0.0947 0.021 0.0836"/>
      <mass value="5"/>
      <inertia ixx="0.0582" ixy="0.0293" ixz="-0.0004" iyy="0.0407" iyz="-0.0341" izz="0.0585"/>
    </inertial>
  </link>
  <joint name="joint_12" type="revolute">
    <parent link="link_11"/>
    <child link="link_12"/>
    <origin rpy="-1.5707963267948966 -1.5707963267948966 0" xyz="0 0 0.0173"/>
    <axis xyz="0 0 1"/>
    <limit effort="300" lower="-2.09439510239" upper="2.09439510239" velocity="10"/>
    <dynamics damping="0.5"/>
  </joint>
</robot>
