<?xml version="1.0" encoding="utf-8"?>
<robot name="iiwa">
  <link name="world"/>
  <link name="link_1">
    <inertial>
      <origin rpy="0 0 0" xyz="0.0024 0.022 0.0593"/>
      <mass value="5"/>
      <inertia ixx="-0.035" ixy="-0.0936" ixz="0.0332" iyy="-0.0569" iyz="-0.0586" izz="-0.0924"/>
    </inertial>
  </link>
  <joint name="joint_1" type="revolute">
    <parent link="world"/>
    <child link="link_1"/>
    <origin rpy="-3.141592653589793 3.141592653589793 -1.5707963267948966" xyz="0 0 0.1734"/>
    <axis xyz="0 0 1"/>
    <limit effort="300" lower="-2.09439510239" upper="2.09439510239" velocity="10"/>
    <dynamics damping="0.5"/>
  </joint>
  <link name="link_2">
    <inertial>
      <origin rpy="0 0 0" xyz="0.0102 0.042 0.0824"/>
      <mass value="5"/>
      <inertia ixx="0.0148" ixy="0.0459" ixz="0.0783" iyy="-0.0261" iyz="0.0447" izz="-0.0955"/>
    </inertial>
  </link>
  <joint name="joint_2" type="revolute">
    <parent link="link_1"/>
    <child link="link_2"/>
    <origin rpy="-1.5707963267948966 -3.141592653589793 -1.5707963267948966" xyz="0 0 0.0085"/>
    <axis xyz="0 0 1"/>
    <limit effort="300" lower="-2.09439510239" upper="2.09439510239" velocity="10"/>
    <dynamics damping="0.5"/>
  </joint>
  <link name="link_3">
    <inertial>
      <origin rpy="0 0 0" xyz="0.0722 0.0461 0.0203"/>
      <mass value="5"/>
      <inertia ixx="0.0549" ixy="-0.043" ixz="-0.0248" iyy="-0.0776" iyz="0.0301" izz="-0.061"/>
    </inertial>
  </link>
  <joint name="joint_3" type="revolute">
    <parent link="link_2"/>
    <child link="link_3"/>
    <origin rpy="3.141592653589793 -3.141592653589793 -1.5707963267948966" xyz="0 0 0.065"/>
    <axis xyz="0 0 1"/>
    <limit effort="300" lower="-2.09439510239" upper="2.09439510239" velocity="10"/>
    <dynamics damping="0.5"/>
  </joint>
  <link name="link_4">
    <inertial>
      <origin rpy="0 0 0" xyz="0.0143 0.0047 0.0334"/>
      <mass value="5"/>
      <inertia ixx="0.0274" ixy="0.0613" ixz="0.0687" iyy="0.0114" iyz="-0.031" izz="-0.076"/>
    </inertial>
  </link>
  <joint name="joint_4" type="revolute">
    <parent link="link_3"/>
    <child link="link_4"/>
    <origin rpy="-3.141592653589793 3.141592653589793 3.141592653589793" xyz="0 0 0.0666"/>
    <axis xyz="0 0 1"/>
    <limit effort="300" lower="-2.09439510239" upper="2.09439510239" velocity="10"/>
    <dynamics damping="0.5"/>
  </joint>
  <!-- ======== LEFT BRANCH STARTS ======= -->
  <link name="link_5_left">
    <inertial>
      <origin rpy="0 0 0" xyz="0.0393 0.0001 0.0258"/>
      <mass value="5"/>
      <inertia ixx="0.039" ixy="-0.0149" ixz="0.0069" iyy="-0.0527" iyz="0.0519" izz="-0.0844"/>
    </inertial>
  </link>
  <joint name="joint_5_left" type="revolute">
    <parent link="link_4"/>
    <child link="link_5_left"/>
    <origin rpy="1.5707963267948966 1.5707963267948966 3.141592653589793" xyz="0 0 0.0957"/>
    <axis xyz="0 0 1"/>
    <limit effort="300" lower="-2.09439510239" upper="2.09439510239" velocity="10"/>
    <dynamics damping="0.5"/>
  </joint>
  <link name="link_6_left">
    <inertial>
      <origin rpy="0 0 0" xyz="0.044 0.0175 0.0172"/>
      <mass value="5"/>
      <inertia ixx="0.0134" ixy="-0.0517" ixz="0.0458" iyy="-0.0126" iyz="-0.0716" izz="0.0605"/>
    </inertial>
  </link>
  <joint name="joint_6_left" type="revolute">
    <parent link="link_5_left"/>
    <child link="link_6_left"/>
    <origin rpy="-3.141592653589793 0 3.141592653589793" xyz="0 0 0.094"/>
    <axis xyz="0 0 1"/>
    <limit effort="300" lower="-2.09439510239" upper="2.09439510239" velocity="10"/>
    <dynamics damping="0.5"/>
  </joint>
  <link name="link_7_left">
    <inertial>
      <origin rpy="0 0 0" xyz="0.0336 0.031 0.0581"/>
      <mass value="5"/>
      <inertia ixx="0.0167" ixy="0.051" ixz="-0.0256" iyy="0.0092" iyz="0.0732" izz="0.0746"/>
    </inertial>
  </link>
  <joint name="joint_7_left" type="revolute">
    <parent link="link_6_left"/>
    <child link="link_7_left"/>
    <origin rpy="1.5707963267948966 -1.5707963267948966 -3.141592653589793" xyz="0 0 0.0499"/>
    <axis xyz="0 0 1"/>
    <limit effort="300" lower="-2.09439510239" upper="2.09439510239" velocity="10"/>
    <dynamics damping="0.5"/>
  </joint>
  <!-- ======== LEFT BRANCH END ======= -->
  <!-- ======== RIGHT BRANCH STARTS ======= -->
  <link name="link_5_right">
    <inertial>
      <origin rpy="0 0 0" xyz="0.0829 0.0016 0.036"/>
      <mass value="5"/>
      <inertia ixx="-0.0536" ixy="0.0537" ixz="0.0408" iyy="-0.0399" iyz="0.0447" izz="-0.0481"/>
    </inertial>
  </link>
  <joint name="joint_5_right" type="revolute">
    <parent link="link_4"/>
    <child link="link_5_right"/>
    <origin rpy="3.141592653589793 1.5707963267948966 -1.5707963267948966" xyz="0 0 0.0161"/>
    <axis xyz="0 0 1"/>
    <limit effort="300" lower="-2.09439510239" upper="2.09439510239" velocity="10"/>
    <dynamics damping="0.5"/>
  </joint>
  <link name="link_6_right">
    <inertial>
      <origin rpy="0 0 0" xyz="0.0162 0.0177 0.0081"/>
      <mass value="5"/>
      <inertia ixx="0.0579" ixy="-0.0894" ixz="0.0746" iyy="0.0725" iyz="0.0368" izz="-0.0669"/>
    </inertial>
  </link>
  <joint name="joint_6_right" type="revolute">
    <parent link="link_5_right"/>
    <child link="link_6_right"/>
    <origin rpy="3.141592653589793 1.5707963267948966 1.5707963267948966" xyz="0 0 0.078"/>
    <axis xyz="0 0 1"/>
    <limit effort="300" lower="-2.09439510239" upper="2.09439510239" velocity="10"/>
    <dynamics damping="0.5"/>
  </joint>
  <link name="link_7_right">
    <inertial>
      <origin rpy="0 0 0" xyz="0.0062 0.0933 0.0584"/>
      <mass value="5"/>
      <inertia ixx="-0.0363" ixy="-0.035" ixz="-0.0403" iyy="-0.0749" iyz="-0.0515" izz="0.0791"/>
    </inertial>
  </link>
  <joint name="joint_7_right" type="revolute">
    <parent link="link_6_right"/>
    <child link="link_7_right"/>
    <origin rpy="-3.141592653589793 3.141592653589793 -1.5707963267948966" xyz="0 0 0.1367"/>
    <axis xyz="0 0 1"/>
    <limit effort="300" lower="-2.09439510239" upper="2.09439510239" velocity="10"/>
    <dynamics damping="0.5"/>
  </joint>
  <!-- ======== RIGHT BRANCH ENDS ======= -->
</robot>
