<?xml version="1.0" encoding="utf-8"?>
<robot name="iiwa">
  <link name="world"/>
  <link name="link_1">
    <inertial>
      <origin rpy="0 0 0" xyz="0.077 0.0936 0.0526"/>
      <mass value="5"/>
      <inertia ixx="0.0863" ixy="-0.0833" ixz="-0.0476" iyy="0.0054" iyz="0.0974" izz="0.0797"/>
    </inertial>
  </link>
  <joint name="joint_1" type="revolute">
    <parent link="world"/>
    <child link="link_1"/>
    <origin rpy="3.141592653589793 -1.5707963267948966 0" xyz="0 0 0.0259"/>
    <axis xyz="0 0 1"/>
    <limit effort="300" lower="-2.09439510239" upper="2.09439510239" velocity="10"/>
    <dynamics damping="0.5"/>
  </joint>
  <link name="link_2">
    <inertial>
      <origin rpy="0 0 0" xyz="0.0349 0.0231 0.0455"/>
      <mass value="5"/>
      <inertia ixx="-0.0405" ixy="-0.0151" ixz="0.0354" iyy="-0.064" iyz="-0.0431" izz="-0.075"/>
    </inertial>
  </link>
  <joint name="joint_2" type="revolute">
    <parent link="link_1"/>
    <child link="link_2"/>
    <origin rpy="-3.141592653589793 0 0" xyz="0 0 0.1916"/>
    <axis xyz="0 0 1"/>
    <limit effort="300" lower="-2.09439510239" upper="2.09439510239" velocity="10"/>
    <dynamics damping="0.5"/>
  </joint>
  <link name="link_3">
    <inertial>
      <origin rpy="0 0 0" xyz="0.0618 0.0561 0.0732"/>
      <mass value="5"/>
      <inertia ixx="-0.093" ixy="0.0269" ixz="-0.001" iyy="0.0448" iyz="0.0901" izz="-0.0631"/>
    </inertial>
  </link>
  <joint name="joint_3" type="revolute">
    <parent link="link_2"/>
    <child link="link_3"/>
    <origin rpy="-1.5707963267948966 1.5707963267948966 3.141592653589793" xyz="0 0 0.0854"/>
    <axis xyz="0 0 1"/>
    <limit effort="300" lower="-2.09439510239" upper="2.09439510239" velocity="10"/>
    <dynamics damping="0.5"/>
  </joint>
  <link name="link_4">
    <inertial>
      <origin rpy="0 0 0" xyz="0.002 0.0288 0.0717"/>
      <mass value="5"/>
      <inertia ixx="0.0206" ixy="0.0294" ixz="0.0314" iyy="-0.0615" iyz="0.0302" izz="-0.0585"/>
    </inertial>
  </link>
  <joint name="joint_4" type="revolute">
    <parent link="link_3"/>
    <child link="link_4"/>
    <origin rpy="-1.5707963267948966 1.5707963267948966 -3.141592653589793" xyz="0 0 0.1143"/>
    <axis xyz="0 0 1"/>
    <limit effort="300" lower="-2.09439510239" upper="2.09439510239" velocity="10"/>
    <dynamics damping="0.5"/>
  </joint>
  <link name="link_5">
    <inertial>
      <origin rpy="0 0 0" xyz="0.0458 0.0414 0.0437"/>
      <mass value="5"/>
      <inertia ixx="0.0374" ixy="-0.0008" ixz="-0.0013" iyy="0.076" iyz="-0.0435" izz="-0.0275"/>
    </inertial>
  </link>
  <joint name="joint_5" type="revolute">
    <parent link="link_4"/>
    <child link="link_5"/>
    <origin rpy="-1.5707963267948966 3.141592653589793 3.141592653589793" xyz="0 0 0.0811"/>
    <axis xyz="0 0 1"/>
    <limit effort="300" lower="-2.09439510239" upper="2.09439510239" velocity="10"/>
    <dynamics damping="0.5"/>
  </joint>
  <link name="link_6">
    <inertial>
      <origin rpy="0 0 0" xyz="0.0092 0.0652 0.0223"/>
      <mass value="5"/>
      <inertia ixx="0.0509" ixy="0.0701" ixz="-0.0058" iyy="-0.0957" iyz="0.0861" izz="-0.0176"/>
    </inertial>
  </link>
  <joint name="joint_6" type="revolute">
    <parent link="link_5"/>
    <child link="link_6"/>
    <origin rpy="3.141592653589793 -3.141592653589793 -3.141592653589793" xyz="0 0 0.0357"/>
    <axis xyz="0 0 1"/>
    <limit effort="300" lower="-2.09439510239" upper="2.09439510239" velocity="10"/>
    <dynamics damping="0.5"/>
  </joint>
  <!-- ======== LEFT BRANCH STARTS ======= -->
  <link name="link_7_left">
    <inertial>
      <origin rpy="0 0 0" xyz="0.0957 0.0062 0.0731"/>
      <mass value="5"/>
      <inertia ixx="-0.0204" ixy="-0.0421" ixz="0.0256" iyy="-0.0324" iyz="-0.0424" izz="0.0036"/>
    </inertial>
  </link>
  <joint name="joint_7_left" type="revolute">
    <parent link="link_6"/>
    <child link="link_7_left"/>
    <origin rpy="-1.5707963267948966 -3.141592653589793 -1.5707963267948966" xyz="0 0 0.1022"/>
    <axis xyz="0 0 1"/>
    <limit effort="300" lower="-2.09439510239" upper="2.09439510239" velocity="10"/>
    <dynamics damping="0.5"/>
  </joint>
  <link name="link_8_left">
    <inertial>
      <origin rpy="0 0 0" xyz="0.0135 0.0966 0.0894"/>
      <mass value="5"/>
      <inertia ixx="-0.0392" ixy="-0.0873" ixz="0.004" iyy="-0.0625" iyz="0.0115" izz="0.0528"/>
    </inertial>
  </link>
  <joint name="joint_8_left" type="revolute">
    <parent link="link_7_left"/>
    <child link="link_8_left"/>
    <origin rpy="-1.5707963267948966 0 3.141592653589793" xyz="0 0 0.0575"/>
    <axis xyz="0 0 1"/>
    <limit effort="300" lower="-2.09439510239" upper="2.09439510239" velocity="10"/>
    <dynamics damping="0.5"/>
  </joint>
  <link name="link_9_left">
    <inertial>
      <origin rpy="0 0 0" xyz="0.0989 0.026 0.0975"/>
      <mass value="5"/>
      <inertia ixx="-0.0845" ixy="0.0257" ixz="-0.0041" iyy="0.0744" iyz="-0.0889" izz="0.0496"/>
    </inertial>
  </link>
  <joint name="joint_9_left" type="revolute">
    <parent link="link_8_left"/>
    <child link="link_9_left"/>
    <origin rpy="3.141592653589793 1.5707963267948966 -1.5707963267948966" xyz="0 0 0.0031"/>
    <axis xyz="0 0 1"/>
    <limit effort="300" lower="-2.09439510239" upper="2.09439510239" velocity="10"/>
    <dynamics damping="0.5"/>
  </joint>
  <!-- ======== LEFT BRANCH END ======= -->
  <!-- ======== RIGHT BRANCH STARTS ======= -->
  <link name="link_7_right">
    <inertial>
      <origin rpy="0 0 0" xyz="0.0034 0.0237 0.0211"/>
      <mass value="5"/>
      <inertia ixx="-0.0537" ixy="0.0865" ixz="0.0334" iyy="-0.0992" iyz="0.0698" izz="-0.0495"/>
    </inertial>
  </link>
  <joint name="joint_7_right" type="revolute">
    <parent link="link_6"/>
    <child link="link_7_right"/>
    <origin rpy="0 3.141592653589793 1.5707963267948966" xyz="0 0 0.044"/>
    <axis xyz="0 0 1"/>
    <limit effort="300" lower="-2.09439510239" upper="2.09439510239" velocity="10"/>
    <dynamics damping="0.5"/>
  </joint>
  <link name="link_8_right">
    <inertial>
      <origin rpy="0 0 0" xyz="0.019 0.0524 0.0148"/>
      <mass value="5"/>
      <inertia ixx="-0.0407" ixy="-0.0245" ixz="-0.0984" iyy="-0.0992" iyz="-0.0754" izz="0.0865"/>
    </inertial>
  </link>
  <joint name="joint_8_right" type="revolute">
    <parent link="link_7_right"/>
    <child link="link_8_right"/>
    <origin rpy="-1.5707963267948966 -3.141592653589793 1.5707963267948966" xyz="0 0 0.0198"/>
    <axis xyz="0 0 1"/>
    <limit effort="300" lower="-2.09439510239" upper="2.09439510239" velocity="10"/>
    <dynamics damping="0.5"/>
  </joint>
  <link name="link_9_right">
    <inertial>
      <origin rpy="0 0 0" xyz="0.0957 0.0993 0.0944"/>
      <mass value="5"/>
      <inertia ixx="-0.0435" ixy="-0.0986" ixz="-0.0314" iyy="0.0972" iyz="-0.0679" izz="-0.0667"/>
    </inertial>
  </link>
  <joint name="joint_9_right" type="revolute">
    <parent link="link_8_right"/>
    <child link="link_9_right"/>
    <origin rpy="-3.141592653589793 -3.141592653589793 3.141592653589793" xyz="0 0 0.0645"/>
    <axis xyz="0 0 1"/>
    <limit effort="300" lower="-2.09439510239" upper="2.09439510239" velocity="10"/>
    <dynamics damping="0.5"/>
  </joint>
  <!-- ======== RIGHT BRANCH ENDS ======= -->
</robot>
