<?xml version="1.0" encoding="utf-8"?>
<robot name="iiwa">
  <link name="world"/>
  <link name="link_1">
    <inertial>
      <origin rpy="0 0 0" xyz="0.0349 0.0159 0.0667"/>
      <mass value="5"/>
      <inertia ixx="-0.0041" ixy="0.0608" ixz="-0.0598" iyy="-0.0544" iyz="0.0799" izz="0.0422"/>
    </inertial>
  </link>
  <joint name="joint_1" type="revolute">
    <parent link="world"/>
    <child link="link_1"/>
    <origin rpy="1.5707963267948966 1.5707963267948966 -3.141592653589793" xyz="0 0 0.067"/>
    <axis xyz="0 0 1"/>
    <limit effort="300" lower="-2.09439510239" upper="2.09439510239" velocity="10"/>
    <dynamics damping="0.5"/>
  </joint>
  <!-- ======== LEFT BRANCH STARTS ======= -->
  <link name="link_2_left">
    <inertial>
      <origin rpy="0 0 0" xyz="0.006 0.0941 0.0446"/>
      <mass value="5"/>
      <inertia ixx="0.0698" ixy="0.0596" ixz="0.082" iyy="0.0551" iyz="0.0099" izz="0.0354"/>
    </inertial>
  </link>
  <joint name="joint_2_left" type="revolute">
    <parent link="link_1"/>
    <child link="link_2_left"/>
    <origin rpy="-3.141592653589793 -1.5707963267948966 1.5707963267948966" xyz="0 0 0.1433"/>
    <axis xyz="0 0 1"/>
    <limit effort="300" lower="-2.09439510239" upper="2.09439510239" velocity="10"/>
    <dynamics damping="0.5"/>
  </joint>
  <link name="link_3_left">
    <inertial>
      <origin rpy="0 0 0" xyz="0.0874 0.0964 0.0097"/>
      <mass value="5"/>
      <inertia ixx="-0.064" ixy="0.0263" ixz="0.0911" iyy="-0.0438" iyz="-0.04" izz="-0.0738"/>
    </inertial>
  </link>
  <joint name="joint_3_left" type="revolute">
    <parent link="link_2_left"/>
    <child link="link_3_left"/>
    <origin rpy="-3.141592653589793 1.5707963267948966 -3.141592653589793" xyz="0 0 0.1799"/>
    <axis xyz="0 0 1"/>
    <limit effort="300" lower="-2.09439510239" upper="2.09439510239" velocity="10"/>
    <dynamics damping="0.5"/>
  </joint>
  <link name="link_4_left">
    <inertial>
      <origin rpy="0 0 0" xyz="0.0134 0.0342 0.0011"/>
      <mass value="5"/>
      <inertia ixx="0.0551" ixy="-0.098" ixz="-0.0133" iyy="0.0803" iyz="-0.0619" izz="-0.0977"/>
    </inertial>
  </link>
  <joint name="joint_4_left" type="revolute">
    <parent link="link_3_left"/>
    <child link="link_4_left"/>
    <origin rpy="-3.141592653589793 -1.5707963267948966 1.5707963267948966" xyz="0 0 0.019"/>
    <axis xyz="0 0 1"/>
    <limit effort="300" lower="-2.09439510239" upper="2.09439510239" velocity="10"/>
    <dynamics damping="0.5"/>
  </joint>
  <!-- ======== LEFT BRANCH END ======= -->
  <!-- ======== RIGHT BRANCH STARTS ======= -->
  <link name="link_2_right">
    <inertial>
      <origin rpy="0 0 0" xyz="0.045 0.0728 0.0897"/>
      <mass value="5"/>
      <inertia ixx="0.0615" ixy="-0.0057" ixz="-0.0526" iyy="0.0942" iyz="0.007" izz="-0.0201"/>
    </inertial>
  </link>
  <joint name="joint_2_right" type="revolute">
    <parent link="link_1"/>
    <child link="link_2_right"/>
    <origin rpy="-3.141592653589793 -3.141592653589793 3.141592653589793" xyz="0 0 0.1493"/>
    <axis xyz="0 0 1"/>
    <limit effort="300" lower="-2.09439510239" upper="2.09439510239" velocity="10"/>
    <dynamics damping="0.5"/>
  </joint>
  <link name="link_3_right">
    <inertial>
      <origin rpy="0 0 0" xyz="0.0043 0.0023 0.0324"/>
      <mass value="5"/>
      <inertia ixx="-0.0147" ixy="-0.0285" ixz="0.041" iyy="0.0589" iyz="-0.0495" izz="0.0321"/>
    </inertial>
  </link>
  <joint name="joint_3_right" type="revolute">
    <parent link="link_2_right"/>
    <child link="link_3_right"/>
    <origin rpy="0 3.141592653589793 3.141592653589793" xyz="0 0 0.1487"/>
    <axis xyz="0 0 1"/>
    <limit effort="300" lower="-2.09439510239" upper="2.09439510239" velocity="10"/>
    <dynamics damping="0.5"/>
  </joint>
  <link name="link_4_right">
    <inertial>
      <origin rpy="0 0 0" xyz="0.0162 0.0992 0.0637"/>
      <mass value="5"/>
      <inertia ixx="-0.0224" ixy="-0.0464" ixz="0.0014" iyy="-0.0528" iyz="-0.0371" izz="-0.0305"/>
    </inertial>
  </link>
  <joint name="joint_4_right" type="revolute">
    <parent link="link_3_right"/>
    <child link="link_4_right"/>
    <origin rpy="0 1.5707963267948966 -1.5707963267948966" xyz="0 0 0.0325"/>
    <axis xyz="0 0 1"/>
    <limit effort="300" lower="-2.09439510239" upper="2.09439510239" velocity="10"/>
    <dynamics damping="0.5"/>
  </joint>
  <!-- ======== RIGHT BRANCH ENDS ======= -->
</robot>
