<?xml version="1.0" encoding="utf-8"?>
<robot name="iiwa">
  <link name="world"/>
  <link name="link_1">
    <inertial>
      <origin rpy="0 0 0" xyz="0.0411 0.0118 0.0667"/>
      <mass value="5"/>
      <inertia ixx="-0.0367" ixy="-0.0461" ixz="-0.0833" iyy="0.0236" iyz="0.0617" izz="-0.0815"/>
    </inertial>
  </link>
  <joint name="joint_1" type="revolute">
    <parent link="world"/>
    <child link="link_1"/>
    <origin rpy="-3.141592653589793 0 1.5707963267948966" xyz="0 0 0.0146"/>
    <axis xyz="0 0 1"/>
    <limit effort="300" lower="-2.09439510239" upper="2.09439510239" velocity="10"/>
    <dynamics damping="0.5"/>
  </joint>
  <link name="link_2">
    <inertial>
      <origin rpy="0 0 0" xyz="0.059 0.0738 0.0879"/>
      <mass value="5"/>
      <inertia ixx="0.0709" ixy="-0.0314" ixz="0.0528" iyy="-0.061" iyz="-0.0705" izz="0.0957"/>
    </inertial>
  </link>
  <joint name="joint_2" type="revolute">
    <parent link="link_1"/>
    <child link="link_2"/>
    <origin rpy="3.141592653589793 -1.5707963267948966 1.5707963267948966" xyz="0 0 0.0548"/>
    <axis xyz="0 0 1"/>
    <limit effort="300" lower="-2.09439510239" upper="2.09439510239" velocity="10"/>
    <dynamics damping="0.5"/>
  </joint>
  <link name="link_3">
    <inertial>
      <origin rpy="0 0 0" xyz="0.0471 0.0458 0.0889"/>
      <mass value="5"/>
      <inertia ixx="0.0588" ixy="0.0849" ixz="-0.0872" iyy="-0.0089" iyz="-0.0345" izz="-0.0385"/>
    </inertial>
  </link>
  <joint name="joint_3" type="revolute">
    <parent link="link_2"/>
    <child link="link_3"/>
    <origin rpy="-3.141592653589793 -1.5707963267948966 0" xyz="0 0 0.1878"/>
    <axis xyz="0 0 1"/>
    <limit effort="300" lower="-2.09439510239" upper="2.09439510239" velocity="10"/>
    <dynamics damping="0.5"/>
  </joint>
  <!-- ======== LEFT BRANCH STARTS ======= -->
  <link name="link_4_left">
    <inertial>
      <origin rpy="0 0 0" xyz="0.0531 0.0034 0.0158"/>
      <mass value="5"/>
      <inertia ixx="0.0898" ixy="0.0913" ixz="-0.0728" iyy="-0.096" iyz="-0.0378" izz="-0.0388"/>
    </inertial>
  </link>
  <joint name="joint_4_left" type="revolute">
    <parent link="link_3"/>
    <child link="link_4_left"/>
    <origin rpy="3.141592653589793 -1.5707963267948966 1.5707963267948966" xyz="0 0 0.1168"/>
    <axis xyz="0 0 1"/>
    <limit effort="300" lower="-2.09439510239" upper="2.09439510239" velocity="10"/>
    <dynamics damping="0.5"/>
  </joint>
  <link name="link_5_left">
    <inertial>
      <origin rpy="0 0 0" xyz="0.0178 0.085 0.0181"/>
      <mass value="5"/>
      <inertia ixx="0.0337" ixy="0.0504" ixz="-0.0639" iyy="-0.0216" iyz="-0.0622" izz="0.062"/>
    </inertial>
  </link>
  <joint name="joint_5_left" type="revolute">
    <parent link="link_4_left"/>
    <child link="link_5_left"/>
    <origin rpy="-1.5707963267948966 -3.141592653589793 -1.5707963267948966" xyz="0 0 0.1526"/>
    <axis xyz="0 0 1"/>
    <limit effort="300" lower="-2.09439510239" upper="2.09439510239" velocity="10"/>
    <dynamics damping="0.5"/>
  </joint>
  <link name="link_6_left">
    <inertial>
      <origin rpy="0 0 0" xyz="0.0376 0.0673 0.0149"/>
      <mass value="5"/>
      <inertia ixx="-0.0031" ixy="-0.0362" ixz="0.0333" iyy="-0.0341" iyz="0.025" izz="0.0764"/>
    </inertial>
  </link>
  <joint name="joint_6_left" type="revolute">
    <parent link="link_5_left"/>
    <child link="link_6_left"/>
    <origin rpy="0 0 -1.5707963267948966" xyz="0 0 0.0404"/>
    <axis xyz="0 0 1"/>
    <limit effort="300" lower="-2.09439510239" upper="2.09439510239" velocity="10"/>
    <dynamics damping="0.5"/>
  </joint>
  <!-- ======== LEFT BRANCH END ======= -->
  <!-- ======== RIGHT BRANCH STARTS ======= -->
  <link name="link_4_right">
    <inertial>
      <origin rpy="0 0 0" xyz="0.0801 0.0142 0.0764"/>
      <mass value="5"/>
      <inertia ixx="0.0977" ixy="0.0489" ixz="-0.0625" iyy="0.038" iyz="0.0694" izz="0.0461"/>
    </inertial>
  </link>
  <joint name="joint_4_right" type="revolute">
    <parent link="link_3"/>
    <child link="link_4_right"/>
    <origin rpy="0 -3.141592653589793 0" xyz="0 0 0.1792"/>
    <axis xyz="0 0 1"/>
    <limit effort="300" lower="-2.09439510239" upper="2.09439510239" velocity="10"/>
    <dynamics damping="0.5"/>
  </joint>
  <link name="link_5_right">
    <inertial>
      <origin rpy="0 0 0" xyz="0.0874 0.0564 0.0229"/>
      <mass value="5"/>
      <inertia ixx="0.0166" ixy="-0.075" ixz="0.0738" iyy="-0.0699" iyz="-0.011" izz="0.0426"/>
    </inertial>
  </link>
  <joint name="joint_5_right" type="revolute">
    <parent link="link_4_right"/>
    <child link="link_5_right"/>
    <origin rpy="-1.5707963267948966 -1.5707963267948966 -3.141592653589793" xyz="0 0 0.0268"/>
    <axis xyz="0 0 1"/>
    <limit effort="300" lower="-2.09439510239" upper="2.09439510239" velocity="10"/>
    <dynamics damping="0.5"/>
  </joint>
  <link name="link_6_right">
    <inertial>
      <origin rpy="0 0 0" xyz="0.0844 0.0795 0.0172"/>
      <mass value="5"/>
      <inertia ixx="0.0588" ixy="0.0509" ixz="-0.0264" iyy="0.003" iyz="0.0027" izz="-0.0255"/>
    </inertial>
  </link>
  <joint name="joint_6_right" type="revolute">
    <parent link="link_5_right"/>
    <child link="link_6_right"/>
    <origin rpy="3.141592653589793 -1.5707963267948966 0" xyz="0 0 0.1667"/>
    <axis xyz="0 0 1"/>
    <limit effort="300" lower="-2.09439510239" upper="2.09439510239" velocity="10"/>
    <dynamics damping="0.5"/>
  </joint>
  <!-- ======== RIGHT BRANCH ENDS ======= -->
</robot>
