<?xml version="1.0" encoding="utf-8"?>
<robot name="iiwa">
  <link name="world"/>
  <link name="link_1">
    <inertial>
      <origin rpy="0 0 0" xyz="0.0829 0.0559 0.0214"/>
      <mass value="5"/>
      <inertia ixx="0.0954" ixy="-0.0224" ixz="-0.0996" iyy="0.0507" iyz="-0.0725" izz="-0.0843"/>
    </inertial>
  </link>
  <joint name="joint_1" type="revolute">
    <parent link="world"/>
    <child link="link_1"/>
    <origin rpy="-3.141592653589793 0 1.5707963267948966" xyz="0 0 0.1117"/>
    <axis xyz="0 0 1"/>
    <limit effort="300" lower="-2.09439510239" upper="2.09439510239" velocity="10"/>
    <dynamics damping="0.5"/>
  </joint>
  <link name="link_2">
    <inertial>
      <origin rpy="0 0 0" xyz="0.0612 0.0012 0.0439"/>
      <mass value="5"/>
      <inertia ixx="0.0009" ixy="-0.0649" ixz="-0.0772" iyy="0.0591" iyz="0.0208" izz="-0.0773"/>
    </inertial>
  </link>
  <joint name="joint_2" type="revolute">
    <parent link="link_1"/>
    <child link="link_2"/>
    <origin rpy="-1.5707963267948966 -3.141592653589793 -3.141592653589793" xyz="0 0 0.1963"/>
    <axis xyz="0 0 1"/>
    <limit effort="300" lower="-2.09439510239" upper="2.09439510239" velocity="10"/>
    <dynamics damping="0.5"/>
  </joint>
  <!-- ======== LEFT BRANCH STARTS ======= -->
  <link name="link_3_left">
    <inertial>
      <origin rpy="0 0 0" xyz="0.02 0.0206 0.054"/>
      <mass value="5"/>
      <inertia ixx="-0.0838" ixy="0.0845" ixz="-0.0701" iyy="0.0735" iyz="0.0037" izz="0.0226"/>
    </inertial>
  </link>
  <joint name="joint_3_left" type="revolute">
    <parent link="link_2"/>
    <child link="link_3_left"/>
    <origin rpy="-3.141592653589793 1.5707963267948966 0" xyz="0 0 0.0711"/>
    <axis xyz="0 0 1"/>
    <limit effort="300" lower="-2.09439510239" upper="2.09439510239" velocity="10"/>
    <dynamics damping="0.5"/>
  </joint>
  <link name="link_4_left">
    <inertial>
      <origin rpy="0 0 0" xyz="0.0402 0.0004 0.0405"/>
      <mass value="5"/>
      <inertia ixx="0.0621" ixy="-0.0389" ixz="-0.027" iyy="-0.0296" iyz="-0.0894" izz="-0.0966"/>
    </inertial>
  </link>
  <joint name="joint_4_left" type="revolute">
    <parent link="link_3_left"/>
    <child link="link_4_left"/>
    <origin rpy="1.5707963267948966 -1.5707963267948966 -3.141592653589793" xyz="0 0 0.051"/>
    <axis xyz="0 0 1"/>
    <limit effort="300" lower="-2.09439510239" upper="2.09439510239" velocity="10"/>
    <dynamics damping="0.5"/>
  </joint>
  <link name="link_5_left">
    <inertial>
      <origin rpy="0 0 0" xyz="0.0057 0.042 0.074"/>
      <mass value="5"/>
      <inertia ixx="0.0002" ixy="-0.0017" ixz="-0.0429" iyy="0.0131" iyz="-0.0877" izz="0.0056"/>
    </inertial>
  </link>
  <joint name="joint_5_left" type="revolute">
    <parent link="link_4_left"/>
    <child link="link_5_left"/>
    <origin rpy="0 -1.5707963267948966 -1.5707963267948966" xyz="0 0 0.0052"/>
    <axis xyz="0 0 1"/>
    <limit effort="300" lower="-2.09439510239" upper="2.09439510239" velocity="10"/>
    <dynamics damping="0.5"/>
  </joint>
  <!-- ======== LEFT BRANCH END ======= -->
  <!-- ======== RIGHT BRANCH STARTS ======= -->
  <link name="link_3_right">
    <inertial>
      <origin rpy="0 0 0" xyz="0.0248 0.054 0.0109"/>
      <mass value="5"/>
      <inertia ixx="-0.0901" ixy="-0.0358" ixz="-0.0889" iyy="0.0187" iyz="0.0276" izz="-0.0682"/>
    </inertial>
  </link>
  <joint name="joint_3_right" type="revolute">
    <parent link="link_2"/>
    <child link="link_3_right"/>
    <origin rpy="3.141592653589793 3.141592653589793 3.141592653589793" xyz="0 0 0.1841"/>
    <axis xyz="0 0 1"/>
    <limit effort="300" lower="-2.09439510239" upper="2.09439510239" velocity="10"/>
    <dynamics damping="0.5"/>
  </joint>
  <link name="link_4_right">
    <inertial>
      <origin rpy="0 0 0" xyz="0.0618 0.0765 0.0042"/>
      <mass value="5"/>
      <inertia ixx="0.0866" ixy="0.0606" ixz="0.023" iyy="0.0392" iyz="0.0003" izz="-0.0641"/>
    </inertial>
  </link>
  <joint name="joint_4_right" type="revolute">
    <parent link="link_3_right"/>
    <child link="link_4_right"/>
    <origin rpy="0 3.141592653589793 3.141592653589793" xyz="0 0 0.0308"/>
    <axis xyz="0 0 1"/>
    <limit effort="300" lower="-2.09439510239" upper="2.09439510239" velocity="10"/>
    <dynamics damping="0.5"/>
  </joint>
  <link name="link_5_right">
    <inertial>
      <origin rpy="0 0 0" xyz="0.0313 0.0324 0.0973"/>
      <mass value="5"/>
      <inertia ixx="0.0386" ixy="-0.0958" ixz="-0.0978" iyy="0.0201" iyz="-0.0217" izz="-0.0844"/>
    </inertial>
  </link>
  <joint name="joint_5_right" type="revolute">
    <parent link="link_4_right"/>
    <child link="link_5_right"/>
    <origin rpy="1.5707963267948966 0 3.141592653589793" xyz="0 0 0.1615"/>
    <axis xyz="0 0 1"/>
    <limit effort="300" lower="-2.09439510239" upper="2.09439510239" velocity="10"/>
    <dynamics damping="0.5"/>
  </joint>
  <!-- ======== RIGHT BRANCH ENDS ======= -->
</robot>
