<?xml version="1.0" encoding="utf-8"?>
<robot name="iiwa">
  <link name="world"/>
  <link name="link_1">
    <inertial>
      <origin rpy="0 0 0" xyz="0.0 0.067 0.0433"/>
      <mass value="5"/>
      <inertia ixx="0.0022" ixy="0.0753" ixz="-0.0378" iyy="-0.0983" iyz="-0.0325" izz="-0.0242"/>
    </inertial>
  </link>
  <joint name="joint_1" type="revolute">
    <parent link="world"/>
    <child link="link_1"/>
    <origin rpy="-3.141592653589793 1.5707963267948966 1.5707963267948966" xyz="0 0 0.0864"/>
    <axis xyz="0 0 1"/>
    <limit effort="300" lower="-2.09439510239" upper="2.09439510239" velocity="10"/>
    <dynamics damping="0.5"/>
  </joint>
  <link name="link_2">
    <inertial>
      <origin rpy="0 0 0" xyz="0.0668 0.0519 0.0983"/>
      <mass value="5"/>
      <inertia ixx="0.0942" ixy="-0.0085" ixz="0.0993" iyy="0.0405" iyz="0.0104" izz="-0.0676"/>
    </inertial>
  </link>
  <joint name="joint_2" type="revolute">
    <parent link="link_1"/>
    <child link="link_2"/>
    <origin rpy="1.5707963267948966 3.141592653589793 3.141592653589793" xyz="0 0 0.0046"/>
    <axis xyz="0 0 1"/>
    <limit effort="300" lower="-2.09439510239" upper="2.09439510239" velocity="10"/>
    <dynamics damping="0.5"/>
  </joint>
  <link name="link_3">
    <inertial>
      <origin rpy="0 0 0" xyz="0.0903 0.0275 0.0814"/>
      <mass value="5"/>
      <inertia ixx="-0.0272" ixy="-0.0846" ixz="0.0292" iyy="0.0907" iyz="0.0923" izz="0.0699"/>
    </inertial>
  </link>
  <joint name="joint_3" type="revolute">
    <parent link="link_2"/>
    <child link="link_3"/>
    <origin rpy="1.5707963267948966 1.5707963267948966 0" xyz="0 0 0.0977"/>
    <axis xyz="0 0 1"/>
    <limit effort="300" lower="-2.09439510239" upper="2.09439510239" velocity="10"/>
    <dynamics damping="0.5"/>
  </joint>
  <link name="link_4">
    <inertial>
      <origin rpy="0 0 0" xyz="0.0608 0.0266 0.0764"/>
      <mass value="5"/>
      <inertia ixx="-0.0986" ixy="-0.0159" ixz="-0.0452" iyy="-0.0067" iyz="-0.0911" izz="-0.036"/>
    </inertial>
  </link>
  <joint name="joint_4" type="revolute">
    <parent link="link_3"/>
    <child link="link_4"/>
    <origin rpy="3.141592653589793 3.141592653589793 0" xyz="0 0 0.1797"/>
    <axis xyz="0 0 1"/>
    <limit effort="300" lower="-2.09439510239" upper="2.09439510239" velocity="10"/>
    <dynamics damping="0.5"/>
  </joint>
  <link name="link_5">
    <inertial>
      <origin rpy="0 0 0" xyz="0.0252 0.0074 0.0314"/>
      <mass value="5"/>
      <inertia ixx="0.0417" ixy="-0.0117" ixz="0.0502" iyy="0.0365" iyz="-0.0748" izz="-0.0932"/>
    </inertial>
  </link>
  <joint name="joint_5" type="revolute">
    <parent link="link_4"/>
    <child link="link_5"/>
    <origin rpy="0 -3.141592653589793 3.141592653589793" xyz="0 0 0.0873"/>
    <axis xyz="0 0 1"/>
    <limit effort="300" lower="-2.09439510239" upper="2.09439510239" velocity="10"/>
    <dynamics damping="0.5"/>
  </joint>
  <!-- ======== LEFT BRANCH STARTS ======= -->
  <link name="link_6_left">
    <inertial>
      <origin rpy="0 0 0" xyz="0.0035 0.0955 0.0894"/>
      <mass value="5"/>
      <inertia ixx="-0.036" ixy="-0.0369" ixz="0.0933" iyy="0.0072" iyz="0.049" izz="0.0583"/>
    </inertial>
  </link>
  <joint name="joint_6_left" type="revolute">
    <parent link="link_5"/>
    <child link="link_6_left"/>
    <origin rpy="3.141592653589793 -3.141592653589793 0" xyz="0 0 0.1769"/>
    <axis xyz="0 0 1"/>
    <limit effort="300" lower="-2.09439510239" upper="2.09439510239" velocity="10"/>
    <dynamics damping="0.5"/>
  </joint>
  <link name="link_7_left">
    <inertial>
      <origin rpy="0 0 0" xyz="0.0827 0.0458 0.0884"/>
      <mass value="5"/>
      <inertia ixx="-0.0379" ixy="-0.067" ixz="-0.0241" iyy="0.0231" iyz="-0.0436" izz="-0.0658"/>
    </inertial>
  </link>
  <joint name="joint_7_left" type="revolute">
    <parent link="link_6_left"/>
    <child link="link_7_left"/>
    <origin rpy="3.141592653589793 0 -3.141592653589793" xyz="0 0 0.0216"/>
    <axis xyz="0 0 1"/>
    <limit effort="300" lower="-2.09439510239" upper="2.09439510239" velocity="10"/>
    <dynamics damping="0.5"/>
  </joint>
  <link name="link_8_left">
    <inertial>
      <origin rpy="0 0 0" xyz="0.0861 0.0012 0.0744"/>
      <mass value="5"/>
      <inertia ixx="0.0972" ixy="0.0427" ixz="0.034" iyy="-0.0329" iyz="0.0905" izz="0.0251"/>
    </inertial>
  </link>
  <joint name="joint_8_left" type="revolute">
    <parent link="link_7_left"/>
    <child link="link_8_left"/>
    <origin rpy="-3.141592653589793 1.5707963267948966 -1.5707963267948966" xyz="0 0 0.1701"/>
    <axis xyz="0 0 1"/>
    <limit effort="300" lower="-2.09439510239" upper="2.09439510239" velocity="10"/>
    <dynamics damping="0.5"/>
  </joint>
  <!-- ======== LEFT BRANCH END ======= -->
  <!-- ======== RIGHT BRANCH STARTS ======= -->
  <link name="link_6_right">
    <inertial>
      <origin rpy="0 0 0" xyz="0.0639 0.0405 0.0825"/>
      <mass value="5"/>
      <inertia ixx="-0.0993" ixy="-0.0217" ixz="0.0472" iyy="0.07" iyz="-0.0199" izz="0.0431"/>
    </inertial>
  </link>
  <joint name="joint_6_right" type="revolute">
    <parent link="link_5"/>
    <child link="link_6_right"/>
    <origin rpy="-3.141592653589793 3.141592653589793 -3.141592653589793" xyz="0 0 0.0164"/>
    <axis xyz="0 0 1"/>
    <limit effort="300" lower="-2.09439510239" upper="2.09439510239" velocity="10"/>
    <dynamics damping="0.5"/>
  </joint>
  <link name="link_7_right">
    <inertial>
      <origin rpy="0 0 0" xyz="0.0665 0.0682 0.0405"/>
      <mass value="5"/>
      <inertia ixx="-0.0888" ixy="0.0141" ixz="-0.0586" iyy="0.0454" iyz="0.0959" izz="0.0822"/>
    </inertial>
  </link>
  <joint name="joint_7_right" type="revolute">
    <parent link="link_6_right"/>
    <child link="link_7_right"/>
    <origin rpy="1.5707963267948966 0 -3.141592653589793" xyz="0 0 0.1925"/>
    <axis xyz="0 0 1"/>
    <limit effort="300" lower="-2.09439510239" upper="2.09439510239" velocity="10"/>
    <dynamics damping="0.5"/>
  </joint>
  <link name="link_8_right">
    <inertial>
      <origin rpy="0 0 0" xyz="0.0121 0.0072 0.0191"/>
      <mass value="5"/>
      <inertia ixx="0.0153" ixy="-0.0877" ixz="-0.0352" iyy="-0.0917" iyz="0.0658" izz="0.0613"/>
    </inertial>
  </link>
  <joint name="joint_8_right" type="revolute">
    <parent link="link_7_right"/>
    <child link="link_8_right"/>
    <origin rpy="0 1.5707963267948966 3.141592653589793" xyz="0 0 0.106"/>
    <axis xyz="0 0 1"/>
    <limit effort="300" lower="-2.09439510239" upper="2.09439510239" velocity="10"/>
    <dynamics damping="0.5"/>
  </joint>
  <!-- ======== RIGHT BRANCH ENDS ======= -->
</robot>
