<?xml version="1.0" encoding="utf-8"?>
<robot name="pants">
  <link name="utorso">
    <inertial>
      <origin xyz="0.0 -0.03 0.12" rpy="0.0 0.0 0.0"/>
      <mass value="4.0"/>
      <inertia ixx="0.1" ixy="0.0" ixz="0.0" iyy="0.09" iyz="0.0" izz="0.02"/>
    </inertial>
  </link>
  <joint name="joint_torso" type="revolute">
    <parent link="utorso"/>
    <child link="ltorso"/>
    <origin xyz="0.0 0.0 0.1575" rpy="0.0 0.0 0.0"/>
    <axis xyz="0.0 0.0 1.0"/>
    <limit effort="300" lower="-3" upper="3" velocity="10"/>
  </joint>
  <link name="ltorso">
    <inertial>
      <origin xyz="0.0 -0.03 0.12" rpy="0.0 0.0 0.0"/>
      <mass value="4.0"/>
      <inertia ixx="0.1" ixy="0.0" ixz="0.0" iyy="0.09" iyz="0.0" izz="0.02"/>
    </inertial>
  </link>

  <joint name="joint_l1" type="revolute">
    <parent link="ltorso"/>
    <child link="link_l1"/>
    <origin xyz="-1.0 0.0 0.1575" rpy="0.0 -0.0 0.0"/>
    <axis xyz="0.0 0.0 1.0"/>
    <limit effort="300" lower="-3" upper="3" velocity="10"/>
  </joint>
  <link name="link_l1">
    <inertial>
      <origin xyz="0.0003 0.059 0.042" rpy="0.0 0.0 0.0"/>
      <mass value="4.0"/>
      <inertia ixx="0.05" ixy="0.0" ixz="0.0" iyy="0.018" iyz="0.0" izz="0.044"/>
    </inertial>
  </link>
  <joint name="joint_l2" type="revolute">
    <parent link="link_l1"/>
    <child link="link_l2"/>
    <origin xyz="0.0 0.0 0.2025" rpy="1.57080 0 3.14159"/>
    <axis xyz="0.0 0.0 1.0"/>
    <limit effort="300" lower="-3" upper="3" velocity="10"/>
  </joint>
  <link name="link_l2">
    <inertial>
      <origin xyz="0.0 0.03 0.13" rpy="0.0 0.0 0.0"/>
      <mass value="3.0"/>
      <inertia ixx="0.08" ixy="0.0" ixz="0.0" iyy="0.075" iyz="0.0" izz="0.01"/>
    </inertial>
  </link>
  <joint name="joint_l3" type="revolute">
    <parent link="link_l2"/>
    <child link="link_l3"/>
    <origin xyz="0.0 0.2045 -0.0" rpy="1.57080 0 3.14159"/>
    <axis xyz="0.0 0.0 1.0"/>
    <limit effort="300" lower="-3" upper="3" velocity="10"/>
  </joint>
  <link name="link_l3">
    <inertial>
      <origin xyz="0.0 0.067 0.034" rpy="0.0 0.0 0.0"/>
      <mass value="2.7"/>
      <inertia ixx="0.03" ixy="0.0" ixz="0.0" iyy="0.01" iyz="0.0" izz="0.029"/>
    </inertial>
  </link>
  <joint name="joint_l4" type="revolute">
    <parent link="link_l3"/>
    <child link="link_l4"/>
    <origin xyz="0.0 0.0 0.2155" rpy="1.57080 -0.0 0.0"/>
    <axis xyz="0.0 0.0 1.0"/>
    <limit effort="300" lower="-3" upper="3" velocity="10"/>
  </joint>
  <link name="link_l4">
    <inertial>
      <origin xyz="0.0001 0.021 0.076" rpy="0.0 0.0 0.0"/>
      <mass value="1.7"/>
      <inertia ixx="0.02" ixy="0.0" ixz="0.0" iyy="0.018" iyz="0.0" izz="0.005"/>
    </inertial>
  </link>

  <joint name="joint_r1" type="revolute">
    <parent link="ltorso"/>
    <child link="link_r1"/>
    <origin xyz="1.0 0.0 0.1575" rpy="0.0 -0.0 0.0"/>
    <axis xyz="0.0 0.0 1.0"/>
    <limit effort="300" lower="-3" upper="3" velocity="10"/>
  </joint>
  <link name="link_r1">
    <inertial>
      <origin xyz="0.0003 0.059 0.042" rpy="0.0 0.0 0.0"/>
      <mass value="4.0"/>
      <inertia ixx="0.05" ixy="0.0" ixz="0.0" iyy="0.018" iyz="0.0" izz="0.044"/>
    </inertial>
  </link>
  <joint name="joint_r2" type="revolute">
    <parent link="link_r1"/>
    <child link="link_r2"/>
    <origin xyz="0.0 0.0 0.2025" rpy="1.57080 0 3.14159"/>
    <axis xyz="0.0 0.0 1.0"/>
    <limit effort="300" lower="-3" upper="3" velocity="10"/>
  </joint>
  <link name="link_r2">
    <inertial>
      <origin xyz="0.0 0.03 0.13" rpy="0.0 0.0 0.0"/>
      <mass value="3.0"/>
      <inertia ixx="0.08" ixy="0.0" ixz="0.0" iyy="0.075" iyz="0.0" izz="0.01"/>
    </inertial>
  </link>
  <joint name="joint_r3" type="revolute">
    <parent link="link_r2"/>
    <child link="link_r3"/>
    <origin xyz="0.0 0.2045 -0.0" rpy="1.57080 0 3.14159"/>
    <axis xyz="0.0 0.0 1.0"/>
    <limit effort="300" lower="-3" upper="3" velocity="10"/>
  </joint>
  <link name="link_r3">
    <inertial>
      <origin xyz="0.0 0.067 0.034" rpy="0.0 0.0 0.0"/>
      <mass value="2.7"/>
      <inertia ixx="0.03" ixy="0.0" ixz="0.0" iyy="0.01" iyz="0.0" izz="0.029"/>
    </inertial>
  </link>
  <joint name="joint_r4" type="revolute">
    <parent link="link_r3"/>
    <child link="link_r4"/>
    <origin xyz="0.0 0.0 0.2155" rpy="1.57080 -0.0 0.0"/>
    <axis xyz="0.0 0.0 1.0"/>
    <limit effort="300" lower="-3" upper="3" velocity="10"/>
  </joint>
  <link name="link_r4">
    <inertial>
      <origin xyz="0.0001 0.021 0.076" rpy="0.0 0.0 0.0"/>
      <mass value="1.7"/>
      <inertia ixx="0.02" ixy="0.0" ixz="0.0" iyy="0.018" iyz="0.0" izz="0.005"/>
    </inertial>
  </link>
</robot>
