<?xml version="1.0" ?>
<!-- ===================================================================== -->
<!-- Collision models: All collision models are omitted in this version of 
     the iiwa arm.-->
<!-- ===================================================================== -->
<!--
2021-06-25:
    (1)-(2)-(3)...(8) [iiwa_link_x_left]
   /
(0)
   \
    (1)-(2)-(3)...(8) [iiwa_link_x_right]
-->
<!-- ===================================================================== -->
<robot name="iiwa14" xmlns:xacro="http://www.ros.org/wiki/xacro">
  <!-- Defines a base link that will serve as the model's root. -->
  <link name="base"/>
  <!-- ======== LEFT FORK STARTS ======== -->
  <!-- joint between base and link_1_left -->
  <joint name="iiwa_joint_1_left" type="revolute">
    <parent link="base"/>
    <child link="iiwa_link_1_left"/>
    <origin rpy="0 0 0" xyz="0 0 0.1575"/>
    <axis xyz="0 0 1"/>
    <limit effort="300" lower="-2.96705972839" upper="2.96705972839" velocity="10"/>
    <dynamics damping="0.5"/>
  </joint>
  <link name="iiwa_link_1_left">
    <inertial>
      <origin rpy="0 0 0" xyz="0 -0.03 0.12"/>
      <mass value="5.76"/>
      <inertia ixx="0.121" ixy="0" ixz="0" iyy="0.116" iyz="-0.021" izz="0.0175"/>
    </inertial>
  </link>
  <!-- joint between link_1_left and link_2_left -->
  <joint name="iiwa_joint_2_left" type="revolute">
    <parent link="iiwa_link_1_left"/>
    <child link="iiwa_link_2_left"/>
    <origin rpy="1.570796326794897 0 3.141592653589793" xyz="0 0 0.2025"/>
    <axis xyz="0 0 1"/>
    <limit effort="300" lower="-2.09439510239" upper="2.09439510239" velocity="10"/>
    <dynamics damping="0.5"/>
  </joint>
  <link name="iiwa_link_2_left">
    <inertial>
      <origin rpy="0 0 0" xyz="0.0003 0.059 0.042"/>
      <mass value="6.35"/>
      <inertia ixx="0.0638" ixy="0.0001" ixz="0.00008" iyy="0.0416" iyz="0.0157" izz="0.0331"/>
    </inertial>
  </link>
  <!-- joint between link_2_left and link_3_left -->
  <joint name="iiwa_joint_3_left" type="revolute">
    <parent link="iiwa_link_2_left"/>
    <child link="iiwa_link_3_left"/>
    <origin rpy="1.570796326794897 0 3.141592653589793" xyz="0 0.2045 0"/>
    <axis xyz="0 0 1"/>
    <limit effort="300" lower="-2.96705972839" upper="2.96705972839" velocity="10"/>
    <dynamics damping="0.5"/>
  </joint>
  <link name="iiwa_link_3_left">
    <inertial>
      <origin rpy="0 0 0" xyz="0 0.03 0.13"/>
      <mass value="3.5"/>
      <inertia ixx="0.0873" ixy="0" ixz="0" iyy="0.083" iyz="0.014" izz="0.0108"/>
    </inertial>
  </link>
  <!-- joint between link_3_left and link_4_left -->
  <joint name="iiwa_joint_4_left" type="revolute">
    <parent link="iiwa_link_3_left"/>
    <child link="iiwa_link_4_left"/>
    <origin rpy="1.570796326794897 0 0" xyz="0 0 0.2155"/>
    <axis xyz="0 0 1"/>
    <limit effort="300" lower="-2.09439510239" upper="2.09439510239" velocity="10"/>
    <dynamics damping="0.5"/>
  </joint>
  <link name="iiwa_link_4_left">
    <inertial>
      <origin rpy="0 0 0" xyz="0 0.067 0.034"/>
      <mass value="3.5"/>
      <inertia ixx="0.0368" ixy="0" ixz="0" iyy="0.02045" iyz="0.008" izz="0.02171"/>
    </inertial>
  </link>
  <!-- joint between link_4_left and link_5_left -->
  <joint name="iiwa_joint_5_left" type="revolute">
    <parent link="iiwa_link_4_left"/>
    <child link="iiwa_link_5_left"/>
    <origin rpy="-1.570796326794897 3.141592653589793 0" xyz="0 0.1845 0"/>
    <axis xyz="0 0 1"/>
    <limit effort="300" lower="-2.96705972839" upper="2.96705972839" velocity="10"/>
    <dynamics damping="0.5"/>
  </joint>
  <link name="iiwa_link_5_left">
    <inertial>
      <origin rpy="0 0 0" xyz="0.0001 0.021 0.076"/>
      <mass value="3.5"/>
      <inertia ixx="0.0318" ixy="0.000007" ixz="0.000027" iyy="0.028916" iyz="0.005586" izz="0.006"/>
    </inertial>
  </link>
  <!-- joint between link_5_left and link_6_left -->
  <joint name="iiwa_joint_6_left" type="revolute">
    <parent link="iiwa_link_5_left"/>
    <child link="iiwa_link_6_left"/>
    <origin rpy="1.570796326794897 0 0" xyz="0 0 0.2155"/>
    <axis xyz="0 0 1"/>
    <limit effort="300" lower="-2.09439510239" upper="2.09439510239" velocity="10"/>
    <dynamics damping="0.5"/>
  </joint>
  <link name="iiwa_link_6_left">
    <inertial>
      <origin rpy="0 0 0" xyz="0 0.0006 0.0004"/>
      <mass value="1.8"/>
      <!--1.8 kuka CAD value-->
      <!--1.8 Original Drake URDF value-->
      <inertia ixx="0.0049" ixy="0" ixz="0" iyy="0.0047" iyz="0" izz="0.0036"/>
    </inertial>
  </link>
  <!-- joint between link_6_left and link_7_left -->
  <joint name="iiwa_joint_7_left" type="revolute">
    <parent link="iiwa_link_6_left"/>
    <child link="iiwa_link_7_left"/>
    <origin rpy="-1.570796326794897 3.141592653589793 0" xyz="0 0.081 0"/>
    <axis xyz="0 0 1"/>
    <limit effort="300" lower="-3.05432619099" upper="3.05432619099" velocity="10"/>
    <dynamics damping="0.5"/>
  </joint>
  <link name="iiwa_link_7_left">
    <inertial>
      <origin rpy="0 0 0" xyz="0 0 0.02"/>
      <mass value="1.2"/>
      <!--0.31 kuka CAD value-->
      <!--0.3 Original Drake URDF value-->
      <!--<inertia ixx="0.001" ixy="0" ixz="0" iyy="0.001" iyz="0" izz="0.001"/>-->
      <inertia ixx="0.0055" ixy="0" ixz="0" iyy="0.0055" iyz="0" izz="0.005"/>
    </inertial>
  </link>
  <!-- joint between link_7_left and link_8_left -->
  <joint name="iiwa_joint_8_left" type="revolute">
    <parent link="iiwa_link_7_left"/>
    <child link="iiwa_link_8_left"/>
    <origin rpy="-1.570796326794897 3.141592653589793 0" xyz="0 0.081 0"/>
    <axis xyz="0 0 1"/>
    <limit effort="300" lower="-3.05432619099" upper="3.05432619099" velocity="10"/>
    <dynamics damping="0.5"/>
  </joint>
  <link name="iiwa_link_8_left">
    <inertial>
      <origin rpy="0 0 0" xyz="0 0 0.02"/>
      <mass value="1.2"/>
      <!--0.31 kuka CAD value-->
      <!--0.3 Original Drake URDF value-->
      <!--<inertia ixx="0.001" ixy="0" ixz="0" iyy="0.001" iyz="0" izz="0.001"/>-->
      <inertia ixx="0.0055" ixy="0" ixz="0" iyy="0.0055" iyz="0" izz="0.005"/>
    </inertial>
  </link>
  <!-- ======== LEFT FORK ENDS ======== -->
  <!-- ======== RIGHT FORK STARTS ======== -->
  <!-- joint between base and link_1_right -->
  <joint name="iiwa_joint_1_right" type="revolute">
    <parent link="base"/>
    <child link="iiwa_link_1_right"/>
    <origin rpy="0 0 0" xyz="0 0 0.1575"/>
    <axis xyz="0 0 1"/>
    <limit effort="300" lower="-2.96705972839" upper="2.96705972839" velocity="10"/>
    <dynamics damping="0.5"/>
  </joint>
  <link name="iiwa_link_1_right">
    <inertial>
      <origin rpy="0 0 0" xyz="0 -0.03 0.12"/>
      <mass value="5.76"/>
      <inertia ixx="0.121" ixy="0" ixz="0" iyy="0.116" iyz="-0.021" izz="0.0175"/>
    </inertial>
  </link>
  <!-- joint between link_1_right and link_2_right -->
  <joint name="iiwa_joint_2_right" type="revolute">
    <parent link="iiwa_link_1_right"/>
    <child link="iiwa_link_2_right"/>
    <origin rpy="1.570796326794897 0 3.141592653589793" xyz="0 0 0.2025"/>
    <axis xyz="0 0 1"/>
    <limit effort="300" lower="-2.09439510239" upper="2.09439510239" velocity="10"/>
    <dynamics damping="0.5"/>
  </joint>
  <link name="iiwa_link_2_right">
    <inertial>
      <origin rpy="0 0 0" xyz="0.0003 0.059 0.042"/>
      <mass value="6.35"/>
      <inertia ixx="0.0638" ixy="0.0001" ixz="0.00008" iyy="0.0416" iyz="0.0157" izz="0.0331"/>
    </inertial>
  </link>
  <!-- joint between link_2_right and link_3_right -->
  <joint name="iiwa_joint_3_right" type="revolute">
    <parent link="iiwa_link_2_right"/>
    <child link="iiwa_link_3_right"/>
    <origin rpy="1.570796326794897 0 3.141592653589793" xyz="0 0.2045 0"/>
    <axis xyz="0 0 1"/>
    <limit effort="300" lower="-2.96705972839" upper="2.96705972839" velocity="10"/>
    <dynamics damping="0.5"/>
  </joint>
  <link name="iiwa_link_3_right">
    <inertial>
      <origin rpy="0 0 0" xyz="0 0.03 0.13"/>
      <mass value="3.5"/>
      <inertia ixx="0.0873" ixy="0" ixz="0" iyy="0.083" iyz="0.014" izz="0.0108"/>
    </inertial>
  </link>
  <!-- joint between link_3_right and link_4_right -->
  <joint name="iiwa_joint_4_right" type="revolute">
    <parent link="iiwa_link_3_right"/>
    <child link="iiwa_link_4_right"/>
    <origin rpy="1.570796326794897 0 0" xyz="0 0 0.2155"/>
    <axis xyz="0 0 1"/>
    <limit effort="300" lower="-2.09439510239" upper="2.09439510239" velocity="10"/>
    <dynamics damping="0.5"/>
  </joint>
  <link name="iiwa_link_4_right">
    <inertial>
      <origin rpy="0 0 0" xyz="0 0.067 0.034"/>
      <mass value="3.5"/>
      <inertia ixx="0.0368" ixy="0" ixz="0" iyy="0.02045" iyz="0.008" izz="0.02171"/>
    </inertial>
  </link>
  <!-- joint between link_4_right and link_5_right -->
  <joint name="iiwa_joint_5_right" type="revolute">
    <parent link="iiwa_link_4_right"/>
    <child link="iiwa_link_5_right"/>
    <origin rpy="-1.570796326794897 3.141592653589793 0" xyz="0 0.1845 0"/>
    <axis xyz="0 0 1"/>
    <limit effort="300" lower="-2.96705972839" upper="2.96705972839" velocity="10"/>
    <dynamics damping="0.5"/>
  </joint>
  <link name="iiwa_link_5_right">
    <inertial>
      <origin rpy="0 0 0" xyz="0.0001 0.021 0.076"/>
      <mass value="3.5"/>
      <inertia ixx="0.0318" ixy="0.000007" ixz="0.000027" iyy="0.028916" iyz="0.005586" izz="0.006"/>
    </inertial>
  </link>
  <!-- joint between link_5_right and link_6_right -->
  <joint name="iiwa_joint_6_right" type="revolute">
    <parent link="iiwa_link_5_right"/>
    <child link="iiwa_link_6_right"/>
    <origin rpy="1.570796326794897 0 0" xyz="0 0 0.2155"/>
    <axis xyz="0 0 1"/>
    <limit effort="300" lower="-2.09439510239" upper="2.09439510239" velocity="10"/>
    <dynamics damping="0.5"/>
  </joint>
  <link name="iiwa_link_6_right">
    <inertial>
      <origin rpy="0 0 0" xyz="0 0.0006 0.0004"/>
      <mass value="1.8"/>
      <!--1.8 kuka CAD value-->
      <!--1.8 Original Drake URDF value-->
      <inertia ixx="0.0049" ixy="0" ixz="0" iyy="0.0047" iyz="0" izz="0.0036"/>
    </inertial>
  </link>
  <!-- joint between link_6_right and link_7_right -->
  <joint name="iiwa_joint_7_right" type="revolute">
    <parent link="iiwa_link_6_right"/>
    <child link="iiwa_link_7_right"/>
    <origin rpy="-1.570796326794897 3.141592653589793 0" xyz="0 0.081 0"/>
    <axis xyz="0 0 1"/>
    <limit effort="300" lower="-3.05432619099" upper="3.05432619099" velocity="10"/>
    <dynamics damping="0.5"/>
  </joint>
  <link name="iiwa_link_7_right">
    <inertial>
      <origin rpy="0 0 0" xyz="0 0 0.02"/>
      <mass value="1.2"/>
      <!--0.31 kuka CAD value-->
      <!--0.3 Original Drake URDF value-->
      <!--<inertia ixx="0.001" ixy="0" ixz="0" iyy="0.001" iyz="0" izz="0.001"/>-->
      <inertia ixx="0.0055" ixy="0" ixz="0" iyy="0.0055" iyz="0" izz="0.005"/>
    </inertial>
  </link>
  <!-- joint between link_7_right and link_8_right -->
  <joint name="iiwa_joint_8_right" type="revolute">
    <parent link="iiwa_link_7_right"/>
    <child link="iiwa_link_8_right"/>
    <origin rpy="-1.570796326794897 3.141592653589793 0" xyz="0 0.081 0"/>
    <axis xyz="0 0 1"/>
    <limit effort="300" lower="-3.05432619099" upper="3.05432619099" velocity="10"/>
    <dynamics damping="0.5"/>
  </joint>
  <link name="iiwa_link_8_right">
    <inertial>
      <origin rpy="0 0 0" xyz="0 0 0.02"/>
      <mass value="1.2"/>
      <!--0.31 kuka CAD value-->
      <!--0.3 Original Drake URDF value-->
      <!--<inertia ixx="0.001" ixy="0" ixz="0" iyy="0.001" iyz="0" izz="0.001"/>-->
      <inertia ixx="0.0055" ixy="0" ixz="0" iyy="0.0055" iyz="0" izz="0.005"/>
    </inertial>
  </link>
  <!-- ======== RIGHT FORK ENDS ======== -->
</robot>
