<?xml version="1.0" encoding="utf-8"?>
<robot name="iiwa">
  <link name="world"/>
  <link name="link_1">
    <inertial>
      <origin rpy="0 0 0" xyz="0.039 0.0145 0.0907"/>
      <mass value="5"/>
      <inertia ixx="-0.0397" ixy="-0.0198" ixz="0.0079" iyy="0.0432" iyz="0.0055" izz="0.0456"/>
    </inertial>
  </link>
  <joint name="joint_1" type="revolute">
    <parent link="world"/>
    <child link="link_1"/>
    <origin rpy="3.141592653589793 -1.5707963267948966 1.5707963267948966" xyz="0 0 0.0883"/>
    <axis xyz="0 0 1"/>
    <limit effort="300" lower="-2.09439510239" upper="2.09439510239" velocity="10"/>
    <dynamics damping="0.5"/>
  </joint>
  <link name="link_2">
    <inertial>
      <origin rpy="0 0 0" xyz="0.096 0.0921 0.0704"/>
      <mass value="5"/>
      <inertia ixx="0.0083" ixy="0.0771" ixz="-0.0334" iyy="0.0595" iyz="0.0247" izz="0.0685"/>
    </inertial>
  </link>
  <joint name="joint_2" type="revolute">
    <parent link="link_1"/>
    <child link="link_2"/>
    <origin rpy="-3.141592653589793 -3.141592653589793 3.141592653589793" xyz="0 0 0.0006"/>
    <axis xyz="0 0 1"/>
    <limit effort="300" lower="-2.09439510239" upper="2.09439510239" velocity="10"/>
    <dynamics damping="0.5"/>
  </joint>
  <link name="link_3">
    <inertial>
      <origin rpy="0 0 0" xyz="0.0393 0.0325 0.0924"/>
      <mass value="5"/>
      <inertia ixx="-0.0027" ixy="0.0103" ixz="0.0384" iyy="-0.0784" iyz="0.0118" izz="0.0171"/>
    </inertial>
  </link>
  <joint name="joint_3" type="revolute">
    <parent link="link_2"/>
    <child link="link_3"/>
    <origin rpy="1.5707963267948966 1.5707963267948966 -1.5707963267948966" xyz="0 0 0.1145"/>
    <axis xyz="0 0 1"/>
    <limit effort="300" lower="-2.09439510239" upper="2.09439510239" velocity="10"/>
    <dynamics damping="0.5"/>
  </joint>
  <link name="link_4">
    <inertial>
      <origin rpy="0 0 0" xyz="0.054 0.067 0.0534"/>
      <mass value="5"/>
      <inertia ixx="-0.0092" ixy="-0.0704" ixz="-0.0494" iyy="-0.0211" iyz="-0.0773" izz="-0.069"/>
    </inertial>
  </link>
  <joint name="joint_4" type="revolute">
    <parent link="link_3"/>
    <child link="link_4"/>
    <origin rpy="-1.5707963267948966 0 0" xyz="0 0 0.0663"/>
    <axis xyz="0 0 1"/>
    <limit effort="300" lower="-2.09439510239" upper="2.09439510239" velocity="10"/>
    <dynamics damping="0.5"/>
  </joint>
  <link name="link_5">
    <inertial>
      <origin rpy="0 0 0" xyz="0.0217 0.0448 0.0656"/>
      <mass value="5"/>
      <inertia ixx="-0.0372" ixy="-0.067" ixz="-0.0575" iyy="0.0103" iyz="-0.015" izz="-0.0881"/>
    </inertial>
  </link>
  <joint name="joint_5" type="revolute">
    <parent link="link_4"/>
    <child link="link_5"/>
    <origin rpy="0 -3.141592653589793 -1.5707963267948966" xyz="0 0 0.1014"/>
    <axis xyz="0 0 1"/>
    <limit effort="300" lower="-2.09439510239" upper="2.09439510239" velocity="10"/>
    <dynamics damping="0.5"/>
  </joint>
  <link name="link_6">
    <inertial>
      <origin rpy="0 0 0" xyz="0.0604 0.036 0.0116"/>
      <mass value="5"/>
      <inertia ixx="0.0505" ixy="-0.0029" ixz="-0.0035" iyy="0.084" iyz="0.0879" izz="-0.0715"/>
    </inertial>
  </link>
  <joint name="joint_6" type="revolute">
    <parent link="link_5"/>
    <child link="link_6"/>
    <origin rpy="-1.5707963267948966 -3.141592653589793 3.141592653589793" xyz="0 0 0.1792"/>
    <axis xyz="0 0 1"/>
    <limit effort="300" lower="-2.09439510239" upper="2.09439510239" velocity="10"/>
    <dynamics damping="0.5"/>
  </joint>
  <link name="link_7">
    <inertial>
      <origin rpy="0 0 0" xyz="0.0105 0.0826 0.0163"/>
      <mass value="5"/>
      <inertia ixx="0.049" ixy="-0.0834" ixz="-0.0855" iyy="-0.0453" iyz="0.0579" izz="0.0707"/>
    </inertial>
  </link>
  <joint name="joint_7" type="revolute">
    <parent link="link_6"/>
    <child link="link_7"/>
    <origin rpy="-1.5707963267948966 3.141592653589793 -3.141592653589793" xyz="0 0 0.078"/>
    <axis xyz="0 0 1"/>
    <limit effort="300" lower="-2.09439510239" upper="2.09439510239" velocity="10"/>
    <dynamics damping="0.5"/>
  </joint>
  <link name="link_8">
    <inertial>
      <origin rpy="0 0 0" xyz="0.0451 0.0695 0.0802"/>
      <mass value="5"/>
      <inertia ixx="0.0895" ixy="-0.0508" ixz="-0.0833" iyy="-0.0565" iyz="0.0888" izz="0.0696"/>
    </inertial>
  </link>
  <joint name="joint_8" type="revolute">
    <parent link="world"/>
    <child link="link_8"/>
    <origin rpy="3.141592653589793 0 3.141592653589793" xyz="0 0 0.0674"/>
    <axis xyz="0 0 1"/>
    <limit effort="300" lower="-2.09439510239" upper="2.09439510239" velocity="10"/>
    <dynamics damping="0.5"/>
  </joint>
  <link name="link_9">
    <inertial>
      <origin rpy="0 0 0" xyz="0.0046 0.0517 0.0579"/>
      <mass value="5"/>
      <inertia ixx="-0.0482" ixy="0.0851" ixz="-0.0563" iyy="-0.0088" iyz="0.0335" izz="0.0155"/>
    </inertial>
  </link>
  <joint name="joint_9" type="revolute">
    <parent link="link_8"/>
    <child link="link_9"/>
    <origin rpy="0 -3.141592653589793 1.5707963267948966" xyz="0 0 0.0948"/>
    <axis xyz="0 0 1"/>
    <limit effort="300" lower="-2.09439510239" upper="2.09439510239" velocity="10"/>
    <dynamics damping="0.5"/>
  </joint>
  <link name="link_10">
    <inertial>
      <origin rpy="0 0 0" xyz="0.0936 0.0542 0.0992"/>
      <mass value="5"/>
      <inertia ixx="0.0088" ixy="-0.0844" ixz="-0.0106" iyy="-0.0979" iyz="-0.0879" izz="-0.0066"/>
    </inertial>
  </link>
  <joint name="joint_10" type="revolute">
    <parent link="link_9"/>
    <child link="link_10"/>
    <origin rpy="-3.141592653589793 -1.5707963267948966 -3.141592653589793" xyz="0 0 0.0568"/>
    <axis xyz="0 0 1"/>
    <limit effort="300" lower="-2.09439510239" upper="2.09439510239" velocity="10"/>
    <dynamics damping="0.5"/>
  </joint>
  <link name="link_11">
    <inertial>
      <origin rpy="0 0 0" xyz="0.0067 0.0451 0.0467"/>
      <mass value="5"/>
      <inertia ixx="0.0241" ixy="-0.0569" ixz="0.0218" iyy="0.0448" iyz="-0.0083" izz="0.0518"/>
    </inertial>
  </link>
  <joint name="joint_11" type="revolute">
    <parent link="link_10"/>
    <child link="link_11"/>
    <origin rpy="0 -1.5707963267948966 -1.5707963267948966" xyz="0 0 0.1868"/>
    <axis xyz="0 0 1"/>
    <limit effort="300" lower="-2.09439510239" upper="2.09439510239" velocity="10"/>
    <dynamics damping="0.5"/>
  </joint>
  <link name="link_12">
    <inertial>
      <origin rpy="0 0 0" xyz="0.0512 0.0306 0.0424"/>
      <mass value="5"/>
      <inertia ixx="-0.039" ixy="-0.0829" ixz="-0.0706" iyy="-0.0717" iyz="0.0635" izz="-0.0496"/>
    </inertial>
  </link>
  <joint name="joint_12" type="revolute">
    <parent link="world"/>
    <child link="link_12"/>
    <origin rpy="3.141592653589793 3.141592653589793 -1.5707963267948966" xyz="0 0 0.136"/>
    <axis xyz="0 0 1"/>
    <limit effort="300" lower="-2.09439510239" upper="2.09439510239" velocity="10"/>
    <dynamics damping="0.5"/>
  </joint>
  <link name="link_13">
    <inertial>
      <origin rpy="0 0 0" xyz="0.0411 0.0129 0.0324"/>
      <mass value="5"/>
      <inertia ixx="0.0724" ixy="-0.0735" ixz="0.0929" iyy="-0.0765" iyz="-0.0459" izz="-0.0842"/>
    </inertial>
  </link>
  <joint name="joint_13" type="revolute">
    <parent link="link_12"/>
    <child link="link_13"/>
    <origin rpy="-3.141592653589793 0 -3.141592653589793" xyz="0 0 0.0331"/>
    <axis xyz="0 0 1"/>
    <limit effort="300" lower="-2.09439510239" upper="2.09439510239" velocity="10"/>
    <dynamics damping="0.5"/>
  </joint>
  <link name="link_14">
    <inertial>
      <origin rpy="0 0 0" xyz="0.0358 0.0043 0.0325"/>
      <mass value="5"/>
      <inertia ixx="0.0508" ixy="0.0834" ixz="-0.0338" iyy="0.089" iyz="-0.0107" izz="0.0757"/>
    </inertial>
  </link>
  <joint name="joint_14" type="revolute">
    <parent link="link_13"/>
    <child link="link_14"/>
    <origin rpy="-1.5707963267948966 -3.141592653589793 3.141592653589793" xyz="0 0 0.0048"/>
    <axis xyz="0 0 1"/>
    <limit effort="300" lower="-2.09439510239" upper="2.09439510239" velocity="10"/>
    <dynamics damping="0.5"/>
  </joint>
  <link name="link_15">
    <inertial>
      <origin rpy="0 0 0" xyz="0.0448 0.0793 0.0194"/>
      <mass value="5"/>
      <inertia ixx="0.0086" ixy="0.0111" ixz="0.0802" iyy="0.099" iyz="-0.0944" izz="-0.0739"/>
    </inertial>
  </link>
  <joint name="joint_15" type="revolute">
    <parent link="link_14"/>
    <child link="link_15"/>
    <origin rpy="1.5707963267948966 0 -3.141592653589793" xyz="0 0 0.0699"/>
    <axis xyz="0 0 1"/>
    <limit effort="300" lower="-2.09439510239" upper="2.09439510239" velocity="10"/>
    <dynamics damping="0.5"/>
  </joint>
  <link name="link_16">
    <inertial>
      <origin rpy="0 0 0" xyz="0.0557 0.0144 0.0525"/>
      <mass value="5"/>
      <inertia ixx="0.0738" ixy="-0.0199" ixz="0.0391" iyy="0.0869" iyz="-0.0398" izz="0.0232"/>
    </inertial>
  </link>
  <joint name="joint_16" type="revolute">
    <parent link="world"/>
    <child link="link_16"/>
    <origin rpy="3.141592653589793 3.141592653589793 3.141592653589793" xyz="0 0 0.0476"/>
    <axis xyz="0 0 1"/>
    <limit effort="300" lower="-2.09439510239" upper="2.09439510239" velocity="10"/>
    <dynamics damping="0.5"/>
  </joint>
  <link name="link_17">
    <inertial>
      <origin rpy="0 0 0" xyz="0.0165 0.045 0.0697"/>
      <mass value="5"/>
      <inertia ixx="0.0508" ixy="-0.0327" ixz="0.0552" iyy="0.0788" iyz="0.084" izz="-0.0271"/>
    </inertial>
  </link>
  <joint name="joint_17" type="revolute">
    <parent link="link_16"/>
    <child link="link_17"/>
    <origin rpy="0 1.5707963267948966 1.5707963267948966" xyz="0 0 0.1126"/>
    <axis xyz="0 0 1"/>
    <limit effort="300" lower="-2.09439510239" upper="2.09439510239" velocity="10"/>
    <dynamics damping="0.5"/>
  </joint>
  <link name="link_18">
    <inertial>
      <origin rpy="0 0 0" xyz="0.0996 0.0533 0.0788"/>
      <mass value="5"/>
      <inertia ixx="0.0571" ixy="-0.0905" ixz="0.0273" iyy="0.0434" iyz="-0.0775" izz="0.014"/>
    </inertial>
  </link>
  <joint name="joint_18" type="revolute">
    <parent link="link_17"/>
    <child link="link_18"/>
    <origin rpy="-1.5707963267948966 -1.5707963267948966 0" xyz="0 0 0.1501"/>
    <axis xyz="0 0 1"/>
    <limit effort="300" lower="-2.09439510239" upper="2.09439510239" velocity="10"/>
    <dynamics damping="0.5"/>
  </joint>
  <link name="link_19">
    <inertial>
      <origin rpy="0 0 0" xyz="0.055 0.0689 0.016"/>
      <mass value="5"/>
      <inertia ixx="0.026" ixy="0.0136" ixz="0.0405" iyy="-0.0888" iyz="0.0762" izz="-0.069"/>
    </inertial>
  </link>
  <joint name="joint_19" type="revolute">
    <parent link="link_18"/>
    <child link="link_19"/>
    <origin rpy="1.5707963267948966 0 -3.141592653589793" xyz="0 0 0.108"/>
    <axis xyz="0 0 1"/>
    <limit effort="300" lower="-2.09439510239" upper="2.09439510239" velocity="10"/>
    <dynamics damping="0.5"/>
  </joint>
  <link name="link_20">
    <inertial>
      <origin rpy="0 0 0" xyz="0.0836 0.0014 0.0173"/>
      <mass value="5"/>
      <inertia ixx="-0.0202" ixy="-0.031" ixz="0.0024" iyy="0.0938" iyz="-0.0768" izz="0.0894"/>
    </inertial>
  </link>
  <joint name="joint_20" type="revolute">
    <parent link="world"/>
    <child link="link_20"/>
    <origin rpy="-1.5707963267948966 -1.5707963267948966 -1.5707963267948966" xyz="0 0 0.1417"/>
    <axis xyz="0 0 1"/>
    <limit effort="300" lower="-2.09439510239" upper="2.09439510239" velocity="10"/>
    <dynamics damping="0.5"/>
  </joint>
  <link name="link_21">
    <inertial>
      <origin rpy="0 0 0" xyz="0.0758 0.0435 0.0767"/>
      <mass value="5"/>
      <inertia ixx="-0.0619" ixy="-0.0531" ixz="0.0848" iyy="0.0579" iyz="0.0458" izz="-0.0292"/>
    </inertial>
  </link>
  <joint name="joint_21" type="revolute">
    <parent link="link_20"/>
    <child link="link_21"/>
    <origin rpy="-3.141592653589793 -3.141592653589793 -1.5707963267948966" xyz="0 0 0.1702"/>
    <axis xyz="0 0 1"/>
    <limit effort="300" lower="-2.09439510239" upper="2.09439510239" velocity="10"/>
    <dynamics damping="0.5"/>
  </joint>
  <link name="link_22">
    <inertial>
      <origin rpy="0 0 0" xyz="0.0221 0.0625 0.0285"/>
      <mass value="5"/>
      <inertia ixx="0.0234" ixy="0.032" ixz="0.0083" iyy="-0.077" iyz="-0.0162" izz="0.0211"/>
    </inertial>
  </link>
  <joint name="joint_22" type="revolute">
    <parent link="link_21"/>
    <child link="link_22"/>
    <origin rpy="3.141592653589793 3.141592653589793 -1.5707963267948966" xyz="0 0 0.1097"/>
    <axis xyz="0 0 1"/>
    <limit effort="300" lower="-2.09439510239" upper="2.09439510239" velocity="10"/>
    <dynamics damping="0.5"/>
  </joint>
  <link name="link_23">
    <inertial>
      <origin rpy="0 0 0" xyz="0.061 0.0696 0.0618"/>
      <mass value="5"/>
      <inertia ixx="-0.0921" ixy="0.0624" ixz="0.0066" iyy="-0.0008" iyz="0.0231" izz="0.0125"/>
    </inertial>
  </link>
  <joint name="joint_23" type="revolute">
    <parent link="link_22"/>
    <child link="link_23"/>
    <origin rpy="1.5707963267948966 -3.141592653589793 -3.141592653589793" xyz="0 0 0.0693"/>
    <axis xyz="0 0 1"/>
    <limit effort="300" lower="-2.09439510239" upper="2.09439510239" velocity="10"/>
    <dynamics damping="0.5"/>
  </joint>
</robot>
