<?xml version="1.0" encoding="utf-8"?>
<robot name="iiwa">
  <link name="world"/>
  <link name="link_1">
    <inertial>
      <origin rpy="0 0 0" xyz="0.0083 0.0987 0.0549"/>
      <mass value="5"/>
      <inertia ixx="0.0659" ixy="-0.062" ixz="-0.0292" iyy="0.0289" iyz="-0.0417" izz="0.0254"/>
    </inertial>
  </link>
  <joint name="joint_1" type="revolute">
    <parent link="world"/>
    <child link="link_1"/>
    <origin rpy="1.5707963267948966 -1.5707963267948966 1.5707963267948966" xyz="0 0 0.0267"/>
    <axis xyz="0 0 1"/>
    <limit effort="300" lower="-2.09439510239" upper="2.09439510239" velocity="10"/>
    <dynamics damping="0.5"/>
  </joint>
  <link name="link_2">
    <inertial>
      <origin rpy="0 0 0" xyz="0.0536 0.0582 0.0844"/>
      <mass value="5"/>
      <inertia ixx="0.0663" ixy="-0.0998" ixz="0.0432" iyy="-0.0807" iyz="-0.057" izz="0.0176"/>
    </inertial>
  </link>
  <joint name="joint_2" type="revolute">
    <parent link="link_1"/>
    <child link="link_2"/>
    <origin rpy="-1.5707963267948966 0 3.141592653589793" xyz="0 0 0.1266"/>
    <axis xyz="0 0 1"/>
    <limit effort="300" lower="-2.09439510239" upper="2.09439510239" velocity="10"/>
    <dynamics damping="0.5"/>
  </joint>
  <link name="link_3">
    <inertial>
      <origin rpy="0 0 0" xyz="0.0912 0.0164 0.029"/>
      <mass value="5"/>
      <inertia ixx="0.0007" ixy="0.0349" ixz="-0.0701" iyy="0.0332" iyz="0.0106" izz="0.0432"/>
    </inertial>
  </link>
  <joint name="joint_3" type="revolute">
    <parent link="link_2"/>
    <child link="link_3"/>
    <origin rpy="-3.141592653589793 3.141592653589793 3.141592653589793" xyz="0 0 0.0409"/>
    <axis xyz="0 0 1"/>
    <limit effort="300" lower="-2.09439510239" upper="2.09439510239" velocity="10"/>
    <dynamics damping="0.5"/>
  </joint>
  <link name="link_4">
    <inertial>
      <origin rpy="0 0 0" xyz="0.0043 0.0115 0.0592"/>
      <mass value="5"/>
      <inertia ixx="0.0249" ixy="0.089" ixz="0.0015" iyy="-0.0504" iyz="-0.0341" izz="0.033"/>
    </inertial>
  </link>
  <joint name="joint_4" type="revolute">
    <parent link="link_3"/>
    <child link="link_4"/>
    <origin rpy="-1.5707963267948966 1.5707963267948966 0" xyz="0 0 0.1447"/>
    <axis xyz="0 0 1"/>
    <limit effort="300" lower="-2.09439510239" upper="2.09439510239" velocity="10"/>
    <dynamics damping="0.5"/>
  </joint>
  <link name="link_5">
    <inertial>
      <origin rpy="0 0 0" xyz="0.0915 0.0307 0.032"/>
      <mass value="5"/>
      <inertia ixx="0.0646" ixy="0.0748" ixz="0.0977" iyy="-0.0182" iyz="-0.0903" izz="0.0985"/>
    </inertial>
  </link>
  <joint name="joint_5" type="revolute">
    <parent link="link_4"/>
    <child link="link_5"/>
    <origin rpy="-3.141592653589793 3.141592653589793 1.5707963267948966" xyz="0 0 0.0119"/>
    <axis xyz="0 0 1"/>
    <limit effort="300" lower="-2.09439510239" upper="2.09439510239" velocity="10"/>
    <dynamics damping="0.5"/>
  </joint>
  <link name="link_6">
    <inertial>
      <origin rpy="0 0 0" xyz="0.0267 0.0118 0.0926"/>
      <mass value="5"/>
      <inertia ixx="-0.0259" ixy="-0.015" ixz="-0.0524" iyy="-0.03" iyz="0.055" izz="0.0926"/>
    </inertial>
  </link>
  <joint name="joint_6" type="revolute">
    <parent link="link_5"/>
    <child link="link_6"/>
    <origin rpy="1.5707963267948966 -3.141592653589793 3.141592653589793" xyz="0 0 0.1494"/>
    <axis xyz="0 0 1"/>
    <limit effort="300" lower="-2.09439510239" upper="2.09439510239" velocity="10"/>
    <dynamics damping="0.5"/>
  </joint>
  <link name="link_7">
    <inertial>
      <origin rpy="0 0 0" xyz="0.0467 0.0991 0.0039"/>
      <mass value="5"/>
      <inertia ixx="-0.0693" ixy="0.0623" ixz="-0.05" iyy="0.0313" iyz="-0.0142" izz="-0.0607"/>
    </inertial>
  </link>
  <joint name="joint_7" type="revolute">
    <parent link="link_6"/>
    <child link="link_7"/>
    <origin rpy="3.141592653589793 1.5707963267948966 3.141592653589793" xyz="0 0 0.123"/>
    <axis xyz="0 0 1"/>
    <limit effort="300" lower="-2.09439510239" upper="2.09439510239" velocity="10"/>
    <dynamics damping="0.5"/>
  </joint>
  <link name="link_8">
    <inertial>
      <origin rpy="0 0 0" xyz="0.0608 0.0888 0.021"/>
      <mass value="5"/>
      <inertia ixx="0.059" ixy="0.0544" ixz="-0.0811" iyy="0.0055" iyz="-0.0033" izz="-0.0075"/>
    </inertial>
  </link>
  <joint name="joint_8" type="revolute">
    <parent link="world"/>
    <child link="link_8"/>
    <origin rpy="3.141592653589793 -3.141592653589793 -3.141592653589793" xyz="0 0 0.0787"/>
    <axis xyz="0 0 1"/>
    <limit effort="300" lower="-2.09439510239" upper="2.09439510239" velocity="10"/>
    <dynamics damping="0.5"/>
  </joint>
  <link name="link_9">
    <inertial>
      <origin rpy="0 0 0" xyz="0.04 0.0969 0.0929"/>
      <mass value="5"/>
      <inertia ixx="0.0444" ixy="0.0089" ixz="-0.0743" iyy="0.0877" iyz="-0.0698" izz="-0.0592"/>
    </inertial>
  </link>
  <joint name="joint_9" type="revolute">
    <parent link="link_8"/>
    <child link="link_9"/>
    <origin rpy="-3.141592653589793 -3.141592653589793 1.5707963267948966" xyz="0 0 0.0947"/>
    <axis xyz="0 0 1"/>
    <limit effort="300" lower="-2.09439510239" upper="2.09439510239" velocity="10"/>
    <dynamics damping="0.5"/>
  </joint>
  <link name="link_10">
    <inertial>
      <origin rpy="0 0 0" xyz="0.0821 0.0791 0.0847"/>
      <mass value="5"/>
      <inertia ixx="0.0366" ixy="-0.0773" ixz="-0.0758" iyy="-0.0869" iyz="-0.0182" izz="0.0009"/>
    </inertial>
  </link>
  <joint name="joint_10" type="revolute">
    <parent link="link_9"/>
    <child link="link_10"/>
    <origin rpy="0 0 3.141592653589793" xyz="0 0 0.0393"/>
    <axis xyz="0 0 1"/>
    <limit effort="300" lower="-2.09439510239" upper="2.09439510239" velocity="10"/>
    <dynamics damping="0.5"/>
  </joint>
  <link name="link_11">
    <inertial>
      <origin rpy="0 0 0" xyz="0.0911 0.0246 0.0052"/>
      <mass value="5"/>
      <inertia ixx="0.0998" ixy="-0.0312" ixz="0.0183" iyy="-0.0366" iyz="0.0472" izz="0.0701"/>
    </inertial>
  </link>
  <joint name="joint_11" type="revolute">
    <parent link="link_10"/>
    <child link="link_11"/>
    <origin rpy="-3.141592653589793 0 0" xyz="0 0 0.1925"/>
    <axis xyz="0 0 1"/>
    <limit effort="300" lower="-2.09439510239" upper="2.09439510239" velocity="10"/>
    <dynamics damping="0.5"/>
  </joint>
  <link name="link_12">
    <inertial>
      <origin rpy="0 0 0" xyz="0.0385 0.0579 0.0288"/>
      <mass value="5"/>
      <inertia ixx="-0.0785" ixy="-0.0443" ixz="-0.0529" iyy="-0.0367" iyz="0.0252" izz="0.0635"/>
    </inertial>
  </link>
  <joint name="joint_12" type="revolute">
    <parent link="link_11"/>
    <child link="link_12"/>
    <origin rpy="3.141592653589793 3.141592653589793 0" xyz="0 0 0.1803"/>
    <axis xyz="0 0 1"/>
    <limit effort="300" lower="-2.09439510239" upper="2.09439510239" velocity="10"/>
    <dynamics damping="0.5"/>
  </joint>
  <link name="link_13">
    <inertial>
      <origin rpy="0 0 0" xyz="0.063 0.0555 0.066"/>
      <mass value="5"/>
      <inertia ixx="-0.0989" ixy="0.0527" ixz="-0.0528" iyy="-0.0439" iyz="-0.0599" izz="-0.0972"/>
    </inertial>
  </link>
  <joint name="joint_13" type="revolute">
    <parent link="link_12"/>
    <child link="link_13"/>
    <origin rpy="0 -1.5707963267948966 -3.141592653589793" xyz="0 0 0.1245"/>
    <axis xyz="0 0 1"/>
    <limit effort="300" lower="-2.09439510239" upper="2.09439510239" velocity="10"/>
    <dynamics damping="0.5"/>
  </joint>
  <link name="link_14">
    <inertial>
      <origin rpy="0 0 0" xyz="0.0845 0.0336 0.0375"/>
      <mass value="5"/>
      <inertia ixx="-0.0557" ixy="0.0939" ixz="-0.0326" iyy="0.068" iyz="0.0735" izz="-0.0153"/>
    </inertial>
  </link>
  <joint name="joint_14" type="revolute">
    <parent link="world"/>
    <child link="link_14"/>
    <origin rpy="-1.5707963267948966 0 1.5707963267948966" xyz="0 0 0.1996"/>
    <axis xyz="0 0 1"/>
    <limit effort="300" lower="-2.09439510239" upper="2.09439510239" velocity="10"/>
    <dynamics damping="0.5"/>
  </joint>
  <link name="link_15">
    <inertial>
      <origin rpy="0 0 0" xyz="0.0002 0.0954 0.0329"/>
      <mass value="5"/>
      <inertia ixx="-0.0448" ixy="0.0881" ixz="-0.0674" iyy="0.0378" iyz="-0.0578" izz="0.0759"/>
    </inertial>
  </link>
  <joint name="joint_15" type="revolute">
    <parent link="link_14"/>
    <child link="link_15"/>
    <origin rpy="1.5707963267948966 3.141592653589793 0" xyz="0 0 0.1602"/>
    <axis xyz="0 0 1"/>
    <limit effort="300" lower="-2.09439510239" upper="2.09439510239" velocity="10"/>
    <dynamics damping="0.5"/>
  </joint>
  <link name="link_16">
    <inertial>
      <origin rpy="0 0 0" xyz="0.0076 0.0927 0.0661"/>
      <mass value="5"/>
      <inertia ixx="-0.0697" ixy="0.0646" ixz="0.0323" iyy="0.0086" iyz="-0.0916" izz="-0.0644"/>
    </inertial>
  </link>
  <joint name="joint_16" type="revolute">
    <parent link="link_15"/>
    <child link="link_16"/>
    <origin rpy="-1.5707963267948966 0 3.141592653589793" xyz="0 0 0.1135"/>
    <axis xyz="0 0 1"/>
    <limit effort="300" lower="-2.09439510239" upper="2.09439510239" velocity="10"/>
    <dynamics damping="0.5"/>
  </joint>
  <link name="link_17">
    <inertial>
      <origin rpy="0 0 0" xyz="0.0395 0.0878 0.0692"/>
      <mass value="5"/>
      <inertia ixx="-0.0949" ixy="-0.0042" ixz="-0.0453" iyy="0.0681" iyz="-0.0346" izz="0.0891"/>
    </inertial>
  </link>
  <joint name="joint_17" type="revolute">
    <parent link="link_16"/>
    <child link="link_17"/>
    <origin rpy="-3.141592653589793 -1.5707963267948966 0" xyz="0 0 0.0042"/>
    <axis xyz="0 0 1"/>
    <limit effort="300" lower="-2.09439510239" upper="2.09439510239" velocity="10"/>
    <dynamics damping="0.5"/>
  </joint>
  <link name="link_18">
    <inertial>
      <origin rpy="0 0 0" xyz="0.0806 0.0967 0.0693"/>
      <mass value="5"/>
      <inertia ixx="-0.0015" ixy="0.0026" ixz="-0.0325" iyy="-0.0125" iyz="-0.0428" izz="0.0859"/>
    </inertial>
  </link>
  <joint name="joint_18" type="revolute">
    <parent link="link_17"/>
    <child link="link_18"/>
    <origin rpy="1.5707963267948966 1.5707963267948966 -1.5707963267948966" xyz="0 0 0.1557"/>
    <axis xyz="0 0 1"/>
    <limit effort="300" lower="-2.09439510239" upper="2.09439510239" velocity="10"/>
    <dynamics damping="0.5"/>
  </joint>
  <link name="link_19">
    <inertial>
      <origin rpy="0 0 0" xyz="0.0882 0.0926 0.0918"/>
      <mass value="5"/>
      <inertia ixx="-0.0401" ixy="-0.0432" ixz="-0.0425" iyy="0.0236" iyz="-0.0625" izz="0.0143"/>
    </inertial>
  </link>
  <joint name="joint_19" type="revolute">
    <parent link="link_18"/>
    <child link="link_19"/>
    <origin rpy="0 -3.141592653589793 3.141592653589793" xyz="0 0 0.0307"/>
    <axis xyz="0 0 1"/>
    <limit effort="300" lower="-2.09439510239" upper="2.09439510239" velocity="10"/>
    <dynamics damping="0.5"/>
  </joint>
  <link name="link_20">
    <inertial>
      <origin rpy="0 0 0" xyz="0.0135 0.0826 0.0917"/>
      <mass value="5"/>
      <inertia ixx="-0.0756" ixy="-0.0172" ixz="-0.0926" iyy="-0.0963" iyz="0.0514" izz="0.0147"/>
    </inertial>
  </link>
  <joint name="joint_20" type="revolute">
    <parent link="world"/>
    <child link="link_20"/>
    <origin rpy="-1.5707963267948966 3.141592653589793 -3.141592653589793" xyz="0 0 0.1569"/>
    <axis xyz="0 0 1"/>
    <limit effort="300" lower="-2.09439510239" upper="2.09439510239" velocity="10"/>
    <dynamics damping="0.5"/>
  </joint>
  <link name="link_21">
    <inertial>
      <origin rpy="0 0 0" xyz="0.0178 0.0186 0.0078"/>
      <mass value="5"/>
      <inertia ixx="-0.0112" ixy="-0.0643" ixz="-0.0901" iyy="-0.0914" iyz="0.0164" izz="0.0605"/>
    </inertial>
  </link>
  <joint name="joint_21" type="revolute">
    <parent link="link_20"/>
    <child link="link_21"/>
    <origin rpy="3.141592653589793 3.141592653589793 -3.141592653589793" xyz="0 0 0.041"/>
    <axis xyz="0 0 1"/>
    <limit effort="300" lower="-2.09439510239" upper="2.09439510239" velocity="10"/>
    <dynamics damping="0.5"/>
  </joint>
  <link name="link_22">
    <inertial>
      <origin rpy="0 0 0" xyz="0.0099 0.0985 0.0261"/>
      <mass value="5"/>
      <inertia ixx="-0.0725" ixy="0.0884" ixz="-0.0458" iyy="-0.0805" iyz="-0.0341" izz="0.0973"/>
    </inertial>
  </link>
  <joint name="joint_22" type="revolute">
    <parent link="link_21"/>
    <child link="link_22"/>
    <origin rpy="-1.5707963267948966 1.5707963267948966 1.5707963267948966" xyz="0 0 0.1682"/>
    <axis xyz="0 0 1"/>
    <limit effort="300" lower="-2.09439510239" upper="2.09439510239" velocity="10"/>
    <dynamics damping="0.5"/>
  </joint>
  <link name="link_23">
    <inertial>
      <origin rpy="0 0 0" xyz="0.0923 0.0623 0.0148"/>
      <mass value="5"/>
      <inertia ixx="-0.0194" ixy="0.0549" ixz="0.0353" iyy="0.0591" iyz="0.0208" izz="-0.0541"/>
    </inertial>
  </link>
  <joint name="joint_23" type="revolute">
    <parent link="link_22"/>
    <child link="link_23"/>
    <origin rpy="1.5707963267948966 -3.141592653589793 1.5707963267948966" xyz="0 0 0.0507"/>
    <axis xyz="0 0 1"/>
    <limit effort="300" lower="-2.09439510239" upper="2.09439510239" velocity="10"/>
    <dynamics damping="0.5"/>
  </joint>
  <link name="link_24">
    <inertial>
      <origin rpy="0 0 0" xyz="0.087 0.0749 0.0676"/>
      <mass value="5"/>
      <inertia ixx="0.078" ixy="0.0743" ixz="0.0766" iyy="-0.0551" iyz="-0.0305" izz="0.0417"/>
    </inertial>
  </link>
  <joint name="joint_24" type="revolute">
    <parent link="link_23"/>
    <child link="link_24"/>
    <origin rpy="-1.5707963267948966 -3.141592653589793 1.5707963267948966" xyz="0 0 0.1485"/>
    <axis xyz="0 0 1"/>
    <limit effort="300" lower="-2.09439510239" upper="2.09439510239" velocity="10"/>
    <dynamics damping="0.5"/>
  </joint>
  <link name="link_25">
    <inertial>
      <origin rpy="0 0 0" xyz="0.0987 0.071 0.0062"/>
      <mass value="5"/>
      <inertia ixx="0.0657" ixy="0.0959" ixz="-0.0034" iyy="-0.0074" iyz="-0.0036" izz="-0.0458"/>
    </inertial>
  </link>
  <joint name="joint_25" type="revolute">
    <parent link="link_24"/>
    <child link="link_25"/>
    <origin rpy="3.141592653589793 3.141592653589793 3.141592653589793" xyz="0 0 0.0667"/>
    <axis xyz="0 0 1"/>
    <limit effort="300" lower="-2.09439510239" upper="2.09439510239" velocity="10"/>
    <dynamics damping="0.5"/>
  </joint>
  <link name="link_26">
    <inertial>
      <origin rpy="0 0 0" xyz="0.0488 0.0789 0.0223"/>
      <mass value="5"/>
      <inertia ixx="-0.0719" ixy="0.025" ixz="-0.098" iyy="-0.0617" iyz="0.092" izz="-0.0829"/>
    </inertial>
  </link>
  <joint name="joint_26" type="revolute">
    <parent link="world"/>
    <child link="link_26"/>
    <origin rpy="3.141592653589793 0 1.5707963267948966" xyz="0 0 0.1455"/>
    <axis xyz="0 0 1"/>
    <limit effort="300" lower="-2.09439510239" upper="2.09439510239" velocity="10"/>
    <dynamics damping="0.5"/>
  </joint>
  <link name="link_27">
    <inertial>
      <origin rpy="0 0 0" xyz="0.0013 0.061 0.0827"/>
      <mass value="5"/>
      <inertia ixx="0.0401" ixy="0.0992" ixz="0.0329" iyy="-0.0469" iyz="-0.0291" izz="0.0245"/>
    </inertial>
  </link>
  <joint name="joint_27" type="revolute">
    <parent link="link_26"/>
    <child link="link_27"/>
    <origin rpy="-1.5707963267948966 3.141592653589793 0" xyz="0 0 0.0247"/>
    <axis xyz="0 0 1"/>
    <limit effort="300" lower="-2.09439510239" upper="2.09439510239" velocity="10"/>
    <dynamics damping="0.5"/>
  </joint>
  <link name="link_28">
    <inertial>
      <origin rpy="0 0 0" xyz="0.0381 0.0488 0.0054"/>
      <mass value="5"/>
      <inertia ixx="-0.0524" ixy="-0.09" ixz="0.0944" iyy="-0.0518" iyz="-0.0899" izz="0.0826"/>
    </inertial>
  </link>
  <joint name="joint_28" type="revolute">
    <parent link="link_27"/>
    <child link="link_28"/>
    <origin rpy="0 0 1.5707963267948966" xyz="0 0 0.1782"/>
    <axis xyz="0 0 1"/>
    <limit effort="300" lower="-2.09439510239" upper="2.09439510239" velocity="10"/>
    <dynamics damping="0.5"/>
  </joint>
  <link name="link_29">
    <inertial>
      <origin rpy="0 0 0" xyz="0.0566 0.0869 0.0443"/>
      <mass value="5"/>
      <inertia ixx="0.0273" ixy="-0.0562" ixz="0.0338" iyy="-0.0701" iyz="-0.0308" izz="0.0155"/>
    </inertial>
  </link>
  <joint name="joint_29" type="revolute">
    <parent link="link_28"/>
    <child link="link_29"/>
    <origin rpy="-3.141592653589793 0 -3.141592653589793" xyz="0 0 0.0666"/>
    <axis xyz="0 0 1"/>
    <limit effort="300" lower="-2.09439510239" upper="2.09439510239" velocity="10"/>
    <dynamics damping="0.5"/>
  </joint>
  <link name="link_30">
    <inertial>
      <origin rpy="0 0 0" xyz="0.0078 0.0323 0.0397"/>
      <mass value="5"/>
      <inertia ixx="-0.0771" ixy="-0.0537" ixz="0.0759" iyy="0.0466" iyz="-0.0757" izz="-0.0983"/>
    </inertial>
  </link>
  <joint name="joint_30" type="revolute">
    <parent link="link_29"/>
    <child link="link_30"/>
    <origin rpy="-3.141592653589793 3.141592653589793 3.141592653589793" xyz="0 0 0.1843"/>
    <axis xyz="0 0 1"/>
    <limit effort="300" lower="-2.09439510239" upper="2.09439510239" velocity="10"/>
    <dynamics damping="0.5"/>
  </joint>
  <link name="link_31">
    <inertial>
      <origin rpy="0 0 0" xyz="0.04 0.0463 0.059"/>
      <mass value="5"/>
      <inertia ixx="0.0472" ixy="0.028" ixz="0.0339" iyy="-0.0069" iyz="0.0207" izz="0.0155"/>
    </inertial>
  </link>
  <joint name="joint_31" type="revolute">
    <parent link="link_30"/>
    <child link="link_31"/>
    <origin rpy="-3.141592653589793 3.141592653589793 -1.5707963267948966" xyz="0 0 0.1344"/>
    <axis xyz="0 0 1"/>
    <limit effort="300" lower="-2.09439510239" upper="2.09439510239" velocity="10"/>
    <dynamics damping="0.5"/>
  </joint>
</robot>
