<?xml version="1.0" encoding="utf-8"?>
<robot name="iiwa">
  <link name="world"/>
  <link name="link_1">
    <inertial>
      <origin rpy="0 0 0" xyz="0.0148 0.0293 0.0574"/>
      <mass value="5"/>
      <inertia ixx="0.0464" ixy="0.0311" ixz="0.0639" iyy="0.019" iyz="-0.0825" izz="-0.0941"/>
    </inertial>
  </link>
  <joint name="joint_1" type="revolute">
    <parent link="world"/>
    <child link="link_1"/>
    <origin rpy="3.141592653589793 -3.141592653589793 0" xyz="0 0 0.1098"/>
    <axis xyz="0 0 1"/>
    <limit effort="300" lower="-2.09439510239" upper="2.09439510239" velocity="10"/>
    <dynamics damping="0.5"/>
  </joint>
  <link name="link_2">
    <inertial>
      <origin rpy="0 0 0" xyz="0.0038 0.0153 0.0353"/>
      <mass value="5"/>
      <inertia ixx="-0.0601" ixy="0.0513" ixz="0.0571" iyy="-0.0017" iyz="0.0896" izz="0.0527"/>
    </inertial>
  </link>
  <joint name="joint_2" type="revolute">
    <parent link="link_1"/>
    <child link="link_2"/>
    <origin rpy="3.141592653589793 0 0" xyz="0 0 0.1047"/>
    <axis xyz="0 0 1"/>
    <limit effort="300" lower="-2.09439510239" upper="2.09439510239" velocity="10"/>
    <dynamics damping="0.5"/>
  </joint>
  <link name="link_3">
    <inertial>
      <origin rpy="0 0 0" xyz="0.0696 0.0325 0.0208"/>
      <mass value="5"/>
      <inertia ixx="0.0229" ixy="-0.001" ixz="0.0116" iyy="0.0382" iyz="0.0651" izz="-0.0917"/>
    </inertial>
  </link>
  <joint name="joint_3" type="revolute">
    <parent link="link_2"/>
    <child link="link_3"/>
    <origin rpy="1.5707963267948966 3.141592653589793 3.141592653589793" xyz="0 0 0.1284"/>
    <axis xyz="0 0 1"/>
    <limit effort="300" lower="-2.09439510239" upper="2.09439510239" velocity="10"/>
    <dynamics damping="0.5"/>
  </joint>
  <link name="link_4">
    <inertial>
      <origin rpy="0 0 0" xyz="0.0472 0.0084 0.0454"/>
      <mass value="5"/>
      <inertia ixx="-0.0469" ixy="-0.0136" ixz="0.0798" iyy="0.0384" iyz="0.0572" izz="0.0342"/>
    </inertial>
  </link>
  <joint name="joint_4" type="revolute">
    <parent link="link_3"/>
    <child link="link_4"/>
    <origin rpy="-3.141592653589793 -3.141592653589793 0" xyz="0 0 0.1695"/>
    <axis xyz="0 0 1"/>
    <limit effort="300" lower="-2.09439510239" upper="2.09439510239" velocity="10"/>
    <dynamics damping="0.5"/>
  </joint>
  <link name="link_5">
    <inertial>
      <origin rpy="0 0 0" xyz="0.0349 0.0914 0.0209"/>
      <mass value="5"/>
      <inertia ixx="0.0945" ixy="-0.0812" ixz="0.0495" iyy="0.0031" iyz="0.0717" izz="-0.0872"/>
    </inertial>
  </link>
  <joint name="joint_5" type="revolute">
    <parent link="link_4"/>
    <child link="link_5"/>
    <origin rpy="0 -3.141592653589793 0" xyz="0 0 0.1602"/>
    <axis xyz="0 0 1"/>
    <limit effort="300" lower="-2.09439510239" upper="2.09439510239" velocity="10"/>
    <dynamics damping="0.5"/>
  </joint>
  <link name="link_6">
    <inertial>
      <origin rpy="0 0 0" xyz="0.0892 0.0829 0.0931"/>
      <mass value="5"/>
      <inertia ixx="0.079" ixy="-0.0098" ixz="0.0217" iyy="0.0702" iyz="0.0619" izz="-0.0535"/>
    </inertial>
  </link>
  <joint name="joint_6" type="revolute">
    <parent link="link_5"/>
    <child link="link_6"/>
    <origin rpy="0 -1.5707963267948966 1.5707963267948966" xyz="0 0 0.0178"/>
    <axis xyz="0 0 1"/>
    <limit effort="300" lower="-2.09439510239" upper="2.09439510239" velocity="10"/>
    <dynamics damping="0.5"/>
  </joint>
  <link name="link_7">
    <inertial>
      <origin rpy="0 0 0" xyz="0.0262 0.0051 0.0991"/>
      <mass value="5"/>
      <inertia ixx="-0.0233" ixy="-0.0245" ixz="0.0503" iyy="-0.0547" iyz="-0.0166" izz="-0.0073"/>
    </inertial>
  </link>
  <joint name="joint_7" type="revolute">
    <parent link="link_6"/>
    <child link="link_7"/>
    <origin rpy="3.141592653589793 -3.141592653589793 -1.5707963267948966" xyz="0 0 0.0467"/>
    <axis xyz="0 0 1"/>
    <limit effort="300" lower="-2.09439510239" upper="2.09439510239" velocity="10"/>
    <dynamics damping="0.5"/>
  </joint>
  <link name="link_8">
    <inertial>
      <origin rpy="0 0 0" xyz="0.0041 0.0724 0.0039"/>
      <mass value="5"/>
      <inertia ixx="-0.0906" ixy="0.0897" ixz="-0.0216" iyy="-0.0121" iyz="0.0397" izz="-0.0758"/>
    </inertial>
  </link>
  <joint name="joint_8" type="revolute">
    <parent link="world"/>
    <child link="link_8"/>
    <origin rpy="-3.141592653589793 0 -3.141592653589793" xyz="0 0 0.1596"/>
    <axis xyz="0 0 1"/>
    <limit effort="300" lower="-2.09439510239" upper="2.09439510239" velocity="10"/>
    <dynamics damping="0.5"/>
  </joint>
  <link name="link_9">
    <inertial>
      <origin rpy="0 0 0" xyz="0.0777 0.0578 0.0948"/>
      <mass value="5"/>
      <inertia ixx="-0.0477" ixy="-0.0923" ixz="-0.078" iyy="-0.0029" iyz="-0.0011" izz="-0.0069"/>
    </inertial>
  </link>
  <joint name="joint_9" type="revolute">
    <parent link="link_8"/>
    <child link="link_9"/>
    <origin rpy="3.141592653589793 -3.141592653589793 -3.141592653589793" xyz="0 0 0.0574"/>
    <axis xyz="0 0 1"/>
    <limit effort="300" lower="-2.09439510239" upper="2.09439510239" velocity="10"/>
    <dynamics damping="0.5"/>
  </joint>
  <link name="link_10">
    <inertial>
      <origin rpy="0 0 0" xyz="0.0018 0.0062 0.0599"/>
      <mass value="5"/>
      <inertia ixx="0.0485" ixy="0.0885" ixz="-0.0505" iyy="-0.0631" iyz="0.0129" izz="-0.0647"/>
    </inertial>
  </link>
  <joint name="joint_10" type="revolute">
    <parent link="link_9"/>
    <child link="link_10"/>
    <origin rpy="-1.5707963267948966 0 1.5707963267948966" xyz="0 0 0.1449"/>
    <axis xyz="0 0 1"/>
    <limit effort="300" lower="-2.09439510239" upper="2.09439510239" velocity="10"/>
    <dynamics damping="0.5"/>
  </joint>
  <link name="link_11">
    <inertial>
      <origin rpy="0 0 0" xyz="0.0508 0.0027 0.0985"/>
      <mass value="5"/>
      <inertia ixx="-0.0363" ixy="0.0273" ixz="-0.0416" iyy="-0.0559" iyz="0.049" izz="-0.0335"/>
    </inertial>
  </link>
  <joint name="joint_11" type="revolute">
    <parent link="link_10"/>
    <child link="link_11"/>
    <origin rpy="-1.5707963267948966 3.141592653589793 -1.5707963267948966" xyz="0 0 0.1661"/>
    <axis xyz="0 0 1"/>
    <limit effort="300" lower="-2.09439510239" upper="2.09439510239" velocity="10"/>
    <dynamics damping="0.5"/>
  </joint>
  <link name="link_12">
    <inertial>
      <origin rpy="0 0 0" xyz="0.0024 0.0254 0.0025"/>
      <mass value="5"/>
      <inertia ixx="0.0856" ixy="-0.0937" ixz="-0.0469" iyy="0.0739" iyz="-0.0068" izz="-0.0543"/>
    </inertial>
  </link>
  <joint name="joint_12" type="revolute">
    <parent link="link_11"/>
    <child link="link_12"/>
    <origin rpy="1.5707963267948966 0 1.5707963267948966" xyz="0 0 0.1811"/>
    <axis xyz="0 0 1"/>
    <limit effort="300" lower="-2.09439510239" upper="2.09439510239" velocity="10"/>
    <dynamics damping="0.5"/>
  </joint>
  <link name="link_13">
    <inertial>
      <origin rpy="0 0 0" xyz="0.0224 0.0304 0.0645"/>
      <mass value="5"/>
      <inertia ixx="-0.0033" ixy="-0.0127" ixz="0.0562" iyy="0.0219" iyz="0.0204" izz="-0.0042"/>
    </inertial>
  </link>
  <joint name="joint_13" type="revolute">
    <parent link="link_12"/>
    <child link="link_13"/>
    <origin rpy="3.141592653589793 3.141592653589793 -3.141592653589793" xyz="0 0 0.0069"/>
    <axis xyz="0 0 1"/>
    <limit effort="300" lower="-2.09439510239" upper="2.09439510239" velocity="10"/>
    <dynamics damping="0.5"/>
  </joint>
  <link name="link_14">
    <inertial>
      <origin rpy="0 0 0" xyz="0.0973 0.0754 0.0312"/>
      <mass value="5"/>
      <inertia ixx="-0.0024" ixy="0.0589" ixz="0.001" iyy="-0.0197" iyz="-0.0311" izz="0.0484"/>
    </inertial>
  </link>
  <joint name="joint_14" type="revolute">
    <parent link="link_13"/>
    <child link="link_14"/>
    <origin rpy="0 -1.5707963267948966 -1.5707963267948966" xyz="0 0 0.0552"/>
    <axis xyz="0 0 1"/>
    <limit effort="300" lower="-2.09439510239" upper="2.09439510239" velocity="10"/>
    <dynamics damping="0.5"/>
  </joint>
  <link name="link_15">
    <inertial>
      <origin rpy="0 0 0" xyz="0.0064 0.0037 0.092"/>
      <mass value="5"/>
      <inertia ixx="-0.0629" ixy="-0.0538" ixz="-0.0491" iyy="-0.0413" iyz="-0.0342" izz="-0.0563"/>
    </inertial>
  </link>
  <joint name="joint_15" type="revolute">
    <parent link="link_14"/>
    <child link="link_15"/>
    <origin rpy="3.141592653589793 3.141592653589793 3.141592653589793" xyz="0 0 0.1925"/>
    <axis xyz="0 0 1"/>
    <limit effort="300" lower="-2.09439510239" upper="2.09439510239" velocity="10"/>
    <dynamics damping="0.5"/>
  </joint>
  <link name="link_16">
    <inertial>
      <origin rpy="0 0 0" xyz="0.0694 0.0691 0.0189"/>
      <mass value="5"/>
      <inertia ixx="0.0586" ixy="-0.0492" ixz="-0.0802" iyy="-0.0717" iyz="0.064" izz="-0.0787"/>
    </inertial>
  </link>
  <joint name="joint_16" type="revolute">
    <parent link="world"/>
    <child link="link_16"/>
    <origin rpy="1.5707963267948966 1.5707963267948966 1.5707963267948966" xyz="0 0 0.0496"/>
    <axis xyz="0 0 1"/>
    <limit effort="300" lower="-2.09439510239" upper="2.09439510239" velocity="10"/>
    <dynamics damping="0.5"/>
  </joint>
  <link name="link_17">
    <inertial>
      <origin rpy="0 0 0" xyz="0.0078 0.0208 0.0258"/>
      <mass value="5"/>
      <inertia ixx="0.0683" ixy="-0.0933" ixz="0.0738" iyy="0.0086" iyz="-0.0464" izz="0.0599"/>
    </inertial>
  </link>
  <joint name="joint_17" type="revolute">
    <parent link="link_16"/>
    <child link="link_17"/>
    <origin rpy="-3.141592653589793 -1.5707963267948966 1.5707963267948966" xyz="0 0 0.1293"/>
    <axis xyz="0 0 1"/>
    <limit effort="300" lower="-2.09439510239" upper="2.09439510239" velocity="10"/>
    <dynamics damping="0.5"/>
  </joint>
  <link name="link_18">
    <inertial>
      <origin rpy="0 0 0" xyz="0.0643 0.0019 0.0114"/>
      <mass value="5"/>
      <inertia ixx="0.0276" ixy="-0.0337" ixz="-0.0264" iyy="-0.0071" iyz="0.047" izz="-0.0811"/>
    </inertial>
  </link>
  <joint name="joint_18" type="revolute">
    <parent link="link_17"/>
    <child link="link_18"/>
    <origin rpy="1.5707963267948966 -1.5707963267948966 1.5707963267948966" xyz="0 0 0.1954"/>
    <axis xyz="0 0 1"/>
    <limit effort="300" lower="-2.09439510239" upper="2.09439510239" velocity="10"/>
    <dynamics damping="0.5"/>
  </joint>
  <link name="link_19">
    <inertial>
      <origin rpy="0 0 0" xyz="0.0037 0.0168 0.041"/>
      <mass value="5"/>
      <inertia ixx="-0.0202" ixy="-0.0497" ixz="-0.0257" iyy="0.0501" iyz="0.0619" izz="0.0007"/>
    </inertial>
  </link>
  <joint name="joint_19" type="revolute">
    <parent link="link_18"/>
    <child link="link_19"/>
    <origin rpy="3.141592653589793 1.5707963267948966 0" xyz="0 0 0.1481"/>
    <axis xyz="0 0 1"/>
    <limit effort="300" lower="-2.09439510239" upper="2.09439510239" velocity="10"/>
    <dynamics damping="0.5"/>
  </joint>
  <link name="link_20">
    <inertial>
      <origin rpy="0 0 0" xyz="0.0909 0.0352 0.0808"/>
      <mass value="5"/>
      <inertia ixx="0.0212" ixy="-0.0003" ixz="0.0267" iyy="0.0047" iyz="0.0457" izz="-0.0947"/>
    </inertial>
  </link>
  <joint name="joint_20" type="revolute">
    <parent link="link_19"/>
    <child link="link_20"/>
    <origin rpy="1.5707963267948966 1.5707963267948966 -1.5707963267948966" xyz="0 0 0.0168"/>
    <axis xyz="0 0 1"/>
    <limit effort="300" lower="-2.09439510239" upper="2.09439510239" velocity="10"/>
    <dynamics damping="0.5"/>
  </joint>
  <link name="link_21">
    <inertial>
      <origin rpy="0 0 0" xyz="0.0189 0.0319 0.0391"/>
      <mass value="5"/>
      <inertia ixx="-0.0956" ixy="0.0944" ixz="0.091" iyy="-0.0099" iyz="0.0452" izz="0.0895"/>
    </inertial>
  </link>
  <joint name="joint_21" type="revolute">
    <parent link="link_20"/>
    <child link="link_21"/>
    <origin rpy="1.5707963267948966 -3.141592653589793 1.5707963267948966" xyz="0 0 0.1224"/>
    <axis xyz="0 0 1"/>
    <limit effort="300" lower="-2.09439510239" upper="2.09439510239" velocity="10"/>
    <dynamics damping="0.5"/>
  </joint>
  <link name="link_22">
    <inertial>
      <origin rpy="0 0 0" xyz="0.007 0.058 0.0087"/>
      <mass value="5"/>
      <inertia ixx="0.0305" ixy="0.0119" ixz="-0.0808" iyy="0.0102" iyz="-0.0992" izz="0.0912"/>
    </inertial>
  </link>
  <joint name="joint_22" type="revolute">
    <parent link="link_21"/>
    <child link="link_22"/>
    <origin rpy="1.5707963267948966 0 -1.5707963267948966" xyz="0 0 0.0438"/>
    <axis xyz="0 0 1"/>
    <limit effort="300" lower="-2.09439510239" upper="2.09439510239" velocity="10"/>
    <dynamics damping="0.5"/>
  </joint>
  <link name="link_23">
    <inertial>
      <origin rpy="0 0 0" xyz="0.0113 0.0774 0.0281"/>
      <mass value="5"/>
      <inertia ixx="0.053" ixy="-0.0788" ixz="0.0573" iyy="0.0206" iyz="0.0793" izz="0.0936"/>
    </inertial>
  </link>
  <joint name="joint_23" type="revolute">
    <parent link="link_22"/>
    <child link="link_23"/>
    <origin rpy="-1.5707963267948966 0 3.141592653589793" xyz="0 0 0.1616"/>
    <axis xyz="0 0 1"/>
    <limit effort="300" lower="-2.09439510239" upper="2.09439510239" velocity="10"/>
    <dynamics damping="0.5"/>
  </joint>
  <link name="link_24">
    <inertial>
      <origin rpy="0 0 0" xyz="0.0766 0.0344 0.0084"/>
      <mass value="5"/>
      <inertia ixx="0.0976" ixy="0.019" ixz="0.0007" iyy="0.0667" iyz="0.0851" izz="0.0024"/>
    </inertial>
  </link>
  <joint name="joint_24" type="revolute">
    <parent link="world"/>
    <child link="link_24"/>
    <origin rpy="0 1.5707963267948966 1.5707963267948966" xyz="0 0 0.1652"/>
    <axis xyz="0 0 1"/>
    <limit effort="300" lower="-2.09439510239" upper="2.09439510239" velocity="10"/>
    <dynamics damping="0.5"/>
  </joint>
  <link name="link_25">
    <inertial>
      <origin rpy="0 0 0" xyz="0.0811 0.0881 0.0558"/>
      <mass value="5"/>
      <inertia ixx="0.0843" ixy="0.0487" ixz="-0.078" iyy="0.0736" iyz="-0.0609" izz="-0.0451"/>
    </inertial>
  </link>
  <joint name="joint_25" type="revolute">
    <parent link="link_24"/>
    <child link="link_25"/>
    <origin rpy="-1.5707963267948966 3.141592653589793 0" xyz="0 0 0.1195"/>
    <axis xyz="0 0 1"/>
    <limit effort="300" lower="-2.09439510239" upper="2.09439510239" velocity="10"/>
    <dynamics damping="0.5"/>
  </joint>
  <link name="link_26">
    <inertial>
      <origin rpy="0 0 0" xyz="0.0655 0.0845 0.0694"/>
      <mass value="5"/>
      <inertia ixx="0.0331" ixy="-0.0674" ixz="0.0261" iyy="-0.0157" iyz="0.0893" izz="-0.028"/>
    </inertial>
  </link>
  <joint name="joint_26" type="revolute">
    <parent link="link_25"/>
    <child link="link_26"/>
    <origin rpy="3.141592653589793 3.141592653589793 1.5707963267948966" xyz="0 0 0.1642"/>
    <axis xyz="0 0 1"/>
    <limit effort="300" lower="-2.09439510239" upper="2.09439510239" velocity="10"/>
    <dynamics damping="0.5"/>
  </joint>
  <link name="link_27">
    <inertial>
      <origin rpy="0 0 0" xyz="0.086 0.0655 0.0018"/>
      <mass value="5"/>
      <inertia ixx="0.0964" ixy="-0.0085" ixz="-0.07" iyy="-0.0432" iyz="-0.0791" izz="-0.0364"/>
    </inertial>
  </link>
  <joint name="joint_27" type="revolute">
    <parent link="link_26"/>
    <child link="link_27"/>
    <origin rpy="-1.5707963267948966 0 -1.5707963267948966" xyz="0 0 0.1563"/>
    <axis xyz="0 0 1"/>
    <limit effort="300" lower="-2.09439510239" upper="2.09439510239" velocity="10"/>
    <dynamics damping="0.5"/>
  </joint>
  <link name="link_28">
    <inertial>
      <origin rpy="0 0 0" xyz="0.0685 0.0287 0.0963"/>
      <mass value="5"/>
      <inertia ixx="0.0092" ixy="-0.0667" ixz="0.0584" iyy="0.0107" iyz="0.0567" izz="-0.0275"/>
    </inertial>
  </link>
  <joint name="joint_28" type="revolute">
    <parent link="link_27"/>
    <child link="link_28"/>
    <origin rpy="1.5707963267948966 1.5707963267948966 0" xyz="0 0 0.1753"/>
    <axis xyz="0 0 1"/>
    <limit effort="300" lower="-2.09439510239" upper="2.09439510239" velocity="10"/>
    <dynamics damping="0.5"/>
  </joint>
  <link name="link_29">
    <inertial>
      <origin rpy="0 0 0" xyz="0.0003 0.0924 0.0115"/>
      <mass value="5"/>
      <inertia ixx="0.0899" ixy="-0.0732" ixz="0.01" iyy="0.0928" iyz="0.0574" izz="0.0695"/>
    </inertial>
  </link>
  <joint name="joint_29" type="revolute">
    <parent link="link_28"/>
    <child link="link_29"/>
    <origin rpy="-1.5707963267948966 3.141592653589793 -3.141592653589793" xyz="0 0 0.167"/>
    <axis xyz="0 0 1"/>
    <limit effort="300" lower="-2.09439510239" upper="2.09439510239" velocity="10"/>
    <dynamics damping="0.5"/>
  </joint>
  <link name="link_30">
    <inertial>
      <origin rpy="0 0 0" xyz="0.0434 0.0889 0.0096"/>
      <mass value="5"/>
      <inertia ixx="-0.0324" ixy="-0.022" ixz="-0.0786" iyy="0.0185" iyz="-0.0317" izz="0.0528"/>
    </inertial>
  </link>
  <joint name="joint_30" type="revolute">
    <parent link="link_29"/>
    <child link="link_30"/>
    <origin rpy="-1.5707963267948966 -1.5707963267948966 3.141592653589793" xyz="0 0 0.1351"/>
    <axis xyz="0 0 1"/>
    <limit effort="300" lower="-2.09439510239" upper="2.09439510239" velocity="10"/>
    <dynamics damping="0.5"/>
  </joint>
  <link name="link_31">
    <inertial>
      <origin rpy="0 0 0" xyz="0.085 0.0752 0.0458"/>
      <mass value="5"/>
      <inertia ixx="-0.0689" ixy="0.0462" ixz="0.0174" iyy="-0.0735" iyz="-0.079" izz="-0.0495"/>
    </inertial>
  </link>
  <joint name="joint_31" type="revolute">
    <parent link="link_30"/>
    <child link="link_31"/>
    <origin rpy="1.5707963267948966 0 0" xyz="0 0 0.1624"/>
    <axis xyz="0 0 1"/>
    <limit effort="300" lower="-2.09439510239" upper="2.09439510239" velocity="10"/>
    <dynamics damping="0.5"/>
  </joint>
  <link name="link_32">
    <inertial>
      <origin rpy="0 0 0" xyz="0.0712 0.0747 0.012"/>
      <mass value="5"/>
      <inertia ixx="0.0934" ixy="-0.0222" ixz="0.0669" iyy="0.0182" iyz="-0.0694" izz="-0.0406"/>
    </inertial>
  </link>
  <joint name="joint_32" type="revolute">
    <parent link="world"/>
    <child link="link_32"/>
    <origin rpy="1.5707963267948966 1.5707963267948966 -1.5707963267948966" xyz="0 0 0.0204"/>
    <axis xyz="0 0 1"/>
    <limit effort="300" lower="-2.09439510239" upper="2.09439510239" velocity="10"/>
    <dynamics damping="0.5"/>
  </joint>
  <link name="link_33">
    <inertial>
      <origin rpy="0 0 0" xyz="0.0836 0.0197 0.0742"/>
      <mass value="5"/>
      <inertia ixx="-0.0338" ixy="-0.0335" ixz="-0.0872" iyy="-0.0421" iyz="-0.0986" izz="0.0169"/>
    </inertial>
  </link>
  <joint name="joint_33" type="revolute">
    <parent link="link_32"/>
    <child link="link_33"/>
    <origin rpy="3.141592653589793 -1.5707963267948966 0" xyz="0 0 0.1641"/>
    <axis xyz="0 0 1"/>
    <limit effort="300" lower="-2.09439510239" upper="2.09439510239" velocity="10"/>
    <dynamics damping="0.5"/>
  </joint>
  <link name="link_34">
    <inertial>
      <origin rpy="0 0 0" xyz="0.0952 0.0704 0.085"/>
      <mass value="5"/>
      <inertia ixx="-0.0141" ixy="-0.0087" ixz="-0.0293" iyy="0.0284" iyz="0.0795" izz="-0.0679"/>
    </inertial>
  </link>
  <joint name="joint_34" type="revolute">
    <parent link="link_33"/>
    <child link="link_34"/>
    <origin rpy="-3.141592653589793 3.141592653589793 0" xyz="0 0 0.1346"/>
    <axis xyz="0 0 1"/>
    <limit effort="300" lower="-2.09439510239" upper="2.09439510239" velocity="10"/>
    <dynamics damping="0.5"/>
  </joint>
  <link name="link_35">
    <inertial>
      <origin rpy="0 0 0" xyz="0.0919 0.0644 0.0279"/>
      <mass value="5"/>
      <inertia ixx="0.0853" ixy="-0.0746" ixz="0.0115" iyy="-0.0705" iyz="0.0219" izz="0.0364"/>
    </inertial>
  </link>
  <joint name="joint_35" type="revolute">
    <parent link="link_34"/>
    <child link="link_35"/>
    <origin rpy="1.5707963267948966 -1.5707963267948966 -3.141592653589793" xyz="0 0 0.1212"/>
    <axis xyz="0 0 1"/>
    <limit effort="300" lower="-2.09439510239" upper="2.09439510239" velocity="10"/>
    <dynamics damping="0.5"/>
  </joint>
  <link name="link_36">
    <inertial>
      <origin rpy="0 0 0" xyz="0.0834 0.0804 0.0119"/>
      <mass value="5"/>
      <inertia ixx="-0.097" ixy="-0.0857" ixz="-0.0032" iyy="-0.0144" iyz="-0.0506" izz="-0.0531"/>
    </inertial>
  </link>
  <joint name="joint_36" type="revolute">
    <parent link="link_35"/>
    <child link="link_36"/>
    <origin rpy="0 -3.141592653589793 1.5707963267948966" xyz="0 0 0.0672"/>
    <axis xyz="0 0 1"/>
    <limit effort="300" lower="-2.09439510239" upper="2.09439510239" velocity="10"/>
    <dynamics damping="0.5"/>
  </joint>
  <link name="link_37">
    <inertial>
      <origin rpy="0 0 0" xyz="0.0243 0.0976 0.0811"/>
      <mass value="5"/>
      <inertia ixx="-0.0014" ixy="0.0471" ixz="-0.0498" iyy="-0.0438" iyz="0.0468" izz="0.0158"/>
    </inertial>
  </link>
  <joint name="joint_37" type="revolute">
    <parent link="link_36"/>
    <child link="link_37"/>
    <origin rpy="1.5707963267948966 -3.141592653589793 0" xyz="0 0 0.0412"/>
    <axis xyz="0 0 1"/>
    <limit effort="300" lower="-2.09439510239" upper="2.09439510239" velocity="10"/>
    <dynamics damping="0.5"/>
  </joint>
  <link name="link_38">
    <inertial>
      <origin rpy="0 0 0" xyz="0.0206 0.088 0.0704"/>
      <mass value="5"/>
      <inertia ixx="-0.0508" ixy="0.0576" ixz="-0.0029" iyy="0.0908" iyz="-0.0736" izz="-0.0297"/>
    </inertial>
  </link>
  <joint name="joint_38" type="revolute">
    <parent link="link_37"/>
    <child link="link_38"/>
    <origin rpy="-1.5707963267948966 1.5707963267948966 -1.5707963267948966" xyz="0 0 0.1321"/>
    <axis xyz="0 0 1"/>
    <limit effort="300" lower="-2.09439510239" upper="2.09439510239" velocity="10"/>
    <dynamics damping="0.5"/>
  </joint>
  <link name="link_39">
    <inertial>
      <origin rpy="0 0 0" xyz="0.0185 0.0323 0.0228"/>
      <mass value="5"/>
      <inertia ixx="0.0919" ixy="0.0726" ixz="0.0712" iyy="0.0747" iyz="-0.0473" izz="-0.0163"/>
    </inertial>
  </link>
  <joint name="joint_39" type="revolute">
    <parent link="link_38"/>
    <child link="link_39"/>
    <origin rpy="1.5707963267948966 1.5707963267948966 0" xyz="0 0 0.1111"/>
    <axis xyz="0 0 1"/>
    <limit effort="300" lower="-2.09439510239" upper="2.09439510239" velocity="10"/>
    <dynamics damping="0.5"/>
  </joint>
</robot>
