<?xml version="1.0" encoding="utf-8"?>
<robot name="iiwa">
  <link name="world"/>
  <link name="link_1">
    <inertial>
      <origin rpy="0 0 0" xyz="0.056 0.0678 0.0447"/>
      <mass value="5"/>
      <inertia ixx="0.0858" ixy="-0.0295" ixz="0.0761" iyy="-0.0297" iyz="-0.0249" izz="0.0029"/>
    </inertial>
  </link>
  <joint name="joint_1" type="revolute">
    <parent link="world"/>
    <child link="link_1"/>
    <origin rpy="-3.141592653589793 0 3.141592653589793" xyz="0 0 0.0585"/>
    <axis xyz="0 0 1"/>
    <limit effort="300" lower="-2.09439510239" upper="2.09439510239" velocity="10"/>
    <dynamics damping="0.5"/>
  </joint>
  <link name="link_2">
    <inertial>
      <origin rpy="0 0 0" xyz="0.0348 0.0386 0.0322"/>
      <mass value="5"/>
      <inertia ixx="0.0027" ixy="-0.0223" ixz="-0.0406" iyy="0.0795" iyz="0.0753" izz="0.0877"/>
    </inertial>
  </link>
  <joint name="joint_2" type="revolute">
    <parent link="link_1"/>
    <child link="link_2"/>
    <origin rpy="-3.141592653589793 0 1.5707963267948966" xyz="0 0 0.1961"/>
    <axis xyz="0 0 1"/>
    <limit effort="300" lower="-2.09439510239" upper="2.09439510239" velocity="10"/>
    <dynamics damping="0.5"/>
  </joint>
  <link name="link_3">
    <inertial>
      <origin rpy="0 0 0" xyz="0.021 0.0526 0.0419"/>
      <mass value="5"/>
      <inertia ixx="-0.0391" ixy="0.0117" ixz="0.0137" iyy="0.0447" iyz="0.0495" izz="-0.0648"/>
    </inertial>
  </link>
  <joint name="joint_3" type="revolute">
    <parent link="link_2"/>
    <child link="link_3"/>
    <origin rpy="3.141592653589793 3.141592653589793 3.141592653589793" xyz="0 0 0.1911"/>
    <axis xyz="0 0 1"/>
    <limit effort="300" lower="-2.09439510239" upper="2.09439510239" velocity="10"/>
    <dynamics damping="0.5"/>
  </joint>
  <link name="link_4">
    <inertial>
      <origin rpy="0 0 0" xyz="0.0343 0.0226 0.0622"/>
      <mass value="5"/>
      <inertia ixx="-0.0324" ixy="-0.0428" ixz="-0.0849" iyy="-0.0343" iyz="-0.0582" izz="0.0392"/>
    </inertial>
  </link>
  <joint name="joint_4" type="revolute">
    <parent link="link_3"/>
    <child link="link_4"/>
    <origin rpy="-1.5707963267948966 0 -3.141592653589793" xyz="0 0 0.0331"/>
    <axis xyz="0 0 1"/>
    <limit effort="300" lower="-2.09439510239" upper="2.09439510239" velocity="10"/>
    <dynamics damping="0.5"/>
  </joint>
  <link name="link_5">
    <inertial>
      <origin rpy="0 0 0" xyz="0.0016 0.0797 0.0539"/>
      <mass value="5"/>
      <inertia ixx="0.0654" ixy="-0.0095" ixz="-0.0582" iyy="-0.0239" iyz="0.067" izz="0.0563"/>
    </inertial>
  </link>
  <joint name="joint_5" type="revolute">
    <parent link="link_4"/>
    <child link="link_5"/>
    <origin rpy="1.5707963267948966 -1.5707963267948966 1.5707963267948966" xyz="0 0 0.0146"/>
    <axis xyz="0 0 1"/>
    <limit effort="300" lower="-2.09439510239" upper="2.09439510239" velocity="10"/>
    <dynamics damping="0.5"/>
  </joint>
  <link name="link_6">
    <inertial>
      <origin rpy="0 0 0" xyz="0.0748 0.097 0.0898"/>
      <mass value="5"/>
      <inertia ixx="0.0717" ixy="0.089" ixz="0.0288" iyy="0.0838" iyz="0.042" izz="-0.01"/>
    </inertial>
  </link>
  <joint name="joint_6" type="revolute">
    <parent link="link_5"/>
    <child link="link_6"/>
    <origin rpy="1.5707963267948966 -3.141592653589793 1.5707963267948966" xyz="0 0 0.0382"/>
    <axis xyz="0 0 1"/>
    <limit effort="300" lower="-2.09439510239" upper="2.09439510239" velocity="10"/>
    <dynamics damping="0.5"/>
  </joint>
  <link name="link_7">
    <inertial>
      <origin rpy="0 0 0" xyz="0.0673 0.08 0.0846"/>
      <mass value="5"/>
      <inertia ixx="-0.0391" ixy="0.034" ixz="-0.069" iyy="0.0998" iyz="0.0556" izz="0.0201"/>
    </inertial>
  </link>
  <joint name="joint_7" type="revolute">
    <parent link="link_6"/>
    <child link="link_7"/>
    <origin rpy="0 1.5707963267948966 0" xyz="0 0 0.1631"/>
    <axis xyz="0 0 1"/>
    <limit effort="300" lower="-2.09439510239" upper="2.09439510239" velocity="10"/>
    <dynamics damping="0.5"/>
  </joint>
  <link name="link_8">
    <inertial>
      <origin rpy="0 0 0" xyz="0.0831 0.0731 0.0017"/>
      <mass value="5"/>
      <inertia ixx="-0.0059" ixy="0.0719" ixz="0.0084" iyy="-0.0558" iyz="-0.0661" izz="0.0341"/>
    </inertial>
  </link>
  <joint name="joint_8" type="revolute">
    <parent link="world"/>
    <child link="link_8"/>
    <origin rpy="-3.141592653589793 0 1.5707963267948966" xyz="0 0 0.0797"/>
    <axis xyz="0 0 1"/>
    <limit effort="300" lower="-2.09439510239" upper="2.09439510239" velocity="10"/>
    <dynamics damping="0.5"/>
  </joint>
  <link name="link_9">
    <inertial>
      <origin rpy="0 0 0" xyz="0.0039 0.0942 0.0523"/>
      <mass value="5"/>
      <inertia ixx="0.0025" ixy="-0.019" ixz="-0.0376" iyy="-0.095" iyz="-0.0415" izz="0.0208"/>
    </inertial>
  </link>
  <joint name="joint_9" type="revolute">
    <parent link="world"/>
    <child link="link_9"/>
    <origin rpy="3.141592653589793 -3.141592653589793 3.141592653589793" xyz="0 0 0.121"/>
    <axis xyz="0 0 1"/>
    <limit effort="300" lower="-2.09439510239" upper="2.09439510239" velocity="10"/>
    <dynamics damping="0.5"/>
  </joint>
  <link name="link_10">
    <inertial>
      <origin rpy="0 0 0" xyz="0.0514 0.0464 0.0803"/>
      <mass value="5"/>
      <inertia ixx="0.0973" ixy="0.0198" ixz="0.0487" iyy="0.0837" iyz="0.0641" izz="-0.0422"/>
    </inertial>
  </link>
  <joint name="joint_10" type="revolute">
    <parent link="world"/>
    <child link="link_10"/>
    <origin rpy="-1.5707963267948966 0 0" xyz="0 0 0.1815"/>
    <axis xyz="0 0 1"/>
    <limit effort="300" lower="-2.09439510239" upper="2.09439510239" velocity="10"/>
    <dynamics damping="0.5"/>
  </joint>
  <link name="link_11">
    <inertial>
      <origin rpy="0 0 0" xyz="0.0672 0.0613 0.048"/>
      <mass value="5"/>
      <inertia ixx="-0.061" ixy="0.0112" ixz="-0.0204" iyy="0.0454" iyz="0.0726" izz="0.0505"/>
    </inertial>
  </link>
  <joint name="joint_11" type="revolute">
    <parent link="world"/>
    <child link="link_11"/>
    <origin rpy="1.5707963267948966 3.141592653589793 1.5707963267948966" xyz="0 0 0.1396"/>
    <axis xyz="0 0 1"/>
    <limit effort="300" lower="-2.09439510239" upper="2.09439510239" velocity="10"/>
    <dynamics damping="0.5"/>
  </joint>
</robot>
