<?xml version="1.0" encoding="utf-8"?>
<robot name="iiwa">
  <link name="world"/>
  <link name="link_1">
    <inertial>
      <origin rpy="0 0 0" xyz="0.0097 0.0463 0.0545"/>
      <mass value="5"/>
      <inertia ixx="-0.0955" ixy="-0.0012" ixz="-0.0194" iyy="0.0741" iyz="0.0619" izz="-0.0499"/>
    </inertial>
  </link>
  <joint name="joint_1" type="revolute">
    <parent link="world"/>
    <child link="link_1"/>
    <origin rpy="0 -1.5707963267948966 3.141592653589793" xyz="0 0 0.0879"/>
    <axis xyz="0 0 1"/>
    <limit effort="300" lower="-2.09439510239" upper="2.09439510239" velocity="10"/>
    <dynamics damping="0.5"/>
  </joint>
  <link name="link_2">
    <inertial>
      <origin rpy="0 0 0" xyz="0.0718 0.0206 0.0741"/>
      <mass value="5"/>
      <inertia ixx="0.0485" ixy="-0.0565" ixz="-0.0347" iyy="-0.071" iyz="0.0319" izz="-0.0891"/>
    </inertial>
  </link>
  <joint name="joint_2" type="revolute">
    <parent link="link_1"/>
    <child link="link_2"/>
    <origin rpy="3.141592653589793 -1.5707963267948966 -1.5707963267948966" xyz="0 0 0.1102"/>
    <axis xyz="0 0 1"/>
    <limit effort="300" lower="-2.09439510239" upper="2.09439510239" velocity="10"/>
    <dynamics damping="0.5"/>
  </joint>
  <link name="link_3">
    <inertial>
      <origin rpy="0 0 0" xyz="0.0676 0.033 0.097"/>
      <mass value="5"/>
      <inertia ixx="0.0548" ixy="-0.0236" ixz="-0.0293" iyy="0.0281" iyz="-0.0519" izz="0.0231"/>
    </inertial>
  </link>
  <joint name="joint_3" type="revolute">
    <parent link="link_2"/>
    <child link="link_3"/>
    <origin rpy="-1.5707963267948966 1.5707963267948966 1.5707963267948966" xyz="0 0 0.0105"/>
    <axis xyz="0 0 1"/>
    <limit effort="300" lower="-2.09439510239" upper="2.09439510239" velocity="10"/>
    <dynamics damping="0.5"/>
  </joint>
  <link name="link_4">
    <inertial>
      <origin rpy="0 0 0" xyz="0.0186 0.0702 0.0992"/>
      <mass value="5"/>
      <inertia ixx="0.0761" ixy="-0.0473" ixz="-0.0943" iyy="-0.0266" iyz="0.0921" izz="-0.0664"/>
    </inertial>
  </link>
  <joint name="joint_4" type="revolute">
    <parent link="link_3"/>
    <child link="link_4"/>
    <origin rpy="3.141592653589793 3.141592653589793 -3.141592653589793" xyz="0 0 0.1987"/>
    <axis xyz="0 0 1"/>
    <limit effort="300" lower="-2.09439510239" upper="2.09439510239" velocity="10"/>
    <dynamics damping="0.5"/>
  </joint>
  <link name="link_5">
    <inertial>
      <origin rpy="0 0 0" xyz="0.01 0.0887 0.0996"/>
      <mass value="5"/>
      <inertia ixx="-0.0469" ixy="0.015" ixz="-0.0081" iyy="0.0217" iyz="0.0136" izz="0.0103"/>
    </inertial>
  </link>
  <joint name="joint_5" type="revolute">
    <parent link="link_4"/>
    <child link="link_5"/>
    <origin rpy="1.5707963267948966 -3.141592653589793 0" xyz="0 0 0.008"/>
    <axis xyz="0 0 1"/>
    <limit effort="300" lower="-2.09439510239" upper="2.09439510239" velocity="10"/>
    <dynamics damping="0.5"/>
  </joint>
  <link name="link_6">
    <inertial>
      <origin rpy="0 0 0" xyz="0.0264 0.0962 0.0744"/>
      <mass value="5"/>
      <inertia ixx="0.0372" ixy="-0.0533" ixz="0.0068" iyy="-0.0836" iyz="-0.0492" izz="-0.0605"/>
    </inertial>
  </link>
  <joint name="joint_6" type="revolute">
    <parent link="link_5"/>
    <child link="link_6"/>
    <origin rpy="-3.141592653589793 -3.141592653589793 3.141592653589793" xyz="0 0 0.1827"/>
    <axis xyz="0 0 1"/>
    <limit effort="300" lower="-2.09439510239" upper="2.09439510239" velocity="10"/>
    <dynamics damping="0.5"/>
  </joint>
  <link name="link_7">
    <inertial>
      <origin rpy="0 0 0" xyz="0.0581 0.0446 0.0584"/>
      <mass value="5"/>
      <inertia ixx="-0.0147" ixy="-0.0544" ixz="0.0747" iyy="-0.0215" iyz="0.0872" izz="-0.0616"/>
    </inertial>
  </link>
  <joint name="joint_7" type="revolute">
    <parent link="link_6"/>
    <child link="link_7"/>
    <origin rpy="1.5707963267948966 0 0" xyz="0 0 0.0154"/>
    <axis xyz="0 0 1"/>
    <limit effort="300" lower="-2.09439510239" upper="2.09439510239" velocity="10"/>
    <dynamics damping="0.5"/>
  </joint>
  <link name="link_8">
    <inertial>
      <origin rpy="0 0 0" xyz="0.0076 0.0874 0.0729"/>
      <mass value="5"/>
      <inertia ixx="0.0314" ixy="-0.0364" ixz="-0.0678" iyy="0.0758" iyz="-0.0619" izz="-0.0156"/>
    </inertial>
  </link>
  <joint name="joint_8" type="revolute">
    <parent link="world"/>
    <child link="link_8"/>
    <origin rpy="0 -3.141592653589793 3.141592653589793" xyz="0 0 0.1576"/>
    <axis xyz="0 0 1"/>
    <limit effort="300" lower="-2.09439510239" upper="2.09439510239" velocity="10"/>
    <dynamics damping="0.5"/>
  </joint>
  <link name="link_9">
    <inertial>
      <origin rpy="0 0 0" xyz="0.0676 0.045 0.0616"/>
      <mass value="5"/>
      <inertia ixx="0.0225" ixy="-0.0862" ixz="-0.0731" iyy="0.0707" iyz="-0.0579" izz="-0.0179"/>
    </inertial>
  </link>
  <joint name="joint_9" type="revolute">
    <parent link="link_8"/>
    <child link="link_9"/>
    <origin rpy="0 -1.5707963267948966 -3.141592653589793" xyz="0 0 0.0629"/>
    <axis xyz="0 0 1"/>
    <limit effort="300" lower="-2.09439510239" upper="2.09439510239" velocity="10"/>
    <dynamics damping="0.5"/>
  </joint>
  <link name="link_10">
    <inertial>
      <origin rpy="0 0 0" xyz="0.008 0.0873 0.0908"/>
      <mass value="5"/>
      <inertia ixx="-0.0258" ixy="-0.0098" ixz="0.0266" iyy="0.0294" iyz="-0.0187" izz="0.0195"/>
    </inertial>
  </link>
  <joint name="joint_10" type="revolute">
    <parent link="link_9"/>
    <child link="link_10"/>
    <origin rpy="-3.141592653589793 0 3.141592653589793" xyz="0 0 0.1875"/>
    <axis xyz="0 0 1"/>
    <limit effort="300" lower="-2.09439510239" upper="2.09439510239" velocity="10"/>
    <dynamics damping="0.5"/>
  </joint>
  <link name="link_11">
    <inertial>
      <origin rpy="0 0 0" xyz="0.0981 0.0741 0.0903"/>
      <mass value="5"/>
      <inertia ixx="0.084" ixy="-0.0196" ixz="-0.0285" iyy="0.0467" iyz="0.0056" izz="0.0414"/>
    </inertial>
  </link>
  <joint name="joint_11" type="revolute">
    <parent link="world"/>
    <child link="link_11"/>
    <origin rpy="-3.141592653589793 -3.141592653589793 1.5707963267948966" xyz="0 0 0.1932"/>
    <axis xyz="0 0 1"/>
    <limit effort="300" lower="-2.09439510239" upper="2.09439510239" velocity="10"/>
    <dynamics damping="0.5"/>
  </joint>
  <link name="link_12">
    <inertial>
      <origin rpy="0 0 0" xyz="0.0787 0.0723 0.0101"/>
      <mass value="5"/>
      <inertia ixx="0.0385" ixy="-0.042" ixz="-0.0468" iyy="0.0561" iyz="0.0874" izz="-0.0625"/>
    </inertial>
  </link>
  <joint name="joint_12" type="revolute">
    <parent link="link_11"/>
    <child link="link_12"/>
    <origin rpy="3.141592653589793 -1.5707963267948966 -3.141592653589793" xyz="0 0 0.1698"/>
    <axis xyz="0 0 1"/>
    <limit effort="300" lower="-2.09439510239" upper="2.09439510239" velocity="10"/>
    <dynamics damping="0.5"/>
  </joint>
  <link name="link_13">
    <inertial>
      <origin rpy="0 0 0" xyz="0.0821 0.0884 0.0841"/>
      <mass value="5"/>
      <inertia ixx="0.0646" ixy="-0.0411" ixz="0.0169" iyy="-0.0094" iyz="-0.0022" izz="0.0344"/>
    </inertial>
  </link>
  <joint name="joint_13" type="revolute">
    <parent link="link_12"/>
    <child link="link_13"/>
    <origin rpy="3.141592653589793 -3.141592653589793 0" xyz="0 0 0.1125"/>
    <axis xyz="0 0 1"/>
    <limit effort="300" lower="-2.09439510239" upper="2.09439510239" velocity="10"/>
    <dynamics damping="0.5"/>
  </joint>
  <link name="link_14">
    <inertial>
      <origin rpy="0 0 0" xyz="0.0902 0.042 0.0924"/>
      <mass value="5"/>
      <inertia ixx="-0.0235" ixy="0.0862" ixz="0.0342" iyy="-0.0828" iyz="0.0511" izz="-0.0945"/>
    </inertial>
  </link>
  <joint name="joint_14" type="revolute">
    <parent link="world"/>
    <child link="link_14"/>
    <origin rpy="0 3.141592653589793 0" xyz="0 0 0.1146"/>
    <axis xyz="0 0 1"/>
    <limit effort="300" lower="-2.09439510239" upper="2.09439510239" velocity="10"/>
    <dynamics damping="0.5"/>
  </joint>
  <link name="link_15">
    <inertial>
      <origin rpy="0 0 0" xyz="0.0215 0.0796 0.0469"/>
      <mass value="5"/>
      <inertia ixx="0.0543" ixy="-0.0586" ixz="0.0654" iyy="0.051" iyz="-0.0867" izz="0.0087"/>
    </inertial>
  </link>
  <joint name="joint_15" type="revolute">
    <parent link="link_14"/>
    <child link="link_15"/>
    <origin rpy="-3.141592653589793 0 3.141592653589793" xyz="0 0 0.1747"/>
    <axis xyz="0 0 1"/>
    <limit effort="300" lower="-2.09439510239" upper="2.09439510239" velocity="10"/>
    <dynamics damping="0.5"/>
  </joint>
  <link name="link_16">
    <inertial>
      <origin rpy="0 0 0" xyz="0.0027 0.0716 0.0225"/>
      <mass value="5"/>
      <inertia ixx="0.0381" ixy="0.0509" ixz="0.0659" iyy="-0.0303" iyz="-0.0576" izz="0.0995"/>
    </inertial>
  </link>
  <joint name="joint_16" type="revolute">
    <parent link="link_15"/>
    <child link="link_16"/>
    <origin rpy="1.5707963267948966 3.141592653589793 1.5707963267948966" xyz="0 0 0.1471"/>
    <axis xyz="0 0 1"/>
    <limit effort="300" lower="-2.09439510239" upper="2.09439510239" velocity="10"/>
    <dynamics damping="0.5"/>
  </joint>
  <link name="link_17">
    <inertial>
      <origin rpy="0 0 0" xyz="0.065 0.0041 0.0274"/>
      <mass value="5"/>
      <inertia ixx="-0.0344" ixy="-0.0815" ixz="-0.0729" iyy="-0.06" iyz="0.0333" izz="-0.0778"/>
    </inertial>
  </link>
  <joint name="joint_17" type="revolute">
    <parent link="world"/>
    <child link="link_17"/>
    <origin rpy="-3.141592653589793 1.5707963267948966 1.5707963267948966" xyz="0 0 0.0087"/>
    <axis xyz="0 0 1"/>
    <limit effort="300" lower="-2.09439510239" upper="2.09439510239" velocity="10"/>
    <dynamics damping="0.5"/>
  </joint>
  <link name="link_18">
    <inertial>
      <origin rpy="0 0 0" xyz="0.0725 0.0461 0.0968"/>
      <mass value="5"/>
      <inertia ixx="0.0038" ixy="-0.0551" ixz="0.0145" iyy="0.0967" iyz="-0.0532" izz="-0.0372"/>
    </inertial>
  </link>
  <joint name="joint_18" type="revolute">
    <parent link="link_17"/>
    <child link="link_18"/>
    <origin rpy="-1.5707963267948966 3.141592653589793 -1.5707963267948966" xyz="0 0 0.077"/>
    <axis xyz="0 0 1"/>
    <limit effort="300" lower="-2.09439510239" upper="2.09439510239" velocity="10"/>
    <dynamics damping="0.5"/>
  </joint>
  <link name="link_19">
    <inertial>
      <origin rpy="0 0 0" xyz="0.0595 0.0842 0.0472"/>
      <mass value="5"/>
      <inertia ixx="-0.0751" ixy="-0.0642" ixz="0.0207" iyy="0.0669" iyz="-0.0256" izz="-0.0659"/>
    </inertial>
  </link>
  <joint name="joint_19" type="revolute">
    <parent link="link_18"/>
    <child link="link_19"/>
    <origin rpy="-1.5707963267948966 0 3.141592653589793" xyz="0 0 0.0623"/>
    <axis xyz="0 0 1"/>
    <limit effort="300" lower="-2.09439510239" upper="2.09439510239" velocity="10"/>
    <dynamics damping="0.5"/>
  </joint>
</robot>
