<?xml version="1.0" encoding="utf-8"?>
<robot name="iiwa">
  <link name="world"/>
  <link name="link_1">
    <inertial>
      <origin rpy="0 0 0" xyz="0.0522 0.0595 0.0619"/>
      <mass value="5"/>
      <inertia ixx="0.0212" ixy="-0.0704" ixz="0.0302" iyy="-0.0023" iyz="-0.0679" izz="0.0992"/>
    </inertial>
  </link>
  <joint name="joint_1" type="revolute">
    <parent link="world"/>
    <child link="link_1"/>
    <origin rpy="1.5707963267948966 3.141592653589793 3.141592653589793" xyz="0 0 0.0439"/>
    <axis xyz="0 0 1"/>
    <limit effort="300" lower="-2.09439510239" upper="2.09439510239" velocity="10"/>
    <dynamics damping="0.5"/>
  </joint>
  <link name="link_2">
    <inertial>
      <origin rpy="0 0 0" xyz="0.0869 0.0917 0.0552"/>
      <mass value="5"/>
      <inertia ixx="0.0085" ixy="-0.08" ixz="-0.0427" iyy="-0.017" iyz="-0.0436" izz="0.0357"/>
    </inertial>
  </link>
  <joint name="joint_2" type="revolute">
    <parent link="link_1"/>
    <child link="link_2"/>
    <origin rpy="-3.141592653589793 0 -1.5707963267948966" xyz="0 0 0.0754"/>
    <axis xyz="0 0 1"/>
    <limit effort="300" lower="-2.09439510239" upper="2.09439510239" velocity="10"/>
    <dynamics damping="0.5"/>
  </joint>
  <link name="link_3">
    <inertial>
      <origin rpy="0 0 0" xyz="0.0194 0.0892 0.0341"/>
      <mass value="5"/>
      <inertia ixx="-0.0328" ixy="-0.0694" ixz="0.0573" iyy="0.0118" iyz="-0.0829" izz="-0.0929"/>
    </inertial>
  </link>
  <joint name="joint_3" type="revolute">
    <parent link="link_2"/>
    <child link="link_3"/>
    <origin rpy="-1.5707963267948966 -1.5707963267948966 -1.5707963267948966" xyz="0 0 0.0439"/>
    <axis xyz="0 0 1"/>
    <limit effort="300" lower="-2.09439510239" upper="2.09439510239" velocity="10"/>
    <dynamics damping="0.5"/>
  </joint>
  <link name="link_4">
    <inertial>
      <origin rpy="0 0 0" xyz="0.0982 0.0807 0.0371"/>
      <mass value="5"/>
      <inertia ixx="-0.0019" ixy="0.0678" ixz="-0.0318" iyy="0.0137" iyz="0.089" izz="-0.0909"/>
    </inertial>
  </link>
  <joint name="joint_4" type="revolute">
    <parent link="link_3"/>
    <child link="link_4"/>
    <origin rpy="1.5707963267948966 3.141592653589793 1.5707963267948966" xyz="0 0 0.1477"/>
    <axis xyz="0 0 1"/>
    <limit effort="300" lower="-2.09439510239" upper="2.09439510239" velocity="10"/>
    <dynamics damping="0.5"/>
  </joint>
  <link name="link_5">
    <inertial>
      <origin rpy="0 0 0" xyz="0.0596 0.0501 0.0239"/>
      <mass value="5"/>
      <inertia ixx="0.0446" ixy="0.078" ixz="-0.0603" iyy="-0.0842" iyz="0.0547" izz="-0.0342"/>
    </inertial>
  </link>
  <joint name="joint_5" type="revolute">
    <parent link="link_4"/>
    <child link="link_5"/>
    <origin rpy="3.141592653589793 1.5707963267948966 -1.5707963267948966" xyz="0 0 0.033"/>
    <axis xyz="0 0 1"/>
    <limit effort="300" lower="-2.09439510239" upper="2.09439510239" velocity="10"/>
    <dynamics damping="0.5"/>
  </joint>
  <link name="link_6">
    <inertial>
      <origin rpy="0 0 0" xyz="0.0327 0.0826 0.0516"/>
      <mass value="5"/>
      <inertia ixx="-0.07" ixy="0.0683" ixz="0.0601" iyy="-0.0667" iyz="0.0059" izz="-0.0554"/>
    </inertial>
  </link>
  <joint name="joint_6" type="revolute">
    <parent link="link_5"/>
    <child link="link_6"/>
    <origin rpy="3.141592653589793 0 0" xyz="0 0 0.0545"/>
    <axis xyz="0 0 1"/>
    <limit effort="300" lower="-2.09439510239" upper="2.09439510239" velocity="10"/>
    <dynamics damping="0.5"/>
  </joint>
  <link name="link_7">
    <inertial>
      <origin rpy="0 0 0" xyz="0.0159 0.0431 0.0097"/>
      <mass value="5"/>
      <inertia ixx="-0.0706" ixy="0.0677" ixz="-0.0847" iyy="0.0923" iyz="-0.0598" izz="-0.0983"/>
    </inertial>
  </link>
  <joint name="joint_7" type="revolute">
    <parent link="link_6"/>
    <child link="link_7"/>
    <origin rpy="-3.141592653589793 -3.141592653589793 1.5707963267948966" xyz="0 0 0.022"/>
    <axis xyz="0 0 1"/>
    <limit effort="300" lower="-2.09439510239" upper="2.09439510239" velocity="10"/>
    <dynamics damping="0.5"/>
  </joint>
  <link name="link_8">
    <inertial>
      <origin rpy="0 0 0" xyz="0.0456 0.0777 0.0281"/>
      <mass value="5"/>
      <inertia ixx="0.057" ixy="-0.0336" ixz="0.0708" iyy="-0.0084" iyz="0.0623" izz="-0.0457"/>
    </inertial>
  </link>
  <joint name="joint_8" type="revolute">
    <parent link="world"/>
    <child link="link_8"/>
    <origin rpy="-1.5707963267948966 0 -1.5707963267948966" xyz="0 0 0.1046"/>
    <axis xyz="0 0 1"/>
    <limit effort="300" lower="-2.09439510239" upper="2.09439510239" velocity="10"/>
    <dynamics damping="0.5"/>
  </joint>
  <link name="link_9">
    <inertial>
      <origin rpy="0 0 0" xyz="0.0165 0.0324 0.0922"/>
      <mass value="5"/>
      <inertia ixx="0.0642" ixy="0.0249" ixz="-0.0581" iyy="-0.0449" iyz="0.0268" izz="0.0161"/>
    </inertial>
  </link>
  <joint name="joint_9" type="revolute">
    <parent link="link_8"/>
    <child link="link_9"/>
    <origin rpy="-1.5707963267948966 -3.141592653589793 1.5707963267948966" xyz="0 0 0.0157"/>
    <axis xyz="0 0 1"/>
    <limit effort="300" lower="-2.09439510239" upper="2.09439510239" velocity="10"/>
    <dynamics damping="0.5"/>
  </joint>
  <link name="link_10">
    <inertial>
      <origin rpy="0 0 0" xyz="0.0652 0.0859 0.0049"/>
      <mass value="5"/>
      <inertia ixx="-0.0829" ixy="0.0434" ixz="0.0126" iyy="0.0233" iyz="0.0387" izz="-0.0643"/>
    </inertial>
  </link>
  <joint name="joint_10" type="revolute">
    <parent link="world"/>
    <child link="link_10"/>
    <origin rpy="1.5707963267948966 -3.141592653589793 1.5707963267948966" xyz="0 0 0.0692"/>
    <axis xyz="0 0 1"/>
    <limit effort="300" lower="-2.09439510239" upper="2.09439510239" velocity="10"/>
    <dynamics damping="0.5"/>
  </joint>
  <link name="link_11">
    <inertial>
      <origin rpy="0 0 0" xyz="0.0115 0.0568 0.0231"/>
      <mass value="5"/>
      <inertia ixx="0.0729" ixy="0.0288" ixz="0.0543" iyy="-0.0602" iyz="0.0929" izz="0.0583"/>
    </inertial>
  </link>
  <joint name="joint_11" type="revolute">
    <parent link="link_10"/>
    <child link="link_11"/>
    <origin rpy="-3.141592653589793 0 1.5707963267948966" xyz="0 0 0.0172"/>
    <axis xyz="0 0 1"/>
    <limit effort="300" lower="-2.09439510239" upper="2.09439510239" velocity="10"/>
    <dynamics damping="0.5"/>
  </joint>
  <link name="link_12">
    <inertial>
      <origin rpy="0 0 0" xyz="0.0028 0.0092 0.0092"/>
      <mass value="5"/>
      <inertia ixx="0.0099" ixy="-0.06" ixz="-0.0077" iyy="-0.0343" iyz="-0.0802" izz="0.0968"/>
    </inertial>
  </link>
  <joint name="joint_12" type="revolute">
    <parent link="world"/>
    <child link="link_12"/>
    <origin rpy="0 -3.141592653589793 -1.5707963267948966" xyz="0 0 0.1193"/>
    <axis xyz="0 0 1"/>
    <limit effort="300" lower="-2.09439510239" upper="2.09439510239" velocity="10"/>
    <dynamics damping="0.5"/>
  </joint>
  <link name="link_13">
    <inertial>
      <origin rpy="0 0 0" xyz="0.0628 0.0229 0.0844"/>
      <mass value="5"/>
      <inertia ixx="-0.0094" ixy="0.0784" ixz="-0.0811" iyy="-0.0661" iyz="0.0414" izz="0.0393"/>
    </inertial>
  </link>
  <joint name="joint_13" type="revolute">
    <parent link="link_12"/>
    <child link="link_13"/>
    <origin rpy="1.5707963267948966 3.141592653589793 1.5707963267948966" xyz="0 0 0.0344"/>
    <axis xyz="0 0 1"/>
    <limit effort="300" lower="-2.09439510239" upper="2.09439510239" velocity="10"/>
    <dynamics damping="0.5"/>
  </joint>
  <link name="link_14">
    <inertial>
      <origin rpy="0 0 0" xyz="0.0524 0.0943 0.0283"/>
      <mass value="5"/>
      <inertia ixx="-0.0175" ixy="-0.0871" ixz="0.0342" iyy="-0.0156" iyz="-0.0649" izz="0.0749"/>
    </inertial>
  </link>
  <joint name="joint_14" type="revolute">
    <parent link="world"/>
    <child link="link_14"/>
    <origin rpy="1.5707963267948966 0 0" xyz="0 0 0.0341"/>
    <axis xyz="0 0 1"/>
    <limit effort="300" lower="-2.09439510239" upper="2.09439510239" velocity="10"/>
    <dynamics damping="0.5"/>
  </joint>
  <link name="link_15">
    <inertial>
      <origin rpy="0 0 0" xyz="0.0554 0.0492 0.099"/>
      <mass value="5"/>
      <inertia ixx="0.0351" ixy="0.0878" ixz="-0.0872" iyy="0.0219" iyz="-0.0475" izz="0.0676"/>
    </inertial>
  </link>
  <joint name="joint_15" type="revolute">
    <parent link="link_14"/>
    <child link="link_15"/>
    <origin rpy="-1.5707963267948966 -3.141592653589793 0" xyz="0 0 0.1652"/>
    <axis xyz="0 0 1"/>
    <limit effort="300" lower="-2.09439510239" upper="2.09439510239" velocity="10"/>
    <dynamics damping="0.5"/>
  </joint>
</robot>
