<?xml version="1.0" encoding="utf-8"?>
<robot name="iiwa">
  <link name="world"/>
  <link name="link_1">
    <inertial>
      <origin rpy="0 0 0" xyz="0.0556 0.0551 0.0271"/>
      <mass value="5"/>
      <inertia ixx="-0.0528" ixy="0.0414" ixz="0.0215" iyy="-0.0277" iyz="0.0922" izz="0.0049"/>
    </inertial>
  </link>
  <joint name="joint_1" type="revolute">
    <parent link="world"/>
    <child link="link_1"/>
    <origin rpy="3.141592653589793 1.5707963267948966 0" xyz="0 0 0.0578"/>
    <axis xyz="0 0 1"/>
    <limit effort="300" lower="-2.09439510239" upper="2.09439510239" velocity="10"/>
    <dynamics damping="0.5"/>
  </joint>
  <link name="link_2">
    <inertial>
      <origin rpy="0 0 0" xyz="0.0639 0.0801 0.059"/>
      <mass value="5"/>
      <inertia ixx="-0.0271" ixy="-0.0107" ixz="-0.037" iyy="-0.0647" iyz="-0.0816" izz="-0.081"/>
    </inertial>
  </link>
  <joint name="joint_2" type="revolute">
    <parent link="link_1"/>
    <child link="link_2"/>
    <origin rpy="-3.141592653589793 3.141592653589793 -1.5707963267948966" xyz="0 0 0.0503"/>
    <axis xyz="0 0 1"/>
    <limit effort="300" lower="-2.09439510239" upper="2.09439510239" velocity="10"/>
    <dynamics damping="0.5"/>
  </joint>
  <link name="link_3">
    <inertial>
      <origin rpy="0 0 0" xyz="0.0331 0.0721 0.0142"/>
      <mass value="5"/>
      <inertia ixx="0.0736" ixy="-0.0458" ixz="0.0564" iyy="0.0136" iyz="-0.0263" izz="0.0505"/>
    </inertial>
  </link>
  <joint name="joint_3" type="revolute">
    <parent link="link_2"/>
    <child link="link_3"/>
    <origin rpy="3.141592653589793 0 -3.141592653589793" xyz="0 0 0.0791"/>
    <axis xyz="0 0 1"/>
    <limit effort="300" lower="-2.09439510239" upper="2.09439510239" velocity="10"/>
    <dynamics damping="0.5"/>
  </joint>
  <link name="link_4">
    <inertial>
      <origin rpy="0 0 0" xyz="0.0548 0.0128 0.0348"/>
      <mass value="5"/>
      <inertia ixx="-0.068" ixy="-0.0923" ixz="-0.0986" iyy="0.0822" iyz="-0.0335" izz="-0.0731"/>
    </inertial>
  </link>
  <joint name="joint_4" type="revolute">
    <parent link="link_3"/>
    <child link="link_4"/>
    <origin rpy="0 3.141592653589793 -3.141592653589793" xyz="0 0 0.1868"/>
    <axis xyz="0 0 1"/>
    <limit effort="300" lower="-2.09439510239" upper="2.09439510239" velocity="10"/>
    <dynamics damping="0.5"/>
  </joint>
  <link name="link_5">
    <inertial>
      <origin rpy="0 0 0" xyz="0.0544 0.0001 0.0164"/>
      <mass value="5"/>
      <inertia ixx="0.012" ixy="-0.075" ixz="0.0524" iyy="-0.052" iyz="-0.0164" izz="-0.0384"/>
    </inertial>
  </link>
  <joint name="joint_5" type="revolute">
    <parent link="link_4"/>
    <child link="link_5"/>
    <origin rpy="-1.5707963267948966 0 -3.141592653589793" xyz="0 0 0.074"/>
    <axis xyz="0 0 1"/>
    <limit effort="300" lower="-2.09439510239" upper="2.09439510239" velocity="10"/>
    <dynamics damping="0.5"/>
  </joint>
  <link name="link_6">
    <inertial>
      <origin rpy="0 0 0" xyz="0.0384 0.0152 0.0984"/>
      <mass value="5"/>
      <inertia ixx="0.0144" ixy="0.0006" ixz="0.0626" iyy="0.0228" iyz="0.0108" izz="-0.089"/>
    </inertial>
  </link>
  <joint name="joint_6" type="revolute">
    <parent link="link_5"/>
    <child link="link_6"/>
    <origin rpy="0 1.5707963267948966 3.141592653589793" xyz="0 0 0.1751"/>
    <axis xyz="0 0 1"/>
    <limit effort="300" lower="-2.09439510239" upper="2.09439510239" velocity="10"/>
    <dynamics damping="0.5"/>
  </joint>
  <link name="link_7">
    <inertial>
      <origin rpy="0 0 0" xyz="0.0982 0.0947 0.0047"/>
      <mass value="5"/>
      <inertia ixx="-0.008" ixy="-0.0538" ixz="0.0889" iyy="0.0962" iyz="0.0695" izz="-0.0459"/>
    </inertial>
  </link>
  <joint name="joint_7" type="revolute">
    <parent link="link_6"/>
    <child link="link_7"/>
    <origin rpy="-3.141592653589793 0 -3.141592653589793" xyz="0 0 0.1131"/>
    <axis xyz="0 0 1"/>
    <limit effort="300" lower="-2.09439510239" upper="2.09439510239" velocity="10"/>
    <dynamics damping="0.5"/>
  </joint>
  <link name="link_8">
    <inertial>
      <origin rpy="0 0 0" xyz="0.0135 0.0513 0.07"/>
      <mass value="5"/>
      <inertia ixx="0.0349" ixy="-0.0406" ixz="-0.0429" iyy="0.008" iyz="0.0588" izz="-0.0106"/>
    </inertial>
  </link>
  <joint name="joint_8" type="revolute">
    <parent link="world"/>
    <child link="link_8"/>
    <origin rpy="-3.141592653589793 -1.5707963267948966 1.5707963267948966" xyz="0 0 0.0176"/>
    <axis xyz="0 0 1"/>
    <limit effort="300" lower="-2.09439510239" upper="2.09439510239" velocity="10"/>
    <dynamics damping="0.5"/>
  </joint>
  <link name="link_9">
    <inertial>
      <origin rpy="0 0 0" xyz="0.09 0.083 0.036"/>
      <mass value="5"/>
      <inertia ixx="-0.0051" ixy="-0.0055" ixz="0.0701" iyy="0.0962" iyz="-0.0309" izz="-0.0496"/>
    </inertial>
  </link>
  <joint name="joint_9" type="revolute">
    <parent link="link_8"/>
    <child link="link_9"/>
    <origin rpy="-3.141592653589793 -3.141592653589793 3.141592653589793" xyz="0 0 0.0212"/>
    <axis xyz="0 0 1"/>
    <limit effort="300" lower="-2.09439510239" upper="2.09439510239" velocity="10"/>
    <dynamics damping="0.5"/>
  </joint>
  <link name="link_10">
    <inertial>
      <origin rpy="0 0 0" xyz="0.0284 0.0233 0.0874"/>
      <mass value="5"/>
      <inertia ixx="0.0317" ixy="-0.0116" ixz="0.0415" iyy="0.0339" iyz="0.0522" izz="0.0766"/>
    </inertial>
  </link>
  <joint name="joint_10" type="revolute">
    <parent link="link_9"/>
    <child link="link_10"/>
    <origin rpy="3.141592653589793 1.5707963267948966 -3.141592653589793" xyz="0 0 0.0764"/>
    <axis xyz="0 0 1"/>
    <limit effort="300" lower="-2.09439510239" upper="2.09439510239" velocity="10"/>
    <dynamics damping="0.5"/>
  </joint>
  <link name="link_11">
    <inertial>
      <origin rpy="0 0 0" xyz="0.0086 0.0491 0.0784"/>
      <mass value="5"/>
      <inertia ixx="-0.0179" ixy="-0.063" ixz="0.035" iyy="0.0098" iyz="-0.0498" izz="0.0192"/>
    </inertial>
  </link>
  <joint name="joint_11" type="revolute">
    <parent link="link_10"/>
    <child link="link_11"/>
    <origin rpy="1.5707963267948966 0 -3.141592653589793" xyz="0 0 0.0844"/>
    <axis xyz="0 0 1"/>
    <limit effort="300" lower="-2.09439510239" upper="2.09439510239" velocity="10"/>
    <dynamics damping="0.5"/>
  </joint>
  <link name="link_12">
    <inertial>
      <origin rpy="0 0 0" xyz="0.053 0.0893 0.0757"/>
      <mass value="5"/>
      <inertia ixx="0.042" ixy="-0.0028" ixz="0.0359" iyy="0.0577" iyz="0.045" izz="-0.089"/>
    </inertial>
  </link>
  <joint name="joint_12" type="revolute">
    <parent link="link_11"/>
    <child link="link_12"/>
    <origin rpy="-1.5707963267948966 -3.141592653589793 0" xyz="0 0 0.0453"/>
    <axis xyz="0 0 1"/>
    <limit effort="300" lower="-2.09439510239" upper="2.09439510239" velocity="10"/>
    <dynamics damping="0.5"/>
  </joint>
  <link name="link_13">
    <inertial>
      <origin rpy="0 0 0" xyz="0.0891 0.0727 0.0871"/>
      <mass value="5"/>
      <inertia ixx="0.099" ixy="-0.0984" ixz="0.0803" iyy="0.0331" iyz="-0.026" izz="-0.0071"/>
    </inertial>
  </link>
  <joint name="joint_13" type="revolute">
    <parent link="world"/>
    <child link="link_13"/>
    <origin rpy="0 -1.5707963267948966 -1.5707963267948966" xyz="0 0 0.1602"/>
    <axis xyz="0 0 1"/>
    <limit effort="300" lower="-2.09439510239" upper="2.09439510239" velocity="10"/>
    <dynamics damping="0.5"/>
  </joint>
  <link name="link_14">
    <inertial>
      <origin rpy="0 0 0" xyz="0.0458 0.0386 0.0997"/>
      <mass value="5"/>
      <inertia ixx="0.0007" ixy="-0.0587" ixz="-0.0394" iyy="0.0869" iyz="-0.0168" izz="-0.0058"/>
    </inertial>
  </link>
  <joint name="joint_14" type="revolute">
    <parent link="link_13"/>
    <child link="link_14"/>
    <origin rpy="-1.5707963267948966 -3.141592653589793 -1.5707963267948966" xyz="0 0 0.1849"/>
    <axis xyz="0 0 1"/>
    <limit effort="300" lower="-2.09439510239" upper="2.09439510239" velocity="10"/>
    <dynamics damping="0.5"/>
  </joint>
  <link name="link_15">
    <inertial>
      <origin rpy="0 0 0" xyz="0.088 0.061 0.0685"/>
      <mass value="5"/>
      <inertia ixx="-0.0744" ixy="0.0791" ixz="0.0049" iyy="0.0224" iyz="-0.0288" izz="0.0389"/>
    </inertial>
  </link>
  <joint name="joint_15" type="revolute">
    <parent link="link_14"/>
    <child link="link_15"/>
    <origin rpy="0 3.141592653589793 3.141592653589793" xyz="0 0 0.1883"/>
    <axis xyz="0 0 1"/>
    <limit effort="300" lower="-2.09439510239" upper="2.09439510239" velocity="10"/>
    <dynamics damping="0.5"/>
  </joint>
  <link name="link_16">
    <inertial>
      <origin rpy="0 0 0" xyz="0.0962 0.0025 0.0493"/>
      <mass value="5"/>
      <inertia ixx="0.07" ixy="0.0024" ixz="-0.0825" iyy="0.0937" iyz="-0.0974" izz="0.0591"/>
    </inertial>
  </link>
  <joint name="joint_16" type="revolute">
    <parent link="link_15"/>
    <child link="link_16"/>
    <origin rpy="0 -1.5707963267948966 -3.141592653589793" xyz="0 0 0.0733"/>
    <axis xyz="0 0 1"/>
    <limit effort="300" lower="-2.09439510239" upper="2.09439510239" velocity="10"/>
    <dynamics damping="0.5"/>
  </joint>
  <link name="link_17">
    <inertial>
      <origin rpy="0 0 0" xyz="0.0466 0.0626 0.0584"/>
      <mass value="5"/>
      <inertia ixx="0.0316" ixy="-0.0976" ixz="-0.0463" iyy="-0.0896" iyz="-0.1" izz="0.0559"/>
    </inertial>
  </link>
  <joint name="joint_17" type="revolute">
    <parent link="link_16"/>
    <child link="link_17"/>
    <origin rpy="-1.5707963267948966 3.141592653589793 -1.5707963267948966" xyz="0 0 0.0715"/>
    <axis xyz="0 0 1"/>
    <limit effort="300" lower="-2.09439510239" upper="2.09439510239" velocity="10"/>
    <dynamics damping="0.5"/>
  </joint>
  <link name="link_18">
    <inertial>
      <origin rpy="0 0 0" xyz="0.0281 0.0522 0.0072"/>
      <mass value="5"/>
      <inertia ixx="0.0162" ixy="-0.0157" ixz="-0.0585" iyy="0.083" iyz="-0.0971" izz="0.0852"/>
    </inertial>
  </link>
  <joint name="joint_18" type="revolute">
    <parent link="world"/>
    <child link="link_18"/>
    <origin rpy="3.141592653589793 -3.141592653589793 1.5707963267948966" xyz="0 0 0.0339"/>
    <axis xyz="0 0 1"/>
    <limit effort="300" lower="-2.09439510239" upper="2.09439510239" velocity="10"/>
    <dynamics damping="0.5"/>
  </joint>
  <link name="link_19">
    <inertial>
      <origin rpy="0 0 0" xyz="0.0914 0.0332 0.0594"/>
      <mass value="5"/>
      <inertia ixx="0.026" ixy="-0.0903" ixz="-0.0813" iyy="0.0365" iyz="0.0584" izz="-0.0623"/>
    </inertial>
  </link>
  <joint name="joint_19" type="revolute">
    <parent link="link_18"/>
    <child link="link_19"/>
    <origin rpy="3.141592653589793 1.5707963267948966 -1.5707963267948966" xyz="0 0 0.0066"/>
    <axis xyz="0 0 1"/>
    <limit effort="300" lower="-2.09439510239" upper="2.09439510239" velocity="10"/>
    <dynamics damping="0.5"/>
  </joint>
  <link name="link_20">
    <inertial>
      <origin rpy="0 0 0" xyz="0.0312 0.0984 0.0071"/>
      <mass value="5"/>
      <inertia ixx="-0.0813" ixy="0.0971" ixz="0.0077" iyy="0.0159" iyz="-0.0545" izz="-0.0533"/>
    </inertial>
  </link>
  <joint name="joint_20" type="revolute">
    <parent link="link_19"/>
    <child link="link_20"/>
    <origin rpy="-1.5707963267948966 -3.141592653589793 3.141592653589793" xyz="0 0 0.0695"/>
    <axis xyz="0 0 1"/>
    <limit effort="300" lower="-2.09439510239" upper="2.09439510239" velocity="10"/>
    <dynamics damping="0.5"/>
  </joint>
  <link name="link_21">
    <inertial>
      <origin rpy="0 0 0" xyz="0.0497 0.0537 0.064"/>
      <mass value="5"/>
      <inertia ixx="-0.015" ixy="0.0755" ixz="-0.0234" iyy="0.0214" iyz="-0.0892" izz="-0.0298"/>
    </inertial>
  </link>
  <joint name="joint_21" type="revolute">
    <parent link="link_20"/>
    <child link="link_21"/>
    <origin rpy="1.5707963267948966 0 -3.141592653589793" xyz="0 0 0.1928"/>
    <axis xyz="0 0 1"/>
    <limit effort="300" lower="-2.09439510239" upper="2.09439510239" velocity="10"/>
    <dynamics damping="0.5"/>
  </joint>
  <link name="link_22">
    <inertial>
      <origin rpy="0 0 0" xyz="0.0432 0.0607 0.0093"/>
      <mass value="5"/>
      <inertia ixx="-0.0009" ixy="0.0584" ixz="-0.0369" iyy="0.0951" iyz="-0.0322" izz="-0.0089"/>
    </inertial>
  </link>
  <joint name="joint_22" type="revolute">
    <parent link="link_21"/>
    <child link="link_22"/>
    <origin rpy="1.5707963267948966 3.141592653589793 0" xyz="0 0 0.1915"/>
    <axis xyz="0 0 1"/>
    <limit effort="300" lower="-2.09439510239" upper="2.09439510239" velocity="10"/>
    <dynamics damping="0.5"/>
  </joint>
  <link name="link_23">
    <inertial>
      <origin rpy="0 0 0" xyz="0.0217 0.0375 0.0478"/>
      <mass value="5"/>
      <inertia ixx="0.0462" ixy="-0.0234" ixz="-0.0608" iyy="-0.0653" iyz="0.0949" izz="0.079"/>
    </inertial>
  </link>
  <joint name="joint_23" type="revolute">
    <parent link="world"/>
    <child link="link_23"/>
    <origin rpy="0 1.5707963267948966 -1.5707963267948966" xyz="0 0 0.0241"/>
    <axis xyz="0 0 1"/>
    <limit effort="300" lower="-2.09439510239" upper="2.09439510239" velocity="10"/>
    <dynamics damping="0.5"/>
  </joint>
  <link name="link_24">
    <inertial>
      <origin rpy="0 0 0" xyz="0.0882 0.043 0.0009"/>
      <mass value="5"/>
      <inertia ixx="0.0765" ixy="0.0895" ixz="0.0645" iyy="-0.0745" iyz="0.0446" izz="-0.022"/>
    </inertial>
  </link>
  <joint name="joint_24" type="revolute">
    <parent link="link_23"/>
    <child link="link_24"/>
    <origin rpy="3.141592653589793 -1.5707963267948966 -3.141592653589793" xyz="0 0 0.0497"/>
    <axis xyz="0 0 1"/>
    <limit effort="300" lower="-2.09439510239" upper="2.09439510239" velocity="10"/>
    <dynamics damping="0.5"/>
  </joint>
  <link name="link_25">
    <inertial>
      <origin rpy="0 0 0" xyz="0.0008 0.0867 0.0644"/>
      <mass value="5"/>
      <inertia ixx="-0.0176" ixy="-0.0094" ixz="0.0837" iyy="0.0547" iyz="-0.0759" izz="0.0333"/>
    </inertial>
  </link>
  <joint name="joint_25" type="revolute">
    <parent link="link_24"/>
    <child link="link_25"/>
    <origin rpy="-1.5707963267948966 3.141592653589793 -3.141592653589793" xyz="0 0 0.1092"/>
    <axis xyz="0 0 1"/>
    <limit effort="300" lower="-2.09439510239" upper="2.09439510239" velocity="10"/>
    <dynamics damping="0.5"/>
  </joint>
  <link name="link_26">
    <inertial>
      <origin rpy="0 0 0" xyz="0.0645 0.0724 0.0236"/>
      <mass value="5"/>
      <inertia ixx="-0.0299" ixy="-0.0998" ixz="-0.0923" iyy="0.0949" iyz="0.088" izz="-0.0338"/>
    </inertial>
  </link>
  <joint name="joint_26" type="revolute">
    <parent link="link_25"/>
    <child link="link_26"/>
    <origin rpy="1.5707963267948966 0 3.141592653589793" xyz="0 0 0.0786"/>
    <axis xyz="0 0 1"/>
    <limit effort="300" lower="-2.09439510239" upper="2.09439510239" velocity="10"/>
    <dynamics damping="0.5"/>
  </joint>
  <link name="link_27">
    <inertial>
      <origin rpy="0 0 0" xyz="0.0729 0.0215 0.0008"/>
      <mass value="5"/>
      <inertia ixx="-0.092" ixy="0.0075" ixz="0.0192" iyy="-0.0166" iyz="-0.0515" izz="-0.0115"/>
    </inertial>
  </link>
  <joint name="joint_27" type="revolute">
    <parent link="link_26"/>
    <child link="link_27"/>
    <origin rpy="-1.5707963267948966 0 0" xyz="0 0 0.021"/>
    <axis xyz="0 0 1"/>
    <limit effort="300" lower="-2.09439510239" upper="2.09439510239" velocity="10"/>
    <dynamics damping="0.5"/>
  </joint>
</robot>
